Workbook

Sheet DISEÑO
B2: CONEXIÓN DE MOMENTO PRECALIFICADA — BOLTED FLANGE PLATE (BFP)
B3: AISC 358-16 Cap. 7 · AISC 341-16 (SMF / IMF) · AISC 360-16 (J3, J4, J10, E) · Diseño por capacidad LRFD · Unidades: Tonf, Tonf·m, mm, kgf/cm²
B4: Celdas de ingreso: | C4: valor | D4: Calculado: | E4: valor | G4: Estados: VERDE ≤ límite · AMARILLO entre límite y 1.00 · ROJO > 1.00 (ratio = demanda / capacidad, o requerido / provisto)
B6: DATOS GENERALES | G6: PLANTA — ALA SUPERIOR (--- rótula) | J6: ELEVACIÓN | N6: VERIFICACIONES — AISC 358-16 Cap. 7
B7: Proyecto | C7: Edificio — ejemplo | N7: =IF(MAX(R12:R55)>1,"✖ NO CUMPLE — ratio máx. "&TEXT(MAX(R12:R55),"0.00"),IF(MAX(R12:R55)>lim_verde,"▲ CUMPLE AL LÍMITE — ratio máx. "&TEXT(MAX(R12:R55),"0.00"),"✔ CUMPLE — ratio máx. "&TEXT(MAX(R12:R55),"0.00"))) -> ▲ CUMPLE AL LÍMITE — ratio máx. 0.95
B8: Elemento / nudo | C8: Pórtico eje B, nivel 2
B9: Límite verde / amarillo (ratio) | C9: 0.9
B10: Sistema resistente | C10: IMF | N10: Verificación | O10: Referencia | P10: Demanda / req. | Q10: Capacidad / prov. | R10: Unidad | S10: Ratio | T10: Estado
B11: 1. VIGA | N11: PRECALIFICACIÓN (AISC 358-16 §7.3 · AISC 341-16)
B12: Perfil (catálogo o ARMADO) | C12: VK400X180X6X12 | E12: Armado (mm) | N12: Peralte de viga ≤ W36 (914 mm) | O12: 358 §7.3.1(2) | P12: =vg_d_mm -> 400 | Q12: =914 -> 914 | R12: =(vg_d_mm)/MAX(914,0.000000001) -> 0.43763676 | S12: mm | T12: =IF(ISNUMBER(R12),IF(R12>1,"NO CUMPLE",IF(R12>lim_verde,"AL LÍMITE","CUMPLE")),"N/A") -> CUMPLE
B13: Peralte d | C13: =IF(vg_perfil="ARMADO (flejes soldados)",E13,INDEX(CATALOGOS!$B$5:$B$40,MATCH(vg_perfil,CATALOGOS!$A$5:$A$40,0))) -> 400 | D13: mm | E13: 400 | N13: Peso de viga ≤ 150 lb/ft (223 kg/m) | O13: 358 §7.3.1(3) | P13: =b_w -> 51.6216 | Q13: =223 -> 223 | R13: =(b_w)/MAX(223,0.000000001) -> 0.231487 | S13: kg/m | T13: =IF(ISNUMBER(R13),IF(R13>1,"NO CUMPLE",IF(R13>lim_verde,"AL LÍMITE","CUMPLE")),"N/A") -> CUMPLE
B14: Ancho de ala bf | C14: =IF(vg_perfil="ARMADO (flejes soldados)",E14,INDEX(CATALOGOS!$C$5:$C$40,MATCH(vg_perfil,CATALOGOS!$A$5:$A$40,0))) -> 180 | D14: mm | E14: 180 | N14: Espesor de ala de viga ≤ 1 in (25.4 mm) | O14: 358 §7.3.1(4) | P14: =vg_tf_mm -> 12 | Q14: =25.4 -> 25.4 | R14: =(vg_tf_mm)/MAX(25.4,0.000000001) -> 0.47244094 | S14: mm | T14: =IF(ISNUMBER(R14),IF(R14>1,"NO CUMPLE",IF(R14>lim_verde,"AL LÍMITE","CUMPLE")),"N/A") -> CUMPLE
B15: Espesor de alma tw | C15: =IF(vg_perfil="ARMADO (flejes soldados)",E15,INDEX(CATALOGOS!$D$5:$D$40,MATCH(vg_perfil,CATALOGOS!$A$5:$A$40,0))) -> 6 | D15: mm | E15: 6 | N15: Luz libre / peralte ≥ 9 (SMF) | 7 (IMF) | O15: 358 §7.3.1(5) | P15: =q_Lreq -> 7 | Q15: =q_Lcl -> 18.75 | R15: =(q_Lreq)/MAX(q_Lcl,0.000000001) -> 0.37333333 | S15: - | T15: =IF(ISNUMBER(R15),IF(R15>1,"NO CUMPLE",IF(R15>lim_verde,"AL LÍMITE","CUMPLE")),"N/A") -> CUMPLE
B16: Espesor de ala tf | C16: =IF(vg_perfil="ARMADO (flejes soldados)",E16,INDEX(CATALOGOS!$E$5:$E$40,MATCH(vg_perfil,CATALOGOS!$A$5:$A$40,0))) -> 12 | D16: mm | E16: 12 | N16: Diámetro de perno de ala ≤ 1-1/8 in | O16: 358 §7.3 | P16: =a_dbi*25.4 -> 22.225 | Q16: =28.575 -> 28.575 | R16: =(a_dbi*25.4)/MAX(28.575,0.000000001) -> 0.77777778 | S16: mm | T16: =IF(ISNUMBER(R16),IF(R16>1,"NO CUMPLE",IF(R16>lim_verde,"AL LÍMITE","CUMPLE")),"N/A") -> CUMPLE
B17: Acero | C17: A572 Gr50 (plancha) | N17: Pernos de ala A490 / F2280, roscas excluidas | O17: 358 §7.5 | P17: =1 -> 1 | Q17: =q_pn -> 1 | R17: =IF(q_pn=1,0,1.5) -> 0 | S17: - | T17: =IF(ISNUMBER(R17),IF(R17>1,"NO CUMPLE",IF(R17>lim_verde,"AL LÍMITE","CUMPLE")),"N/A") -> CUMPLE
B18: Fy / Fu | C18: =INDEX(CATALOGOS!$N$5:$N$12,MATCH(vg_acero,CATALOGOS!$M$5:$M$12,0)) -> 3515 | D18: kgf/cm² | E18: =INDEX(CATALOGOS!$O$5:$O$12,MATCH(vg_acero,CATALOGOS!$M$5:$M$12,0)) -> 4570 | N18: Esbeltez ala de viga bf/2tf | O18: 341 Tabla D1.1 | P18: =q_bb -> 7.5 | Q18: =q_bbl -> 9.1878959 | R18: =(q_bb)/MAX(q_bbl,0.000000001) -> 0.81629135 | S18: - | T18: =IF(ISNUMBER(R18),IF(R18>1,"NO CUMPLE",IF(R18>lim_verde,"AL LÍMITE","CUMPLE")),"N/A") -> CUMPLE
B19: Ry / Rt | C19: =INDEX(CATALOGOS!$P$5:$P$12,MATCH(vg_acero,CATALOGOS!$M$5:$M$12,0)) -> 1.1 | E19: =INDEX(CATALOGOS!$Q$5:$Q$12,MATCH(vg_acero,CATALOGOS!$M$5:$M$12,0)) -> 1.2 | N19: Esbeltez alma de viga h/tw | O19: 341 Tabla D1.1 | P19: =q_bw -> 62.666667 | Q19: =q_bwl -> 90.96017 | R19: =(q_bw)/MAX(q_bwl,0.000000001) -> 0.68894624 | S19: - | T19: =IF(ISNUMBER(R19),IF(R19>1,"NO CUMPLE",IF(R19>lim_verde,"AL LÍMITE","CUMPLE")),"N/A") -> CUMPLE
B20: Luz entre ejes de columnas L | C20: 8 | D20: m | N20: Esbeltez ala de columna bf/2tf | O20: 341 Tabla D1.1 | P20: =q_cb -> 8.3333333 | Q20: =q_cbl -> 9.1878959 | R20: =(q_cb)/MAX(q_cbl,0.000000001) -> 0.90699039 | S20: - | T20: =IF(ISNUMBER(R20),IF(R20>1,"NO CUMPLE",IF(R20>lim_verde,"AL LÍMITE","CUMPLE")),"N/A") -> AL LÍMITE
B21: Vgrav en la rótula (1.2D + f1L + 0.2S) | C21: 3 | D21: Tonf | G21: PROCEDIMIENTO AISC 358-16 §7.6 — VALORES CLAVE | N21: Esbeltez alma de columna h/tw (con Ca) | O21: 341 Tabla D1.1 | P21: =q_cw -> 47 | Q21: =q_cwl -> 76.630797 | R21: =(q_cw)/MAX(q_cwl,0.000000001) -> 0.61333043 | S21: - | T21: =IF(ISNUMBER(R21),IF(R21>1,"NO CUMPLE",IF(R21>lim_verde,"AL LÍMITE","CUMPLE")),"N/A") -> CUMPLE
B22: 2. COLUMNA (conexión al ala) | G22: Paso 1 | H22: Cpr = (Fy+Fu)/2Fy ≤ 1.2 | K22: =s_Cpr -> 1.1500711 | N22: PLACAS DE ALA Y PERNOS (AISC 358-16 §7.6)
B23: Perfil (catálogo o ARMADO) | C23: HA500X250X10X15 | E23: Armado (mm) | G23: Paso 1 | H23: Mpr = Cpr·Ry·Fy·Zx | K23: =s_Mpr/100000 -> 46.697278 | L23: Tonf·m | N23: Diámetro máximo por ruptura del ala de viga | O23: Paso 2 | P23: =a_db*10 -> 22.225 | Q23: =s_dbmax*10 -> 23.370405 | R23: =(a_db*10)/MAX(s_dbmax*10,0.000000001) -> 0.95098909 | S23: mm | T23: =IF(ISNUMBER(R23),IF(R23>1,"NO CUMPLE",IF(R23>lim_verde,"AL LÍMITE","CUMPLE")),"N/A") -> AL LÍMITE
B24: Peralte d | C24: =IF(co_perfil="ARMADO (flejes soldados)",E24,INDEX(CATALOGOS!$H$5:$H$40,MATCH(co_perfil,CATALOGOS!$G$5:$G$40,0))) -> 500 | D24: mm | E24: 500 | G24: Paso 2 | H24: db,máx (ruptura ala de viga) | K24: =s_dbmax*10 -> 23.370405 | L24: mm | N24: Número de pernos — Paso 5: 1.25Mpr/(φn·rn·(d+tp)) | O24: Paso 5 | P24: =s_n5 -> 6.6604455 | Q24: =n_b -> 8 | R24: =(s_n5)/MAX(n_b,0.000000001) -> 0.83255569 | S24: pernos | T24: =IF(ISNUMBER(R24),IF(R24>1,"NO CUMPLE",IF(R24>lim_verde,"AL LÍMITE","CUMPLE")),"N/A") -> CUMPLE
B25: Ancho de ala bf | C25: =IF(co_perfil="ARMADO (flejes soldados)",E25,INDEX(CATALOGOS!$I$5:$I$40,MATCH(co_perfil,CATALOGOS!$G$5:$G$40,0))) -> 250 | D25: mm | E25: 250 | G25: Paso 4 | H25: rn por perno (corte / aplast. ala / placa) | K25: =s_rn/1000 -> 22.912204 | L25: Tonf | N25: Corte en pernos — Paso 10: Ff ≤ φn·n·rn | O25: Pasos 4 y 10 | P25: =s_Ff/1000 -> 121.3399 | Q25: =0.9*n_b*s_rn/1000 -> 164.96787 | R25: =(s_Ff/1000)/MAX(0.9*n_b*s_rn/1000,0.000000001) -> 0.73553655 | S25: Tonf | T25: =IF(ISNUMBER(R25),IF(R25>1,"NO CUMPLE",IF(R25>lim_verde,"AL LÍMITE","CUMPLE")),"N/A") -> CUMPLE
B26: Espesor de alma tw | C26: =IF(co_perfil="ARMADO (flejes soldados)",E26,INDEX(CATALOGOS!$J$5:$J$40,MATCH(co_perfil,CATALOGOS!$G$5:$G$40,0))) -> 10 | D26: mm | E26: 10 | G26: Paso 5 | H26: n requerido (1.25·Mpr) | K26: =s_n5 -> 6.6604455 | L26: pernos | N26: Placa — fluencia en tracción | O26: Paso 11 (φd = 1.0) | P26: =s_Ff/1000 -> 121.3399 | Q26: =r_ty/1000 -> 175.75 | R26: =(s_Ff/1000)/MAX(r_ty/1000,0.000000001) -> 0.69041192 | S26: Tonf | T26: =IF(ISNUMBER(R26),IF(R26>1,"NO CUMPLE",IF(R26>lim_verde,"AL LÍMITE","CUMPLE")),"N/A") -> CUMPLE
B27: Espesor de ala tf | C27: =IF(co_perfil="ARMADO (flejes soldados)",E27,INDEX(CATALOGOS!$K$5:$K$40,MATCH(co_perfil,CATALOGOS!$G$5:$G$40,0))) -> 15 | D27: mm | E27: 15 | G27: Paso 6 | H27: Sh = S1 + s(n/2 − 1) | K27: =s_Sh -> 29.5 | L27: cm | N27: Placa — ruptura en tracción | O27: Paso 12 · J4.1(b) | P27: =s_Ff/1000 -> 121.3399 | Q27: =r_tr/1000 -> 153.4149 | R27: =(s_Ff/1000)/MAX(r_tr/1000,0.000000001) -> 0.7909264 | S27: Tonf | T27: =IF(ISNUMBER(R27),IF(R27>1,"NO CUMPLE",IF(R27>lim_verde,"AL LÍMITE","CUMPLE")),"N/A") -> CUMPLE
B28: Acero | C28: A572 Gr50 (plancha) | G28: — | H28: Lh = L − dc − 2Sh | K28: =s_Lh -> 691 | L28: cm | N28: Placa — bloque de cortante | O28: Paso 13 · J4.3 | P28: =s_Ff/1000 -> 121.3399 | Q28: =r_bsp/1000 -> 289.88424 | R28: =(s_Ff/1000)/MAX(r_bsp/1000,0.000000001) -> 0.41858052 | S28: Tonf | T28: =IF(ISNUMBER(R28),IF(R28>1,"NO CUMPLE",IF(R28>lim_verde,"AL LÍMITE","CUMPLE")),"N/A") -> CUMPLE
B29: Fy / Fu | C29: =INDEX(CATALOGOS!$N$5:$N$12,MATCH(co_acero,CATALOGOS!$M$5:$M$12,0)) -> 3515 | D29: kgf/cm² | E29: =INDEX(CATALOGOS!$O$5:$O$12,MATCH(co_acero,CATALOGOS!$M$5:$M$12,0)) -> 4570 | G29: Paso 7 | H29: Vh = 2Mpr/Lh + Vgrav | K29: =s_Vh/1000 -> 16.515855 | L29: Tonf | N29: Ala de viga — bloque de cortante | O29: Paso 13 · J4.3 | P29: =s_Ff/1000 -> 121.3399 | Q29: =r_bsb/1000 -> 135.19596 | R29: =(s_Ff/1000)/MAX(r_bsb/1000,0.000000001) -> 0.89751128 | S29: Tonf | T29: =IF(ISNUMBER(R29),IF(R29>1,"NO CUMPLE",IF(R29>lim_verde,"AL LÍMITE","CUMPLE")),"N/A") -> CUMPLE
B30: Ry / Rt | C30: =INDEX(CATALOGOS!$P$5:$P$12,MATCH(co_acero,CATALOGOS!$M$5:$M$12,0)) -> 1.1 | E30: =INDEX(CATALOGOS!$Q$5:$Q$12,MATCH(co_acero,CATALOGOS!$M$5:$M$12,0)) -> 1.2 | G30: Paso 8 | H30: Mf = Mpr + Vh·Sh | K30: =s_Mf/100000 -> 51.569455 | L30: Tonf·m | N30: Placa — pandeo en compresión (K = 0.65, L = S1) | O30: Paso 14 · J4.4 / E3 | P30: =s_Ff/1000 -> 121.3399 | Q30: =r_cb/1000 -> 158.175 | R30: =(s_Ff/1000)/MAX(r_cb/1000,0.000000001) -> 0.76712436 | S30: Tonf | T30: =IF(ISNUMBER(R30),IF(R30>1,"NO CUMPLE",IF(R30>lim_verde,"AL LÍMITE","CUMPLE")),"N/A") -> CUMPLE
B31: Filete / radio alma–ala (para k) | C31: 6 | D31: mm | G31: Paso 9 | H31: Ff = Mf/(d + tp) | K31: =s_Ff/1000 -> 121.3399 | L31: Tonf | N31: Desgarre de pernos en placa | O31: J3.10 | P31: =s_Ff/1000 -> 121.3399 | Q31: =r_tp/1000 -> 410.74989 | R31: =(s_Ff/1000)/MAX(r_tp/1000,0.000000001) -> 0.29541066 | S31: Tonf | T31: =IF(ISNUMBER(R31),IF(R31>1,"NO CUMPLE",IF(R31>lim_verde,"AL LÍMITE","CUMPLE")),"N/A") -> CUMPLE
B32: Tope de columna → placa superior | C32: 1000 | D32: mm | G32: Paso 10 | H32: n requerido (Ff) | K32: =s_n10 -> 5.8842924 | L32: pernos | N32: Desgarre de pernos en ala de viga | O32: J3.10 | P32: =s_Ff/1000 -> 121.3399 | Q32: =r_tb/1000 -> 209.00539 | R32: =(s_Ff/1000)/MAX(r_tb/1000,0.000000001) -> 0.5805587 | S32: Tonf | T32: =IF(ISNUMBER(R32),IF(R32>1,"NO CUMPLE",IF(R32>lim_verde,"AL LÍMITE","CUMPLE")),"N/A") -> CUMPLE
B33: Vigas a ambos lados | C33: No | G33: §7.4 | H33: Zona protegida desde cara de columna | K33: =s_PZ -> 69.5 | L33: cm | N33: CONEXIÓN DE ALMA (Paso 15: Vu = 2Mpr/Lh + Vgrav)
B34: Pu de la columna (compresión) | C34: 20 | D34: Tonf | G34: — | H34: Largo de placa de ala Lp | K34: =p_Lp -> 34 | L34: cm | N34: Pernos de alma a corte | O34: J3.6 | P34: =s_Vu/1000 -> 16.515855 | Q34: =w_Rb/1000 -> 32.466965 | R34: =(s_Vu/1000)/MAX(w_Rb/1000,0.000000001) -> 0.50869722 | S34: Tonf | T34: =IF(ISNUMBER(R34),IF(R34>1,"NO CUMPLE",IF(R34>lim_verde,"AL LÍMITE","CUMPLE")),"N/A") -> CUMPLE
B35: Rigidizadores de continuidad | C35: Sí | G35: 16 | H35: Fuerza para rigidizadores Fsu | K35: =j_Fsu/1000 -> 76.853177 | L35: Tonf | N35: Aplastamiento / desgarre (alma o placa) | O35: J3.10 | P35: =s_Vu/1000 -> 16.515855 | Q35: =w_Rbr/1000 -> 35.531693 | R35: =(s_Vu/1000)/MAX(w_Rbr/1000,0.000000001) -> 0.46482037 | S35: Tonf | T35: =IF(ISNUMBER(R35),IF(R35>1,"NO CUMPLE",IF(R35>lim_verde,"AL LÍMITE","CUMPLE")),"N/A") -> CUMPLE
B36: Rigid. continuidad: espesor | C36: 15 | D36: mm | N36: Placa de cortante — fluencia | O36: J4.2(a) | P36: =s_Vu/1000 -> 16.515855 | Q36: =w_Ry/1000 -> 46.299 | R36: =(s_Vu/1000)/MAX(w_Ry/1000,0.000000001) -> 0.35672163 | S36: Tonf | T36: =IF(ISNUMBER(R36),IF(R36>1,"NO CUMPLE",IF(R36>lim_verde,"AL LÍMITE","CUMPLE")),"N/A") -> CUMPLE
B37: Rigid. continuidad: ancho (c/lado) | C37: 110 | D37: mm | G37: REQUISITOS DE DETALLE (AISC 358-16 Cap. 7) | N37: Placa de cortante — ruptura | O37: J4.2(b) | P37: =s_Vu/1000 -> 16.515855 | Q37: =w_Rr/1000 -> 39.67596 | R37: =(s_Vu/1000)/MAX(w_Rr/1000,0.000000001) -> 0.41626856 | S37: Tonf | T37: =IF(ISNUMBER(R37),IF(R37>1,"NO CUMPLE",IF(R37>lim_verde,"AL LÍMITE","CUMPLE")),"N/A") -> CUMPLE
B38: Placa de refuerzo del alma (doubler) | C38: 6 | D38: mm | G38: • Placas de ala soldadas al ala de la columna con CJP (penetración completa). | N38: Soldadura placa de cortante – columna | O38: J2.4 | P38: =s_Vu/1000 -> 16.515855 | Q38: =w_Rw/1000 -> 76.386542 | R38: =(s_Vu/1000)/MAX(w_Rw/1000,0.000000001) -> 0.2162142 | S38: Tonf | T38: =IF(ISNUMBER(R38),IF(R38>1,"NO CUMPLE",IF(R38>lim_verde,"AL LÍMITE","CUMPLE")),"N/A") -> CUMPLE
B39: 3. PLACAS DE ALA Y PERNOS | G39: • Pernos pretensados A490 / F2280, roscas excluidas; agujeros taladrados o subpunzonados y escariados. | N39: COLUMNA (Paso 16–17 · AISC 341-16 E3)
B40: Acero de placa | C40: A572 Gr50 (plancha) | G40: • Placa simple de alma soldada a la columna y apernada a la viga. | N40: Flexión local del ala | O40: J10.1 | P40: =IF(cp_usar="Sí","—",s_Ff/1000) -> — | Q40: =IF(cp_usar="Sí","—",j_Rfb/1000) -> — | R40: =IF(cp_usar="Sí","N/A",(s_Ff/1000)/MAX(j_Rfb/1000,0.000000001)) -> N/A | S40: Tonf | T40: =IF(ISNUMBER(R40),IF(R40>1,"NO CUMPLE",IF(R40>lim_verde,"AL LÍMITE","CUMPLE")),"N/A") -> N/A
B41: Fy / Fu | C41: =INDEX(CATALOGOS!$N$5:$N$12,MATCH(pl_acero,CATALOGOS!$M$5:$M$12,0)) -> 3515 | D41: kgf/cm² | E41: =INDEX(CATALOGOS!$O$5:$O$12,MATCH(pl_acero,CATALOGOS!$M$5:$M$12,0)) -> 4570 | G41: • Zona protegida: desde la cara de la columna hasta Sh + d (sin soldaduras ni anclajes). | N41: Fluencia local del alma | O41: J10.2 | P41: =IF(cp_usar="Sí","—",s_Ff/1000) -> — | Q41: =IF(cp_usar="Sí","—",j_Rwy/1000) -> — | R41: =IF(cp_usar="Sí","N/A",(s_Ff/1000)/MAX(j_Rwy/1000,0.000000001)) -> N/A | S41: Tonf | T41: =IF(ISNUMBER(R41),IF(R41>1,"NO CUMPLE",IF(R41>lim_verde,"AL LÍMITE","CUMPLE")),"N/A") -> N/A
B42: tp — espesor de placa | C42: 25 | D42: mm | G42: • Suplementos (shims) entre placa y ala ≤ 1/4 in permitidos. | N42: Aplastamiento del alma (crippling) | O42: J10.3 | P42: =IF(cp_usar="Sí","—",s_Ff/1000) -> — | Q42: =IF(cp_usar="Sí","—",j_Rwc/1000) -> — | R42: =IF(cp_usar="Sí","N/A",(s_Ff/1000)/MAX(j_Rwc/1000,0.000000001)) -> N/A | S42: Tonf | T42: =IF(ISNUMBER(R42),IF(R42>1,"NO CUMPLE",IF(R42>lim_verde,"AL LÍMITE","CUMPLE")),"N/A") -> N/A
...

Sheet CALCULO
A1: HOJA DE CÁLCULO — AISC 358-16 §7.6, procedimiento paso a paso (no editar)
A2: Unidades: kgf, cm. φd = 1.00 (estados dúctiles) y φn = 0.90 (no dúctiles) según AISC 358-16 §2.4.1; J10 y conexión de alma con φ de AISC 360-16.
A4: 0. GEOMETRÍA, MATERIALES Y PERNOS
A5: SMF | B5: 1 = SMF ; 0 = IMF | C5: - | D5: =IF(sistema="SMF",1,0) -> 0
A6: E | B6: Módulo de elasticidad | C6: kgf/cm² | D6: =2040000 -> 2040000
A7: d | B7: d (cm) | C7: cm | D7: =vg_d_mm/10 -> 40
A8: bbf | B8: bbf (cm) | C8: cm | D8: =vg_bf_mm/10 -> 18
A9: tbw | B9: tbw (cm) | C9: cm | D9: =vg_tw_mm/10 -> 0.6
A10: tbf | B10: tbf (cm) | C10: cm | D10: =vg_tf_mm/10 -> 1.2
A11: dc | B11: dc (cm) | C11: cm | D11: =co_d_mm/10 -> 50
A12: bcf | B12: bcf (cm) | C12: cm | D12: =co_bf_mm/10 -> 25
A13: tcw | B13: tcw (cm) | C13: cm | D13: =co_tw_mm/10 -> 1
A14: tcf | B14: tcf (cm) | C14: cm | D14: =co_tf_mm/10 -> 1.5
A15: A | B15: Área de viga | C15: cm² | D15: =2*b_bf*b_tf+(b_d-2*b_tf)*b_tw -> 65.76
A16: w | B16: Peso de viga = 0.785·A | C16: kg/m | D16: =0.785*b_A -> 51.6216
A17: Zx | B17: bf·tf·(d−tf) + tw·(d−2tf)²/4 | C17: cm³ | D17: =b_bf*b_tf*(b_d-b_tf)+b_tw*(b_d-2*b_tf)^2/4 -> 1050.144
A18: Ac | B18: Área de columna | C18: cm² | D18: =2*c_bf*c_tf+(c_d-2*c_tf)*c_tw -> 122
A19: Zc | B19: Módulo plástico de columna | C19: cm³ | D19: =c_bf*c_tf*(c_d-c_tf)+c_tw*(c_d-2*c_tf)^2/4 -> 2371
A20: kc | B20: tcf + filete | C20: cm | D20: =c_tf+co_kw/10 -> 2.1
A21: tp | B21: Espesor de placa de ala | C21: cm | D21: =pl_tp/10 -> 2.5
A22: bfp | B22: Ancho de placa de ala | C22: cm | D22: =pl_bfp/10 -> 20
A23: g | B23: Gramil | C23: cm | D23: =pl_g/10 -> 11
A24: S1 | B24: Cara de columna a primera fila | C24: cm | D24: =pl_S1/10 -> 7
A25: s | B25: Paso entre filas | C25: cm | D25: =pl_s/10 -> 7.5
A26: Le,p | B26: Borde extremo de placa | C26: cm | D26: =pl_Le/10 -> 4.5
A27: n/2 | B27: Filas de pernos | C27: - | D27: =n_b/2 -> 4
A28: Lp | B28: Largo de placa = S1 + s(n/2 − 1) + Le | C28: cm | D28: =p_S1+p_s*(p_nr-1)+p_Le -> 34
A29: Le,b | B29: Borde del ala de viga = S1 − holgura | C29: cm | D29: =p_S1-setback/10 -> 5.5
A30: db | B30: Diámetro perno de ala | C30: in | D30: =INDEX(CATALOGOS!$X$5:$X$10,MATCH(pn_diam,CATALOGOS!$W$5:$W$10,0)) -> 0.875
A31: db | B31: Diámetro perno de ala | C31: cm | D31: =a_dbi*2.54 -> 2.2225
A32: Ab | B32: π·db²/4 | C32: cm² | D32: =PI()*a_db^2/4 -> 3.8794791
A33: dh | B33: Agujero estándar (Tabla J3.3) | C33: cm | D33: =IF(a_dbi<1,a_dbi+1/16,a_dbi+1/8)*2.54 -> 2.38125
A34: dh,net | B34: dh + 1/16 in para área neta (B4.3b) | C34: cm | D34: =a_dh+0.15875 -> 2.54
A35: Le,min | B35: Borde mínimo (Tabla J3.4) | C35: cm | D35: =INDEX(CATALOGOS!$Y$5:$Y$10,MATCH(pn_diam,CATALOGOS!$W$5:$W$10,0))*2.54 -> 2.8575
A36: Fnv | B36: Resistencia nominal a corte | C36: kgf/cm² | D36: =INDEX(CATALOGOS!$T$5:$T$9,MATCH(pn_grado,CATALOGOS!$S$5:$S$9,0)) -> 5906
A37: 1. AISC 358-16 §7.6 — DEMANDA POR CAPACIDAD
A38: Cpr | B38: Paso 1: (Fy + Fu)/(2Fy) ≤ 1.2 | C38: - | D38: =MIN(1.2,(vg_Fy+vg_Fu)/(2*vg_Fy)) -> 1.1500711
A39: Mpr | B39: Paso 1: Cpr·Ry·Fy·Ze (Ze = Zx de la viga) | C39: kgf·cm | D39: =s_Cpr*vg_Ry*vg_Fy*b_Zx -> 4669727.8
A40: db,máx | B40: Paso 2: (bf/2)·(1 − Ry·Fy/(Rt·Fu)) − 1/8 in (ruptura del ala de viga) | C40: cm | D40: =b_bf/2*(1-vg_Ry*vg_Fy/(vg_Rt*vg_Fu))-0.3175 -> 2.3370405
A41: rn | B41: Paso 4: mín(Fnv·Ab ; 2.4·Fub·db·tf ; 2.4·Fup·db·tp) | C41: kgf | D41: =MIN(a_Fnv*a_Ab,2.4*vg_Fu*a_db*b_tf,2.4*pl_Fu*a_db*p_tp) -> 22912.204
...

Sheet CATALOGOS
A1: CATÁLOGOS — ampliables agregando filas dentro de cada rango
A3: Vigas (VK: KUBIEC; W: AISC redondeado a mm) | G3: Columnas (HA: KUBIEC; W: AISC) | M3: Aceros (kgf/cm²) — Ry, Rt: AISC 341-16 Tabla A3.1 | S3: Pernos pretensados (kgf/cm²) — AISC 360-16 Tabla J3.2 | W3: Diámetros — borde mín. AISC 360-16 Tabla J3.4 | AA3: Electrodo | AD3: Opción | AF3: Sistema | AH3: Espesores (mm) | AJ3: Pernos por ala (n, par)
A4: Viga | B4: d | C4: bf | D4: tw | E4: tf | G4: Columna | H4: d | I4: bf | J4: tw | K4: tf | M4: Acero | N4: Fy | O4: Fu | P4: Ry | Q4: Rt | S4: Grado | T4: Fnv | U4: Fub | W4: Ø | X4: db (in) | Y4: borde mín (in) | AA4: Electrodo | AB4: FEXX | AD4: Sí/No | AF4: Sistema | AH4: t | AJ4: n
A5: ARMADO (flejes soldados) | G5: ARMADO (flejes soldados) | M5: A36 (plancha) | N5: 2530 | O5: 4080 | P5: 1.3 | Q5: 1.2 | S5: A490-X (roscas excl.) | T5: 5906 | U5: 10545 | W5: 5/8" | X5: 0.625 | Y5: 0.875 | AA5: E60XX | AB5: 4220 | AD5: Sí | AF5: SMF | AH5: 0 | AJ5: 4
A6: VK300X150X4X10 | B6: 300 | C6: 150 | D6: 4 | E6: 10 | G6: HA360X180X6X12 | H6: 360 | I6: 180 | J6: 6 | K6: 12 | M6: A572 Gr50 (plancha) | N6: 3515 | O6: 4570 | P6: 1.1 | Q6: 1.2 | S6: F2280-X (roscas excl.) | T6: 5906 | U6: 10545 | W6: 3/4" | X6: 0.75 | Y6: 1 | AA6: E70XX | AB6: 4920 | AD6: No | AF6: IMF | AH6: 6 | AJ6: 6
A7: VK330X160X6X10 | B7: 330 | C7: 160 | D7: 6 | E7: 10 | G7: HA400X200X8X15 | H7: 400 | I7: 200 | J7: 8 | K7: 15 | M7: A36 (laminado) | N7: 2530 | O7: 4080 | P7: 1.5 | Q7: 1.2 | S7: A490-N (roscas incl.) | T7: 4781 | U7: 10545 | W7: 7/8" | X7: 0.875 | Y7: 1.125 | AH7: 8 | AJ7: 8
A8: VK360X180X6X10 | B8: 360 | C8: 180 | D8: 6 | E8: 10 | G8: HA440X220X8X15 | H8: 440 | I8: 220 | J8: 8 | K8: 15 | M8: A572 Gr50 (laminado) | N8: 3515 | O8: 4570 | P8: 1.1 | Q8: 1.1 | S8: A325-X (roscas excl.) | T8: 4781 | U8: 8436 | W8: 1" | X8: 1 | Y8: 1.25 | AH8: 10 | AJ8: 10
A9: VK380X180X6X10 | B9: 380 | C9: 180 | D9: 6 | E9: 10 | G9: HA480X240X8X15 | H9: 480 | I9: 240 | J9: 8 | K9: 15 | M9: A992 | N9: 3515 | O9: 4570 | P9: 1.1 | Q9: 1.1 | S9: A325-N (roscas incl.) | T9: 3797 | U9: 8436 | W9: 1-1/8" | X9: 1.125 | Y9: 1.5 | AH9: 12 | AJ9: 12
A10: VK400X180X6X10 | B10: 400 | C10: 180 | D10: 6 | E10: 10 | G10: HA500X250X10X15 | H10: 500 | I10: 250 | J10: 10 | K10: 15 | W10: 1-1/4" | X10: 1.25 | Y10: 1.625 | AH10: 15 | AJ10: 14
A11: VK400X180X6X12 | B11: 400 | C11: 180 | D11: 6 | E11: 12 | G11: HA520X260X10X15 | H11: 520 | I11: 260 | J11: 10 | K11: 15 | AH11: 16 | AJ11: 16
A12: VK420X180X6X12 | B12: 420 | C12: 180 | D12: 6 | E12: 12 | G12: HA540X270X10X15 | H12: 540 | I12: 270 | J12: 10 | K12: 15 | AH12: 19 | AJ12: 18
A13: VK440X180X6X12 | B13: 440 | C13: 180 | D13: 6 | E13: 12 | G13: W14X90 | H13: 356 | I13: 368 | J13: 11.2 | K13: 18 | AH13: 20 | AJ13: 20
A14: W14X30 | B14: 351 | C14: 171 | D14: 6.9 | E14: 9.8 | G14: W14X120 | H14: 368 | I14: 373 | J14: 15 | K14: 23.9 | AH14: 22
A15: W16X40 | B15: 407 | C15: 178 | D15: 7.7 | E15: 12.8 | G15: W14X159 | H15: 381 | I15: 395 | J15: 18.9 | K15: 30.2 | AH15: 25
A16: W18X50 | B16: 457 | C16: 190 | D16: 9 | E16: 14.5 | G16: W24X131 | H16: 622 | I16: 327 | J16: 15.4 | K16: 24.4 | AH16: 28
A17: W21X62 | B17: 533 | C17: 209 | D17: 10.2 | E17: 15.6 | AH17: 30
A18: W24X76 | B18: 608 | C18: 228 | D18: 11.2 | E18: 17.3 | AH18: 32
A19: W27X94 | B19: 684 | C19: 254 | D19: 12.4 | E19: 18.9 | AH19: 35
A20: W30X108 | B20: 758 | C20: 266 | D20: 13.8 | E20: 19.3 | AH20: 38
AH21: 40
AH22: 45
AH23: 50

Sheet DIBUJO
A1: Coordenadas de las vistas (normalizadas a ±1). No editar.
D2: Ala columna | G2: Ala viga | J2: Placa | M2: Rótula | P2: Pernos | S2: Columna | V2: Ala int. | Y2: Ala ext. | AB2: Cont. sup | AE2: Cont. inf | AH2: Ala sup | AK2: Ala inf | AN2: Placa sup | AQ2: Placa inf | AT2: Placa alma | AW2: Rótula | AZ2: Pernos ala | BC2: Pernos alma
A3: Largo de viga dibujado | B3: =MAX(p_Lp+12,s_Sh+0.6*b_d) -> 53.5
A4: x centro planta | B4: =(-c_tf+dLb)/2 -> 26 | D4: =((-c_tf)-dxp)/dSp -> -0.95238095 | E4: =(-c_bf/2)/dSp -> -0.43290043 | G4: =((dLb)-dxp)/dSp -> 0.95238095 | H4: =(b_bf/2)/dSp -> 0.31168831 | J4: =((0)-dxp)/dSp -> -0.9004329 | K4: =(-p_b/2)/dSp -> -0.34632035 | M4: =((s_Sh)-dxp)/dSp -> 0.12121212 | N4: =(-MAX(b_bf,p_b)/2-3)/dSp -> -0.45021645 | P4: =((p_S1+p_s*MIN(0,p_nr-1))-dxp)/dSp -> -0.65800866 | Q4: =(-p_g/2)/dSp -> -0.19047619 | S4: =((-c_d)-dxe)/dSe -> -0.95238095 | T4: =(-dHc)/dSe -> -0.63492063 | V4: =((-c_tf)-dxe)/dSe -> -0.059811364 | W4: =(-dHc)/dSe -> -0.63492063 | Y4: =((-c_d+c_tf)-dxe)/dSe -> -0.92477571 | Z4: =(-dHc)/dSe -> -0.63492063 | AB4: =((-c_d+c_tf)-dxe)/dSe -> -0.92477571 | AC4: =((b_d/2+p_tp/2))/dSe -> 0.3910743 | AE4: =((-c_d+c_tf)-dxe)/dSe -> -0.92477571 | AF4: =(-(b_d/2+p_tp/2))/dSe -> -0.3910743 | AH4: =((setback/10)-dxe)/dSe -> -0.0046008742 | AI4: =(b_d/2-b_tf)/dSe -> 0.34598574 | AK4: =((setback/10)-dxe)/dSe -> -0.0046008742 | AL4: =(-b_d/2)/dSe -> -0.36806993 | AN4: =((0)-dxe)/dSe -> -0.032206119 | AO4: =(b_d/2)/dSe -> 0.36806993 | AQ4: =((0)-dxe)/dSe -> -0.032206119 | AR4: =(-b_d/2-p_tp)/dSe -> -0.41407867 | AT4: =((0)-dxe)/dSe -> -0.032206119 | AU4: =(-w_Lp/2)/dSe -> -0.28065332 | AW4: =((s_Sh)-dxe)/dSe -> 0.51069703 | AX4: =(-b_d/2-p_tp-3)/dSe -> -0.46928916 | AZ4: =((p_S1+p_s*MIN(0,p_nr-1))-dxe)/dSe -> 0.096618357 | BA4: =(b_d/2+p_tp/2-b_tf/2)/dSe -> 0.38003221 | BC4: =((setback/10+w_ev/10)-dxe)/dSe -> 0.069013112 | BD4: =(-w_Lp/2+w_ev/10+w_s/10*MIN(0,w_n-1))/dSe -> -0.20703934
A5: S planta | B5: =MAX(c_tf+dLb,c_bf,p_b)/2*1.05 -> 28.875 | D5: =((-c_tf)-dxp)/dSp -> -0.95238095 | E5: =(c_bf/2)/dSp -> 0.43290043 | G5: =((setback/10)-dxp)/dSp -> -0.84848485 | H5: =(b_bf/2)/dSp -> 0.31168831 | J5: =((0)-dxp)/dSp -> -0.9004329 | K5: =(p_b/2)/dSp -> 0.34632035 | M5: =((s_Sh)-dxp)/dSp -> 0.12121212 | N5: =(MAX(b_bf,p_b)/2+3)/dSp -> 0.45021645 | P5: =((p_S1+p_s*MIN(0,p_nr-1))-dxp)/dSp -> -0.65800866 | Q5: =(p_g/2)/dSp -> 0.19047619 | S5: =((-c_d)-dxe)/dSe -> -0.95238095 | T5: =(dHc)/dSe -> 0.63492063 | V5: =((-c_tf)-dxe)/dSe -> -0.059811364 | W5: =(dHc)/dSe -> 0.63492063 | Y5: =((-c_d+c_tf)-dxe)/dSe -> -0.92477571 | Z5: =(dHc)/dSe -> 0.63492063 | AB5: =((IF(cp_usar="Sí",-c_tf,-c_d+c_tf))-dxe)/dSe -> -0.059811364 | AC5: =((b_d/2+p_tp/2))/dSe -> 0.3910743 | AE5: =((IF(cp_usar="Sí",-c_tf,-c_d+c_tf))-dxe)/dSe -> -0.059811364 | AF5: =(-(b_d/2+p_tp/2))/dSe -> -0.3910743 | AH5: =((setback/10)-dxe)/dSe -> -0.0046008742 | AI5: =(b_d/2)/dSe -> 0.36806993 | AK5: =((setback/10)-dxe)/dSe -> -0.0046008742 | AL5: =(-b_d/2+b_tf)/dSe -> -0.34598574 | AN5: =((0)-dxe)/dSe -> -0.032206119 | AO5: =(b_d/2+p_tp)/dSe -> 0.41407867 | AQ5: =((0)-dxe)/dSe -> -0.032206119 | AR5: =(-b_d/2)/dSe -> -0.36806993 | AT5: =((0)-dxe)/dSe -> -0.032206119 | AU5: =(w_Lp/2)/dSe -> 0.28065332 | AW5: =((s_Sh)-dxe)/dSe -> 0.51069703 | AX5: =(b_d/2+p_tp+3)/dSe -> 0.46928916 | AZ5: =((p_S1+p_s*MIN(0,p_nr-1))-dxe)/dSe -> 0.096618357 | BA5: =(-(b_d/2+p_tp/2-b_tf/2))/dSe -> -0.38003221 | BC5: =((setback/10+w_ev/10)-dxe)/dSe -> 0.069013112 | BD5: =(-w_Lp/2+w_ev/10+w_s/10*MIN(1,w_n-1))/dSe -> -0.069013112
A6: x centro elevación | B6: =(-c_d+dLb)/2 -> 1.75 | D6: =((0)-dxp)/dSp -> -0.9004329 | E6: =(c_bf/2)/dSp -> 0.43290043 | G6: =((setback/10)-dxp)/dSp -> -0.84848485 | H6: =(-b_bf/2)/dSp -> -0.31168831 | J6: =((p_Lp)-dxp)/dSp -> 0.27705628 | K6: =(p_b/2)/dSp -> 0.34632035 | P6: =((p_S1+p_s*MIN(1,p_nr-1))-dxp)/dSp -> -0.3982684 | Q6: =(-p_g/2)/dSp -> -0.19047619 | S6: =((0)-dxe)/dSe -> -0.032206119 | T6: =(dHc)/dSe -> 0.63492063 | AH6: =((dLb)-dxe)/dSe -> 0.95238095 | AI6: =(b_d/2)/dSe -> 0.36806993 | AK6: =((dLb)-dxe)/dSe -> 0.95238095 | AL6: =(-b_d/2+b_tf)/dSe -> -0.34598574 | AN6: =((p_Lp)-dxe)/dSe -> 0.59351277 | AO6: =(b_d/2+p_tp)/dSe -> 0.41407867 | AQ6: =((p_Lp)-dxe)/dSe -> 0.59351277 | AR6: =(-b_d/2)/dSe -> -0.36806993 | AT6: =((setback/10+2*w_ev/10)-dxe)/dSe -> 0.1426271 | AU6: =(w_Lp/2)/dSe -> 0.28065332 | AZ6: =((p_S1+p_s*MIN(1,p_nr-1))-dxe)/dSe -> 0.23464458 | BA6: =(b_d/2+p_tp/2-b_tf/2)/dSe -> 0.38003221 | BC6: =((setback/10+w_ev/10)-dxe)/dSe -> 0.069013112 | BD6: =(-w_Lp/2+w_ev/10+w_s/10*MIN(2,w_n-1))/dSe -> 0.069013112
A7: Hc/2 | B7: =b_d/2+p_tp+12 -> 34.5 | D7: =((0)-dxp)/dSp -> -0.9004329 | E7: =(-c_bf/2)/dSp -> -0.43290043 | G7: =((dLb)-dxp)/dSp -> 0.95238095 | H7: =(-b_bf/2)/dSp -> -0.31168831 | J7: =((p_Lp)-dxp)/dSp -> 0.27705628 | K7: =(-p_b/2)/dSp -> -0.34632035 | P7: =((p_S1+p_s*MIN(1,p_nr-1))-dxp)/dSp -> -0.3982684 | Q7: =(p_g/2)/dSp -> 0.19047619 | S7: =((0)-dxe)/dSe -> -0.032206119 | T7: =(-dHc)/dSe -> -0.63492063 | AH7: =((dLb)-dxe)/dSe -> 0.95238095 | AI7: =(b_d/2-b_tf)/dSe -> 0.34598574 | AK7: =((dLb)-dxe)/dSe -> 0.95238095 | AL7: =(-b_d/2)/dSe -> -0.36806993 | AN7: =((p_Lp)-dxe)/dSe -> 0.59351277 | AO7: =(b_d/2)/dSe -> 0.36806993 | AQ7: =((p_Lp)-dxe)/dSe -> 0.59351277 | AR7: =(-b_d/2-p_tp)/dSe -> -0.41407867 | AT7: =((setback/10+2*w_ev/10)-dxe)/dSe -> 0.1426271 | AU7: =(-w_Lp/2)/dSe -> -0.28065332 | AZ7: =((p_S1+p_s*MIN(1,p_nr-1))-dxe)/dSe -> 0.23464458 | BA7: =(-(b_d/2+p_tp/2-b_tf/2))/dSe -> -0.38003221 | BC7: =((setback/10+w_ev/10)-dxe)/dSe -> 0.069013112 | BD7: =(-w_Lp/2+w_ev/10+w_s/10*MIN(3,w_n-1))/dSe -> 0.20703934
A8: S elevación | B8: =MAX(c_d+dLb,2*dHc)/2*1.05 -> 54.3375 | D8: =((-c_tf)-dxp)/dSp -> -0.95238095 | E8: =(-c_bf/2)/dSp -> -0.43290043 | J8: =((0)-dxp)/dSp -> -0.9004329 | K8: =(-p_b/2)/dSp -> -0.34632035 | P8: =((p_S1+p_s*MIN(2,p_nr-1))-dxp)/dSp -> -0.13852814 | Q8: =(-p_g/2)/dSp -> -0.19047619 | S8: =((-c_d)-dxe)/dSe -> -0.95238095 | T8: =(-dHc)/dSe -> -0.63492063 | AH8: =((setback/10)-dxe)/dSe -> -0.0046008742 | AI8: =(b_d/2-b_tf)/dSe -> 0.34598574 | AK8: =((setback/10)-dxe)/dSe -> -0.0046008742 | AL8: =(-b_d/2)/dSe -> -0.36806993 | AN8: =((0)-dxe)/dSe -> -0.032206119 | AO8: =(b_d/2)/dSe -> 0.36806993 | AQ8: =((0)-dxe)/dSe -> -0.032206119 | AR8: =(-b_d/2-p_tp)/dSe -> -0.41407867 | AT8: =((0)-dxe)/dSe -> -0.032206119 | AU8: =(-w_Lp/2)/dSe -> -0.28065332 | AZ8: =((p_S1+p_s*MIN(2,p_nr-1))-dxe)/dSe -> 0.37267081 | BA8: =(b_d/2+p_tp/2-b_tf/2)/dSe -> 0.38003221 | BC8: =((setback/10+w_ev/10)-dxe)/dSe -> 0.069013112 | BD8: =(-w_Lp/2+w_ev/10+w_s/10*MIN(4,w_n-1))/dSe -> 0.20703934
P9: =((p_S1+p_s*MIN(2,p_nr-1))-dxp)/dSp -> -0.13852814 | Q9: =(p_g/2)/dSp -> 0.19047619 | AZ9: =((p_S1+p_s*MIN(2,p_nr-1))-dxe)/dSe -> 0.37267081 | BA9: =(-(b_d/2+p_tp/2-b_tf/2))/dSe -> -0.38003221 | BC9: =((setback/10+w_ev/10)-dxe)/dSe -> 0.069013112 | BD9: =(-w_Lp/2+w_ev/10+w_s/10*MIN(5,w_n-1))/dSe -> 0.20703934
P10: =((p_S1+p_s*MIN(3,p_nr-1))-dxp)/dSp -> 0.12121212 | Q10: =(-p_g/2)/dSp -> -0.19047619 | AZ10: =((p_S1+p_s*MIN(3,p_nr-1))-dxe)/dSe -> 0.51069703 | BA10: =(b_d/2+p_tp/2-b_tf/2)/dSe -> 0.38003221 | BC10: =((setback/10+w_ev/10)-dxe)/dSe -> 0.069013112 | BD10: =(-w_Lp/2+w_ev/10+w_s/10*MIN(6,w_n-1))/dSe -> 0.20703934
P11: =((p_S1+p_s*MIN(3,p_nr-1))-dxp)/dSp -> 0.12121212 | Q11: =(p_g/2)/dSp -> 0.19047619 | AZ11: =((p_S1+p_s*MIN(3,p_nr-1))-dxe)/dSe -> 0.51069703 | BA11: =(-(b_d/2+p_tp/2-b_tf/2))/dSe -> -0.38003221 | BC11: =((setback/10+w_ev/10)-dxe)/dSe -> 0.069013112 | BD11: =(-w_Lp/2+w_ev/10+w_s/10*MIN(7,w_n-1))/dSe -> 0.20703934
P12: =((p_S1+p_s*MIN(4,p_nr-1))-dxp)/dSp -> 0.12121212 | Q12: =(-p_g/2)/dSp -> -0.19047619 | AZ12: =((p_S1+p_s*MIN(4,p_nr-1))-dxe)/dSe -> 0.51069703 | BA12: =(b_d/2+p_tp/2-b_tf/2)/dSe -> 0.38003221
P13: =((p_S1+p_s*MIN(4,p_nr-1))-dxp)/dSp -> 0.12121212 | Q13: =(p_g/2)/dSp -> 0.19047619 | AZ13: =((p_S1+p_s*MIN(4,p_nr-1))-dxe)/dSe -> 0.51069703 | BA13: =(-(b_d/2+p_tp/2-b_tf/2))/dSe -> -0.38003221
P14: =((p_S1+p_s*MIN(5,p_nr-1))-dxp)/dSp -> 0.12121212 | Q14: =(-p_g/2)/dSp -> -0.19047619 | AZ14: =((p_S1+p_s*MIN(5,p_nr-1))-dxe)/dSe -> 0.51069703 | BA14: =(b_d/2+p_tp/2-b_tf/2)/dSe -> 0.38003221
P15: =((p_S1+p_s*MIN(5,p_nr-1))-dxp)/dSp -> 0.12121212 | Q15: =(p_g/2)/dSp -> 0.19047619 | AZ15: =((p_S1+p_s*MIN(5,p_nr-1))-dxe)/dSe -> 0.51069703 | BA15: =(-(b_d/2+p_tp/2-b_tf/2))/dSe -> -0.38003221
P16: =((p_S1+p_s*MIN(6,p_nr-1))-dxp)/dSp -> 0.12121212 | Q16: =(-p_g/2)/dSp -> -0.19047619 | AZ16: =((p_S1+p_s*MIN(6,p_nr-1))-dxe)/dSe -> 0.51069703 | BA16: =(b_d/2+p_tp/2-b_tf/2)/dSe -> 0.38003221
P17: =((p_S1+p_s*MIN(6,p_nr-1))-dxp)/dSp -> 0.12121212 | Q17: =(p_g/2)/dSp -> 0.19047619 | AZ17: =((p_S1+p_s*MIN(6,p_nr-1))-dxe)/dSe -> 0.51069703 | BA17: =(-(b_d/2+p_tp/2-b_tf/2))/dSe -> -0.38003221
P18: =((p_S1+p_s*MIN(7,p_nr-1))-dxp)/dSp -> 0.12121212 | Q18: =(-p_g/2)/dSp -> -0.19047619 | AZ18: =((p_S1+p_s*MIN(7,p_nr-1))-dxe)/dSe -> 0.51069703 | BA18: =(b_d/2+p_tp/2-b_tf/2)/dSe -> 0.38003221
P19: =((p_S1+p_s*MIN(7,p_nr-1))-dxp)/dSp -> 0.12121212 | Q19: =(p_g/2)/dSp -> 0.19047619 | AZ19: =((p_S1+p_s*MIN(7,p_nr-1))-dxe)/dSe -> 0.51069703 | BA19: =(-(b_d/2+p_tp/2-b_tf/2))/dSe -> -0.38003221
P20: =((p_S1+p_s*MIN(8,p_nr-1))-dxp)/dSp -> 0.12121212 | Q20: =(-p_g/2)/dSp -> -0.19047619 | AZ20: =((p_S1+p_s*MIN(8,p_nr-1))-dxe)/dSe -> 0.51069703 | BA20: =(b_d/2+p_tp/2-b_tf/2)/dSe -> 0.38003221
P21: =((p_S1+p_s*MIN(8,p_nr-1))-dxp)/dSp -> 0.12121212 | Q21: =(p_g/2)/dSp -> 0.19047619 | AZ21: =((p_S1+p_s*MIN(8,p_nr-1))-dxe)/dSe -> 0.51069703 | BA21: =(-(b_d/2+p_tp/2-b_tf/2))/dSe -> -0.38003221
P22: =((p_S1+p_s*MIN(9,p_nr-1))-dxp)/dSp -> 0.12121212 | Q22: =(-p_g/2)/dSp -> -0.19047619 | AZ22: =((p_S1+p_s*MIN(9,p_nr-1))-dxe)/dSe -> 0.51069703 | BA22: =(b_d/2+p_tp/2-b_tf/2)/dSe -> 0.38003221
P23: =((p_S1+p_s*MIN(9,p_nr-1))-dxp)/dSp -> 0.12121212 | Q23: =(p_g/2)/dSp -> 0.19047619 | AZ23: =((p_S1+p_s*MIN(9,p_nr-1))-dxe)/dSe -> 0.51069703 | BA23: =(-(b_d/2+p_tp/2-b_tf/2))/dSe -> -0.38003221
