Workbook

Sheet DISEÑO
B2: CONEXIÓN SIMPLE A CORTANTE — VIGA SECUNDARIA A ALMA DE VIGA PRINCIPAL
B3: AISC 360-16 (J2, J3, J4) · AISC Manual 15ª ed. Parte 9 (vigas con destaje) y Parte 10 (conexiones simples) · LRFD · Unidades: Tonf, mm, kgf/cm²
B4: Celdas de ingreso: | C4: valor | D4: Calculado: | E4: valor | G4: Estados: VERDE ≤ límite · AMARILLO entre límite y 1.00 · ROJO > 1.00 (ratio = demanda / capacidad, o requerido / provisto)
B6: DATOS GENERALES | G6: ELEVACIÓN | J6: PLANTA (corte bajo el ala) | N6: VERIFICACIONES
B7: Proyecto | C7: Edificio — ejemplo | N7: =IF(MAX(R12:R53)>1,"✖ NO CUMPLE — ratio máx. "&TEXT(MAX(R12:R53),"0.00"),IF(MAX(R12:R53)>lim_verde,"▲ CUMPLE AL LÍMITE — ratio máx. "&TEXT(MAX(R12:R53),"0.00"),"✔ CUMPLE — ratio máx. "&TEXT(MAX(R12:R53),"0.00"))) -> ✔ CUMPLE — ratio máx. 0.89
B8: Elemento / nudo | C8: Vigueta V-3 a viga principal VP-1
B9: Límite verde / amarillo (ratio) | C9: 0.9
B10: TIPO DE CONEXIÓN Y CARGA | N10: Verificación | O10: Referencia | P10: Demanda / req. | Q10: Capacidad / prov. | R10: Unidad | S10: Ratio | T10: Estado
B11: Tipo | C11: Placa simple convencional | N11: PERNOS — LADO VIGA
B12: Reacción factorada Ru | C12: 6 | D12: Tonf | N12: Corte en pernos (perno crítico) | O12: J3.6 · grupo excéntrico elástico | P12: =p_r/1000 -> 2.3853721 | Q12: =p_rv/1000 -> 8.1167413 | R12: =(p_r/1000)/MAX(p_rv/1000,0.000000001) -> 0.29388298 | S12: Tonf | T12: =IF(ISNUMBER(R12),IF(R12>1,"NO CUMPLE",IF(R12>lim_verde,"AL LÍMITE","CUMPLE")),"N/A") -> CUMPLE
B13: Reacción de la viga del otro lado (0 si no hay) | C13: 0 | D13: Tonf | N13: Aplastamiento / desgarre — alma de viga | O13: J3.10 | P13: =p_r/1000 -> 2.3853721 | Q13: =p_rbw/1000 -> 4.8831593 | R13: =(p_r/1000)/MAX(p_rbw/1000,0.000000001) -> 0.48848951 | S13: Tonf | T13: =IF(ISNUMBER(R13),IF(R13>1,"NO CUMPLE",IF(R13>lim_verde,"AL LÍMITE","CUMPLE")),"N/A") -> CUMPLE
B14: 1. VIGA SOPORTADA | N14: Aplastamiento / desgarre — placa o ángulos | O14: J3.10 | P14: =p_r/1000 -> 2.3853721 | Q14: =p_rbe/1000 -> 7.250364 | R14: =(p_r/1000)/MAX(p_rbe/1000,0.000000001) -> 0.32900032 | S14: Tonf | T14: =IF(ISNUMBER(R14),IF(R14>1,"NO CUMPLE",IF(R14>lim_verde,"AL LÍMITE","CUMPLE")),"N/A") -> CUMPLE
B15: Perfil (catálogo o ARMADO) | C15: VK300X150X4X10 | E15: Armado (mm) | N15: DOBLE ÁNGULO — LADO SOPORTE
B16: Peralte d | C16: =IF(vg_perfil="ARMADO (flejes soldados)",E16,INDEX(CATALOGOS!$B$5:$B$40,MATCH(vg_perfil,CATALOGOS!$A$5:$A$40,0))) -> 300 | D16: mm | E16: 300 | N16: Corte en pernos (2n, corte simple) | O16: J3.6 | P16: =IF(t_da=0,"—",k_R/1000) -> — | Q16: =IF(t_da=0,"—",q_rv/1000) -> — | R16: =IF(t_da=0,"N/A",(k_R/1000)/MAX(q_rv/1000,0.000000001)) -> N/A | S16: Tonf | T16: =IF(ISNUMBER(R16),IF(R16>1,"NO CUMPLE",IF(R16>lim_verde,"AL LÍMITE","CUMPLE")),"N/A") -> N/A
B17: Ancho de ala bf | C17: =IF(vg_perfil="ARMADO (flejes soldados)",E17,INDEX(CATALOGOS!$C$5:$C$40,MATCH(vg_perfil,CATALOGOS!$A$5:$A$40,0))) -> 150 | D17: mm | E17: 150 | N17: Aplastamiento / desgarre — alas de ángulo | O17: J3.10 | P17: =IF(t_da=0,"—",k_R/1000) -> — | Q17: =IF(t_da=0,"—",q_rba/1000) -> — | R17: =IF(t_da=0,"N/A",(k_R/1000)/MAX(q_rba/1000,0.000000001)) -> N/A | S17: Tonf | T17: =IF(ISNUMBER(R17),IF(R17>1,"NO CUMPLE",IF(R17>lim_verde,"AL LÍMITE","CUMPLE")),"N/A") -> N/A
B18: Espesor de alma tw | C18: =IF(vg_perfil="ARMADO (flejes soldados)",E18,INDEX(CATALOGOS!$D$5:$D$40,MATCH(vg_perfil,CATALOGOS!$A$5:$A$40,0))) -> 4 | D18: mm | E18: 5 | N18: Aplastamiento — alma de viga principal | O18: J3.10 | P18: =IF(t_da=0,"—",(k_R+Ru_op*1000)/1000) -> — | Q18: =IF(t_da=0,"—",q_rbg/1000) -> — | R18: =IF(t_da=0,"N/A",((k_R+Ru_op*1000)/1000)/MAX(q_rbg/1000,0.000000001)) -> N/A | S18: Tonf | T18: =IF(ISNUMBER(R18),IF(R18>1,"NO CUMPLE",IF(R18>lim_verde,"AL LÍMITE","CUMPLE")),"N/A") -> N/A
B19: Espesor de ala tf | C19: =IF(vg_perfil="ARMADO (flejes soldados)",E19,INDEX(CATALOGOS!$E$5:$E$40,MATCH(vg_perfil,CATALOGOS!$A$5:$A$40,0))) -> 10 | D19: mm | E19: 10 | N19: Bloque de cortante — alas en el soporte | O19: J4.3 | P19: =IF(t_da=0,"—",k_R/1000) -> — | Q19: =IF(t_da=0,"—",m_bso/1000) -> — | R19: =IF(t_da=0,"N/A",(k_R/1000)/MAX(m_bso/1000,0.000000001)) -> N/A | S19: Tonf | T19: =IF(ISNUMBER(R19),IF(R19>1,"NO CUMPLE",IF(R19>lim_verde,"AL LÍMITE","CUMPLE")),"N/A") -> N/A
B20: Acero | C20: A572 Gr50 | N20: PLACA / ÁNGULOS
B21: Fy / Fu | C21: =INDEX(CATALOGOS!$H$5:$H$10,MATCH(vg_acero,CATALOGOS!$G$5:$G$10,0)) -> 3515 | D21: kgf/cm² | E21: =INDEX(CATALOGOS!$I$5:$I$10,MATCH(vg_acero,CATALOGOS!$G$5:$G$10,0)) -> 4570 | G21: VALORES CLAVE | N21: Fluencia por corte | O21: J4.2(a) | P21: =k_R/1000 -> 6 | Q21: =m_vy/1000 -> 26.7168 | R21: =(k_R/1000)/MAX(m_vy/1000,0.000000001) -> 0.22457779 | S21: Tonf | T21: =IF(ISNUMBER(R21),IF(R21>1,"NO CUMPLE",IF(R21>lim_verde,"AL LÍMITE","CUMPLE")),"N/A") -> CUMPLE
B22: Filete / radio alma–ala (para k) | C22: 5 | D22: mm | G22: Excentricidad del grupo e | K22: =p_e -> 3.25 | L22: cm | N22: Ruptura por corte | O22: J4.2(b) | P22: =k_R/1000 -> 6 | Q22: =m_vr/1000 -> 22.520376 | R22: =(k_R/1000)/MAX(m_vr/1000,0.000000001) -> 0.26642539 | S22: Tonf | T22: =IF(ISNUMBER(R22),IF(R22>1,"NO CUMPLE",IF(R22>lim_verde,"AL LÍMITE","CUMPLE")),"N/A") -> CUMPLE
B23: Destaje | C23: Destaje superior | G23: Fuerza en el perno crítico rmáx | K23: =p_r/1000 -> 2.3853721 | L23: Tonf | N23: Bloque de cortante (lado viga) | O23: J4.3 | P23: =k_R/1000 -> 6 | Q23: =m_bs/1000 -> 25.14546 | R23: =(k_R/1000)/MAX(m_bs/1000,0.000000001) -> 0.23861166 | S23: Tonf | T23: =IF(ISNUMBER(R23),IF(R23>1,"NO CUMPLE",IF(R23>lim_verde,"AL LÍMITE","CUMPLE")),"N/A") -> CUMPLE
B24: Profundidad del destaje dc | C24: 30 | D24: mm | G24: Corte por perno φrn | K24: =p_rv/1000 -> 8.1167413 | L24: Tonf | N24: Placa extendida — corte + flexión | O24: Manual Ec. 10-5 | P24: =IF(t_se=0,"—",x_int) -> — | Q24: =IF(t_se=0,"—",1) -> — | R24: =IF(t_se=0,"N/A",(x_int)/MAX(1,0.000000001)) -> N/A | S24: - | T24: =IF(ISNUMBER(R24),IF(R24>1,"NO CUMPLE",IF(R24>lim_verde,"AL LÍMITE","CUMPLE")),"N/A") -> N/A
B25: Longitud del destaje c | C25: 90 | D25: mm | G25: Largo de placa / ángulo L | K25: =e_L -> 22 | L25: cm | N25: Placa extendida — ruptura por flexión | O25: Manual Parte 10 | P25: =IF(t_se=0,"—",x_Mu/100000) -> — | Q25: =IF(t_se=0,"—",x_Mr/100000) -> — | R25: =IF(t_se=0,"N/A",(x_Mu/100000)/MAX(x_Mr/100000,0.000000001)) -> N/A | S25: Tonf·m | T25: =IF(ISNUMBER(R25),IF(R25>1,"NO CUMPLE",IF(R25>lim_verde,"AL LÍMITE","CUMPLE")),"N/A") -> N/A
B26: Holgura viga – alma de viga principal | C26: 15 | D26: mm | G26: Alma de viga: Leh (a extremo) | K26: =b_Leh -> 5 | L26: cm | N26: Placa extendida — pandeo | O26: Manual Parte 9 (método Q) | P26: =IF(t_se=0,"—",x_Mu/100000) -> — | Q26: =IF(t_se=0,"—",x_Mb/100000) -> — | R26: =IF(t_se=0,"N/A",(x_Mu/100000)/MAX(x_Mb/100000,0.000000001)) -> N/A | S26: Tonf·m | T26: =IF(ISNUMBER(R26),IF(R26>1,"NO CUMPLE",IF(R26>lim_verde,"AL LÍMITE","CUMPLE")),"N/A") -> N/A
B27: 2. VIGA PRINCIPAL (soporte) | G27: Alma de viga: Lev (a destaje) | K27: =IF(c_top>0,b_Lev,"—") -> 4 | L27: cm | N27: SOLDADURA Y VIGA PRINCIPAL (placa simple)
B28: Perfil (catálogo o ARMADO) | C28: VK400X180X6X12 | E28: Armado (mm) | G28: Peralte remanente ho | K28: =b_ho -> 27 | L28: cm | N28: Resistencia de filetes placa – alma | O28: J2.4 | P28: =IF(t_pl=0,"—",k_R/1000) -> 6 | Q28: =IF(t_pl=0,"—",w_R/1000) -> 41.323867 | R28: =IF(t_pl=0,"N/A",(k_R/1000)/MAX(w_R/1000,0.000000001)) -> 0.14519454 | S28: Tonf | T28: =IF(ISNUMBER(R28),IF(R28>1,"NO CUMPLE",IF(R28>lim_verde,"AL LÍMITE","CUMPLE")),"N/A") -> CUMPLE
B29: Peralte d | C29: =IF(vp_perfil="ARMADO (flejes soldados)",E29,INDEX(CATALOGOS!$B$5:$B$40,MATCH(vp_perfil,CATALOGOS!$A$5:$A$40,0))) -> 400 | D29: mm | E29: 400 | G29: Snet en el destaje | K29: =IF(c_c>0,v_S,"—") -> 81.366179 | L29: cm³ | N29: Filete ≥ 5/8·tp (ductilidad) | O29: Manual Parte 10 | P29: =IF(t_pl=0,"—",0.625*pl_tp) -> 5 | Q29: =IF(t_pl=0,"—",pl_w) -> 6 | R29: =IF(t_pl=0,"N/A",(0.625*pl_tp)/MAX(pl_w,0.000000001)) -> 0.83333333 | S29: mm | T29: =IF(ISNUMBER(R29),IF(R29>1,"NO CUMPLE",IF(R29>lim_verde,"AL LÍMITE","CUMPLE")),"N/A") -> CUMPLE
B30: Ancho de ala bf | C30: =IF(vp_perfil="ARMADO (flejes soldados)",E30,INDEX(CATALOGOS!$C$5:$C$40,MATCH(vp_perfil,CATALOGOS!$A$5:$A$40,0))) -> 180 | D30: mm | E30: 180 | G30: Fcr en el destaje | K30: =IF(c_c>0,v_Fcr,"—") -> 3271.0113 | L30: kgf/cm² | N30: Alma de viga principal: t ≥ tmín para los filetes | O30: Manual Ec. 9-2/9-3 | P30: =IF(t_pl=0,"—",w_tmin*10) -> 4.5668796 | Q30: =IF(t_pl=0,"—",vp_tw_mm) -> 6 | R30: =IF(t_pl=0,"N/A",(w_tmin*10)/MAX(vp_tw_mm,0.000000001)) -> 0.76114661 | S30: mm | T30: =IF(ISNUMBER(R30),IF(R30>1,"NO CUMPLE",IF(R30>lim_verde,"AL LÍMITE","CUMPLE")),"N/A") -> CUMPLE
B31: Espesor de alma tw | C31: =IF(vp_perfil="ARMADO (flejes soldados)",E31,INDEX(CATALOGOS!$D$5:$D$40,MATCH(vp_perfil,CATALOGOS!$A$5:$A$40,0))) -> 6 | D31: mm | E31: 6 | G31: Momento en el destaje Mu | K31: =IF(c_c>0,v_Mu/100000,"—") -> 0.63 | L31: Tonf·m | N31: VIGA SOPORTADA (Manual Parte 9)
B32: Espesor de ala tf | C32: =IF(vp_perfil="ARMADO (flejes soldados)",E32,INDEX(CATALOGOS!$E$5:$E$40,MATCH(vp_perfil,CATALOGOS!$A$5:$A$40,0))) -> 12 | D32: mm | E32: 12 | G32: Placa extendida: tmáx | K32: =IF(t_se=1,x_tmax*10,"—") -> — | L32: mm | N32: Fluencia por corte del alma (ho) | O32: J4.2(a) | P32: =k_R/1000 -> 6 | Q32: =v_vy/1000 -> 22.7772 | R32: =(k_R/1000)/MAX(v_vy/1000,0.000000001) -> 0.26342132 | S32: Tonf | T32: =IF(ISNUMBER(R32),IF(R32>1,"NO CUMPLE",IF(R32>lim_verde,"AL LÍMITE","CUMPLE")),"N/A") -> CUMPLE
B33: Acero | C33: A572 Gr50 | G33: Alma viga principal: tmín soldadura | K33: =IF(t_pl=1,w_tmin*10,"—") -> 4.5668796 | L33: mm | N33: Ruptura por corte del alma | O33: J4.2(b) | P33: =k_R/1000 -> 6 | Q33: =v_vr/1000 -> 16.725514 | R33: =(k_R/1000)/MAX(v_vr/1000,0.000000001) -> 0.35873336 | S33: Tonf | T33: =IF(ISNUMBER(R33),IF(R33>1,"NO CUMPLE",IF(R33>lim_verde,"AL LÍMITE","CUMPLE")),"N/A") -> CUMPLE
B34: Fy / Fu | C34: =INDEX(CATALOGOS!$H$5:$H$10,MATCH(vp_acero,CATALOGOS!$G$5:$G$10,0)) -> 3515 | D34: kgf/cm² | E34: =INDEX(CATALOGOS!$I$5:$I$10,MATCH(vp_acero,CATALOGOS!$G$5:$G$10,0)) -> 4570 | N34: Bloque de cortante del alma (con destaje) | O34: J4.3 | P34: =IF(c_c=0,"—",k_R/1000) -> 6 | Q34: =IF(c_c=0,"—",v_bs/1000) -> 16.390305 | R34: =IF(c_c=0,"N/A",(k_R/1000)/MAX(v_bs/1000,0.000000001)) -> 0.36607006 | S34: Tonf | T34: =IF(ISNUMBER(R34),IF(R34>1,"NO CUMPLE",IF(R34>lim_verde,"AL LÍMITE","CUMPLE")),"N/A") -> CUMPLE
B35: 3. PERNOS | G35: ALCANCE Y SUPUESTOS | N35: Pandeo local por flexión en el destaje | O35: Manual Parte 9 | P35: =IF(c_c=0,"—",v_Mu/100000) -> 0.63 | Q35: =IF(c_c=0,"—",v_Mn/100000) -> 2.3953472 | R35: =IF(c_c=0,"N/A",(v_Mu/100000)/MAX(v_Mn/100000,0.000000001)) -> 0.26300989 | S35: Tonf·m | T35: =IF(ISNUMBER(R35),IF(R35>1,"NO CUMPLE",IF(R35>lim_verde,"AL LÍMITE","CUMPLE")),"N/A") -> CUMPLE
B36: Grado | C36: A325-N (roscas incl.) | G36: • Viga secundaria conectada al alma de la viga principal, alas superiores a nivel (destaje). | N36: LÍMITES Y DETALLES (requerido / provisto)
B37: Diámetro | C37: 3/4" | G37: • Grupo de pernos excéntrico por método elástico: conservador frente al centro instantáneo del Manual. | N37: Convencional: a ≤ 3.5 in (89 mm) | O37: Manual Tabla 10-9 | P37: =IF(t_sp=0,"—",pl_a) -> 65 | Q37: =IF(t_sp=0,"—",88.9) -> 88.9 | R37: =IF(t_sp=0,"N/A",pl_a/88.9) -> 0.73115861 | S37: mm | T37: =IF(ISNUMBER(R37),IF(R37>1,"NO CUMPLE",IF(R37>lim_verde,"AL LÍMITE","CUMPLE")),"N/A") -> CUMPLE
B38: Número de pernos n (1 línea vertical) | C38: 3 | G38: • Convencional: excentricidad de Tabla 10-9 (a/2 o a); extendida: e = a. | N38: Placa simple: 2 ≤ n ≤ 12 | O38: Manual Parte 10 | P38: =IF(t_pl=0,"—",n_b) -> 3 | Q38: =IF(t_pl=0,"—",12) -> 12 | R38: =IF(t_pl=0,"N/A",MAX(n_b/12,2/n_b)) -> 0.66666667 | S38: pernos | T38: =IF(ISNUMBER(R38),IF(R38>1,"NO CUMPLE",IF(R38>lim_verde,"AL LÍMITE","CUMPLE")),"N/A") -> CUMPLE
B39: Paso vertical s | C39: 75 | D39: mm | G39: • Doble ángulo: excentricidad despreciada en ambos lados (Manual Parte 10). | N39: Convencional: mín(tp ; tw) ≤ tmáx | O39: Manual Tabla 10-9 | P39: =IF(t_sp=0,"—",MIN(pl_tp,vg_tw_mm)) -> 4 | Q39: =IF(t_sp=0,"—",(a_dbi/2+IF(OR(agujero<>"STD",n_b<=5),1/16,-1/16))*25.4) -> 11.1125 | R39: =IF(t_sp=0,"N/A",(MIN(pl_tp,vg_tw_mm))/MAX((a_dbi/2+IF(OR(agujero<>"STD",n_b<=5),1/16,-1/16))*25.4,0.000000001)) -> 0.35995501 | S39: mm | T39: =IF(ISNUMBER(R39),IF(R39>1,"NO CUMPLE",IF(R39>lim_verde,"AL LÍMITE","CUMPLE")),"N/A") -> CUMPLE
B40: Tope de viga → primer perno | C40: 70 | D40: mm | G40: • Momento en el destaje con e = c + holgura (reacción en la cara del soporte). | N40: Extendida: tp ≤ tmáx | O40: Manual Ec. 10-3 | P40: =IF(t_se=0,"—",pl_tp) -> — | Q40: =IF(t_se=0,"—",x_tmax*10) -> — | R40: =IF(t_se=0,"N/A",(pl_tp)/MAX(x_tmax*10,0.000000001)) -> N/A | S40: mm | T40: =IF(ISNUMBER(R40),IF(R40>1,"NO CUMPLE",IF(R40>lim_verde,"AL LÍMITE","CUMPLE")),"N/A") -> N/A
B41: Borde vertical en placa / ángulo Lev | C41: 35 | D41: mm | G41: • Sin carga axial en la conexión; alma de viga principal no se verifica a flexión local. | N41: Leh en placa ≥ 2·db | O41: Manual Parte 10 | P41: =IF(t_pl=0,"—",2*a_db) -> 3.81 | Q41: =IF(t_pl=0,"—",e_Leh) -> 4.5 | R41: =IF(t_pl=0,"N/A",(2*a_db)/MAX(e_Leh,0.000000001)) -> 0.84666667 | S41: cm | T41: =IF(ISNUMBER(R41),IF(R41>1,"NO CUMPLE",IF(R41>lim_verde,"AL LÍMITE","CUMPLE")),"N/A") -> CUMPLE
B42: Agujero en la placa | C42: STD | G42: • Herramienta de apoyo: la responsabilidad del diseño es del ingeniero que la usa. | N42: Leh en alma de viga ≥ 2·db | O42: Manual Parte 10 | P42: =IF(t_pl=0,"—",2*a_db) -> 3.81 | Q42: =IF(t_pl=0,"—",b_Leh) -> 5 | R42: =IF(t_pl=0,"N/A",(2*a_db)/MAX(b_Leh,0.000000001)) -> 0.762 | S42: cm | T42: =IF(ISNUMBER(R42),IF(R42>1,"NO CUMPLE",IF(R42>lim_verde,"AL LÍMITE","CUMPLE")),"N/A") -> CUMPLE
...

Sheet CALCULO
A1: HOJA DE CÁLCULO — memoria detallada (no editar)
A2: Unidades: kgf, cm. Grupo excéntrico de pernos por método elástico (más conservador que el centro instantáneo del Manual). φ según AISC 360-16.
A4: 0. TIPO, GEOMETRÍA Y MATERIALES
A5: conv. | B5: 1 = placa simple convencional | C5: - | D5: =IF(tipo="Placa simple convencional",1,0) -> 1
A6: ext. | B6: 1 = placa simple extendida | C6: - | D6: =IF(tipo="Placa simple extendida",1,0) -> 0
A7: 2L | B7: 1 = doble ángulo | C7: - | D7: =IF(tipo="Doble ángulo apernado",1,0) -> 0
A8: placa | B8: 1 = placa simple (conv. o ext.) | C8: - | D8: =t_sp+t_se -> 1
A9: E | B9: Módulo de elasticidad | C9: kgf/cm² | D9: =2040000 -> 2040000
A10: Ru | B10: Reacción factorada | C10: kgf | D10: =Ru*1000 -> 6000
A11: d | B11: d (cm) | C11: cm | D11: =vg_d_mm/10 -> 30
A12: bf | B12: bf (cm) | C12: cm | D12: =vg_bf_mm/10 -> 15
A13: tw | B13: tw (cm) | C13: cm | D13: =vg_tw_mm/10 -> 0.4
A14: tf | B14: tf (cm) | C14: cm | D14: =vg_tf_mm/10 -> 1
A15: dg | B15: dg (cm) | C15: cm | D15: =vp_d_mm/10 -> 40
A16: bfg | B16: bfg (cm) | C16: cm | D16: =vp_bf_mm/10 -> 18
A17: twg | B17: twg (cm) | C17: cm | D17: =vp_tw_mm/10 -> 0.6
A18: tfg | B18: tfg (cm) | C18: cm | D18: =vp_tf_mm/10 -> 1.2
A19: k | B19: tf + filete (viga soportada) | C19: cm | D19: =b_tf+vg_kw/10 -> 1.5
A20: dct | B20: Destaje superior | C20: cm | D20: =IF(destaje="Sin destaje",0,cope_dc/10) -> 3
A21: dcb | B21: Destaje inferior (destaje doble) | C21: cm | D21: =IF(destaje="Destaje doble (sup. = inf.)",cope_dc/10,0) -> 0
A22: c | B22: Longitud del destaje | C22: cm | D22: =IF(destaje="Sin destaje",0,cope_c/10) -> 9
A23: ho | B23: Peralte remanente d − dct − dcb | C23: cm | D23: =b_d-c_top-c_bot -> 27
A24: db | B24: Diámetro | C24: in | D24: =INDEX(CATALOGOS!$O$5:$O$9,MATCH(pn_diam,CATALOGOS!$N$5:$N$9,0)) -> 0.75
A25: db | B25: Diámetro | C25: cm | D25: =a_dbi*2.54 -> 1.905
A26: Ab | B26: π·db²/4 | C26: cm² | D26: =PI()*a_db^2/4 -> 2.8502296
A27: dh | B27: Agujero estándar (Tabla J3.3) | C27: cm | D27: =IF(a_dbi<1,a_dbi+1/16,a_dbi+1/8)*2.54 -> 2.06375
A28: dh,net | B28: dh + 1/16 in (B4.3b) | C28: cm | D28: =a_dh+0.15875 -> 2.2225
A29: Lslot | B29: Longitud de ranura corta SSL (Tabla J3.3), si aplica | C29: cm | D29: =IF(agujero="STD",a_dh,IF(a_dbi<1,a_dbi+0.25,IF(a_dbi<1.1,a_dbi+5/16,a_dbi+3/8))*2.54) -> 2.06375
A30: Le,min | B30: Borde mínimo (Tabla J3.4) | C30: cm | D30: =INDEX(CATALOGOS!$P$5:$P$9,MATCH(pn_diam,CATALOGOS!$N$5:$N$9,0))*2.54 -> 2.54
A31: Fnv | B31: Resistencia nominal a corte del perno | C31: kgf/cm² | D31: =INDEX(CATALOGOS!$L$5:$L$9,MATCH(pn_grado,CATALOGOS!$K$5:$K$9,0)) -> 3797
A32: s | B32: Paso vertical | C32: cm | D32: =pn_s/10 -> 7.5
A33: Lev | B33: Borde vertical en placa / ángulo | C33: cm | D33: =pn_Lev/10 -> 3.5
A34: L | B34: Largo de placa / ángulo = (n−1)s + 2Lev | C34: cm | D34: =(n_b-1)*a_s+2*e_Lev -> 22
A35: ztop | B35: Profundidad del borde superior de la placa/ángulo desde el tope de la viga | C35: cm | D35: =pn_top/10-e_Lev -> 3.5
A36: Lev,b | B36: Primer perno a borde superior del alma (destaje) ; sin destaje: no gobierna | C36: cm | D36: =IF(c_top>0,pn_top/10-c_top,1000) -> 4
A37: t | B37: Espesor del elemento (placa o ángulo) | C37: cm | D37: =IF(t_pl=1,pl_tp,an_t)/10 -> 0.8
A38: Fy,e | B38: Fy del elemento | C38: kgf/cm² | D38: =IF(t_pl=1,pl_Fy,an_Fy) -> 2530
A39: Fu,e | B39: Fu del elemento | C39: kgf/cm² | D39: =IF(t_pl=1,pl_Fu,an_Fu) -> 4080
A40: xb | B40: Alma de viga principal → línea de pernos de la viga (a | gramil lado viga) | C40: cm | D40: =IF(t_pl=1,pl_a,an_gb)/10 -> 6.5
A41: Leh,e | B41: Línea de pernos → borde del elemento | C41: cm | D41: =IF(t_pl=1,pl_Leh/10,(an_lb-an_gb)/10) -> 4.5
...

Sheet CATALOGOS
A1: CATÁLOGOS — ampliables agregando filas dentro de cada rango
A3: Vigas (VK: KUBIEC; W: AISC redondeado a mm; ARMADO: medidas manuales) | G3: Aceros (kgf/cm²) | K3: Pernos (kgf/cm²) — AISC 360-16 Tabla J3.2 | N3: Diámetros — borde mín. Tabla J3.4 | R3: Electrodo | U3: Opción | W3: Tipo de conexión | Y3: Destaje | AA3: Agujero en placa | AC3: Espesores (mm)
A4: Perfil | B4: d | C4: bf | D4: tw | E4: tf | G4: Acero | H4: Fy | I4: Fu | K4: Grado | L4: Fnv | N4: Ø | O4: db (in) | P4: borde mín (in) | R4: Electrodo | S4: FEXX | U4: Sí/No | W4: Tipo | Y4: Destaje | AA4: Agujero | AC4: t
A5: ARMADO (flejes soldados) | G5: A36 | H5: 2530 | I5: 4080 | K5: A325-N (roscas incl.) | L5: 3797 | N5: 5/8" | O5: 0.625 | P5: 0.875 | R5: E60XX | S5: 4220 | U5: Sí | W5: Placa simple convencional | Y5: Sin destaje | AA5: STD | AC5: 5
A6: VK180X100X4X6 | B6: 180 | C6: 100 | D6: 4 | E6: 6 | G6: A572 Gr50 | H6: 3515 | I6: 4570 | K6: A325-X (roscas excl.) | L6: 4781 | N6: 3/4" | O6: 0.75 | P6: 1 | R6: E70XX | S6: 4920 | U6: No | W6: Placa simple extendida | Y6: Destaje superior | AA6: SSLT (ranura corta horiz.) | AC6: 6
A7: VK200X100X4X8 | B7: 200 | C7: 100 | D7: 4 | E7: 8 | G7: A992 | H7: 3515 | I7: 4570 | K7: A490-N (roscas incl.) | L7: 4781 | N7: 7/8" | O7: 0.875 | P7: 1.125 | W7: Doble ángulo apernado | Y7: Destaje doble (sup. = inf.) | AC7: 8
A8: VK220X110X4X8 | B8: 220 | C8: 110 | D8: 4 | E8: 8 | G8: A588 Gr50 | H8: 3515 | I8: 4920 | K8: A490-X (roscas excl.) | L8: 5906 | N8: 1" | O8: 1 | P8: 1.25 | AC8: 10
A9: VK250X130X4X8 | B9: 250 | C9: 130 | D9: 4 | E9: 8 | K9: A307 | L9: 1906 | N9: 1-1/8" | O9: 1.125 | P9: 1.5 | AC9: 12
A10: VK270X140X4X8 | B10: 270 | C10: 140 | D10: 4 | E10: 8 | AC10: 15
A11: VK300X150X4X10 | B11: 300 | C11: 150 | D11: 4 | E11: 10 | AC11: 16
A12: VK330X160X6X10 | B12: 330 | C12: 160 | D12: 6 | E12: 10 | AC12: 19
A13: VK360X180X6X10 | B13: 360 | C13: 180 | D13: 6 | E13: 10 | AC13: 20
A14: VK380X180X6X10 | B14: 380 | C14: 180 | D14: 6 | E14: 10 | AC14: 22
A15: VK400X180X6X10 | B15: 400 | C15: 180 | D15: 6 | E15: 10 | AC15: 25
A16: VK400X180X6X12 | B16: 400 | C16: 180 | D16: 6 | E16: 12
A17: VK420X180X6X12 | B17: 420 | C17: 180 | D17: 6 | E17: 12
A18: VK440X180X6X12 | B18: 440 | C18: 180 | D18: 6 | E18: 12
A19: W8X18 | B19: 207 | C19: 133 | D19: 5.8 | E19: 8.4
A20: W10X22 | B20: 259 | C20: 146 | D20: 6.1 | E20: 9.1
A21: W12X26 | B21: 310 | C21: 165 | D21: 5.8 | E21: 9.7
A22: W14X30 | B22: 351 | C22: 171 | D22: 6.9 | E22: 9.8
A23: W16X31 | B23: 403 | C23: 140 | D23: 7 | E23: 11.2
A24: W18X35 | B24: 450 | C24: 152 | D24: 7.6 | E24: 10.8
A25: W18X50 | B25: 457 | C25: 190 | D25: 9 | E25: 14.5
A26: W21X44 | B26: 525 | C26: 165 | D26: 8.9 | E26: 11.4
A27: W21X62 | B27: 533 | C27: 209 | D27: 10.2 | E27: 15.6
... A29: W24X76 | B29: 608 | C29: 228 | D29: 11.2 | E29: 17.3

Sheet DIBUJO
A1: Coordenadas de las vistas (normalizadas a ±1). No editar.
D2: Viga principal | G2: Viga | J2: Ala sup | M2: Ala inf | P2: Elemento | S2: Pernos | V2: Alma VP | Y2: Alas VP | AB2: Alas VP2 | AE2: Alma viga | AH2: Ala viga | AK2: Placa | AN2: Ángulo 1 | AQ2: Ángulo 2 | AT2: Perno viga | AW2: Perno sop. 1 | AZ2: Perno sop. 2 | BC2: Soldadura
A3: Extremo de viga | B3: =g_tw/2+setback/10 -> 1.8
A4: Largo dibujado | B4: =dxe+MAX(c_c+0.9*b_d,e_xb+e_Leh+0.6*b_d) -> 37.8 | D4: =((-g_bf/2)-dxc)/dSe -> -0.94339623 | E4: =((0)+dH/2)/dSe -> 0.80632156 | G4: =((dxf)-dxc)/dSe -> 0.94339623 | H4: =((0)+dH/2)/dSe -> 0.80632156 | J4: =((dxe+c_c)-dxc)/dSe -> -0.14513788 | K4: =((-b_tf)+dH/2)/dSe -> 0.76600548 | M4: =((dxe+IF(c_bot>0,c_c,0))-dxc)/dSe -> -0.50798258 | N4: =((-b_d+b_tf)+dH/2)/dSe -> -0.3628447 | P4: =((g_tw/2)-dxc)/dSe -> -0.5684567 | Q4: =((-e_top)+dH/2)/dSe -> 0.66521529 | S4: =((g_tw/2+e_xb)-dxc)/dSe -> -0.30640219 | T4: =((-pn_top/10-a_s*MIN(0,n_b-1))+dH/2)/dSe -> 0.52410901 | V4: =((-g_tw/2)-dxc)/dSp -> -0.59264635 | W4: =(-dZw)/dSp -> -0.48379294 | Y4: =((-g_bf/2)-dxc)/dSp -> -0.94339623 | Z4: =(-dZw)/dSp -> -0.48379294 | AB4: =((g_bf/2)-dxc)/dSp -> -0.21770682 | AC4: =(-dZw)/dSp -> -0.48379294 | AE4: =((dxf)-dxc)/dSp -> 0.94339623 | AF4: =(b_tw/2)/dSp -> 0.0080632156 | AH4: =((dxf)-dxc)/dSp -> 0.94339623 | AI4: =(b_bf/2)/dSp -> 0.30237059 | AK4: =((g_tw/2)-dxc)/dSp -> -0.5684567 | AL4: =(b_tw/2)/dSp -> 0.0080632156 | AN4: =((g_tw/2)-dxc)/dSp -> -0.5684567 | AO4: =((b_tw/2))/dSp -> 0.0080632156 | AQ4: =((g_tw/2)-dxc)/dSp -> -0.5684567 | AR4: =(-(b_tw/2))/dSp -> -0.0080632156 | AT4: =((g_tw/2+e_xb)-dxc)/dSp -> -0.30640219 | AU4: =(-b_tw/2-IF(t_da=1,an_t/10,0)-0.8)/dSp -> -0.040316078 | AW4: =((-g_tw/2-0.8)-dxc)/dSp -> -0.62489921 | AX4: =((b_tw/2+IF(t_da=1,an_gs/10,0)))/dSp -> 0.0080632156 | AZ4: =((-g_tw/2-0.8)-dxc)/dSp -> -0.62489921 | BA4: =(-(b_tw/2+IF(t_da=1,an_gs/10,0)))/dSp -> -0.0080632156 | BC4: =((g_tw/2)-dxc)/dSp -> -0.5684567 | BD4: =(b_tw/2)/dSp -> 0.0080632156
A5: x centro | B5: =(-g_bf/2+dxf)/2 -> 14.4 | D5: =((g_bf/2)-dxc)/dSe -> -0.21770682 | E5: =((0)+dH/2)/dSe -> 0.80632156 | G5: =((dxe+c_c)-dxc)/dSe -> -0.14513788 | H5: =((0)+dH/2)/dSe -> 0.80632156 | J5: =((dxf)-dxc)/dSe -> 0.94339623 | K5: =((-b_tf)+dH/2)/dSe -> 0.76600548 | M5: =((dxf)-dxc)/dSe -> 0.94339623 | N5: =((-b_d+b_tf)+dH/2)/dSe -> -0.3628447 | P5: =((g_tw/2)-dxc)/dSe -> -0.5684567 | Q5: =((-e_top-e_L)+dH/2)/dSe -> -0.22173843 | S5: =((g_tw/2+e_xb)-dxc)/dSe -> -0.30640219 | T5: =((-pn_top/10-a_s*MIN(1,n_b-1))+dH/2)/dSe -> 0.22173843 | V5: =((-g_tw/2)-dxc)/dSp -> -0.59264635 | W5: =(dZw)/dSp -> 0.48379294 | Y5: =((-g_bf/2)-dxc)/dSp -> -0.94339623 | Z5: =(dZw)/dSp -> 0.48379294 | AB5: =((g_bf/2)-dxc)/dSp -> -0.21770682 | AC5: =(dZw)/dSp -> 0.48379294 | AE5: =((dxe)-dxc)/dSp -> -0.50798258 | AF5: =(b_tw/2)/dSp -> 0.0080632156 | AH5: =((dxe+c_c)-dxc)/dSp -> -0.14513788 | AI5: =(b_bf/2)/dSp -> 0.30237059 | AK5: =((g_tw/2)-dxc)/dSp -> -0.5684567 | AL5: =(b_tw/2+IF(t_pl=1,pl_tp/10,0))/dSp -> 0.040316078 | AN5: =((g_tw/2+IF(t_da=1,an_lb/10,0))-dxc)/dSp -> -0.5684567 | AO5: =((b_tw/2))/dSp -> 0.0080632156 | AQ5: =((g_tw/2+IF(t_da=1,an_lb/10,0))-dxc)/dSp -> -0.5684567 | AR5: =(-(b_tw/2))/dSp -> -0.0080632156 | AT5: =((g_tw/2+e_xb)-dxc)/dSp -> -0.30640219 | AU5: =(b_tw/2+IF(t_pl=1,IF(t_pl=1,pl_tp/10,0),IF(t_da=1,an_t/10,0))+0.8)/dSp -> 0.07256894 | AW5: =((g_tw/2+IF(t_da=1,an_t/10,0)+0.8)-dxc)/dSp -> -0.53620384 | AX5: =((b_tw/2+IF(t_da=1,an_gs/10,0)))/dSp -> 0.0080632156 | AZ5: =((g_tw/2+IF(t_da=1,an_t/10,0)+0.8)-dxc)/dSp -> -0.53620384 | BA5: =(-(b_tw/2+IF(t_da=1,an_gs/10,0)))/dSp -> -0.0080632156 | BC5: =((g_tw/2)-dxc)/dSp -> -0.5684567 | BD5: =(b_tw/2+IF(t_pl=1,pl_tp/10,0))/dSp -> 0.040316078
A6: Alto máx | B6: =MAX(g_d,b_d) -> 40 | D6: =((g_bf/2)-dxc)/dSe -> -0.21770682 | E6: =((-g_tf)+dH/2)/dSe -> 0.75794227 | G6: =((dxe+c_c)-dxc)/dSe -> -0.14513788 | H6: =((-c_top)+dH/2)/dSe -> 0.68537333 | P6: =((g_tw/2+dWe)-dxc)/dSe -> -0.12497984 | Q6: =((-e_top-e_L)+dH/2)/dSe -> -0.22173843 | S6: =((g_tw/2+e_xb)-dxc)/dSe -> -0.30640219 | T6: =((-pn_top/10-a_s*MIN(2,n_b-1))+dH/2)/dSe -> -0.080632156 | V6: =((g_tw/2)-dxc)/dSp -> -0.5684567 | W6: =(dZw)/dSp -> 0.48379294 | AE6: =((dxe)-dxc)/dSp -> -0.50798258 | AF6: =(-b_tw/2)/dSp -> -0.0080632156 | AH6: =((dxe+c_c)-dxc)/dSp -> -0.14513788 | AI6: =(-b_bf/2)/dSp -> -0.30237059 | AK6: =((g_tw/2+IF(t_pl=1,dWe,0))-dxc)/dSp -> -0.12497984 | AL6: =(b_tw/2+IF(t_pl=1,pl_tp/10,0))/dSp -> 0.040316078 | AN6: =((g_tw/2+IF(t_da=1,an_lb/10,0))-dxc)/dSp -> -0.5684567 | AO6: =((b_tw/2+IF(t_da=1,an_t/10,0)))/dSp -> 0.0080632156 | AQ6: =((g_tw/2+IF(t_da=1,an_lb/10,0))-dxc)/dSp -> -0.5684567 | AR6: =(-(b_tw/2+IF(t_da=1,an_t/10,0)))/dSp -> -0.0080632156
A7: S elevación | B7: =MAX(dxf+g_bf/2,dH)/2*1.06 -> 24.804 | D7: =((g_tw/2)-dxc)/dSe -> -0.5684567 | E7: =((-g_tf)+dH/2)/dSe -> 0.75794227 | G7: =((dxe)-dxc)/dSe -> -0.50798258 | H7: =((-c_top)+dH/2)/dSe -> 0.68537333 | P7: =((g_tw/2+dWe)-dxc)/dSe -> -0.12497984 | Q7: =((-e_top)+dH/2)/dSe -> 0.66521529 | S7: =((g_tw/2+e_xb)-dxc)/dSe -> -0.30640219 | T7: =((-pn_top/10-a_s*MIN(3,n_b-1))+dH/2)/dSe -> -0.080632156 | V7: =((g_tw/2)-dxc)/dSp -> -0.5684567 | W7: =(-dZw)/dSp -> -0.48379294 | AE7: =((dxf)-dxc)/dSp -> 0.94339623 | AF7: =(-b_tw/2)/dSp -> -0.0080632156 | AH7: =((dxf)-dxc)/dSp -> 0.94339623 | AI7: =(-b_bf/2)/dSp -> -0.30237059 | AK7: =((g_tw/2+IF(t_pl=1,dWe,0))-dxc)/dSp -> -0.12497984 | AL7: =(b_tw/2)/dSp -> 0.0080632156 | AN7: =((g_tw/2+IF(t_da=1,an_t/10,0))-dxc)/dSp -> -0.5684567 | AO7: =((b_tw/2+IF(t_da=1,an_t/10,0)))/dSp -> 0.0080632156 | AQ7: =((g_tw/2+IF(t_da=1,an_t/10,0))-dxc)/dSp -> -0.5684567 | AR7: =(-(b_tw/2+IF(t_da=1,an_t/10,0)))/dSp -> -0.0080632156
A8: Semiancho planta | B8: =MAX(b_bf/2,IF(t_da=1,an_ls/10+b_tw/2,0),g_bf/2)+3 -> 12 | D8: =((g_tw/2)-dxc)/dSe -> -0.5684567 | E8: =((-g_d+g_tf)+dH/2)/dSe -> -0.75794227 | G8: =((dxe)-dxc)/dSe -> -0.50798258 | H8: =((-b_d+c_bot)+dH/2)/dSe -> -0.40316078 | P8: =((g_tw/2)-dxc)/dSe -> -0.5684567 | Q8: =((-e_top)+dH/2)/dSe -> 0.66521529 | S8: =((g_tw/2+e_xb)-dxc)/dSe -> -0.30640219 | T8: =((-pn_top/10-a_s*MIN(4,n_b-1))+dH/2)/dSe -> -0.080632156 | V8: =((-g_tw/2)-dxc)/dSp -> -0.59264635 | W8: =(-dZw)/dSp -> -0.48379294 | AK8: =((g_tw/2)-dxc)/dSp -> -0.5684567 | AL8: =(b_tw/2)/dSp -> 0.0080632156 | AN8: =((g_tw/2+IF(t_da=1,an_t/10,0))-dxc)/dSp -> -0.5684567 | AO8: =((b_tw/2+IF(t_da=1,an_ls/10,0)))/dSp -> 0.0080632156 | AQ8: =((g_tw/2+IF(t_da=1,an_t/10,0))-dxc)/dSp -> -0.5684567 | AR8: =(-(b_tw/2+IF(t_da=1,an_ls/10,0)))/dSp -> -0.0080632156
A9: S planta | B9: =MAX(dxf+g_bf/2,2*dZw)/2*1.06 -> 24.804 | D9: =((g_bf/2)-dxc)/dSe -> -0.21770682 | E9: =((-g_d+g_tf)+dH/2)/dSe -> -0.75794227 | G9: =((dxe+IF(c_bot>0,c_c,0))-dxc)/dSe -> -0.50798258 | H9: =((-b_d+c_bot)+dH/2)/dSe -> -0.40316078 | S9: =((g_tw/2+e_xb)-dxc)/dSe -> -0.30640219 | T9: =((-pn_top/10-a_s*MIN(5,n_b-1))+dH/2)/dSe -> -0.080632156 | AN9: =((g_tw/2)-dxc)/dSp -> -0.5684567 | AO9: =((b_tw/2+IF(t_da=1,an_ls/10,0)))/dSp -> 0.0080632156 | AQ9: =((g_tw/2)-dxc)/dSp -> -0.5684567 | AR9: =(-(b_tw/2+IF(t_da=1,an_ls/10,0)))/dSp -> -0.0080632156
A10: Ancho del elemento en elevación | B10: =IF(t_pl=1,e_xb+e_Leh,an_lb/10) -> 11 | D10: =((g_bf/2)-dxc)/dSe -> -0.21770682 | E10: =((-g_d)+dH/2)/dSe -> -0.80632156 | G10: =((dxe+IF(c_bot>0,c_c,0))-dxc)/dSe -> -0.50798258 | H10: =((-b_d)+dH/2)/dSe -> -0.40316078 | S10: =((g_tw/2+e_xb)-dxc)/dSe -> -0.30640219 | T10: =((-pn_top/10-a_s*MIN(6,n_b-1))+dH/2)/dSe -> -0.080632156 | AN10: =((g_tw/2)-dxc)/dSp -> -0.5684567 | AO10: =((b_tw/2))/dSp -> 0.0080632156 | AQ10: =((g_tw/2)-dxc)/dSp -> -0.5684567 | AR10: =(-(b_tw/2))/dSp -> -0.0080632156
D11: =((-g_bf/2)-dxc)/dSe -> -0.94339623 | E11: =((-g_d)+dH/2)/dSe -> -0.80632156 | G11: =((dxf)-dxc)/dSe -> 0.94339623 | H11: =((-b_d)+dH/2)/dSe -> -0.40316078 | S11: =((g_tw/2+e_xb)-dxc)/dSe -> -0.30640219 | T11: =((-pn_top/10-a_s*MIN(7,n_b-1))+dH/2)/dSe -> -0.080632156
D12: =((-g_bf/2)-dxc)/dSe -> -0.94339623 | E12: =((-g_d+g_tf)+dH/2)/dSe -> -0.75794227 | S12: =((g_tw/2+e_xb)-dxc)/dSe -> -0.30640219 | T12: =((-pn_top/10-a_s*MIN(8,n_b-1))+dH/2)/dSe -> -0.080632156
D13: =((-g_tw/2)-dxc)/dSe -> -0.59264635 | E13: =((-g_d+g_tf)+dH/2)/dSe -> -0.75794227 | S13: =((g_tw/2+e_xb)-dxc)/dSe -> -0.30640219 | T13: =((-pn_top/10-a_s*MIN(9,n_b-1))+dH/2)/dSe -> -0.080632156
D14: =((-g_tw/2)-dxc)/dSe -> -0.59264635 | E14: =((-g_tf)+dH/2)/dSe -> 0.75794227 | S14: =((g_tw/2+e_xb)-dxc)/dSe -> -0.30640219 | T14: =((-pn_top/10-a_s*MIN(10,n_b-1))+dH/2)/dSe -> -0.080632156
D15: =((-g_bf/2)-dxc)/dSe -> -0.94339623 | E15: =((-g_tf)+dH/2)/dSe -> 0.75794227 | S15: =((g_tw/2+e_xb)-dxc)/dSe -> -0.30640219 | T15: =((-pn_top/10-a_s*MIN(11,n_b-1))+dH/2)/dSe -> -0.080632156
D16: =((-g_bf/2)-dxc)/dSe -> -0.94339623 | E16: =((0)+dH/2)/dSe -> 0.80632156
