Workbook

Sheet DISEÑO
B2: EMPALME DE VIGA APERNADO (BEAM SPLICE) — PLACAS DE ALA Y DE ALMA
B3: AISC 360-16 (J3, J3.8, J4, J5, F13.1) · AISC Manual Parte 12 · LRFD · Unidades: Tonf, Tonf·m, mm, kgf/cm²
B4: Celdas de ingreso: | C4: valor | D4: Calculado: | E4: valor | G4: Estados: VERDE ≤ límite · AMARILLO entre límite y 1.00 · ROJO > 1.00 (ratio = demanda / capacidad, o requerido / provisto)
B6: DATOS GENERALES | G6: ELEVACIÓN DEL EMPALME | J6: SECCIÓN EN EL EMPALME | N6: VERIFICACIONES — combinación gobernante por chequeo
B7: Proyecto | C7: Edificio — ejemplo | N7: =IF(COUNT(S12:S39)=0,"SIN CARGAS",IF(MAX(S12:S39)>1,"✖ NO CUMPLE — ratio máx. "&TEXT(MAX(S12:S39),"0.00"),IF(MAX(S12:S39)>lim_verde,"▲ CUMPLE AL LÍMITE — ratio máx. "&TEXT(MAX(S12:S39),"0.00"),"✔ CUMPLE — ratio máx. "&TEXT(MAX(S12:S39),"0.00")))) -> ✔ CUMPLE — ratio máx. 0.86
B8: Elemento | C8: Viga V-2, empalme a L/4
B9: Límite verde / amarillo (ratio) | C9: 0.9
B10: 1. VIGA | N10: Verificación | O10: Referencia | P10: Demanda | Q10: Capacidad | R10: Unidad | S10: Ratio | T10: Estado | U10: Combo
B11: Perfil (catálogo o ARMADO) | C11: VK400X180X6X12 | E11: Armado (mm) | N11: ALAS
B12: Peralte d | C12: =IF(vg_perfil="ARMADO (flejes soldados)",E12,INDEX(CATALOGOS!$B$5:$B$40,MATCH(vg_perfil,CATALOGOS!$A$5:$A$40,0))) -> 400 | D12: mm | E12: 400 | N12: Pernos de ala — corte / deslizamiento | O12: J3.6 / J3.8 | P12: =INDEX(CALCULO!$D$81:$M$81,MATCH(MAX(CALCULO!$D$82:$M$82),CALCULO!$D$82:$M$82,0))/1000 -> 28.350515 | Q12: =f_nb*MIN(f_rv,f_rvs)/1000 -> 97.400895 | R12: Tonf | S12: =MAX(CALCULO!$D$82:$M$82) -> 0.29107038 | T12: =IF(ISNUMBER(S12),IF(S12>1,"NO CUMPLE",IF(S12>lim_verde,"AL LÍMITE","CUMPLE")),"N/A") -> CUMPLE | U12: =IF(ISNUMBER(S12),INDEX(CALCULO!$D$76:$M$76,MATCH(MAX(CALCULO!$D$82:$M$82),CALCULO!$D$82:$M$82,0)),"—") -> 1.2D+1.0E+L
B13: Ancho de ala bf | C13: =IF(vg_perfil="ARMADO (flejes soldados)",E13,INDEX(CATALOGOS!$C$5:$C$40,MATCH(vg_perfil,CATALOGOS!$A$5:$A$40,0))) -> 180 | D13: mm | E13: 180 | N13: Pernos de ala — aplastamiento / desgarre | O13: J3.10 | P13: =INDEX(CALCULO!$D$81:$M$81,MATCH(MAX(CALCULO!$D$83:$M$83),CALCULO!$D$83:$M$83,0))/1000 -> 28.350515 | Q13: =f_nb*MIN(f_rbb,f_rbp)/1000 -> 87.896867 | R13: Tonf | S13: =MAX(CALCULO!$D$83:$M$83) -> 0.32254296 | T13: =IF(ISNUMBER(S13),IF(S13>1,"NO CUMPLE",IF(S13>lim_verde,"AL LÍMITE","CUMPLE")),"N/A") -> CUMPLE | U13: =IF(ISNUMBER(S13),INDEX(CALCULO!$D$76:$M$76,MATCH(MAX(CALCULO!$D$83:$M$83),CALCULO!$D$83:$M$83,0)),"—") -> 1.2D+1.0E+L
B14: Espesor de alma tw | C14: =IF(vg_perfil="ARMADO (flejes soldados)",E14,INDEX(CATALOGOS!$D$5:$D$40,MATCH(vg_perfil,CATALOGOS!$A$5:$A$40,0))) -> 6 | D14: mm | E14: 6 | N14: Placas de ala — fluencia en tracción | O14: J4.1(a) | P14: =INDEX(CALCULO!$D$81:$M$81,MATCH(MAX(CALCULO!$D$84:$M$84),CALCULO!$D$84:$M$84,0))/1000 -> 28.350515 | Q14: =p_ty/1000 -> 112.6206 | R14: Tonf | S14: =MAX(CALCULO!$D$84:$M$84) -> 0.25173472 | T14: =IF(ISNUMBER(S14),IF(S14>1,"NO CUMPLE",IF(S14>lim_verde,"AL LÍMITE","CUMPLE")),"N/A") -> CUMPLE | U14: =IF(ISNUMBER(S14),INDEX(CALCULO!$D$76:$M$76,MATCH(MAX(CALCULO!$D$84:$M$84),CALCULO!$D$84:$M$84,0)),"—") -> 1.2D+1.0E+L
B15: Espesor de ala tf | C15: =IF(vg_perfil="ARMADO (flejes soldados)",E15,INDEX(CATALOGOS!$E$5:$E$40,MATCH(vg_perfil,CATALOGOS!$A$5:$A$40,0))) -> 12 | D15: mm | E15: 12 | N15: Placas de ala — ruptura en tracción | O15: J4.1(b) | P15: =INDEX(CALCULO!$D$81:$M$81,MATCH(MAX(CALCULO!$D$85:$M$85),CALCULO!$D$85:$M$85,0))/1000 -> 28.350515 | Q15: =p_tr/1000 -> 88.501477 | R15: Tonf | S15: =MAX(CALCULO!$D$85:$M$85) -> 0.32033946 | T15: =IF(ISNUMBER(S15),IF(S15>1,"NO CUMPLE",IF(S15>lim_verde,"AL LÍMITE","CUMPLE")),"N/A") -> CUMPLE | U15: =IF(ISNUMBER(S15),INDEX(CALCULO!$D$76:$M$76,MATCH(MAX(CALCULO!$D$85:$M$85),CALCULO!$D$85:$M$85,0)),"—") -> 1.2D+1.0E+L
B16: Acero | C16: A572 Gr50 | N16: Placas de ala — bloque de cortante | O16: J4.3 | P16: =INDEX(CALCULO!$D$81:$M$81,MATCH(MAX(CALCULO!$D$86:$M$86),CALCULO!$D$86:$M$86,0))/1000 -> 28.350515 | Q16: =p_bs/1000 -> 157.67185 | R16: Tonf | S16: =MAX(CALCULO!$D$86:$M$86) -> 0.17980708 | T16: =IF(ISNUMBER(S16),IF(S16>1,"NO CUMPLE",IF(S16>lim_verde,"AL LÍMITE","CUMPLE")),"N/A") -> CUMPLE | U16: =IF(ISNUMBER(S16),INDEX(CALCULO!$D$76:$M$76,MATCH(MAX(CALCULO!$D$86:$M$86),CALCULO!$D$86:$M$86,0)),"—") -> 1.2D+1.0E+L
B17: Fy / Fu | C17: =INDEX(CATALOGOS!$H$5:$H$10,MATCH(vg_acero,CATALOGOS!$G$5:$G$10,0)) -> 3515 | D17: kgf/cm² | E17: =INDEX(CATALOGOS!$I$5:$I$10,MATCH(vg_acero,CATALOGOS!$G$5:$G$10,0)) -> 4570 | N17: Placas de ala — compresión | O17: J4.4 / E3 | P17: =INDEX(CALCULO!$D$81:$M$81,MATCH(MAX(CALCULO!$D$87:$M$87),CALCULO!$D$87:$M$87,0))/1000 -> 28.350515 | Q17: =p_cb/1000 -> 112.6206 | R17: Tonf | S17: =MAX(CALCULO!$D$87:$M$87) -> 0.25173472 | T17: =IF(ISNUMBER(S17),IF(S17>1,"NO CUMPLE",IF(S17>lim_verde,"AL LÍMITE","CUMPLE")),"N/A") -> CUMPLE | U17: =IF(ISNUMBER(S17),INDEX(CALCULO!$D$76:$M$76,MATCH(MAX(CALCULO!$D$87:$M$87),CALCULO!$D$87:$M$87,0)),"—") -> 1.2D+1.0E+L
B18: Filete / radio alma–ala (para k) | C18: 6 | D18: mm | N18: Ala de viga — bloque de cortante | O18: J4.3 | P18: =INDEX(CALCULO!$D$81:$M$81,MATCH(MAX(CALCULO!$D$88:$M$88),CALCULO!$D$88:$M$88,0))/1000 -> 28.350515 | Q18: =b_bs/1000 -> 86.00283 | R18: Tonf | S18: =MAX(CALCULO!$D$88:$M$88) -> 0.32964631 | T18: =IF(ISNUMBER(S18),IF(S18>1,"NO CUMPLE",IF(S18>lim_verde,"AL LÍMITE","CUMPLE")),"N/A") -> CUMPLE | U18: =IF(ISNUMBER(S18),INDEX(CALCULO!$D$76:$M$76,MATCH(MAX(CALCULO!$D$88:$M$88),CALCULO!$D$88:$M$88,0)),"—") -> 1.2D+1.0E+L
B19: 2. EMPALME | N19: Viga — agujeros en el ala en tracción | O19: F13.1 | P19: =IF(b_F13=0,"—",INDEX(CALCULO!$D$77:$M$77,MATCH(MAX(CALCULO!$D$89:$M$89),CALCULO!$D$89:$M$89,0))/100000) -> 11 | Q19: =IF(b_F13=0,"—",b_MnF/100000) -> 29.303419 | R19: Tonf·m | S19: =IF(b_F13=0,"N/A",MAX(CALCULO!$D$89:$M$89)) -> 0.37538282 | T19: =IF(ISNUMBER(S19),IF(S19>1,"NO CUMPLE",IF(S19>lim_verde,"AL LÍMITE","CUMPLE")),"N/A") -> CUMPLE | U19: =IF(ISNUMBER(S19),INDEX(CALCULO!$D$76:$M$76,MATCH(MAX(CALCULO!$D$89:$M$89),CALCULO!$D$89:$M$89,0)),"—") -> 1.2D+1.0E+L
B20: Holgura entre extremos de vigas | C20: 10 | D20: mm | N20: ALMA
B21: Tipo de junta | C21: Aplastamiento | G21: SOLICITACIONES EN EL EMPALME (LRFD) | N21: Pernos de alma — corte / deslizamiento (perno crítico) | O21: J3.6 / J3.8 | P21: =INDEX(CALCULO!$D$91:$M$91,MATCH(MAX(CALCULO!$D$92:$M$92),CALCULO!$D$92:$M$92,0))/1000 -> 2.4664977 | Q21: =MIN(w_rv,w_rvs)/1000 -> 16.233483 | R21: Tonf | S21: =MAX(CALCULO!$D$92:$M$92) -> 0.15193892 | T21: =IF(ISNUMBER(S21),IF(S21>1,"NO CUMPLE",IF(S21>lim_verde,"AL LÍMITE","CUMPLE")),"N/A") -> CUMPLE | U21: =IF(ISNUMBER(S21),INDEX(CALCULO!$D$76:$M$76,MATCH(MAX(CALCULO!$D$92:$M$92),CALCULO!$D$92:$M$92,0)),"—") -> 1.2D+1.6L
B22: Momento tomado por el alma | C22: No (solo alas) | G22: Combinación | H22: Mu (Tonf·m) | I22: Vu (Tonf) | J22: Ratio máx. | N22: Pernos de alma — aplastamiento / desgarre | O22: J3.10 | P22: =INDEX(CALCULO!$D$91:$M$91,MATCH(MAX(CALCULO!$D$93:$M$93),CALCULO!$D$93:$M$93,0))/1000 -> 2.4664977 | Q22: =MIN(w_rbw,w_rbp)/1000 -> 7.3247389 | R22: Tonf | S22: =MAX(CALCULO!$D$93:$M$93) -> 0.33673525 | T22: =IF(ISNUMBER(S22),IF(S22>1,"NO CUMPLE",IF(S22>lim_verde,"AL LÍMITE","CUMPLE")),"N/A") -> CUMPLE | U22: =IF(ISNUMBER(S22),INDEX(CALCULO!$D$76:$M$76,MATCH(MAX(CALCULO!$D$93:$M$93),CALCULO!$D$93:$M$93,0)),"—") -> 1.2D+1.6L
B23: 3. PLACAS DE ALA (por ala) | G23: 1.2D+1.6L | H23: 9 | I23: 5.5 | J23: =IF(INDEX(CALCULO!$D$79:$M$79,1)=1,INDEX(CALCULO!$D$98:$M$98,1),"—") -> 0.33673525 | N23: Placas de alma — corte | O23: J4.2 | P23: =INDEX(CALCULO!$D$78:$M$78,MATCH(MAX(CALCULO!$D$94:$M$94),CALCULO!$D$94:$M$94,0))/1000 -> 5.5 | Q23: =MIN(w_vy,w_vr)/1000 -> 62.666352 | R23: Tonf | S23: =MAX(CALCULO!$D$94:$M$94) -> 0.087766398 | T23: =IF(ISNUMBER(S23),IF(S23>1,"NO CUMPLE",IF(S23>lim_verde,"AL LÍMITE","CUMPLE")),"N/A") -> CUMPLE | U23: =IF(ISNUMBER(S23),INDEX(CALCULO!$D$76:$M$76,MATCH(MAX(CALCULO!$D$94:$M$94),CALCULO!$D$94:$M$94,0)),"—") -> 1.2D+1.6L
B24: Acero | C24: A572 Gr50 | G24: 1.2D+1.0E+L | H24: 11 | I24: 4.5 | J24: =IF(INDEX(CALCULO!$D$79:$M$79,2)=1,INDEX(CALCULO!$D$98:$M$98,2),"—") -> 0.37538282 | N24: Placas de alma — corte + flexión | O24: Manual Ec. 10-5 | P24: =INDEX(CALCULO!$D$95:$M$95,MATCH(MAX(CALCULO!$D$95:$M$95),CALCULO!$D$95:$M$95,0))/1 -> 0.0077420812 | Q24: =1 -> 1 | R24: - | S24: =MAX(CALCULO!$D$95:$M$95) -> 0.0077420812 | T24: =IF(ISNUMBER(S24),IF(S24>1,"NO CUMPLE",IF(S24>lim_verde,"AL LÍMITE","CUMPLE")),"N/A") -> CUMPLE | U24: =IF(ISNUMBER(S24),INDEX(CALCULO!$D$76:$M$76,MATCH(MAX(CALCULO!$D$95:$M$95),CALCULO!$D$95:$M$95,0)),"—") -> 1.2D+1.6L
B25: Fy / Fu | C25: =INDEX(CATALOGOS!$H$5:$H$10,MATCH(pf_acero,CATALOGOS!$G$5:$G$10,0)) -> 3515 | D25: kgf/cm² | E25: =INDEX(CATALOGOS!$I$5:$I$10,MATCH(pf_acero,CATALOGOS!$G$5:$G$10,0)) -> 4570 | G25: 0.9D+1.0E | H25: 7.5 | I25: 3 | J25: =IF(INDEX(CALCULO!$D$79:$M$79,3)=1,INDEX(CALCULO!$D$98:$M$98,3),"—") -> 0.25594283 | N25: Placas de alma — bloque de cortante | O25: J4.3 | P25: =INDEX(CALCULO!$D$78:$M$78,MATCH(MAX(CALCULO!$D$96:$M$96),CALCULO!$D$96:$M$96,0))/1000 -> 5.5 | Q25: =w_bs/1000 -> 53.30772 | R25: Tonf | S25: =MAX(CALCULO!$D$96:$M$96) -> 0.10317455 | T25: =IF(ISNUMBER(S25),IF(S25>1,"NO CUMPLE",IF(S25>lim_verde,"AL LÍMITE","CUMPLE")),"N/A") -> CUMPLE | U25: =IF(ISNUMBER(S25),INDEX(CALCULO!$D$76:$M$76,MATCH(MAX(CALCULO!$D$96:$M$96),CALCULO!$D$96:$M$96,0)),"—") -> 1.2D+1.6L
B26: Placa exterior: ancho | C26: 180 | D26: mm | G26: C4 | J26: =IF(INDEX(CALCULO!$D$79:$M$79,4)=1,INDEX(CALCULO!$D$98:$M$98,4),"—") -> — | N26: Alma de viga — ruptura por corte | O26: J4.2(b) | P26: =INDEX(CALCULO!$D$78:$M$78,MATCH(MAX(CALCULO!$D$97:$M$97),CALCULO!$D$97:$M$97,0))/1000 -> 5.5 | Q26: =w_bvr/1000 -> 41.128972 | R26: Tonf | S26: =MAX(CALCULO!$D$97:$M$97) -> 0.13372569 | T26: =IF(ISNUMBER(S26),IF(S26>1,"NO CUMPLE",IF(S26>lim_verde,"AL LÍMITE","CUMPLE")),"N/A") -> CUMPLE | U26: =IF(ISNUMBER(S26),INDEX(CALCULO!$D$76:$M$76,MATCH(MAX(CALCULO!$D$97:$M$97),CALCULO!$D$97:$M$97,0)),"—") -> 1.2D+1.6L
B27: Placa exterior: espesor | C27: 12 | D27: mm | G27: C5 | J27: =IF(INDEX(CALCULO!$D$79:$M$79,5)=1,INDEX(CALCULO!$D$98:$M$98,5),"—") -> — | N27: DETALLES (requerido / provisto)
B28: Placas interiores (2, bajo el ala) | C28: Sí | G28: C6 | J28: =IF(INDEX(CALCULO!$D$79:$M$79,6)=1,INDEX(CALCULO!$D$98:$M$98,6),"—") -> — | N28: Paso de ala s ≥ 3·db | O28: J3.3 | P28: =3*fa_db -> 5.715 | Q28: =fa_s/10 -> 7.5 | R28: cm | S28: =(3*fa_db)/MAX(fa_s/10,0.000000001) -> 0.762 | T28: =IF(ISNUMBER(S28),IF(S28>1,"NO CUMPLE",IF(S28>lim_verde,"AL LÍMITE","CUMPLE")),"N/A") -> CUMPLE | U28: —
B29: Placas interiores: ancho c/u | C29: 70 | D29: mm | G29: C7 | J29: =IF(INDEX(CALCULO!$D$79:$M$79,7)=1,INDEX(CALCULO!$D$98:$M$98,7),"—") -> — | N29: Borde en ala de viga ≥ mínimo | O29: J3.4 | P29: =fa_em -> 2.54 | Q29: =fa_Leb/10 -> 4 | R29: cm | S29: =(fa_em)/MAX(fa_Leb/10,0.000000001) -> 0.635 | T29: =IF(ISNUMBER(S29),IF(S29>1,"NO CUMPLE",IF(S29>lim_verde,"AL LÍMITE","CUMPLE")),"N/A") -> CUMPLE | U29: —
B30: Placas interiores: espesor | C30: 10 | D30: mm | G30: C8 | J30: =IF(INDEX(CALCULO!$D$79:$M$79,8)=1,INDEX(CALCULO!$D$98:$M$98,8),"—") -> — | N30: Borde en placa de ala ≥ mínimo | O30: J3.4 | P30: =fa_em -> 2.54 | Q30: =fa_Lep/10 -> 4 | R30: cm | S30: =(fa_em)/MAX(fa_Lep/10,0.000000001) -> 0.635 | T30: =IF(ISNUMBER(S30),IF(S30>1,"NO CUMPLE",IF(S30>lim_verde,"AL LÍMITE","CUMPLE")),"N/A") -> CUMPLE | U30: —
B31: 4. PERNOS DE ALA | G31: C9 | J31: =IF(INDEX(CALCULO!$D$79:$M$79,9)=1,INDEX(CALCULO!$D$98:$M$98,9),"—") -> — | N31: Borde lateral placa exterior (bo − g)/2 | O31: J3.4 | P31: =fa_em -> 2.54 | Q31: =(pf_bo-fa_g)/20 -> 3.5 | R31: cm | S31: =(fa_em)/MAX((pf_bo-fa_g)/20,0.000000001) -> 0.72571429 | T31: =IF(ISNUMBER(S31),IF(S31>1,"NO CUMPLE",IF(S31>lim_verde,"AL LÍMITE","CUMPLE")),"N/A") -> CUMPLE | U31: —
B32: Grado | C32: A325-N (roscas incl.) | G32: C10 | J32: =IF(INDEX(CALCULO!$D$79:$M$79,10)=1,INDEX(CALCULO!$D$98:$M$98,10),"—") -> — | N32: Borde lateral ala de viga (bf − g)/2 | O32: J3.4 | P32: =fa_em -> 2.54 | Q32: =(b_bf-fa_g/10)/2 -> 3.5 | R32: cm | S32: =(fa_em)/MAX((b_bf-fa_g/10)/2,0.000000001) -> 0.72571429 | T32: =IF(ISNUMBER(S32),IF(S32>1,"NO CUMPLE",IF(S32>lim_verde,"AL LÍMITE","CUMPLE")),"N/A") -> CUMPLE | U32: —
B33: Diámetro | C33: 3/4" | G33: Se usa |Mu| y |Vu| en la sección del empalme. Filas vacías se ignoran. | N33: Placa interior cabe junto al alma: bi ≤ (bf − tw)/2 − filete | O33: Geometría | P33: =IF(j_in=0,"—",pf_bi/10) -> 7 | Q33: =IF(j_in=0,"—",(b_bf-b_tw)/2-vg_kw/10) -> 8.1 | R33: cm | S33: =IF(j_in=0,"N/A",(pf_bi/10)/MAX((b_bf-b_tw)/2-vg_kw/10,0.000000001)) -> 0.86419753 | T33: =IF(ISNUMBER(S33),IF(S33>1,"NO CUMPLE",IF(S33>lim_verde,"AL LÍMITE","CUMPLE")),"N/A") -> CUMPLE | U33: —
B34: Filas por lado del empalme (2 líneas) | C34: 3 | N34: Gramil deja espacio a la llave junto al alma: g/2 − tw/2 ≥ 1.5·db | O34: Geometría | P34: =1.5*fa_db -> 2.8575 | Q34: =fa_g/20-b_tw/2 -> 5.2 | R34: cm | S34: =(1.5*fa_db)/MAX(fa_g/20-b_tw/2,0.000000001) -> 0.54951923 | T34: =IF(ISNUMBER(S34),IF(S34>1,"NO CUMPLE",IF(S34>lim_verde,"AL LÍMITE","CUMPLE")),"N/A") -> CUMPLE | U34: —
B35: Gramil g | C35: 110 | D35: mm | G35: DETALLE DE UNA COMBINACIÓN | N35: Placa de alma cabe entre alas / placas interiores | O35: Geometría | P35: =pw_h/10 -> 28 | Q35: =b_d-2*IF(j_in=1,b_tf+pf_ti/10,b_k)-1 -> 34.6 | R35: cm | S35: =(pw_h/10)/MAX(b_d-2*IF(j_in=1,b_tf+pf_ti/10,b_k)-1,0.000000001) -> 0.80924855 | T35: =IF(ISNUMBER(S35),IF(S35>1,"NO CUMPLE",IF(S35>lim_verde,"AL LÍMITE","CUMPLE")),"N/A") -> CUMPLE | U35: —
B36: Paso s | C36: 75 | D36: mm | G36: Combinación: | H36: =G23 -> 1.2D+1.6L | K36: =IFERROR(MATCH(H36,cb_nom,0),1) -> 1 | N36: Paso de alma sv ≥ 3·db | O36: J3.3 | P36: =3*wa_db -> 5.715 | Q36: =wa_sv/10 -> 7.5 | R36: cm | S36: =(3*wa_db)/MAX(wa_sv/10,0.000000001) -> 0.762 | T36: =IF(ISNUMBER(S36),IF(S36>1,"NO CUMPLE",IF(S36>lim_verde,"AL LÍMITE","CUMPLE")),"N/A") -> CUMPLE | U36: —
B37: Borde en la viga (fila → extremo de viga) | C37: 40 | D37: mm | G37: Momento en el alma Mw | J37: =INDEX(CALCULO!$D$80:$M$80,det_k)/100000 -> 0 | L37: Tonf·m | N37: Borde en alma de viga ≥ mínimo | O37: J3.4 | P37: =wa_em -> 2.54 | Q37: =wa_Leb/10 -> 4 | R37: cm | S37: =(wa_em)/MAX(wa_Leb/10,0.000000001) -> 0.635 | T37: =IF(ISNUMBER(S37),IF(S37>1,"NO CUMPLE",IF(S37>lim_verde,"AL LÍMITE","CUMPLE")),"N/A") -> CUMPLE | U37: —
B38: Borde en la placa (última fila → extremo) | C38: 40 | D38: mm | G38: Fuerza en el ala Ff | J38: =INDEX(CALCULO!$D$81:$M$81,det_k)/1000 -> 23.195876 | L38: Tonf | N38: Borde horizontal placa de alma ≥ mínimo | O38: J3.4 | P38: =wa_em -> 2.54 | Q38: =wa_Lep/10 -> 4 | R38: cm | S38: =(wa_em)/MAX(wa_Lep/10,0.000000001) -> 0.635 | T38: =IF(ISNUMBER(S38),IF(S38>1,"NO CUMPLE",IF(S38>lim_verde,"AL LÍMITE","CUMPLE")),"N/A") -> CUMPLE | U38: —
B39: 5. PLACAS DE ALMA (2, una a cada lado) | G39: Momento en el grupo de alma Mt | J39: =INDEX(CALCULO!$D$90:$M$90,det_k)/100000 -> 0.2475 | L39: Tonf·m | N39: Borde vertical placa de alma ≥ mínimo | O39: J3.4 | P39: =wa_em -> 2.54 | Q39: =(pw_h/10-(wa_nr-1)*wa_sv/10)/2 -> 6.5 | R39: cm | S39: =(wa_em)/MAX((pw_h/10-(wa_nr-1)*wa_sv/10)/2,0.000000001) -> 0.39076923 | T39: =IF(ISNUMBER(S39),IF(S39>1,"NO CUMPLE",IF(S39>lim_verde,"AL LÍMITE","CUMPLE")),"N/A") -> CUMPLE | U39: —
B40: Acero | C40: A36 | G40: Perno crítico de alma rmáx | J40: =INDEX(CALCULO!$D$91:$M$91,det_k)/1000 -> 2.4664977 | L40: Tonf
B41: Fy / Fu | C41: =INDEX(CATALOGOS!$H$5:$H$10,MATCH(pw_acero,CATALOGOS!$G$5:$G$10,0)) -> 2530 | D41: kgf/cm² | E41: =INDEX(CATALOGOS!$I$5:$I$10,MATCH(pw_acero,CATALOGOS!$G$5:$G$10,0)) -> 4080 | G41: Largo de placas de ala | J41: =2*(fa_Leb/10+(fa_n-1)*fa_s/10+fa_Lep/10)+k_gap -> 47 | L41: cm
B42: Alto de placa hp | C42: 280 | D42: mm | G42: Ancho de placas de alma | J42: =2*(wa_Leb/10+(wa_nc-1)*wa_sh/10+wa_Lep/10)+k_gap -> 17 | L42: cm | N42: ALCANCE Y SUPUESTOS
...

Sheet CALCULO
A1: HOJA DE CÁLCULO — memoria detallada (no editar)
A2: Unidades: kgf, cm. Grupo de pernos de alma excéntrico por método elástico (conservador). φ según AISC 360-16.
A4: 0. GEOMETRÍA
A5: d | B5: Peralte | C5: cm | D5: =vg_d_mm/10 -> 40
A6: bf | B6: Ala | C6: cm | D6: =vg_bf_mm/10 -> 18
A7: tw | B7: Alma | C7: cm | D7: =vg_tw_mm/10 -> 0.6
A8: tf | B8: Ala | C8: cm | D8: =vg_tf_mm/10 -> 1.2
A9: k | B9: tf + filete | C9: cm | D9: =b_tf+vg_kw/10 -> 1.8
A10: Ix | B10: [bf·d³ − (bf − tw)(d − 2tf)³]/12 | C10: cm⁴ | D10: =(b_bf*b_d^3-(b_bf-b_tw)*(b_d-2*b_tf)^3)/12 -> 18921.805
A11: Sx | B11: Ix/(d/2) | C11: cm³ | D11: =b_Ix/(b_d/2) -> 946.09024
A12: Iw | B12: tw·(d − 2tf)³/12 | C12: cm⁴ | D12: =b_tw*(b_d-2*b_tf)^3/12 -> 2657.8688
A13: gap | B13: Holgura | C13: cm | D13: =gap/10 -> 1
A14: E | B14: Módulo de elasticidad | C14: kgf/cm² | D14: =2040000 -> 2040000
A15: SC | B15: 1 = deslizamiento crítico | C15: - | D15: =IF(LEFT(junta,3)="Des",1,0) -> 0
A16: μ | B16: 0.30 clase A ; 0.50 clase B | C16: - | D16: =IF(RIGHT(junta,5)="0.50)",0.5,0.3) -> 0.3
A17: int. | B17: 1 = placas interiores | C17: - | D17: =IF(pf_in="Sí",1,0) -> 1
A18: 1. PERNOS Y PLACAS DE ALA
A19: db | B19: Diámetro pernos de ala | C19: in | D19: =INDEX(CATALOGOS!$P$5:$P$10,MATCH(fa_diam,CATALOGOS!$O$5:$O$10,0)) -> 0.75
A20: db | B20: Diámetro pernos de ala | C20: cm | D20: =fa_dbi*2.54 -> 1.905
A21: Ab | B21: π·db²/4 | C21: cm² | D21: =PI()*fa_db^2/4 -> 2.8502296
A22: dh | B22: Agujero estándar (Tabla J3.3) | C22: cm | D22: =IF(fa_dbi<1,fa_dbi+1/16,fa_dbi+1/8)*2.54 -> 2.06375
A23: dh,net | B23: dh + 1/16 in (B4.3b) | C23: cm | D23: =fa_dh+0.15875 -> 2.2225
A24: Le,min | B24: Borde mínimo (Tabla J3.4) | C24: cm | D24: =INDEX(CATALOGOS!$Q$5:$Q$10,MATCH(fa_diam,CATALOGOS!$O$5:$O$10,0))*2.54 -> 2.54
A25: Fnv | B25: Resistencia a corte | C25: kgf/cm² | D25: =INDEX(CATALOGOS!$L$5:$L$8,MATCH(fa_grado,CATALOGOS!$K$5:$K$8,0)) -> 3797
A26: Tb | B26: Pretensión mínima (Tabla J3.1) | C26: kgf | D26: =IF(INDEX(CATALOGOS!$M$5:$M$8,MATCH(fa_grado,CATALOGOS!$K$5:$K$8,0))="A",INDEX(CATALOGOS!$R$5:$R$10,MATCH(fa_diam,CATALOGOS!$O$5:$O$10,0)),INDEX(CATALOGOS!$S$5:$S$10,MATCH(fa_diam,CATALOGOS!$O$5:$O$10,0))) -> 12701
A27: n | B27: Pernos por ala por lado = 2·filas | C27: - | D27: =2*fa_n -> 6
A28: ns | B28: Planos de corte | C28: - | D28: =1+j_in -> 2
A29: φrn | B29: Por perno: aplastamiento 0.75·Fnv·Ab·ns ; deslizamiento 1.0·μ·1.13·Tb·ns | C29: kgf | D29: =IF(j_sc=1,1*j_mu*1.13*fa_Tb*f_ns,0.75*fa_Fnv*fa_Ab*f_ns) -> 16233.483
A30: φrn,v | B30: Corte del perno (se verifica también en juntas de deslizamiento crítico) | C30: kgf | D30: =0.75*fa_Fnv*fa_Ab*f_ns -> 16233.483
A31: Lc,ala | B31: mín(Le,viga − dh/2 ; s − dh) | C31: cm | D31: =MIN(fa_Leb/10-fa_dh/2,fa_s/10-fa_dh) -> 2.968125
A32: Lc,placa | B32: mín(Le,placa − dh/2 ; s − dh) | C32: cm | D32: =MIN(fa_Lep/10-fa_dh/2,fa_s/10-fa_dh) -> 2.968125
A33: φrn | B33: Aplastamiento por perno en el ala: 0.75·mín(1.2Lc ; 2.4db)·tf·Fu | C33: kgf | D33: =0.75*MIN(1.2*f_Lcb,2.4*fa_db)*b_tf*vg_Fu -> 14649.478
A34: φrn | B34: Aplastamiento por perno en placas (exterior + interior) | C34: kgf | D34: =0.75*MIN(1.2*f_Lcp,2.4*fa_db)*(pf_to+j_in*pf_ti)/10*pf_Fu -> 26857.376
A35: Ag | B35: bo·to + 2·bi·ti | C35: cm² | D35: =pf_bo/10*pf_to/10+j_in*2*pf_bi/10*pf_ti/10 -> 35.6
A36: An | B36: mín([bo − 2dh,n]·to + 2[bi − dh,n]·ti ; 0.85Ag) | C36: cm² | D36: =MIN((pf_bo/10-2*fa_dn)*pf_to/10+j_in*2*(pf_bi/10-fa_dn)*pf_ti/10,0.85*p_Ag) -> 25.821
A37: φRn | B37: Fluencia en tracción 0.90·Fy·Ag | C37: kgf | D37: =0.9*pf_Fy*p_Ag -> 112620.6
A38: φRn | B38: Ruptura en tracción 0.75·Fu·An (J4.1) | C38: kgf | D38: =0.75*pf_Fu*p_An -> 88501.477
A39: φRn | B39: Bloque de cortante de placas: mín(bloques exteriores ; central) exterior + interiores (J4.3) | C39: kgf | D39: =MIN(0.75*(MIN(0.6*pf_Fu*(2*(fa_Lep/10+(fa_n-1)*fa_s/10)-2*(fa_n-0.5)*fa_dn),0.6*pf_Fy*2*(fa_Lep/10+(fa_n-1)*fa_s/10))*pf_to/10+pf_Fu*2*((pf_bo/10-fa_g/10)/2-fa_dn/2)*pf_to/10),0.75*(MIN(0.6*pf_Fu*(2*(fa_Lep/10+(fa_n-1)*fa_s/10)-2*(fa_n-0.5)*fa_dn),0.6*pf_Fy*2*(fa_Lep/10+(fa_n-1)*fa_s/10))*pf_to/10+pf_Fu*(fa_g/10-fa_dn)*pf_to/10))+j_in*0.75*(MIN(0.6*pf_Fu*(2*(fa_Lep/10+(fa_n-1)*fa_s/10)-2*(fa_n-0.5)*fa_dn),0.6*pf_Fy*2*(fa_Lep/10+(fa_n-1)*fa_s/10))*pf_ti/10+pf_Fu*2*((b_bf-fa_g/10)/2-fa_dn/2)*pf_ti/10) -> 157671.86
A40: KL/r | B40: 0.65·(gap + 2·Le,viga)/(t,mín/√12) | C40: - | D40: =0.65*(k_gap+2*fa_Leb/10)/(IF(j_in=1,MIN(pf_to,pf_ti),pf_to)/10/SQRT(12)) -> 20.264994
A41: Fcr | B41: KL/r ≤ 25: Fy ; si no Cap. E | C41: kgf/cm² | D41: =IF(p_KLr<=25,pf_Fy,IF(pf_Fy/(PI()^2*k_E/p_KLr^2)<=2.25,0.658^(pf_Fy/(PI()^2*k_E/p_KLr^2))*pf_Fy,0.877*PI()^2*k_E/p_KLr^2)) -> 3515
...

Sheet CATALOGOS
A1: CATÁLOGOS — ampliables agregando filas dentro de cada rango
A3: Perfiles (VK/HA: KUBIEC; W: AISC; ARMADO: medidas manuales) | G3: Aceros (kgf/cm²) | K3: Pernos (kgf/cm²) — Tabla J3.2 ; grupo para Tb | O3: Diámetros — borde mín. J3.4 ; Tb (kgf) Tabla J3.1 | U3: Electrodo | X3: Opción | Z3: Tipo de junta apernada | AB3: Espesores (mm)
A4: Perfil | B4: d | C4: bf | D4: tw | E4: tf | G4: Acero | H4: Fy | I4: Fu | K4: Grado | L4: Fnv | M4: Grupo | O4: Ø | P4: db (in) | Q4: borde (in) | R4: Tb A325 | S4: Tb A490 | U4: Electrodo | V4: FEXX | X4: Sí/No | Z4: Junta | AB4: t
A5: ARMADO (flejes soldados) | G5: A36 | H5: 2530 | I5: 4080 | K5: A325-N (roscas incl.) | L5: 3797 | M5: A | O5: 5/8" | P5: 0.625 | Q5: 0.875 | R5: 8618 | S5: 10886 | U5: E60XX | V5: 4220 | X5: Sí | Z5: Aplastamiento | AB5: 0
A6: VK250X130X4X8 | B6: 250 | C6: 130 | D6: 4 | E6: 8 | G6: A572 Gr50 | H6: 3515 | I6: 4570 | K6: A325-X (roscas excl.) | L6: 4781 | M6: A | O6: 3/4" | P6: 0.75 | Q6: 1 | R6: 12701 | S6: 15876 | U6: E70XX | V6: 4920 | X6: No | Z6: Deslizamiento crítico clase A (μ = 0.30) | AB6: 3
A7: VK300X150X4X10 | B7: 300 | C7: 150 | D7: 4 | E7: 10 | G7: A992 | H7: 3515 | I7: 4570 | K7: A490-N (roscas incl.) | L7: 4781 | M7: B | O7: 7/8" | P7: 0.875 | Q7: 1.125 | R7: 17690 | S7: 22226 | Z7: Deslizamiento crítico clase B (μ = 0.50) | AB7: 5
A8: VK330X160X6X10 | B8: 330 | C8: 160 | D8: 6 | E8: 10 | G8: A588 Gr50 | H8: 3515 | I8: 4920 | K8: A490-X (roscas excl.) | L8: 5906 | M8: B | O8: 1" | P8: 1 | Q8: 1.25 | R8: 23133 | S8: 29030 | AB8: 6
A9: VK360X180X6X10 | B9: 360 | C9: 180 | D9: 6 | E9: 10 | O9: 1-1/8" | P9: 1.125 | Q9: 1.5 | R9: 29030 | S9: 36287 | AB9: 8
A10: VK400X180X6X10 | B10: 400 | C10: 180 | D10: 6 | E10: 10 | O10: 1-1/4" | P10: 1.25 | Q10: 1.625 | R10: 36741 | S10: 46266 | AB10: 10
A11: VK400X180X6X12 | B11: 400 | C11: 180 | D11: 6 | E11: 12 | AB11: 12
A12: VK420X180X6X12 | B12: 420 | C12: 180 | D12: 6 | E12: 12 | AB12: 15
A13: VK440X180X6X12 | B13: 440 | C13: 180 | D13: 6 | E13: 12 | AB13: 16
A14: HA200X140X6X12 | B14: 200 | C14: 140 | D14: 6 | E14: 12 | AB14: 19
A15: HA240X180X6X12 | B15: 240 | C15: 180 | D15: 6 | E15: 12 | AB15: 20
A16: HA300X180X6X12 | B16: 300 | C16: 180 | D16: 6 | E16: 12 | AB16: 22
A17: HA360X180X6X12 | B17: 360 | C17: 180 | D17: 6 | E17: 12 | AB17: 25
A18: HA380X200X8X15 | B18: 380 | C18: 200 | D18: 8 | E18: 15 | AB18: 28
A19: HA400X200X8X15 | B19: 400 | C19: 200 | D19: 8 | E19: 15 | AB19: 30
A20: HA420X210X8X15 | B20: 420 | C20: 210 | D20: 8 | E20: 15 | AB20: 32
A21: HA440X220X8X15 | B21: 440 | C21: 220 | D21: 8 | E21: 15 | AB21: 35
A22: HA460X230X8X15 | B22: 460 | C22: 230 | D22: 8 | E22: 15 | AB22: 38
A23: HA480X240X8X15 | B23: 480 | C23: 240 | D23: 8 | E23: 15
A24: HA500X250X10X15 | B24: 500 | C24: 250 | D24: 10 | E24: 15
A25: HA520X260X10X15 | B25: 520 | C25: 260 | D25: 10 | E25: 15
A26: HA540X270X10X15 | B26: 540 | C26: 270 | D26: 10 | E26: 15
A27: W8X31 | B27: 203 | C27: 203 | D27: 7.2 | E27: 11
A28: W10X49 | B28: 254 | C28: 254 | D28: 8.6 | E28: 14.2
A29: W12X65 | B29: 308 | C29: 305 | D29: 9.9 | E29: 15.4
A30: W14X90 | B30: 356 | C30: 368 | D30: 11.2 | E30: 18
A31: W14X120 | B31: 368 | C31: 373 | D31: 15 | E31: 23.9
A32: W16X40 | B32: 407 | C32: 178 | D32: 7.7 | E32: 12.8
A33: W18X50 | B33: 457 | C33: 190 | D33: 9 | E33: 14.5
A34: W21X62 | B34: 533 | C34: 209 | D34: 10.2 | E34: 15.6
A35: W24X76 | B35: 608 | C35: 228 | D35: 11.2 | E35: 17.3

Sheet DIBUJO
A1: Coordenadas de las vistas (normalizadas a ±1). No editar.
D2: Viga izq | G2: Alas int izq | J2: Alas int2 izq | M2: Viga der | P2: Alas int der | S2: Alas int2 der | V2: Placa ext sup | Y2: Placa ext inf | AB2: Placa int sup | AE2: Placa int inf | AH2: Placa alma | AK2: Pernos ala | AN2: Pernos alma | AQ2: Viga | AT2: Ext sup | AW2: Ext inf | AZ2: Int sup | BC2: Int inf | BF2: Int sup- | BI2: Int inf- | BL2: Alma der | BO2: Alma izq | BR2: Pernos ala | BU2: Pernos alma
A3: Largo placa de ala | B3: =2*(fa_Leb/10+(fa_n-1)*fa_s/10+fa_Lep/10)+k_gap -> 47
A4: Ancho placa de alma | B4: =2*(wa_Leb/10+(wa_nc-1)*wa_sh/10+wa_Lep/10)+k_gap -> 17 | D4: =((-dLb)-(0))/dSe -> -0.95238095 | E4: =((b_d/2)-(0))/dSe -> 0.4378763 | G4: =((-dLb)-(0))/dSe -> -0.95238095 | H4: =((b_d/2-b_tf)-(0))/dSe -> 0.41160372 | J4: =((-dLb)-(0))/dSe -> -0.95238095 | K4: =((-b_d/2+b_tf)-(0))/dSe -> -0.41160372 | M4: =((dLb)-(0))/dSe -> 0.95238095 | N4: =((b_d/2)-(0))/dSe -> 0.4378763 | P4: =((dLb)-(0))/dSe -> 0.95238095 | Q4: =((b_d/2-b_tf)-(0))/dSe -> 0.41160372 | S4: =((dLb)-(0))/dSe -> 0.95238095 | T4: =((-b_d/2+b_tf)-(0))/dSe -> -0.41160372 | V4: =((-dLfp/2)-(0))/dSe -> -0.51450465 | W4: =((b_d/2)-(0))/dSe -> 0.4378763 | Y4: =((-dLfp/2)-(0))/dSe -> -0.51450465 | Z4: =((-b_d/2-pf_to/10)-(0))/dSe -> -0.46414888 | AB4: =((-dLfp/2*j_in)-(0))/dSe -> -0.51450465 | AC4: =((b_d/2-b_tf-j_in*pf_ti/10)-(0))/dSe -> 0.38970991 | AE4: =((-dLfp/2*j_in)-(0))/dSe -> -0.51450465 | AF4: =((-b_d/2+b_tf)-(0))/dSe -> -0.41160372 | AH4: =((-dLwp/2)-(0))/dSe -> -0.18609743 | AI4: =((-pw_h/20)-(0))/dSe -> -0.30651341 | AK4: =((-1*(k_gap/2+fa_Leb/10+fa_s/10*MIN(0,fa_n-1)))-(0))/dSe -> -0.098522167 | AL4: =((b_d/2)-(0))/dSe -> 0.4378763 | AN4: =((-1*(k_gap/2+wa_Leb/10+wa_sh/10*MIN(0,wa_nc-1)))-(0))/dSe -> -0.098522167 | AO4: =((-(wa_nr-1)*wa_sv/20+wa_sv/10*MIN(0,wa_nr-1))-(0))/dSe -> -0.16420361 | AQ4: =((-b_bf/2)-(0))/dSs -> -0.38593482 | AR4: =((b_d/2)-(0))/dSs -> 0.85763293 | AT4: =((-pf_bo/20)-(0))/dSs -> -0.38593482 | AU4: =((b_d/2)-(0))/dSs -> 0.85763293 | AW4: =((-pf_bo/20)-(0))/dSs -> -0.38593482 | AX4: =((-b_d/2-pf_to/10)-(0))/dSs -> -0.90909091 | AZ4: =(((b_bf/2-j_in*pf_bi/10))-(0))/dSs -> 0.085763293 | BA4: =(((b_d/2-b_tf-j_in*pf_ti/10))-(0))/dSs -> 0.76329331 | BC4: =(((b_bf/2-j_in*pf_bi/10))-(0))/dSs -> 0.085763293 | BD4: =((-(b_d/2-b_tf-j_in*pf_ti/10))-(0))/dSs -> -0.76329331 | BF4: =((-(b_bf/2-j_in*pf_bi/10))-(0))/dSs -> -0.085763293 | BG4: =(((b_d/2-b_tf-j_in*pf_ti/10))-(0))/dSs -> 0.76329331 | BI4: =((-(b_bf/2-j_in*pf_bi/10))-(0))/dSs -> -0.085763293 | BJ4: =((-(b_d/2-b_tf-j_in*pf_ti/10))-(0))/dSs -> -0.76329331 | BL4: =((b_tw/2)-(0))/dSs -> 0.012864494 | BM4: =((-pw_h/20)-(0))/dSs -> -0.60034305 | BO4: =((-b_tw/2-pw_t/10)-(0))/dSs -> -0.047169811 | BP4: =((-pw_h/20)-(0))/dSs -> -0.60034305 | BR4: =((-fa_g/20)-(0))/dSs -> -0.23584906 | BS4: =((b_d/2)-(0))/dSs -> 0.85763293 | BU4: =((0)-(0))/dSs -> 0 | BV4: =((-(wa_nr-1)*wa_sv/20+wa_sv/10*MIN(0,wa_nr-1))-(0))/dSs -> -0.32161235
A5: Largo de viga dibujado (semi) | B5: =MAX(dLfp,dLwp)/2+0.5*b_d -> 43.5 | D5: =((-k_gap/2)-(0))/dSe -> -0.010946907 | E5: =((b_d/2)-(0))/dSe -> 0.4378763 | G5: =((-k_gap/2)-(0))/dSe -> -0.010946907 | H5: =((b_d/2-b_tf)-(0))/dSe -> 0.41160372 | J5: =((-k_gap/2)-(0))/dSe -> -0.010946907 | K5: =((-b_d/2+b_tf)-(0))/dSe -> -0.41160372 | M5: =((k_gap/2)-(0))/dSe -> 0.010946907 | N5: =((b_d/2)-(0))/dSe -> 0.4378763 | P5: =((k_gap/2)-(0))/dSe -> 0.010946907 | Q5: =((b_d/2-b_tf)-(0))/dSe -> 0.41160372 | S5: =((k_gap/2)-(0))/dSe -> 0.010946907 | T5: =((-b_d/2+b_tf)-(0))/dSe -> -0.41160372 | V5: =((-dLfp/2)-(0))/dSe -> -0.51450465 | W5: =((b_d/2+pf_to/10)-(0))/dSe -> 0.46414888 | Y5: =((-dLfp/2)-(0))/dSe -> -0.51450465 | Z5: =((-b_d/2)-(0))/dSe -> -0.4378763 | AB5: =((-dLfp/2*j_in)-(0))/dSe -> -0.51450465 | AC5: =((b_d/2-b_tf)-(0))/dSe -> 0.41160372 | AE5: =((-dLfp/2*j_in)-(0))/dSe -> -0.51450465 | AF5: =((-b_d/2+b_tf+j_in*pf_ti/10)-(0))/dSe -> -0.38970991 | AH5: =((-dLwp/2)-(0))/dSe -> -0.18609743 | AI5: =((pw_h/20)-(0))/dSe -> 0.30651341 | AK5: =((-1*(k_gap/2+fa_Leb/10+fa_s/10*MIN(1,fa_n-1)))-(0))/dSe -> -0.26272578 | AL5: =((b_d/2)-(0))/dSe -> 0.4378763 | AN5: =((-1*(k_gap/2+wa_Leb/10+wa_sh/10*MIN(0,wa_nc-1)))-(0))/dSe -> -0.098522167 | AO5: =((-(wa_nr-1)*wa_sv/20+wa_sv/10*MIN(1,wa_nr-1))-(0))/dSe -> 0 | AQ5: =((b_bf/2)-(0))/dSs -> 0.38593482 | AR5: =((b_d/2)-(0))/dSs -> 0.85763293 | AT5: =((-pf_bo/20)-(0))/dSs -> -0.38593482 | AU5: =((b_d/2+pf_to/10)-(0))/dSs -> 0.90909091 | AW5: =((-pf_bo/20)-(0))/dSs -> -0.38593482 | AX5: =((-b_d/2)-(0))/dSs -> -0.85763293 | AZ5: =(((b_bf/2-j_in*pf_bi/10))-(0))/dSs -> 0.085763293 | BA5: =(((b_d/2-b_tf))-(0))/dSs -> 0.80617496 | BC5: =(((b_bf/2-j_in*pf_bi/10))-(0))/dSs -> 0.085763293 | BD5: =((-(b_d/2-b_tf))-(0))/dSs -> -0.80617496 | BF5: =((-(b_bf/2-j_in*pf_bi/10))-(0))/dSs -> -0.085763293 | BG5: =(((b_d/2-b_tf))-(0))/dSs -> 0.80617496 | BI5: =((-(b_bf/2-j_in*pf_bi/10))-(0))/dSs -> -0.085763293 | BJ5: =((-(b_d/2-b_tf))-(0))/dSs -> -0.80617496 | BL5: =((b_tw/2)-(0))/dSs -> 0.012864494 | BM5: =((pw_h/20)-(0))/dSs -> 0.60034305 | BO5: =((-b_tw/2-pw_t/10)-(0))/dSs -> -0.047169811 | BP5: =((pw_h/20)-(0))/dSs -> 0.60034305 | BR5: =((fa_g/20)-(0))/dSs -> 0.23584906 | BS5: =((b_d/2)-(0))/dSs -> 0.85763293 | BU5: =((0)-(0))/dSs -> 0 | BV5: =((-(wa_nr-1)*wa_sv/20+wa_sv/10*MIN(1,wa_nr-1))-(0))/dSs -> 0
A6: S elevación | B6: =MAX(2*dLb,b_d+2*pf_to/10)/2*1.05 -> 45.675 | D6: =((-k_gap/2)-(0))/dSe -> -0.010946907 | E6: =((-b_d/2)-(0))/dSe -> -0.4378763 | M6: =((k_gap/2)-(0))/dSe -> 0.010946907 | N6: =((-b_d/2)-(0))/dSe -> -0.4378763 | V6: =((dLfp/2)-(0))/dSe -> 0.51450465 | W6: =((b_d/2+pf_to/10)-(0))/dSe -> 0.46414888 | Y6: =((dLfp/2)-(0))/dSe -> 0.51450465 | Z6: =((-b_d/2)-(0))/dSe -> -0.4378763 | AB6: =((dLfp/2*j_in)-(0))/dSe -> 0.51450465 | AC6: =((b_d/2-b_tf)-(0))/dSe -> 0.41160372 | AE6: =((dLfp/2*j_in)-(0))/dSe -> 0.51450465 | AF6: =((-b_d/2+b_tf+j_in*pf_ti/10)-(0))/dSe -> -0.38970991 | AH6: =((dLwp/2)-(0))/dSe -> 0.18609743 | AI6: =((pw_h/20)-(0))/dSe -> 0.30651341 | AK6: =((-1*(k_gap/2+fa_Leb/10+fa_s/10*MIN(2,fa_n-1)))-(0))/dSe -> -0.42692939 | AL6: =((b_d/2)-(0))/dSe -> 0.4378763 | AN6: =((-1*(k_gap/2+wa_Leb/10+wa_sh/10*MIN(0,wa_nc-1)))-(0))/dSe -> -0.098522167 | AO6: =((-(wa_nr-1)*wa_sv/20+wa_sv/10*MIN(2,wa_nr-1))-(0))/dSe -> 0.16420361 | AQ6: =((b_bf/2)-(0))/dSs -> 0.38593482 | AR6: =((b_d/2-b_tf)-(0))/dSs -> 0.80617496 | AT6: =((pf_bo/20)-(0))/dSs -> 0.38593482 | AU6: =((b_d/2+pf_to/10)-(0))/dSs -> 0.90909091 | AW6: =((pf_bo/20)-(0))/dSs -> 0.38593482 | AX6: =((-b_d/2)-(0))/dSs -> -0.85763293 | AZ6: =(((b_bf/2))-(0))/dSs -> 0.38593482 | BA6: =(((b_d/2-b_tf))-(0))/dSs -> 0.80617496 | BC6: =(((b_bf/2))-(0))/dSs -> 0.38593482 | BD6: =((-(b_d/2-b_tf))-(0))/dSs -> -0.80617496 | BF6: =((-(b_bf/2))-(0))/dSs -> -0.38593482 | BG6: =(((b_d/2-b_tf))-(0))/dSs -> 0.80617496 | BI6: =((-(b_bf/2))-(0))/dSs -> -0.38593482 | BJ6: =((-(b_d/2-b_tf))-(0))/dSs -> -0.80617496 | BL6: =((b_tw/2+pw_t/10)-(0))/dSs -> 0.047169811 | BM6: =((pw_h/20)-(0))/dSs -> 0.60034305 | BO6: =((-b_tw/2)-(0))/dSs -> -0.012864494 | BP6: =((pw_h/20)-(0))/dSs -> 0.60034305 | BR6: =((-fa_g/20)-(0))/dSs -> -0.23584906 | BS6: =((-b_d/2)-(0))/dSs -> -0.85763293 | BU6: =((0)-(0))/dSs -> 0 | BV6: =((-(wa_nr-1)*wa_sv/20+wa_sv/10*MIN(2,wa_nr-1))-(0))/dSs -> 0.32161235
A7: S sección | B7: =MAX(b_bf,pf_bo/10,b_d+2*pf_to/10)/2*1.1 -> 23.32 | D7: =((-dLb)-(0))/dSe -> -0.95238095 | E7: =((-b_d/2)-(0))/dSe -> -0.4378763 | M7: =((dLb)-(0))/dSe -> 0.95238095 | N7: =((-b_d/2)-(0))/dSe -> -0.4378763 | V7: =((dLfp/2)-(0))/dSe -> 0.51450465 | W7: =((b_d/2)-(0))/dSe -> 0.4378763 | Y7: =((dLfp/2)-(0))/dSe -> 0.51450465 | Z7: =((-b_d/2-pf_to/10)-(0))/dSe -> -0.46414888 | AB7: =((dLfp/2*j_in)-(0))/dSe -> 0.51450465 | AC7: =((b_d/2-b_tf-j_in*pf_ti/10)-(0))/dSe -> 0.38970991 | AE7: =((dLfp/2*j_in)-(0))/dSe -> 0.51450465 | AF7: =((-b_d/2+b_tf)-(0))/dSe -> -0.41160372 | AH7: =((dLwp/2)-(0))/dSe -> 0.18609743 | AI7: =((-pw_h/20)-(0))/dSe -> -0.30651341 | AK7: =((-1*(k_gap/2+fa_Leb/10+fa_s/10*MIN(3,fa_n-1)))-(0))/dSe -> -0.42692939 | AL7: =((b_d/2)-(0))/dSe -> 0.4378763 | AN7: =((-1*(k_gap/2+wa_Leb/10+wa_sh/10*MIN(0,wa_nc-1)))-(0))/dSe -> -0.098522167 | AO7: =((-(wa_nr-1)*wa_sv/20+wa_sv/10*MIN(3,wa_nr-1))-(0))/dSe -> 0.16420361 | AQ7: =((b_tw/2)-(0))/dSs -> 0.012864494 | AR7: =((b_d/2-b_tf)-(0))/dSs -> 0.80617496 | AT7: =((pf_bo/20)-(0))/dSs -> 0.38593482 | AU7: =((b_d/2)-(0))/dSs -> 0.85763293 | AW7: =((pf_bo/20)-(0))/dSs -> 0.38593482 | AX7: =((-b_d/2-pf_to/10)-(0))/dSs -> -0.90909091 | AZ7: =(((b_bf/2))-(0))/dSs -> 0.38593482 | BA7: =(((b_d/2-b_tf-j_in*pf_ti/10))-(0))/dSs -> 0.76329331 | BC7: =(((b_bf/2))-(0))/dSs -> 0.38593482 | BD7: =((-(b_d/2-b_tf-j_in*pf_ti/10))-(0))/dSs -> -0.76329331 | BF7: =((-(b_bf/2))-(0))/dSs -> -0.38593482 | BG7: =(((b_d/2-b_tf-j_in*pf_ti/10))-(0))/dSs -> 0.76329331 | BI7: =((-(b_bf/2))-(0))/dSs -> -0.38593482 | BJ7: =((-(b_d/2-b_tf-j_in*pf_ti/10))-(0))/dSs -> -0.76329331 | BL7: =((b_tw/2+pw_t/10)-(0))/dSs -> 0.047169811 | BM7: =((-pw_h/20)-(0))/dSs -> -0.60034305 | BO7: =((-b_tw/2)-(0))/dSs -> -0.012864494 | BP7: =((-pw_h/20)-(0))/dSs -> -0.60034305 | BR7: =((fa_g/20)-(0))/dSs -> 0.23584906 | BS7: =((-b_d/2)-(0))/dSs -> -0.85763293 | BU7: =((0)-(0))/dSs -> 0 | BV7: =((-(wa_nr-1)*wa_sv/20+wa_sv/10*MIN(3,wa_nr-1))-(0))/dSs -> 0.32161235
V8: =((-dLfp/2)-(0))/dSe -> -0.51450465 | W8: =((b_d/2)-(0))/dSe -> 0.4378763 | Y8: =((-dLfp/2)-(0))/dSe -> -0.51450465 | Z8: =((-b_d/2-pf_to/10)-(0))/dSe -> -0.46414888 | AB8: =((-dLfp/2*j_in)-(0))/dSe -> -0.51450465 | AC8: =((b_d/2-b_tf-j_in*pf_ti/10)-(0))/dSe -> 0.38970991 | AE8: =((-dLfp/2*j_in)-(0))/dSe -> -0.51450465 | AF8: =((-b_d/2+b_tf)-(0))/dSe -> -0.41160372 | AH8: =((-dLwp/2)-(0))/dSe -> -0.18609743 | AI8: =((-pw_h/20)-(0))/dSe -> -0.30651341 | AK8: =((-1*(k_gap/2+fa_Leb/10+fa_s/10*MIN(4,fa_n-1)))-(0))/dSe -> -0.42692939 | AL8: =((b_d/2)-(0))/dSe -> 0.4378763 | AN8: =((-1*(k_gap/2+wa_Leb/10+wa_sh/10*MIN(0,wa_nc-1)))-(0))/dSe -> -0.098522167 | AO8: =((-(wa_nr-1)*wa_sv/20+wa_sv/10*MIN(4,wa_nr-1))-(0))/dSe -> 0.16420361 | AQ8: =((b_tw/2)-(0))/dSs -> 0.012864494 | AR8: =((-b_d/2+b_tf)-(0))/dSs -> -0.80617496 | AT8: =((-pf_bo/20)-(0))/dSs -> -0.38593482 | AU8: =((b_d/2)-(0))/dSs -> 0.85763293 | AW8: =((-pf_bo/20)-(0))/dSs -> -0.38593482 | AX8: =((-b_d/2-pf_to/10)-(0))/dSs -> -0.90909091 | AZ8: =(((b_bf/2-j_in*pf_bi/10))-(0))/dSs -> 0.085763293 | BA8: =(((b_d/2-b_tf-j_in*pf_ti/10))-(0))/dSs -> 0.76329331 | BC8: =(((b_bf/2-j_in*pf_bi/10))-(0))/dSs -> 0.085763293 | BD8: =((-(b_d/2-b_tf-j_in*pf_ti/10))-(0))/dSs -> -0.76329331 | BF8: =((-(b_bf/2-j_in*pf_bi/10))-(0))/dSs -> -0.085763293 | BG8: =(((b_d/2-b_tf-j_in*pf_ti/10))-(0))/dSs -> 0.76329331 | BI8: =((-(b_bf/2-j_in*pf_bi/10))-(0))/dSs -> -0.085763293 | BJ8: =((-(b_d/2-b_tf-j_in*pf_ti/10))-(0))/dSs -> -0.76329331 | BL8: =((b_tw/2)-(0))/dSs -> 0.012864494 | BM8: =((-pw_h/20)-(0))/dSs -> -0.60034305 | BO8: =((-b_tw/2-pw_t/10)-(0))/dSs -> -0.047169811 | BP8: =((-pw_h/20)-(0))/dSs -> -0.60034305 | BU8: =((0)-(0))/dSs -> 0 | BV8: =((-(wa_nr-1)*wa_sv/20+wa_sv/10*MIN(4,wa_nr-1))-(0))/dSs -> 0.32161235
AK9: =((-1*(k_gap/2+fa_Leb/10+fa_s/10*MIN(5,fa_n-1)))-(0))/dSe -> -0.42692939 | AL9: =((b_d/2)-(0))/dSe -> 0.4378763 | AN9: =((-1*(k_gap/2+wa_Leb/10+wa_sh/10*MIN(0,wa_nc-1)))-(0))/dSe -> -0.098522167 | AO9: =((-(wa_nr-1)*wa_sv/20+wa_sv/10*MIN(5,wa_nr-1))-(0))/dSe -> 0.16420361 | AQ9: =((b_bf/2)-(0))/dSs -> 0.38593482 | AR9: =((-b_d/2+b_tf)-(0))/dSs -> -0.80617496 | BU9: =((0)-(0))/dSs -> 0 | BV9: =((-(wa_nr-1)*wa_sv/20+wa_sv/10*MIN(5,wa_nr-1))-(0))/dSs -> 0.32161235
AK10: =((-1*(k_gap/2+fa_Leb/10+fa_s/10*MIN(6,fa_n-1)))-(0))/dSe -> -0.42692939 | AL10: =((b_d/2)-(0))/dSe -> 0.4378763 | AN10: =((-1*(k_gap/2+wa_Leb/10+wa_sh/10*MIN(0,wa_nc-1)))-(0))/dSe -> -0.098522167 | AO10: =((-(wa_nr-1)*wa_sv/20+wa_sv/10*MIN(6,wa_nr-1))-(0))/dSe -> 0.16420361 | AQ10: =((b_bf/2)-(0))/dSs -> 0.38593482 | AR10: =((-b_d/2)-(0))/dSs -> -0.85763293 | BU10: =((0)-(0))/dSs -> 0 | BV10: =((-(wa_nr-1)*wa_sv/20+wa_sv/10*MIN(6,wa_nr-1))-(0))/dSs -> 0.32161235
AK11: =((-1*(k_gap/2+fa_Leb/10+fa_s/10*MIN(7,fa_n-1)))-(0))/dSe -> -0.42692939 | AL11: =((b_d/2)-(0))/dSe -> 0.4378763 | AN11: =((-1*(k_gap/2+wa_Leb/10+wa_sh/10*MIN(0,wa_nc-1)))-(0))/dSe -> -0.098522167 | AO11: =((-(wa_nr-1)*wa_sv/20+wa_sv/10*MIN(7,wa_nr-1))-(0))/dSe -> 0.16420361 | AQ11: =((-b_bf/2)-(0))/dSs -> -0.38593482 | AR11: =((-b_d/2)-(0))/dSs -> -0.85763293 | BU11: =((0)-(0))/dSs -> 0 | BV11: =((-(wa_nr-1)*wa_sv/20+wa_sv/10*MIN(7,wa_nr-1))-(0))/dSs -> 0.32161235
AK12: =((-1*(k_gap/2+fa_Leb/10+fa_s/10*MIN(0,fa_n-1)))-(0))/dSe -> -0.098522167 | AL12: =((-b_d/2)-(0))/dSe -> -0.4378763 | AN12: =((-1*(k_gap/2+wa_Leb/10+wa_sh/10*MIN(1,wa_nc-1)))-(0))/dSe -> -0.098522167 | AO12: =((-(wa_nr-1)*wa_sv/20+wa_sv/10*MIN(0,wa_nr-1))-(0))/dSe -> -0.16420361 | AQ12: =((-b_bf/2)-(0))/dSs -> -0.38593482 | AR12: =((-b_d/2+b_tf)-(0))/dSs -> -0.80617496
AK13: =((-1*(k_gap/2+fa_Leb/10+fa_s/10*MIN(1,fa_n-1)))-(0))/dSe -> -0.26272578 | AL13: =((-b_d/2)-(0))/dSe -> -0.4378763 | AN13: =((-1*(k_gap/2+wa_Leb/10+wa_sh/10*MIN(1,wa_nc-1)))-(0))/dSe -> -0.098522167 | AO13: =((-(wa_nr-1)*wa_sv/20+wa_sv/10*MIN(1,wa_nr-1))-(0))/dSe -> 0 | AQ13: =((-b_tw/2)-(0))/dSs -> -0.012864494 | AR13: =((-b_d/2+b_tf)-(0))/dSs -> -0.80617496
AK14: =((-1*(k_gap/2+fa_Leb/10+fa_s/10*MIN(2,fa_n-1)))-(0))/dSe -> -0.42692939 | AL14: =((-b_d/2)-(0))/dSe -> -0.4378763 | AN14: =((-1*(k_gap/2+wa_Leb/10+wa_sh/10*MIN(1,wa_nc-1)))-(0))/dSe -> -0.098522167 | AO14: =((-(wa_nr-1)*wa_sv/20+wa_sv/10*MIN(2,wa_nr-1))-(0))/dSe -> 0.16420361 | AQ14: =((-b_tw/2)-(0))/dSs -> -0.012864494 | AR14: =((b_d/2-b_tf)-(0))/dSs -> 0.80617496
AK15: =((-1*(k_gap/2+fa_Leb/10+fa_s/10*MIN(3,fa_n-1)))-(0))/dSe -> -0.42692939 | AL15: =((-b_d/2)-(0))/dSe -> -0.4378763 | AN15: =((-1*(k_gap/2+wa_Leb/10+wa_sh/10*MIN(1,wa_nc-1)))-(0))/dSe -> -0.098522167 | AO15: =((-(wa_nr-1)*wa_sv/20+wa_sv/10*MIN(3,wa_nr-1))-(0))/dSe -> 0.16420361 | AQ15: =((-b_bf/2)-(0))/dSs -> -0.38593482 | AR15: =((b_d/2-b_tf)-(0))/dSs -> 0.80617496
AK16: =((-1*(k_gap/2+fa_Leb/10+fa_s/10*MIN(4,fa_n-1)))-(0))/dSe -> -0.42692939 | AL16: =((-b_d/2)-(0))/dSe -> -0.4378763 | AN16: =((-1*(k_gap/2+wa_Leb/10+wa_sh/10*MIN(1,wa_nc-1)))-(0))/dSe -> -0.098522167 | AO16: =((-(wa_nr-1)*wa_sv/20+wa_sv/10*MIN(4,wa_nr-1))-(0))/dSe -> 0.16420361 | AQ16: =((-b_bf/2)-(0))/dSs -> -0.38593482 | AR16: =((b_d/2)-(0))/dSs -> 0.85763293
AK17: =((-1*(k_gap/2+fa_Leb/10+fa_s/10*MIN(5,fa_n-1)))-(0))/dSe -> -0.42692939 | AL17: =((-b_d/2)-(0))/dSe -> -0.4378763 | AN17: =((-1*(k_gap/2+wa_Leb/10+wa_sh/10*MIN(1,wa_nc-1)))-(0))/dSe -> -0.098522167 | AO17: =((-(wa_nr-1)*wa_sv/20+wa_sv/10*MIN(5,wa_nr-1))-(0))/dSe -> 0.16420361
AK18: =((-1*(k_gap/2+fa_Leb/10+fa_s/10*MIN(6,fa_n-1)))-(0))/dSe -> -0.42692939 | AL18: =((-b_d/2)-(0))/dSe -> -0.4378763 | AN18: =((-1*(k_gap/2+wa_Leb/10+wa_sh/10*MIN(1,wa_nc-1)))-(0))/dSe -> -0.098522167 | AO18: =((-(wa_nr-1)*wa_sv/20+wa_sv/10*MIN(6,wa_nr-1))-(0))/dSe -> 0.16420361
AK19: =((-1*(k_gap/2+fa_Leb/10+fa_s/10*MIN(7,fa_n-1)))-(0))/dSe -> -0.42692939 | AL19: =((-b_d/2)-(0))/dSe -> -0.4378763 | AN19: =((-1*(k_gap/2+wa_Leb/10+wa_sh/10*MIN(1,wa_nc-1)))-(0))/dSe -> -0.098522167 | AO19: =((-(wa_nr-1)*wa_sv/20+wa_sv/10*MIN(7,wa_nr-1))-(0))/dSe -> 0.16420361
AK20: =((1*(k_gap/2+fa_Leb/10+fa_s/10*MIN(0,fa_n-1)))-(0))/dSe -> 0.098522167 | AL20: =((b_d/2)-(0))/dSe -> 0.4378763 | AN20: =((-1*(k_gap/2+wa_Leb/10+wa_sh/10*MIN(2,wa_nc-1)))-(0))/dSe -> -0.098522167 | AO20: =((-(wa_nr-1)*wa_sv/20+wa_sv/10*MIN(0,wa_nr-1))-(0))/dSe -> -0.16420361
AK21: =((1*(k_gap/2+fa_Leb/10+fa_s/10*MIN(1,fa_n-1)))-(0))/dSe -> 0.26272578 | AL21: =((b_d/2)-(0))/dSe -> 0.4378763 | AN21: =((-1*(k_gap/2+wa_Leb/10+wa_sh/10*MIN(2,wa_nc-1)))-(0))/dSe -> -0.098522167 | AO21: =((-(wa_nr-1)*wa_sv/20+wa_sv/10*MIN(1,wa_nr-1))-(0))/dSe -> 0
AK22: =((1*(k_gap/2+fa_Leb/10+fa_s/10*MIN(2,fa_n-1)))-(0))/dSe -> 0.42692939 | AL22: =((b_d/2)-(0))/dSe -> 0.4378763 | AN22: =((-1*(k_gap/2+wa_Leb/10+wa_sh/10*MIN(2,wa_nc-1)))-(0))/dSe -> -0.098522167 | AO22: =((-(wa_nr-1)*wa_sv/20+wa_sv/10*MIN(2,wa_nr-1))-(0))/dSe -> 0.16420361
AK23: =((1*(k_gap/2+fa_Leb/10+fa_s/10*MIN(3,fa_n-1)))-(0))/dSe -> 0.42692939 | AL23: =((b_d/2)-(0))/dSe -> 0.4378763 | AN23: =((-1*(k_gap/2+wa_Leb/10+wa_sh/10*MIN(2,wa_nc-1)))-(0))/dSe -> -0.098522167 | AO23: =((-(wa_nr-1)*wa_sv/20+wa_sv/10*MIN(3,wa_nr-1))-(0))/dSe -> 0.16420361
AK24: =((1*(k_gap/2+fa_Leb/10+fa_s/10*MIN(4,fa_n-1)))-(0))/dSe -> 0.42692939 | AL24: =((b_d/2)-(0))/dSe -> 0.4378763 | AN24: =((-1*(k_gap/2+wa_Leb/10+wa_sh/10*MIN(2,wa_nc-1)))-(0))/dSe -> -0.098522167 | AO24: =((-(wa_nr-1)*wa_sv/20+wa_sv/10*MIN(4,wa_nr-1))-(0))/dSe -> 0.16420361
AK25: =((1*(k_gap/2+fa_Leb/10+fa_s/10*MIN(5,fa_n-1)))-(0))/dSe -> 0.42692939 | AL25: =((b_d/2)-(0))/dSe -> 0.4378763 | AN25: =((-1*(k_gap/2+wa_Leb/10+wa_sh/10*MIN(2,wa_nc-1)))-(0))/dSe -> -0.098522167 | AO25: =((-(wa_nr-1)*wa_sv/20+wa_sv/10*MIN(5,wa_nr-1))-(0))/dSe -> 0.16420361
AK26: =((1*(k_gap/2+fa_Leb/10+fa_s/10*MIN(6,fa_n-1)))-(0))/dSe -> 0.42692939 | AL26: =((b_d/2)-(0))/dSe -> 0.4378763 | AN26: =((-1*(k_gap/2+wa_Leb/10+wa_sh/10*MIN(2,wa_nc-1)))-(0))/dSe -> -0.098522167 | AO26: =((-(wa_nr-1)*wa_sv/20+wa_sv/10*MIN(6,wa_nr-1))-(0))/dSe -> 0.16420361
AK27: =((1*(k_gap/2+fa_Leb/10+fa_s/10*MIN(7,fa_n-1)))-(0))/dSe -> 0.42692939 | AL27: =((b_d/2)-(0))/dSe -> 0.4378763 | AN27: =((-1*(k_gap/2+wa_Leb/10+wa_sh/10*MIN(2,wa_nc-1)))-(0))/dSe -> -0.098522167 | AO27: =((-(wa_nr-1)*wa_sv/20+wa_sv/10*MIN(7,wa_nr-1))-(0))/dSe -> 0.16420361
AK28: =((1*(k_gap/2+fa_Leb/10+fa_s/10*MIN(0,fa_n-1)))-(0))/dSe -> 0.098522167 | AL28: =((-b_d/2)-(0))/dSe -> -0.4378763 | AN28: =((1*(k_gap/2+wa_Leb/10+wa_sh/10*MIN(0,wa_nc-1)))-(0))/dSe -> 0.098522167 | AO28: =((-(wa_nr-1)*wa_sv/20+wa_sv/10*MIN(0,wa_nr-1))-(0))/dSe -> -0.16420361
AK29: =((1*(k_gap/2+fa_Leb/10+fa_s/10*MIN(1,fa_n-1)))-(0))/dSe -> 0.26272578 | AL29: =((-b_d/2)-(0))/dSe -> -0.4378763 | AN29: =((1*(k_gap/2+wa_Leb/10+wa_sh/10*MIN(0,wa_nc-1)))-(0))/dSe -> 0.098522167 | AO29: =((-(wa_nr-1)*wa_sv/20+wa_sv/10*MIN(1,wa_nr-1))-(0))/dSe -> 0
AK30: =((1*(k_gap/2+fa_Leb/10+fa_s/10*MIN(2,fa_n-1)))-(0))/dSe -> 0.42692939 | AL30: =((-b_d/2)-(0))/dSe -> -0.4378763 | AN30: =((1*(k_gap/2+wa_Leb/10+wa_sh/10*MIN(0,wa_nc-1)))-(0))/dSe -> 0.098522167 | AO30: =((-(wa_nr-1)*wa_sv/20+wa_sv/10*MIN(2,wa_nr-1))-(0))/dSe -> 0.16420361
AK31: =((1*(k_gap/2+fa_Leb/10+fa_s/10*MIN(3,fa_n-1)))-(0))/dSe -> 0.42692939 | AL31: =((-b_d/2)-(0))/dSe -> -0.4378763 | AN31: =((1*(k_gap/2+wa_Leb/10+wa_sh/10*MIN(0,wa_nc-1)))-(0))/dSe -> 0.098522167 | AO31: =((-(wa_nr-1)*wa_sv/20+wa_sv/10*MIN(3,wa_nr-1))-(0))/dSe -> 0.16420361
AK32: =((1*(k_gap/2+fa_Leb/10+fa_s/10*MIN(4,fa_n-1)))-(0))/dSe -> 0.42692939 | AL32: =((-b_d/2)-(0))/dSe -> -0.4378763 | AN32: =((1*(k_gap/2+wa_Leb/10+wa_sh/10*MIN(0,wa_nc-1)))-(0))/dSe -> 0.098522167 | AO32: =((-(wa_nr-1)*wa_sv/20+wa_sv/10*MIN(4,wa_nr-1))-(0))/dSe -> 0.16420361
AK33: =((1*(k_gap/2+fa_Leb/10+fa_s/10*MIN(5,fa_n-1)))-(0))/dSe -> 0.42692939 | AL33: =((-b_d/2)-(0))/dSe -> -0.4378763 | AN33: =((1*(k_gap/2+wa_Leb/10+wa_sh/10*MIN(0,wa_nc-1)))-(0))/dSe -> 0.098522167 | AO33: =((-(wa_nr-1)*wa_sv/20+wa_sv/10*MIN(5,wa_nr-1))-(0))/dSe -> 0.16420361
AK34: =((1*(k_gap/2+fa_Leb/10+fa_s/10*MIN(6,fa_n-1)))-(0))/dSe -> 0.42692939 | AL34: =((-b_d/2)-(0))/dSe -> -0.4378763 | AN34: =((1*(k_gap/2+wa_Leb/10+wa_sh/10*MIN(0,wa_nc-1)))-(0))/dSe -> 0.098522167 | AO34: =((-(wa_nr-1)*wa_sv/20+wa_sv/10*MIN(6,wa_nr-1))-(0))/dSe -> 0.16420361
AK35: =((1*(k_gap/2+fa_Leb/10+fa_s/10*MIN(7,fa_n-1)))-(0))/dSe -> 0.42692939 | AL35: =((-b_d/2)-(0))/dSe -> -0.4378763 | AN35: =((1*(k_gap/2+wa_Leb/10+wa_sh/10*MIN(0,wa_nc-1)))-(0))/dSe -> 0.098522167 | AO35: =((-(wa_nr-1)*wa_sv/20+wa_sv/10*MIN(7,wa_nr-1))-(0))/dSe -> 0.16420361
AN36: =((1*(k_gap/2+wa_Leb/10+wa_sh/10*MIN(1,wa_nc-1)))-(0))/dSe -> 0.098522167 | AO36: =((-(wa_nr-1)*wa_sv/20+wa_sv/10*MIN(0,wa_nr-1))-(0))/dSe -> -0.16420361
AN37: =((1*(k_gap/2+wa_Leb/10+wa_sh/10*MIN(1,wa_nc-1)))-(0))/dSe -> 0.098522167 | AO37: =((-(wa_nr-1)*wa_sv/20+wa_sv/10*MIN(1,wa_nr-1))-(0))/dSe -> 0
AN38: =((1*(k_gap/2+wa_Leb/10+wa_sh/10*MIN(1,wa_nc-1)))-(0))/dSe -> 0.098522167 | AO38: =((-(wa_nr-1)*wa_sv/20+wa_sv/10*MIN(2,wa_nr-1))-(0))/dSe -> 0.16420361
AN39: =((1*(k_gap/2+wa_Leb/10+wa_sh/10*MIN(1,wa_nc-1)))-(0))/dSe -> 0.098522167 | AO39: =((-(wa_nr-1)*wa_sv/20+wa_sv/10*MIN(3,wa_nr-1))-(0))/dSe -> 0.16420361
AN40: =((1*(k_gap/2+wa_Leb/10+wa_sh/10*MIN(1,wa_nc-1)))-(0))/dSe -> 0.098522167 | AO40: =((-(wa_nr-1)*wa_sv/20+wa_sv/10*MIN(4,wa_nr-1))-(0))/dSe -> 0.16420361
...
