Workbook

Sheet DISEÑO
B2: EMPALME DE COLUMNA (COLUMN SPLICE) — APERNADO, PJP O CJP
B3: AISC 360-16 (J1.4, J2, J3, J4, J5.2, J7) · AISC Manual Parte 14 · AISC 341-16 D2.5 · LRFD · Unidades: Tonf, Tonf·m, mm, kgf/cm²
B4: Celdas de ingreso: | C4: valor | D4: Calculado: | E4: valor | G4: Estados: VERDE ≤ límite · AMARILLO entre límite y 1.00 · ROJO > 1.00 (ratio = demanda / capacidad, o requerido / provisto)
B6: DATOS GENERALES | G6: ELEVACIÓN (vista perpendicular al alma) | J6: SECCIÓN (gris: inferior · azul: superior) | N6: VERIFICACIONES — combinación gobernante por chequeo
B7: Proyecto | C7: Edificio — ejemplo | N7: =IF(COUNT(S12:S44)=0,"SIN CARGAS",IF(MAX(S12:S44)>1,"✖ NO CUMPLE — ratio máx. "&TEXT(MAX(S12:S44),"0.00"),IF(MAX(S12:S44)>lim_verde,"▲ CUMPLE AL LÍMITE — ratio máx. "&TEXT(MAX(S12:S44),"0.00"),"✔ CUMPLE — ratio máx. "&TEXT(MAX(S12:S44),"0.00")))) -> ✔ CUMPLE — ratio máx. 0.90
B8: Elemento | C8: Columna C-4, empalme nivel 3
B9: Límite verde / amarillo (ratio) | C9: 0.9
B10: TIPO DE EMPALME | N10: Verificación | O10: Referencia | P10: Demanda | Q10: Capacidad | R10: Unidad | S10: Ratio | T10: Estado | U10: Combo
B11: Tipo | C11: Placas apernadas | N11: APOYO Y ALAS
B12: Extremos acabados para apoyo (fresados) | C12: Sí | N12: Apoyo por contacto (superficies fresadas) | O12: J1.4 · J7(a) | P12: =IF(k_fr=0,"—",INDEX(CALCULO!$D$83:$M$83,MATCH(MAX(CALCULO!$D$93:$M$93),CALCULO!$D$93:$M$93,0))/1000) -> 85 | Q12: =IF(k_fr=0,"—",k_Rbe/1000) -> 235.3644 | R12: Tonf | S12: =IF(k_fr=0,"N/A",MAX(CALCULO!$D$93:$M$93)) -> 0.36114213 | T12: =IF(ISNUMBER(S12),IF(S12>1,"NO CUMPLE",IF(S12>lim_verde,"AL LÍMITE","CUMPLE")),"N/A") -> CUMPLE | U12: =IF(ISNUMBER(S12),INDEX(CALCULO!$D$82:$M$82,MATCH(MAX(CALCULO!$D$93:$M$93),CALCULO!$D$93:$M$93,0)),"—") -> 1.2D+1.6L
B13: Diseño sísmico (AISC 341-16) | C13: Sí (otros sistemas) | N13: Pernos de ala — corte / deslizamiento (con relleno) | O13: J3.6 · J3.8 · J5.2 | P13: =IF(t_ap=0,"—",INDEX(CALCULO!$D$91:$M$91,MATCH(MAX(CALCULO!$D$94:$M$94),CALCULO!$D$94:$M$94,0))/1000) -> 26.095779 | Q13: =IF(t_ap=0,"—",f_nb*MIN(f_rv,f_rvs)/1000) -> 45.7005 | R13: Tonf | S13: =IF(t_ap=0,"N/A",MAX(CALCULO!$D$94:$M$94)) -> 0.57101737 | T13: =IF(ISNUMBER(S13),IF(S13>1,"NO CUMPLE",IF(S13>lim_verde,"AL LÍMITE","CUMPLE")),"N/A") -> CUMPLE | U13: =IF(ISNUMBER(S13),INDEX(CALCULO!$D$82:$M$82,MATCH(MAX(CALCULO!$D$94:$M$94),CALCULO!$D$94:$M$94,0)),"—") -> 0.9D−Ω0E
B14: Distancia del empalme a la viga más cercana | C14: 1500 | D14: mm | N14: Pernos de ala — aplastamiento / desgarre | O14: J3.10 | P14: =IF(t_ap=0,"—",INDEX(CALCULO!$D$91:$M$91,MATCH(MAX(CALCULO!$D$95:$M$95),CALCULO!$D$95:$M$95,0))/1000) -> 26.095779 | Q14: =IF(t_ap=0,"—",f_nb*MIN(f_rbc,f_rbp)/1000) -> 87.896867 | R14: Tonf | S14: =IF(t_ap=0,"N/A",MAX(CALCULO!$D$95:$M$95)) -> 0.29689089 | T14: =IF(ISNUMBER(S14),IF(S14>1,"NO CUMPLE",IF(S14>lim_verde,"AL LÍMITE","CUMPLE")),"N/A") -> CUMPLE | U14: =IF(ISNUMBER(S14),INDEX(CALCULO!$D$82:$M$82,MATCH(MAX(CALCULO!$D$95:$M$95),CALCULO!$D$95:$M$95,0)),"—") -> 0.9D−Ω0E
B15: Holgura entre columnas | C15: 3 | D15: mm | N15: Placa de ala — fluencia en tracción | O15: J4.1(a) | P15: =IF(t_ap=0,"—",INDEX(CALCULO!$D$89:$M$89,MATCH(MAX(CALCULO!$D$96:$M$96),CALCULO!$D$96:$M$96,0))/1000) -> 26.095779 | Q15: =IF(t_ap=0,"—",p_ty/1000) -> 68.3316 | R15: Tonf | S15: =IF(t_ap=0,"N/A",MAX(CALCULO!$D$96:$M$96)) -> 0.38189914 | T15: =IF(ISNUMBER(S15),IF(S15>1,"NO CUMPLE",IF(S15>lim_verde,"AL LÍMITE","CUMPLE")),"N/A") -> CUMPLE | U15: =IF(ISNUMBER(S15),INDEX(CALCULO!$D$82:$M$82,MATCH(MAX(CALCULO!$D$96:$M$96),CALCULO!$D$96:$M$96,0)),"—") -> 0.9D−Ω0E
B16: 1. COLUMNA SUPERIOR | N16: Placa de ala — ruptura en tracción | O16: J4.1(b) | P16: =IF(t_ap=0,"—",INDEX(CALCULO!$D$89:$M$89,MATCH(MAX(CALCULO!$D$97:$M$97),CALCULO!$D$97:$M$97,0))/1000) -> 26.095779 | Q16: =IF(t_ap=0,"—",p_tr/1000) -> 55.751715 | R16: Tonf | S16: =IF(t_ap=0,"N/A",MAX(CALCULO!$D$97:$M$97)) -> 0.46807133 | T16: =IF(ISNUMBER(S16),IF(S16>1,"NO CUMPLE",IF(S16>lim_verde,"AL LÍMITE","CUMPLE")),"N/A") -> CUMPLE | U16: =IF(ISNUMBER(S16),INDEX(CALCULO!$D$82:$M$82,MATCH(MAX(CALCULO!$D$97:$M$97),CALCULO!$D$97:$M$97,0)),"—") -> 0.9D−Ω0E
B17: Perfil (catálogo o ARMADO) | C17: HA400X200X8X15 | E17: Armado (mm) | N17: Placa de ala — bloque de cortante | O17: J4.3 | P17: =IF(t_ap=0,"—",INDEX(CALCULO!$D$91:$M$91,MATCH(MAX(CALCULO!$D$98:$M$98),CALCULO!$D$98:$M$98,0))/1000) -> 26.095779 | Q17: =IF(t_ap=0,"—",p_bs/1000) -> 86.00283 | R17: Tonf | S17: =IF(t_ap=0,"N/A",MAX(CALCULO!$D$98:$M$98)) -> 0.30342931 | T17: =IF(ISNUMBER(S17),IF(S17>1,"NO CUMPLE",IF(S17>lim_verde,"AL LÍMITE","CUMPLE")),"N/A") -> CUMPLE | U17: =IF(ISNUMBER(S17),INDEX(CALCULO!$D$82:$M$82,MATCH(MAX(CALCULO!$D$98:$M$98),CALCULO!$D$98:$M$98,0)),"—") -> 0.9D−Ω0E
B18: Peralte d | C18: =IF(cu_perfil="ARMADO (flejes soldados)",E18,INDEX(CATALOGOS!$B$5:$B$40,MATCH(cu_perfil,CATALOGOS!$A$5:$A$40,0))) -> 400 | D18: mm | E18: 400 | N18: Placa de ala — compresión (sin fresar) | O18: J4.4 / E3 | P18: =IF(OR(t_ap=0,k_fr=1),"—",INDEX(CALCULO!$D$90:$M$90,MATCH(MAX(CALCULO!$D$99:$M$99),CALCULO!$D$99:$M$99,0))/1000) -> — | Q18: =IF(OR(t_ap=0,k_fr=1),"—",p_cb/1000) -> — | R18: Tonf | S18: =IF(OR(t_ap=0,k_fr=1),"N/A",MAX(CALCULO!$D$99:$M$99)) -> N/A | T18: =IF(ISNUMBER(S18),IF(S18>1,"NO CUMPLE",IF(S18>lim_verde,"AL LÍMITE","CUMPLE")),"N/A") -> N/A | U18: =IF(ISNUMBER(S18),INDEX(CALCULO!$D$82:$M$82,MATCH(MAX(CALCULO!$D$99:$M$99),CALCULO!$D$99:$M$99,0)),"—") -> —
B19: Ancho de ala bf | C19: =IF(cu_perfil="ARMADO (flejes soldados)",E19,INDEX(CATALOGOS!$C$5:$C$40,MATCH(cu_perfil,CATALOGOS!$A$5:$A$40,0))) -> 200 | D19: mm | E19: 200 | N19: Ala de columna superior — ruptura neta | O19: J4.1(b) | P19: =IF(t_ap=0,"—",INDEX(CALCULO!$D$89:$M$89,MATCH(MAX(CALCULO!$D$100:$M$100),CALCULO!$D$100:$M$100,0))/1000) -> 26.095779 | Q19: =IF(t_ap=0,"—",c_tr/1000) -> 79.972144 | R19: Tonf | S19: =IF(t_ap=0,"N/A",MAX(CALCULO!$D$100:$M$100)) -> 0.32631086 | T19: =IF(ISNUMBER(S19),IF(S19>1,"NO CUMPLE",IF(S19>lim_verde,"AL LÍMITE","CUMPLE")),"N/A") -> CUMPLE | U19: =IF(ISNUMBER(S19),INDEX(CALCULO!$D$82:$M$82,MATCH(MAX(CALCULO!$D$100:$M$100),CALCULO!$D$100:$M$100,0)),"—") -> 0.9D−Ω0E
B20: Espesor de alma tw | C20: =IF(cu_perfil="ARMADO (flejes soldados)",E20,INDEX(CATALOGOS!$D$5:$D$40,MATCH(cu_perfil,CATALOGOS!$A$5:$A$40,0))) -> 8 | D20: mm | E20: 8 | N20: Ala de columna superior — bloque de cortante | O20: J4.3 | P20: =IF(t_ap=0,"—",INDEX(CALCULO!$D$91:$M$91,MATCH(MAX(CALCULO!$D$101:$M$101),CALCULO!$D$101:$M$101,0))/1000) -> 26.095779 | Q20: =IF(t_ap=0,"—",c_bs/1000) -> 117.78604 | R20: Tonf | S20: =IF(t_ap=0,"N/A",MAX(CALCULO!$D$101:$M$101)) -> 0.2215524 | T20: =IF(ISNUMBER(S20),IF(S20>1,"NO CUMPLE",IF(S20>lim_verde,"AL LÍMITE","CUMPLE")),"N/A") -> CUMPLE | U20: =IF(ISNUMBER(S20),INDEX(CALCULO!$D$82:$M$82,MATCH(MAX(CALCULO!$D$101:$M$101),CALCULO!$D$101:$M$101,0)),"—") -> 0.9D−Ω0E
B21: Espesor de ala tf | C21: =IF(cu_perfil="ARMADO (flejes soldados)",E21,INDEX(CATALOGOS!$E$5:$E$40,MATCH(cu_perfil,CATALOGOS!$A$5:$A$40,0))) -> 15 | D21: mm | E21: 15 | G21: SOLICITACIONES EN EL EMPALME (LRFD) | N21: ALMA
B22: Acero | C22: A572 Gr50 | G22: Combinación | H22: Pu (Tonf) (+) compresión | I22: Mu (Tonf·m) | J22: Vu (Tonf) | K22: Ratio máx. | N22: Pernos de alma — corte / deslizamiento | O22: J3.6 · J3.8 | P22: =IF(t_ap=0,"—",INDEX(CALCULO!$D$103:$M$103,MATCH(MAX(CALCULO!$D$104:$M$104),CALCULO!$D$104:$M$104,0))/1000) -> 2.6647817 | Q22: =IF(t_ap=0,"—",MIN(w_rv,w_rvs)/1000) -> 16.233483 | R22: Tonf | S22: =IF(t_ap=0,"N/A",MAX(CALCULO!$D$104:$M$104)) -> 0.16415342 | T22: =IF(ISNUMBER(S22),IF(S22>1,"NO CUMPLE",IF(S22>lim_verde,"AL LÍMITE","CUMPLE")),"N/A") -> CUMPLE | U22: =IF(ISNUMBER(S22),INDEX(CALCULO!$D$82:$M$82,MATCH(MAX(CALCULO!$D$104:$M$104),CALCULO!$D$104:$M$104,0)),"—") -> 0.9D−Ω0E
B23: Fy / Fu | C23: =INDEX(CATALOGOS!$H$5:$H$10,MATCH(cu_acero,CATALOGOS!$G$5:$G$10,0)) -> 3515 | D23: kgf/cm² | E23: =INDEX(CATALOGOS!$I$5:$I$10,MATCH(cu_acero,CATALOGOS!$G$5:$G$10,0)) -> 4570 | G23: 1.2D+1.6L | H23: 85 | I23: 2 | J23: 1 | K23: =IF(INDEX(CALCULO!$D$86:$M$86,1)=1,INDEX(CALCULO!$D$109:$M$109,1),"—") -> 0.36114213 | N23: Pernos de alma — aplastamiento / desgarre | O23: J3.10 | P23: =IF(t_ap=0,"—",INDEX(CALCULO!$D$103:$M$103,MATCH(MAX(CALCULO!$D$105:$M$105),CALCULO!$D$105:$M$105,0))/1000) -> 2.6647817 | Q23: =IF(t_ap=0,"—",w_rb/1000) -> 9.7663185 | R23: Tonf | S23: =IF(t_ap=0,"N/A",MAX(CALCULO!$D$105:$M$105)) -> 0.27285427 | T23: =IF(ISNUMBER(S23),IF(S23>1,"NO CUMPLE",IF(S23>lim_verde,"AL LÍMITE","CUMPLE")),"N/A") -> CUMPLE | U23: =IF(ISNUMBER(S23),INDEX(CALCULO!$D$82:$M$82,MATCH(MAX(CALCULO!$D$105:$M$105),CALCULO!$D$105:$M$105,0)),"—") -> 0.9D−Ω0E
B24: 2. COLUMNA INFERIOR | G24: 1.2D+Ω0E+L | H24: 55 | I24: 9 | J24: 4 | K24: =IF(INDEX(CALCULO!$D$86:$M$86,2)=1,INDEX(CALCULO!$D$109:$M$109,2),"—") -> 0.2336802 | N24: Placas de alma — corte y axial | O24: J4.1 · J4.2 | P24: =IF(t_ap=0,"—",INDEX(CALCULO!$D$106:$M$106,MATCH(MAX(CALCULO!$D$106:$M$106),CALCULO!$D$106:$M$106,0))/1) -> 0.08753814 | Q24: =IF(t_ap=0,"—",1) -> 1 | R24: - | S24: =IF(t_ap=0,"N/A",MAX(CALCULO!$D$106:$M$106)) -> 0.08753814 | T24: =IF(ISNUMBER(S24),IF(S24>1,"NO CUMPLE",IF(S24>lim_verde,"AL LÍMITE","CUMPLE")),"N/A") -> CUMPLE | U24: =IF(ISNUMBER(S24),INDEX(CALCULO!$D$82:$M$82,MATCH(MAX(CALCULO!$D$106:$M$106),CALCULO!$D$106:$M$106,0)),"—") -> 1.2D+Ω0E+L
B25: Perfil (catálogo o ARMADO) | C25: HA420X210X8X15 | E25: Armado (mm) | G25: 0.9D−Ω0E | H25: -12 | I25: 8.5 | J25: 4 | K25: =IF(INDEX(CALCULO!$D$86:$M$86,3)=1,INDEX(CALCULO!$D$109:$M$109,3),"—") -> 0.57101737 | N25: SOLDADURAS (PJP / CJP)
B26: Peralte d | C26: =IF(cl_perfil="ARMADO (flejes soldados)",E26,INDEX(CATALOGOS!$B$5:$B$40,MATCH(cl_perfil,CATALOGOS!$A$5:$A$40,0))) -> 420 | D26: mm | E26: 420 | G26: C4 | K26: =IF(INDEX(CALCULO!$D$86:$M$86,4)=1,INDEX(CALCULO!$D$109:$M$109,4),"—") -> — | N26: Alas — tracción / compresión | O26: Tabla J2.5 · 341 D2.5b | P26: =IF(t_ap=1,"—",INDEX(CALCULO!$D$107:$M$107,MATCH(MAX(CALCULO!$D$107:$M$107),CALCULO!$D$107:$M$107,0))/1) -> — | Q26: =IF(t_ap=1,"—",1) -> — | R26: - | S26: =IF(t_ap=1,"N/A",MAX(CALCULO!$D$107:$M$107)) -> N/A | T26: =IF(ISNUMBER(S26),IF(S26>1,"NO CUMPLE",IF(S26>lim_verde,"AL LÍMITE","CUMPLE")),"N/A") -> N/A | U26: =IF(ISNUMBER(S26),INDEX(CALCULO!$D$82:$M$82,MATCH(MAX(CALCULO!$D$107:$M$107),CALCULO!$D$107:$M$107,0)),"—") -> —
B27: Ancho de ala bf | C27: =IF(cl_perfil="ARMADO (flejes soldados)",E27,INDEX(CATALOGOS!$C$5:$C$40,MATCH(cl_perfil,CATALOGOS!$A$5:$A$40,0))) -> 210 | D27: mm | E27: 210 | G27: C5 | K27: =IF(INDEX(CALCULO!$D$86:$M$86,5)=1,INDEX(CALCULO!$D$109:$M$109,5),"—") -> — | N27: Alma — corte | O27: Tabla J2.5 · 341 D2.5b | P27: =IF(t_ap=1,"—",INDEX(CALCULO!$D$85:$M$85,MATCH(MAX(CALCULO!$D$108:$M$108),CALCULO!$D$108:$M$108,0))/1000) -> — | Q27: =IF(t_ap=1,"—",s_Rwv/1000/k_s2) -> — | R27: Tonf | S27: =IF(t_ap=1,"N/A",MAX(CALCULO!$D$108:$M$108)) -> N/A | T27: =IF(ISNUMBER(S27),IF(S27>1,"NO CUMPLE",IF(S27>lim_verde,"AL LÍMITE","CUMPLE")),"N/A") -> N/A | U27: =IF(ISNUMBER(S27),INDEX(CALCULO!$D$82:$M$82,MATCH(MAX(CALCULO!$D$108:$M$108),CALCULO!$D$108:$M$108,0)),"—") -> —
B28: Espesor de alma tw | C28: =IF(cl_perfil="ARMADO (flejes soldados)",E28,INDEX(CATALOGOS!$D$5:$D$40,MATCH(cl_perfil,CATALOGOS!$A$5:$A$40,0))) -> 8 | D28: mm | E28: 8 | G28: C6 | K28: =IF(INDEX(CALCULO!$D$86:$M$86,6)=1,INDEX(CALCULO!$D$109:$M$109,6),"—") -> — | N28: PJP: garganta alas ≥ mínima | O28: Tabla J2.3 | P28: =IF(t_pjp=0,"—",s_Emin) -> — | Q28: =IF(t_pjp=0,"—",E_f) -> — | R28: mm | S28: =IF(t_pjp=0,"N/A",(s_Emin)/MAX(E_f,0.000000001)) -> N/A | T28: =IF(ISNUMBER(S28),IF(S28>1,"NO CUMPLE",IF(S28>lim_verde,"AL LÍMITE","CUMPLE")),"N/A") -> N/A | U28: —
B29: Espesor de ala tf | C29: =IF(cl_perfil="ARMADO (flejes soldados)",E29,INDEX(CATALOGOS!$E$5:$E$40,MATCH(cl_perfil,CATALOGOS!$A$5:$A$40,0))) -> 15 | D29: mm | E29: 15 | G29: C7 | K29: =IF(INDEX(CALCULO!$D$86:$M$86,7)=1,INDEX(CALCULO!$D$109:$M$109,7),"—") -> — | N29: PJP: garganta alma ≥ mínima | O29: Tabla J2.3 | P29: =IF(t_pjp=0,"—",IF(MIN(cu_tw_mm,cl_tw_mm)<=6,3,IF(MIN(cu_tw_mm,cl_tw_mm)<=13,5,6))) -> — | Q29: =IF(t_pjp=0,"—",E_w) -> — | R29: mm | S29: =IF(t_pjp=0,"N/A",(IF(MIN(cu_tw_mm,cl_tw_mm)<=6,3,IF(MIN(cu_tw_mm,cl_tw_mm)<=13,5,6)))/MAX(E_w,0.000000001)) -> N/A | T29: =IF(ISNUMBER(S29),IF(S29>1,"NO CUMPLE",IF(S29>lim_verde,"AL LÍMITE","CUMPLE")),"N/A") -> N/A | U29: —
B30: Acero | C30: A572 Gr50 | G30: C8 | K30: =IF(INDEX(CALCULO!$D$86:$M$86,8)=1,INDEX(CALCULO!$D$109:$M$109,8),"—") -> — | N30: PJP: garganta ≤ espesor del ala | O30: Geometría | P30: =IF(t_pjp=0,"—",E_f) -> — | Q30: =IF(t_pjp=0,"—",MIN(cu_tf_mm,cl_tf_mm)) -> — | R30: mm | S30: =IF(t_pjp=0,"N/A",(E_f)/MAX(MIN(cu_tf_mm,cl_tf_mm),0.000000001)) -> N/A | T30: =IF(ISNUMBER(S30),IF(S30>1,"NO CUMPLE",IF(S30>lim_verde,"AL LÍMITE","CUMPLE")),"N/A") -> N/A | U30: —
B31: Fy / Fu | C31: =INDEX(CATALOGOS!$H$5:$H$10,MATCH(cl_acero,CATALOGOS!$G$5:$G$10,0)) -> 3515 | D31: kgf/cm² | E31: =INDEX(CATALOGOS!$I$5:$I$10,MATCH(cl_acero,CATALOGOS!$G$5:$G$10,0)) -> 4570 | G31: C9 | K31: =IF(INDEX(CALCULO!$D$86:$M$86,9)=1,INDEX(CALCULO!$D$109:$M$109,9),"—") -> — | N31: REQUISITOS Y DETALLES (requerido / provisto)
B32: 3. PLACAS DE ALA (apernado) | G32: C10 | K32: =IF(INDEX(CALCULO!$D$86:$M$86,10)=1,INDEX(CALCULO!$D$109:$M$109,10),"—") -> — | N32: Ubicación ≥ 1.2 m de la conexión viga-columna | O32: 341 D2.5a | P32: =IF(sismico="No","—",1200) -> 1200 | Q32: =IF(sismico="No","—",dist_v) -> 1500 | R32: mm | S32: =IF(sismico="No","N/A",(1200)/MAX(dist_v,0.000000001)) -> 0.8 | T32: =IF(ISNUMBER(S32),IF(S32>1,"NO CUMPLE",IF(S32>lim_verde,"AL LÍMITE","CUMPLE")),"N/A") -> CUMPLE | U32: —
B33: Acero | C33: A572 Gr50 | G33: Pu (+) compresión, (−) tracción. Momento alrededor del eje fuerte; Vu en la dirección del peralte. | N33: Solape de alas para apoyo directo (si no, placa de tope) | O33: Manual Parte 14 | P33: =IF(k_fr=0,"—",MAX(0,(l_d-u_d)/2)) -> 1 | Q33: =IF(k_fr=0,"—",MIN(u_tf,l_tf)) -> 1.5 | R33: cm | S33: =IF(k_fr=0,"N/A",IF(k_ov<=0,1.5,MAX(0,ABS(l_d-u_d)/2)/MAX(MIN(u_tf,l_tf),0.000000001))) -> 0.66666667 | T33: =IF(ISNUMBER(S33),IF(S33>1,"NO CUMPLE",IF(S33>lim_verde,"AL LÍMITE","CUMPLE")),"N/A") -> CUMPLE | U33: —
B34: Fy / Fu | C34: =INDEX(CATALOGOS!$H$5:$H$10,MATCH(pf_acero,CATALOGOS!$G$5:$G$10,0)) -> 3515 | D34: kgf/cm² | E34: =INDEX(CATALOGOS!$I$5:$I$10,MATCH(pf_acero,CATALOGOS!$G$5:$G$10,0)) -> 4570 | N34: Relleno ≤ 19 mm (J5.2; si no, desarrollar el relleno) | O34: J5.2 | P34: =IF(t_ap=0,"—",fill_t) -> 10 | Q34: =IF(t_ap=0,"—",19) -> 19 | R34: mm | S34: =IF(t_ap=0,"N/A",(fill_t)/MAX(19,0.000000001)) -> 0.52631579 | T34: =IF(ISNUMBER(S34),IF(S34>1,"NO CUMPLE",IF(S34>lim_verde,"AL LÍMITE","CUMPLE")),"N/A") -> CUMPLE | U34: —
B35: Ancho de placa | C35: 180 | D35: mm | G35: DETALLE DE UNA COMBINACIÓN | N35: Placa de ala ≤ ancho de ala de la columna menor | O35: Geometría | P35: =IF(t_ap=0,"—",pf_b/10) -> 18 | Q35: =IF(t_ap=0,"—",MIN(u_bf,l_bf)) -> 20 | R35: cm | S35: =IF(t_ap=0,"N/A",(pf_b/10)/MAX(MIN(u_bf,l_bf),0.000000001)) -> 0.9 | T35: =IF(ISNUMBER(S35),IF(S35>1,"NO CUMPLE",IF(S35>lim_verde,"AL LÍMITE","CUMPLE")),"N/A") -> CUMPLE | U35: —
B36: Espesor de placa | C36: 12 | D36: mm | G36: Combinación: | H36: =G23 -> 1.2D+1.6L | K36: =IFERROR(MATCH(H36,cb_nom,0),1) -> 1 | N36: Paso s ≥ 3·db (ala) | O36: J3.3 | P36: =IF(t_ap=0,"—",3*fa_db) -> 5.715 | Q36: =IF(t_ap=0,"—",fa_s/10) -> 7.5 | R36: cm | S36: =IF(t_ap=0,"N/A",(3*fa_db)/MAX(fa_s/10,0.000000001)) -> 0.762 | T36: =IF(ISNUMBER(S36),IF(S36>1,"NO CUMPLE",IF(S36>lim_verde,"AL LÍMITE","CUMPLE")),"N/A") -> CUMPLE | U36: —
B37: Relleno en columna superior (auto) | C37: =ABS(cl_d_mm-cu_d_mm)/2 -> 10 | D37: mm | G37: Tracción en el ala T | J37: =INDEX(CALCULO!$D$89:$M$89,det_k)/1000 -> 0 | L37: Tonf | N37: Borde en columna ≥ mínimo (ala) | O37: J3.4 | P37: =IF(t_ap=0,"—",fa_em) -> 2.54 | Q37: =IF(t_ap=0,"—",fa_Lec/10) -> 4 | R37: cm | S37: =IF(t_ap=0,"N/A",(fa_em)/MAX(fa_Lec/10,0.000000001)) -> 0.635 | T37: =IF(ISNUMBER(S37),IF(S37>1,"NO CUMPLE",IF(S37>lim_verde,"AL LÍMITE","CUMPLE")),"N/A") -> CUMPLE | U37: —
B38: 4. PERNOS DE ALA | G38: Compresión a transmitir C | J38: =INDEX(CALCULO!$D$90:$M$90,det_k)/1000 -> 0 | L38: Tonf | N38: Borde en placa ≥ mínimo (ala) | O38: J3.4 | P38: =IF(t_ap=0,"—",fa_em) -> 2.54 | Q38: =IF(t_ap=0,"—",fa_Lep/10) -> 4 | R38: cm | S38: =IF(t_ap=0,"N/A",(fa_em)/MAX(fa_Lep/10,0.000000001)) -> 0.635 | T38: =IF(ISNUMBER(S38),IF(S38>1,"NO CUMPLE",IF(S38>lim_verde,"AL LÍMITE","CUMPLE")),"N/A") -> CUMPLE | U38: —
B39: Grado | C39: A325-N (roscas incl.) | G39: Axial en el alma Pw | J39: =INDEX(CALCULO!$D$92:$M$92,det_k)/1000 -> 0 | L39: Tonf | N39: Borde lateral de placa (b − g)/2 | O39: J3.4 | P39: =IF(t_ap=0,"—",fa_em) -> 2.54 | Q39: =IF(t_ap=0,"—",(pf_b-fa_g)/20) -> 3.5 | R39: cm | S39: =IF(t_ap=0,"N/A",(fa_em)/MAX((pf_b-fa_g)/20,0.000000001)) -> 0.72571429 | T39: =IF(ISNUMBER(S39),IF(S39>1,"NO CUMPLE",IF(S39>lim_verde,"AL LÍMITE","CUMPLE")),"N/A") -> CUMPLE | U39: —
B40: Diámetro | C40: 3/4" | G40: Perno crítico de alma rmáx | J40: =INDEX(CALCULO!$D$103:$M$103,det_k)/1000 -> 0.50710551 | L40: Tonf | N40: Gramil deja espacio a la llave junto al alma | O40: Geometría | P40: =IF(t_ap=0,"—",1.5*fa_db) -> 2.8575 | Q40: =IF(t_ap=0,"—",fa_g/20-u_tw/2) -> 5.1 | R40: cm | S40: =IF(t_ap=0,"N/A",(1.5*fa_db)/MAX(fa_g/20-u_tw/2,0.000000001)) -> 0.56029412 | T40: =IF(ISNUMBER(S40),IF(S40>1,"NO CUMPLE",IF(S40>lim_verde,"AL LÍMITE","CUMPLE")),"N/A") -> CUMPLE | U40: —
B41: Tipo de junta | C41: Aplastamiento | G41: Relleno / factor J5.2 | J41: =fill_t -> 10 | L41: =f_fill -> 0.9384 | N41: Placa de alma cabe entre alas | O41: Geometría | P41: =IF(t_ap=0,"—",pw_b/10) -> 20 | Q41: =IF(t_ap=0,"—",u_d-2*(u_tf+0.6)) -> 35.8 | R41: cm | S41: =IF(t_ap=0,"N/A",(pw_b/10)/MAX(u_d-2*(u_tf+0.6),0.000000001)) -> 0.55865922 | T41: =IF(ISNUMBER(S41),IF(S41>1,"NO CUMPLE",IF(S41>lim_verde,"AL LÍMITE","CUMPLE")),"N/A") -> CUMPLE | U41: —
B42: Filas por lado (2 líneas) | C42: 3 | G42: Área de apoyo por contacto | J42: =k_Ab -> 49.6 | L42: cm² | N42: Paso sv ≥ 3·db (alma) | O42: J3.3 | P42: =IF(t_ap=0,"—",3*wa_db) -> 5.715 | Q42: =IF(t_ap=0,"—",wa_sv/10) -> 7.5 | R42: cm | S42: =IF(t_ap=0,"N/A",(3*wa_db)/MAX(wa_sv/10,0.000000001)) -> 0.762 | T42: =IF(ISNUMBER(S42),IF(S42>1,"NO CUMPLE",IF(S42>lim_verde,"AL LÍMITE","CUMPLE")),"N/A") -> CUMPLE | U42: —
...

Sheet CALCULO
A1: HOJA DE CÁLCULO — memoria detallada (no editar)
A2: Unidades: kgf, cm. La fuerza en las alas se calcula con la columna superior (menor): Ff = Mu/(d − tf) ± Pu·Af/A.
A4: 0. GEOMETRÍA Y OPCIONES
A5: apern. | B5: 1 = placas apernadas | C5: - | D5: =IF(tipo="Placas apernadas",1,0) -> 1
A6: PJP | B6: 1 = soldado PJP | C6: - | D6: =IF(tipo="Soldado PJP",1,0) -> 0
A7: CJP | B7: 1 = soldado CJP | C7: - | D7: =IF(tipo="Soldado CJP",1,0) -> 0
A8: fresado | B8: 1 = extremos fresados (apoyo por contacto) | C8: - | D8: =IF(fresado="Sí",1,0) -> 1
A9: ×D2.5 | B9: Factor de demanda para PJP en diseño sísmico (2.0) | C9: - | D9: =IF(AND(LEFT(sismico,2)="Sí",t_pjp=1),2,1) -> 1
A10: E | B10: Módulo de elasticidad | C10: kgf/cm² | D10: =2040000 -> 2040000
A11: du | B11: Peralte | C11: cm | D11: =cu_d_mm/10 -> 40
A12: bfu | B12: Ala | C12: cm | D12: =cu_bf_mm/10 -> 20
A13: twu | B13: Alma | C13: cm | D13: =cu_tw_mm/10 -> 0.8
A14: tfu | B14: Ala | C14: cm | D14: =cu_tf_mm/10 -> 1.5
A15: dl | B15: Peralte | C15: cm | D15: =cl_d_mm/10 -> 42
A16: bfl | B16: Ala | C16: cm | D16: =cl_bf_mm/10 -> 21
A17: twl | B17: Alma | C17: cm | D17: =cl_tw_mm/10 -> 0.8
A18: tfl | B18: Ala | C18: cm | D18: =cl_tf_mm/10 -> 1.5
A19: Af | B19: bf·tf (superior) | C19: cm² | D19: =u_bf*u_tf -> 30
A20: A | B20: Área (superior) | C20: cm² | D20: =2*u_bf*u_tf+(u_d-2*u_tf)*u_tw -> 89.6
A21: Aw | B21: A − 2Af | C21: cm² | D21: =u_A-2*u_Af -> 29.6
A22: Fy,mín | B22: Menor Fy de las columnas | C22: kgf/cm² | D22: =MIN(cu_Fy,cl_Fy) -> 3515
A23: Fu,mín | B23: Menor Fu de las columnas | C23: kgf/cm² | D23: =MIN(cu_Fu,cl_Fu) -> 4570
A24: solape | B24: Solape de alas para apoyo: mín(du, dl)/2 − máx(du/2 − tfu, dl/2 − tfl) | C24: cm | D24: =MAX(0,MIN(u_d,l_d)/2-MAX(u_d/2-u_tf,l_d/2-l_tf)) -> 0.5
A25: Aapoyo | B25: 2·mín(bf)·solape + mín(tw)·(du − 2tfu) | C25: cm² | D25: =2*MIN(u_bf,l_bf)*k_ov+MIN(u_tw,l_tw)*(u_d-2*u_tf) -> 49.6
A26: φRn | B26: Apoyo por contacto en superficies fresadas: 0.75·1.8·Fy·Aapoyo (J7a) | C26: kgf | D26: =0.75*1.8*k_Fy*k_Ab -> 235364.4
A27: SC | B27: 1 = deslizamiento crítico | C27: - | D27: =IF(LEFT(junta,3)="Des",1,0) -> 0
A28: μ | B28: 0.30 / 0.50 | C28: - | D28: =IF(RIGHT(junta,5)="0.50)",0.5,0.3) -> 0.3
A29: 1. PLACAS Y PERNOS DE ALA (apernado)
A30: db | B30: Diámetro pernos de ala | C30: in | D30: =INDEX(CATALOGOS!$P$5:$P$10,MATCH(fa_diam,CATALOGOS!$O$5:$O$10,0)) -> 0.75
A31: db | B31: Diámetro pernos de ala | C31: cm | D31: =fa_dbi*2.54 -> 1.905
A32: Ab | B32: π·db²/4 | C32: cm² | D32: =PI()*fa_db^2/4 -> 2.8502296
A33: dh | B33: Agujero estándar (Tabla J3.3) | C33: cm | D33: =IF(fa_dbi<1,fa_dbi+1/16,fa_dbi+1/8)*2.54 -> 2.06375
A34: dh,net | B34: dh + 1/16 in (B4.3b) | C34: cm | D34: =fa_dh+0.15875 -> 2.2225
A35: Le,min | B35: Borde mínimo (Tabla J3.4) | C35: cm | D35: =INDEX(CATALOGOS!$Q$5:$Q$10,MATCH(fa_diam,CATALOGOS!$O$5:$O$10,0))*2.54 -> 2.54
A36: Fnv | B36: Resistencia a corte | C36: kgf/cm² | D36: =INDEX(CATALOGOS!$L$5:$L$8,MATCH(fa_grado,CATALOGOS!$K$5:$K$8,0)) -> 3797
A37: Tb | B37: Pretensión mínima (Tabla J3.1) | C37: kgf | D37: =IF(INDEX(CATALOGOS!$M$5:$M$8,MATCH(fa_grado,CATALOGOS!$K$5:$K$8,0))="A",INDEX(CATALOGOS!$R$5:$R$10,MATCH(fa_diam,CATALOGOS!$O$5:$O$10,0)),INDEX(CATALOGOS!$S$5:$S$10,MATCH(fa_diam,CATALOGOS!$O$5:$O$10,0))) -> 12701
A38: n | B38: Pernos por ala por lado = 2·filas | C38: - | D38: =2*fa_n -> 6
A39: fill | B39: J5.2: factor por relleno 1 − 0.0154(t − 6) [mm], 6 < t ≤ 19 (aplastamiento) | C39: - | D39: =IF(j_sc=1,1,IF(fill_t<=6,1,1-0.0154*(MIN(fill_t,19)-6))) -> 0.9384
A40: φrn | B40: Por perno: 0.75·Fnv·Ab·fill ; deslizamiento 1.0·μ·1.13·hf·Tb (hf = 1, un relleno) | C40: kgf | D40: =IF(j_sc=1,1*j_mu*1.13*fa_Tb,0.75*fa_Fnv*fa_Ab*f_fill) -> 7616.75
A41: φrn,v | B41: Corte del perno con reducción por relleno | C41: kgf | D41: =0.75*fa_Fnv*fa_Ab*f_fill -> 7616.75
...

Sheet CATALOGOS
A1: CATÁLOGOS — ampliables agregando filas dentro de cada rango
A3: Perfiles (VK/HA: KUBIEC; W: AISC; ARMADO: medidas manuales) | G3: Aceros (kgf/cm²) | K3: Pernos (kgf/cm²) — Tabla J3.2 ; grupo para Tb | O3: Diámetros — borde mín. J3.4 ; Tb (kgf) Tabla J3.1 | U3: Electrodo | X3: Opción | Z3: Tipo de junta apernada | AB3: Espesores (mm)
A4: Perfil | B4: d | C4: bf | D4: tw | E4: tf | G4: Acero | H4: Fy | I4: Fu | K4: Grado | L4: Fnv | M4: Grupo | O4: Ø | P4: db (in) | Q4: borde (in) | R4: Tb A325 | S4: Tb A490 | U4: Electrodo | V4: FEXX | X4: Sí/No | Z4: Junta | AB4: t
A5: ARMADO (flejes soldados) | G5: A36 | H5: 2530 | I5: 4080 | K5: A325-N (roscas incl.) | L5: 3797 | M5: A | O5: 5/8" | P5: 0.625 | Q5: 0.875 | R5: 8618 | S5: 10886 | U5: E60XX | V5: 4220 | X5: Sí | Z5: Aplastamiento | AB5: 0
A6: VK250X130X4X8 | B6: 250 | C6: 130 | D6: 4 | E6: 8 | G6: A572 Gr50 | H6: 3515 | I6: 4570 | K6: A325-X (roscas excl.) | L6: 4781 | M6: A | O6: 3/4" | P6: 0.75 | Q6: 1 | R6: 12701 | S6: 15876 | U6: E70XX | V6: 4920 | X6: No | Z6: Deslizamiento crítico clase A (μ = 0.30) | AB6: 3
A7: VK300X150X4X10 | B7: 300 | C7: 150 | D7: 4 | E7: 10 | G7: A992 | H7: 3515 | I7: 4570 | K7: A490-N (roscas incl.) | L7: 4781 | M7: B | O7: 7/8" | P7: 0.875 | Q7: 1.125 | R7: 17690 | S7: 22226 | Z7: Deslizamiento crítico clase B (μ = 0.50) | AB7: 5
A8: VK330X160X6X10 | B8: 330 | C8: 160 | D8: 6 | E8: 10 | G8: A588 Gr50 | H8: 3515 | I8: 4920 | K8: A490-X (roscas excl.) | L8: 5906 | M8: B | O8: 1" | P8: 1 | Q8: 1.25 | R8: 23133 | S8: 29030 | AB8: 6
A9: VK360X180X6X10 | B9: 360 | C9: 180 | D9: 6 | E9: 10 | O9: 1-1/8" | P9: 1.125 | Q9: 1.5 | R9: 29030 | S9: 36287 | AB9: 8
A10: VK400X180X6X10 | B10: 400 | C10: 180 | D10: 6 | E10: 10 | O10: 1-1/4" | P10: 1.25 | Q10: 1.625 | R10: 36741 | S10: 46266 | AB10: 10
A11: VK400X180X6X12 | B11: 400 | C11: 180 | D11: 6 | E11: 12 | AB11: 12
A12: VK420X180X6X12 | B12: 420 | C12: 180 | D12: 6 | E12: 12 | AB12: 15
A13: VK440X180X6X12 | B13: 440 | C13: 180 | D13: 6 | E13: 12 | AB13: 16
A14: HA200X140X6X12 | B14: 200 | C14: 140 | D14: 6 | E14: 12 | AB14: 19
A15: HA240X180X6X12 | B15: 240 | C15: 180 | D15: 6 | E15: 12 | AB15: 20
A16: HA300X180X6X12 | B16: 300 | C16: 180 | D16: 6 | E16: 12 | AB16: 22
A17: HA360X180X6X12 | B17: 360 | C17: 180 | D17: 6 | E17: 12 | AB17: 25
A18: HA380X200X8X15 | B18: 380 | C18: 200 | D18: 8 | E18: 15 | AB18: 28
A19: HA400X200X8X15 | B19: 400 | C19: 200 | D19: 8 | E19: 15 | AB19: 30
A20: HA420X210X8X15 | B20: 420 | C20: 210 | D20: 8 | E20: 15 | AB20: 32
A21: HA440X220X8X15 | B21: 440 | C21: 220 | D21: 8 | E21: 15 | AB21: 35
A22: HA460X230X8X15 | B22: 460 | C22: 230 | D22: 8 | E22: 15 | AB22: 38
A23: HA480X240X8X15 | B23: 480 | C23: 240 | D23: 8 | E23: 15
A24: HA500X250X10X15 | B24: 500 | C24: 250 | D24: 10 | E24: 15
A25: HA520X260X10X15 | B25: 520 | C25: 260 | D25: 10 | E25: 15
A26: HA540X270X10X15 | B26: 540 | C26: 270 | D26: 10 | E26: 15
A27: W8X31 | B27: 203 | C27: 203 | D27: 7.2 | E27: 11
A28: W10X49 | B28: 254 | C28: 254 | D28: 8.6 | E28: 14.2
A29: W12X65 | B29: 308 | C29: 305 | D29: 9.9 | E29: 15.4
A30: W14X90 | B30: 356 | C30: 368 | D30: 11.2 | E30: 18
A31: W14X120 | B31: 368 | C31: 373 | D31: 15 | E31: 23.9
A32: W16X40 | B32: 407 | C32: 178 | D32: 7.7 | E32: 12.8
A33: W18X50 | B33: 457 | C33: 190 | D33: 9 | E33: 14.5
A34: W21X62 | B34: 533 | C34: 209 | D34: 10.2 | E34: 15.6
A35: W24X76 | B35: 608 | C35: 228 | D35: 11.2 | E35: 17.3

Sheet DIBUJO
A1: Coordenadas de las vistas (normalizadas a ±1). No editar.
D2: Col inf ala | G2: Col sup ala | J2: Placa ala | M2: Relleno | P2: Col inf ala- | S2: Col sup ala- | V2: Placa ala- | Y2: Relleno- | AB2: Placa alma | AE2: Soldadura | AH2: Pernos ala | AK2: Pernos alma | AN2: Col inferior | AQ2: Col superior | AT2: Placa | AW2: Relleno s | AZ2: Alma | BC2: Placa- | BF2: Relleno s- | BI2: Alma- | BL2: Pernos ala | BO2: Pernos alma
A3: Largo placa de ala | B3: =gap/10+2*(fa_Lec/10+(fa_n-1)*fa_s/10+fa_Lep/10) -> 46.3
A4: Largo placa de alma | B4: =gap/10+2*(wa_Le/10+(wa_nr-1)*wa_sv/10+wa_Le/10) -> 31.3 | D4: =(((l_d/2))-(0))/dSe -> 0.50062578 | E4: =((-dH)-(0))/dSe -> -0.95238095 | G4: =(((u_d/2))-(0))/dSe -> 0.47678646 | H4: =((dH)-(0))/dSe -> 0.95238095 | J4: =(((dxp))-(0))/dSe -> 0.50062578 | K4: =((-dLp/2*t_ap)-(0))/dSe -> -0.55188033 | M4: =(((u_d/2))-(0))/dSe -> 0.47678646 | N4: =((dg2)-(0))/dSe -> 0.0047678646 | P4: =((-(l_d/2))-(0))/dSe -> -0.50062578 | Q4: =((-dH)-(0))/dSe -> -0.95238095 | S4: =((-(u_d/2))-(0))/dSe -> -0.47678646 | T4: =((dH)-(0))/dSe -> 0.95238095 | V4: =((-(dxp))-(0))/dSe -> -0.50062578 | W4: =((-dLp/2*t_ap)-(0))/dSe -> -0.55188033 | Y4: =((-(u_d/2))-(0))/dSe -> -0.47678646 | Z4: =((dg2)-(0))/dSe -> 0.0047678646 | AB4: =((-pw_b/20*t_ap)-(0))/dSe -> -0.23839323 | AC4: =((-dLw/2*t_ap)-(0))/dSe -> -0.3730854 | AE4: =((-u_d/2*(1-t_ap))-(0))/dSe -> 0 | AF4: =((0)-(0))/dSe -> 0 | AH4: =((IF(t_ap=1,(dxp),99))-(0))/dSe -> 0.50062578 | AI4: =(((gap/20+fa_Lec/10+fa_s/10*MIN(0,fa_n-1)))-(0))/dSe -> 0.09893319 | AK4: =((IF(t_ap=1,-(wa_nc-1)*wa_sh/20+wa_sh/10*MIN(0,wa_nc-1),99))-(0))/dSe -> -0.11919661 | AL4: =(((gap/20+wa_Le/10+wa_sv/10*MIN(0,wa_nr-1)))-(0))/dSe -> 0.09893319 | AN4: =((-l_d/2)-(0))/dSs -> -0.84459459 | AO4: =((-l_bf/2)-(0))/dSs -> -0.4222973 | AQ4: =((-u_d/2)-(0))/dSs -> -0.8043758 | AR4: =((-u_bf/2)-(0))/dSs -> -0.4021879 | AT4: =(((dxp))-(0))/dSs -> 0.84459459 | AU4: =((-pf_b/20*t_ap)-(0))/dSs -> -0.36196911 | AW4: =(((u_d/2))-(0))/dSs -> 0.8043758 | AX4: =((-pf_b/20*t_ap)-(0))/dSs -> -0.36196911 | AZ4: =((-pw_b/20*t_ap)-(0))/dSs -> -0.4021879 | BA4: =(((u_tw/2))-(0))/dSs -> 0.016087516 | BC4: =((-(dxp))-(0))/dSs -> -0.84459459 | BD4: =((-pf_b/20*t_ap)-(0))/dSs -> -0.36196911 | BF4: =((-(u_d/2))-(0))/dSs -> -0.8043758 | BG4: =((-pf_b/20*t_ap)-(0))/dSs -> -0.36196911 | BI4: =((-pw_b/20*t_ap)-(0))/dSs -> -0.4021879 | BJ4: =((-(u_tw/2))-(0))/dSs -> -0.016087516 | BL4: =((IF(t_ap=1,(u_d/2),99))-(0))/dSs -> 0.8043758 | BM4: =(((fa_g/20))-(0))/dSs -> 0.22120335 | BO4: =((IF(t_ap=1,-(wa_nc-1)*wa_sh/20+wa_sh/10*MIN(0,wa_nc-1),99))-(0))/dSs -> -0.20109395 | BP4: =((0)-(0))/dSs -> 0
A5: Semialto dibujado | B5: =MAX(dLp,dLw)/2+0.4*MAX(u_d,l_d) -> 39.95 | D5: =(((l_d/2))-(0))/dSe -> 0.50062578 | E5: =((-dg2)-(0))/dSe -> -0.0047678646 | G5: =(((u_d/2))-(0))/dSe -> 0.47678646 | H5: =((dg2)-(0))/dSe -> 0.0047678646 | J5: =(((dxp))-(0))/dSe -> 0.50062578 | K5: =((dLp/2*t_ap)-(0))/dSe -> 0.55188033 | M5: =(((u_d/2))-(0))/dSe -> 0.47678646 | N5: =((dLp/2*t_ap+dg2*(1-t_ap))-(0))/dSe -> 0.55188033 | P5: =((-(l_d/2))-(0))/dSe -> -0.50062578 | Q5: =((-dg2)-(0))/dSe -> -0.0047678646 | S5: =((-(u_d/2))-(0))/dSe -> -0.47678646 | T5: =((dg2)-(0))/dSe -> 0.0047678646 | V5: =((-(dxp))-(0))/dSe -> -0.50062578 | W5: =((dLp/2*t_ap)-(0))/dSe -> 0.55188033 | Y5: =((-(u_d/2))-(0))/dSe -> -0.47678646 | Z5: =((dLp/2*t_ap+dg2*(1-t_ap))-(0))/dSe -> 0.55188033 | AB5: =((-pw_b/20*t_ap)-(0))/dSe -> -0.23839323 | AC5: =((dLw/2*t_ap)-(0))/dSe -> 0.3730854 | AE5: =((u_d/2*(1-t_ap))-(0))/dSe -> 0 | AF5: =((0)-(0))/dSe -> 0 | AH5: =((IF(t_ap=1,(dxp),99))-(0))/dSe -> 0.50062578 | AI5: =(((gap/20+fa_Lec/10+fa_s/10*MIN(1,fa_n-1)))-(0))/dSe -> 0.27772811 | AK5: =((IF(t_ap=1,-(wa_nc-1)*wa_sh/20+wa_sh/10*MIN(0,wa_nc-1),99))-(0))/dSe -> -0.11919661 | AL5: =(((gap/20+wa_Le/10+wa_sv/10*MIN(1,wa_nr-1)))-(0))/dSe -> 0.27772811 | AN5: =((-l_d/2)-(0))/dSs -> -0.84459459 | AO5: =((l_bf/2)-(0))/dSs -> 0.4222973 | AQ5: =((-u_d/2)-(0))/dSs -> -0.8043758 | AR5: =((u_bf/2)-(0))/dSs -> 0.4021879 | AT5: =(((dxp))-(0))/dSs -> 0.84459459 | AU5: =((pf_b/20*t_ap)-(0))/dSs -> 0.36196911 | AW5: =(((u_d/2))-(0))/dSs -> 0.8043758 | AX5: =((pf_b/20*t_ap)-(0))/dSs -> 0.36196911 | AZ5: =((-pw_b/20*t_ap)-(0))/dSs -> -0.4021879 | BA5: =(((u_tw/2+pw_t/10*t_ap))-(0))/dSs -> 0.048262548 | BC5: =((-(dxp))-(0))/dSs -> -0.84459459 | BD5: =((pf_b/20*t_ap)-(0))/dSs -> 0.36196911 | BF5: =((-(u_d/2))-(0))/dSs -> -0.8043758 | BG5: =((pf_b/20*t_ap)-(0))/dSs -> 0.36196911 | BI5: =((-pw_b/20*t_ap)-(0))/dSs -> -0.4021879 | BJ5: =((-(u_tw/2+pw_t/10*t_ap))-(0))/dSs -> -0.048262548 | BL5: =((IF(t_ap=1,(u_d/2),99))-(0))/dSs -> 0.8043758 | BM5: =((-(fa_g/20))-(0))/dSs -> -0.22120335 | BO5: =((IF(t_ap=1,-(wa_nc-1)*wa_sh/20+wa_sh/10*MIN(1,wa_nc-1),99))-(0))/dSs -> 0.20109395 | BP5: =((0)-(0))/dSs -> 0
A6: S elevación | B6: =MAX(2*dH,MAX(u_d,l_d)+2*pf_t/10)/2*1.05 -> 41.9475 | D6: =(((l_d/2-l_tf))-(0))/dSe -> 0.4648668 | E6: =((-dg2)-(0))/dSe -> -0.0047678646 | G6: =(((u_d/2-u_tf))-(0))/dSe -> 0.44102747 | H6: =((dg2)-(0))/dSe -> 0.0047678646 | J6: =(((dxp+pf_t/10*t_ap))-(0))/dSe -> 0.52923297 | K6: =((dLp/2*t_ap)-(0))/dSe -> 0.55188033 | M6: =(((u_d/2+(l_d-u_d)/2*t_ap))-(0))/dSe -> 0.50062578 | N6: =((dLp/2*t_ap+dg2*(1-t_ap))-(0))/dSe -> 0.55188033 | P6: =((-(l_d/2-l_tf))-(0))/dSe -> -0.4648668 | Q6: =((-dg2)-(0))/dSe -> -0.0047678646 | S6: =((-(u_d/2-u_tf))-(0))/dSe -> -0.44102747 | T6: =((dg2)-(0))/dSe -> 0.0047678646 | V6: =((-(dxp+pf_t/10*t_ap))-(0))/dSe -> -0.52923297 | W6: =((dLp/2*t_ap)-(0))/dSe -> 0.55188033 | Y6: =((-(u_d/2+(l_d-u_d)/2*t_ap))-(0))/dSe -> -0.50062578 | Z6: =((dLp/2*t_ap+dg2*(1-t_ap))-(0))/dSe -> 0.55188033 | AB6: =((pw_b/20*t_ap)-(0))/dSe -> 0.23839323 | AC6: =((dLw/2*t_ap)-(0))/dSe -> 0.3730854 | AH6: =((IF(t_ap=1,(dxp),99))-(0))/dSe -> 0.50062578 | AI6: =(((gap/20+fa_Lec/10+fa_s/10*MIN(2,fa_n-1)))-(0))/dSe -> 0.45652303 | AK6: =((IF(t_ap=1,-(wa_nc-1)*wa_sh/20+wa_sh/10*MIN(0,wa_nc-1),99))-(0))/dSe -> -0.11919661 | AL6: =(((gap/20+wa_Le/10+wa_sv/10*MIN(2,wa_nr-1)))-(0))/dSe -> 0.27772811 | AN6: =((-l_d/2+l_tf)-(0))/dSs -> -0.78426641 | AO6: =((l_bf/2)-(0))/dSs -> 0.4222973 | AQ6: =((-u_d/2+u_tf)-(0))/dSs -> -0.74404762 | AR6: =((u_bf/2)-(0))/dSs -> 0.4021879 | AT6: =(((dxp+pf_t/10*t_ap))-(0))/dSs -> 0.89285714 | AU6: =((pf_b/20*t_ap)-(0))/dSs -> 0.36196911 | AW6: =(((u_d/2+(l_d-u_d)/2*t_ap))-(0))/dSs -> 0.84459459 | AX6: =((pf_b/20*t_ap)-(0))/dSs -> 0.36196911 | AZ6: =((pw_b/20*t_ap)-(0))/dSs -> 0.4021879 | BA6: =(((u_tw/2+pw_t/10*t_ap))-(0))/dSs -> 0.048262548 | BC6: =((-(dxp+pf_t/10*t_ap))-(0))/dSs -> -0.89285714 | BD6: =((pf_b/20*t_ap)-(0))/dSs -> 0.36196911 | BF6: =((-(u_d/2+(l_d-u_d)/2*t_ap))-(0))/dSs -> -0.84459459 | BG6: =((pf_b/20*t_ap)-(0))/dSs -> 0.36196911 | BI6: =((pw_b/20*t_ap)-(0))/dSs -> 0.4021879 | BJ6: =((-(u_tw/2+pw_t/10*t_ap))-(0))/dSs -> -0.048262548 | BL6: =((IF(t_ap=1,-(u_d/2),99))-(0))/dSs -> -0.8043758 | BM6: =(((fa_g/20))-(0))/dSs -> 0.22120335 | BO6: =((IF(t_ap=1,-(wa_nc-1)*wa_sh/20+wa_sh/10*MIN(2,wa_nc-1),99))-(0))/dSs -> 0.20109395 | BP6: =((0)-(0))/dSs -> 0
A7: S sección | B7: =MAX(MAX(u_d,l_d)+2*pf_t/10,MAX(u_bf,l_bf))/2*1.12 -> 24.864 | D7: =(((l_d/2-l_tf))-(0))/dSe -> 0.4648668 | E7: =((-dH)-(0))/dSe -> -0.95238095 | G7: =(((u_d/2-u_tf))-(0))/dSe -> 0.44102747 | H7: =((dH)-(0))/dSe -> 0.95238095 | J7: =(((dxp+pf_t/10*t_ap))-(0))/dSe -> 0.52923297 | K7: =((-dLp/2*t_ap)-(0))/dSe -> -0.55188033 | M7: =(((u_d/2+(l_d-u_d)/2*t_ap))-(0))/dSe -> 0.50062578 | N7: =((dg2)-(0))/dSe -> 0.0047678646 | P7: =((-(l_d/2-l_tf))-(0))/dSe -> -0.4648668 | Q7: =((-dH)-(0))/dSe -> -0.95238095 | S7: =((-(u_d/2-u_tf))-(0))/dSe -> -0.44102747 | T7: =((dH)-(0))/dSe -> 0.95238095 | V7: =((-(dxp+pf_t/10*t_ap))-(0))/dSe -> -0.52923297 | W7: =((-dLp/2*t_ap)-(0))/dSe -> -0.55188033 | Y7: =((-(u_d/2+(l_d-u_d)/2*t_ap))-(0))/dSe -> -0.50062578 | Z7: =((dg2)-(0))/dSe -> 0.0047678646 | AB7: =((pw_b/20*t_ap)-(0))/dSe -> 0.23839323 | AC7: =((-dLw/2*t_ap)-(0))/dSe -> -0.3730854 | AH7: =((IF(t_ap=1,(dxp),99))-(0))/dSe -> 0.50062578 | AI7: =(((gap/20+fa_Lec/10+fa_s/10*MIN(3,fa_n-1)))-(0))/dSe -> 0.45652303 | AK7: =((IF(t_ap=1,-(wa_nc-1)*wa_sh/20+wa_sh/10*MIN(0,wa_nc-1),99))-(0))/dSe -> -0.11919661 | AL7: =(((gap/20+wa_Le/10+wa_sv/10*MIN(3,wa_nr-1)))-(0))/dSe -> 0.27772811 | AN7: =((-l_d/2+l_tf)-(0))/dSs -> -0.78426641 | AO7: =((l_tw/2)-(0))/dSs -> 0.016087516 | AQ7: =((-u_d/2+u_tf)-(0))/dSs -> -0.74404762 | AR7: =((u_tw/2)-(0))/dSs -> 0.016087516 | AT7: =(((dxp+pf_t/10*t_ap))-(0))/dSs -> 0.89285714 | AU7: =((-pf_b/20*t_ap)-(0))/dSs -> -0.36196911 | AW7: =(((u_d/2+(l_d-u_d)/2*t_ap))-(0))/dSs -> 0.84459459 | AX7: =((-pf_b/20*t_ap)-(0))/dSs -> -0.36196911 | AZ7: =((pw_b/20*t_ap)-(0))/dSs -> 0.4021879 | BA7: =(((u_tw/2))-(0))/dSs -> 0.016087516 | BC7: =((-(dxp+pf_t/10*t_ap))-(0))/dSs -> -0.89285714 | BD7: =((-pf_b/20*t_ap)-(0))/dSs -> -0.36196911 | BF7: =((-(u_d/2+(l_d-u_d)/2*t_ap))-(0))/dSs -> -0.84459459 | BG7: =((-pf_b/20*t_ap)-(0))/dSs -> -0.36196911 | BI7: =((pw_b/20*t_ap)-(0))/dSs -> 0.4021879 | BJ7: =((-(u_tw/2))-(0))/dSs -> -0.016087516 | BL7: =((IF(t_ap=1,-(u_d/2),99))-(0))/dSs -> -0.8043758 | BM7: =((-(fa_g/20))-(0))/dSs -> -0.22120335
A8: gap/2 (mín. 0.2 cm para dibujo) | B8: =MAX(gap/20,0.2) -> 0.2 | J8: =(((dxp))-(0))/dSe -> 0.50062578 | K8: =((-dLp/2*t_ap)-(0))/dSe -> -0.55188033 | M8: =(((u_d/2))-(0))/dSe -> 0.47678646 | N8: =((dg2)-(0))/dSe -> 0.0047678646 | V8: =((-(dxp))-(0))/dSe -> -0.50062578 | W8: =((-dLp/2*t_ap)-(0))/dSe -> -0.55188033 | Y8: =((-(u_d/2))-(0))/dSe -> -0.47678646 | Z8: =((dg2)-(0))/dSe -> 0.0047678646 | AB8: =((-pw_b/20*t_ap)-(0))/dSe -> -0.23839323 | AC8: =((-dLw/2*t_ap)-(0))/dSe -> -0.3730854 | AH8: =((IF(t_ap=1,(dxp),99))-(0))/dSe -> 0.50062578 | AI8: =(((gap/20+fa_Lec/10+fa_s/10*MIN(4,fa_n-1)))-(0))/dSe -> 0.45652303 | AK8: =((IF(t_ap=1,-(wa_nc-1)*wa_sh/20+wa_sh/10*MIN(0,wa_nc-1),99))-(0))/dSe -> -0.11919661 | AL8: =(((gap/20+wa_Le/10+wa_sv/10*MIN(4,wa_nr-1)))-(0))/dSe -> 0.27772811 | AN8: =((l_d/2-l_tf)-(0))/dSs -> 0.78426641 | AO8: =((l_tw/2)-(0))/dSs -> 0.016087516 | AQ8: =((u_d/2-u_tf)-(0))/dSs -> 0.74404762 | AR8: =((u_tw/2)-(0))/dSs -> 0.016087516 | AT8: =(((dxp))-(0))/dSs -> 0.84459459 | AU8: =((-pf_b/20*t_ap)-(0))/dSs -> -0.36196911 | AW8: =(((u_d/2))-(0))/dSs -> 0.8043758 | AX8: =((-pf_b/20*t_ap)-(0))/dSs -> -0.36196911 | AZ8: =((-pw_b/20*t_ap)-(0))/dSs -> -0.4021879 | BA8: =(((u_tw/2))-(0))/dSs -> 0.016087516 | BC8: =((-(dxp))-(0))/dSs -> -0.84459459 | BD8: =((-pf_b/20*t_ap)-(0))/dSs -> -0.36196911 | BF8: =((-(u_d/2))-(0))/dSs -> -0.8043758 | BG8: =((-pf_b/20*t_ap)-(0))/dSs -> -0.36196911 | BI8: =((-pw_b/20*t_ap)-(0))/dSs -> -0.4021879 | BJ8: =((-(u_tw/2))-(0))/dSs -> -0.016087516
A9: x placa (cara exterior de ala inferior) | B9: =l_d/2 -> 21 | AH9: =((IF(t_ap=1,(dxp),99))-(0))/dSe -> 0.50062578 | AI9: =(((gap/20+fa_Lec/10+fa_s/10*MIN(5,fa_n-1)))-(0))/dSe -> 0.45652303 | AK9: =((IF(t_ap=1,-(wa_nc-1)*wa_sh/20+wa_sh/10*MIN(0,wa_nc-1),99))-(0))/dSe -> -0.11919661 | AL9: =(((gap/20+wa_Le/10+wa_sv/10*MIN(5,wa_nr-1)))-(0))/dSe -> 0.27772811 | AN9: =((l_d/2-l_tf)-(0))/dSs -> 0.78426641 | AO9: =((l_bf/2)-(0))/dSs -> 0.4222973 | AQ9: =((u_d/2-u_tf)-(0))/dSs -> 0.74404762 | AR9: =((u_bf/2)-(0))/dSs -> 0.4021879
AH10: =((IF(t_ap=1,(dxp),99))-(0))/dSe -> 0.50062578 | AI10: =(((gap/20+fa_Lec/10+fa_s/10*MIN(6,fa_n-1)))-(0))/dSe -> 0.45652303 | AK10: =((IF(t_ap=1,-(wa_nc-1)*wa_sh/20+wa_sh/10*MIN(1,wa_nc-1),99))-(0))/dSe -> 0.11919661 | AL10: =(((gap/20+wa_Le/10+wa_sv/10*MIN(0,wa_nr-1)))-(0))/dSe -> 0.09893319 | AN10: =((l_d/2)-(0))/dSs -> 0.84459459 | AO10: =((l_bf/2)-(0))/dSs -> 0.4222973 | AQ10: =((u_d/2)-(0))/dSs -> 0.8043758 | AR10: =((u_bf/2)-(0))/dSs -> 0.4021879
AH11: =((IF(t_ap=1,(dxp),99))-(0))/dSe -> 0.50062578 | AI11: =(((gap/20+fa_Lec/10+fa_s/10*MIN(7,fa_n-1)))-(0))/dSe -> 0.45652303 | AK11: =((IF(t_ap=1,-(wa_nc-1)*wa_sh/20+wa_sh/10*MIN(1,wa_nc-1),99))-(0))/dSe -> 0.11919661 | AL11: =(((gap/20+wa_Le/10+wa_sv/10*MIN(1,wa_nr-1)))-(0))/dSe -> 0.27772811 | AN11: =((l_d/2)-(0))/dSs -> 0.84459459 | AO11: =((-l_bf/2)-(0))/dSs -> -0.4222973 | AQ11: =((u_d/2)-(0))/dSs -> 0.8043758 | AR11: =((-u_bf/2)-(0))/dSs -> -0.4021879
AH12: =((IF(t_ap=1,(dxp),99))-(0))/dSe -> 0.50062578 | AI12: =((-(gap/20+fa_Lec/10+fa_s/10*MIN(0,fa_n-1)))-(0))/dSe -> -0.09893319 | AK12: =((IF(t_ap=1,-(wa_nc-1)*wa_sh/20+wa_sh/10*MIN(1,wa_nc-1),99))-(0))/dSe -> 0.11919661 | AL12: =(((gap/20+wa_Le/10+wa_sv/10*MIN(2,wa_nr-1)))-(0))/dSe -> 0.27772811 | AN12: =((l_d/2-l_tf)-(0))/dSs -> 0.78426641 | AO12: =((-l_bf/2)-(0))/dSs -> -0.4222973 | AQ12: =((u_d/2-u_tf)-(0))/dSs -> 0.74404762 | AR12: =((-u_bf/2)-(0))/dSs -> -0.4021879
AH13: =((IF(t_ap=1,(dxp),99))-(0))/dSe -> 0.50062578 | AI13: =((-(gap/20+fa_Lec/10+fa_s/10*MIN(1,fa_n-1)))-(0))/dSe -> -0.27772811 | AK13: =((IF(t_ap=1,-(wa_nc-1)*wa_sh/20+wa_sh/10*MIN(1,wa_nc-1),99))-(0))/dSe -> 0.11919661 | AL13: =(((gap/20+wa_Le/10+wa_sv/10*MIN(3,wa_nr-1)))-(0))/dSe -> 0.27772811 | AN13: =((l_d/2-l_tf)-(0))/dSs -> 0.78426641 | AO13: =((-l_tw/2)-(0))/dSs -> -0.016087516 | AQ13: =((u_d/2-u_tf)-(0))/dSs -> 0.74404762 | AR13: =((-u_tw/2)-(0))/dSs -> -0.016087516
AH14: =((IF(t_ap=1,(dxp),99))-(0))/dSe -> 0.50062578 | AI14: =((-(gap/20+fa_Lec/10+fa_s/10*MIN(2,fa_n-1)))-(0))/dSe -> -0.45652303 | AK14: =((IF(t_ap=1,-(wa_nc-1)*wa_sh/20+wa_sh/10*MIN(1,wa_nc-1),99))-(0))/dSe -> 0.11919661 | AL14: =(((gap/20+wa_Le/10+wa_sv/10*MIN(4,wa_nr-1)))-(0))/dSe -> 0.27772811 | AN14: =((-l_d/2+l_tf)-(0))/dSs -> -0.78426641 | AO14: =((-l_tw/2)-(0))/dSs -> -0.016087516 | AQ14: =((-u_d/2+u_tf)-(0))/dSs -> -0.74404762 | AR14: =((-u_tw/2)-(0))/dSs -> -0.016087516
AH15: =((IF(t_ap=1,(dxp),99))-(0))/dSe -> 0.50062578 | AI15: =((-(gap/20+fa_Lec/10+fa_s/10*MIN(3,fa_n-1)))-(0))/dSe -> -0.45652303 | AK15: =((IF(t_ap=1,-(wa_nc-1)*wa_sh/20+wa_sh/10*MIN(1,wa_nc-1),99))-(0))/dSe -> 0.11919661 | AL15: =(((gap/20+wa_Le/10+wa_sv/10*MIN(5,wa_nr-1)))-(0))/dSe -> 0.27772811 | AN15: =((-l_d/2+l_tf)-(0))/dSs -> -0.78426641 | AO15: =((-l_bf/2)-(0))/dSs -> -0.4222973 | AQ15: =((-u_d/2+u_tf)-(0))/dSs -> -0.74404762 | AR15: =((-u_bf/2)-(0))/dSs -> -0.4021879
AH16: =((IF(t_ap=1,(dxp),99))-(0))/dSe -> 0.50062578 | AI16: =((-(gap/20+fa_Lec/10+fa_s/10*MIN(4,fa_n-1)))-(0))/dSe -> -0.45652303 | AK16: =((IF(t_ap=1,-(wa_nc-1)*wa_sh/20+wa_sh/10*MIN(2,wa_nc-1),99))-(0))/dSe -> 0.11919661 | AL16: =(((gap/20+wa_Le/10+wa_sv/10*MIN(0,wa_nr-1)))-(0))/dSe -> 0.09893319 | AN16: =((-l_d/2)-(0))/dSs -> -0.84459459 | AO16: =((-l_bf/2)-(0))/dSs -> -0.4222973 | AQ16: =((-u_d/2)-(0))/dSs -> -0.8043758 | AR16: =((-u_bf/2)-(0))/dSs -> -0.4021879
AH17: =((IF(t_ap=1,(dxp),99))-(0))/dSe -> 0.50062578 | AI17: =((-(gap/20+fa_Lec/10+fa_s/10*MIN(5,fa_n-1)))-(0))/dSe -> -0.45652303 | AK17: =((IF(t_ap=1,-(wa_nc-1)*wa_sh/20+wa_sh/10*MIN(2,wa_nc-1),99))-(0))/dSe -> 0.11919661 | AL17: =(((gap/20+wa_Le/10+wa_sv/10*MIN(1,wa_nr-1)))-(0))/dSe -> 0.27772811
AH18: =((IF(t_ap=1,(dxp),99))-(0))/dSe -> 0.50062578 | AI18: =((-(gap/20+fa_Lec/10+fa_s/10*MIN(6,fa_n-1)))-(0))/dSe -> -0.45652303 | AK18: =((IF(t_ap=1,-(wa_nc-1)*wa_sh/20+wa_sh/10*MIN(2,wa_nc-1),99))-(0))/dSe -> 0.11919661 | AL18: =(((gap/20+wa_Le/10+wa_sv/10*MIN(2,wa_nr-1)))-(0))/dSe -> 0.27772811
AH19: =((IF(t_ap=1,(dxp),99))-(0))/dSe -> 0.50062578 | AI19: =((-(gap/20+fa_Lec/10+fa_s/10*MIN(7,fa_n-1)))-(0))/dSe -> -0.45652303 | AK19: =((IF(t_ap=1,-(wa_nc-1)*wa_sh/20+wa_sh/10*MIN(2,wa_nc-1),99))-(0))/dSe -> 0.11919661 | AL19: =(((gap/20+wa_Le/10+wa_sv/10*MIN(3,wa_nr-1)))-(0))/dSe -> 0.27772811
AH20: =((IF(t_ap=1,-(dxp),99))-(0))/dSe -> -0.50062578 | AI20: =(((gap/20+fa_Lec/10+fa_s/10*MIN(0,fa_n-1)))-(0))/dSe -> 0.09893319 | AK20: =((IF(t_ap=1,-(wa_nc-1)*wa_sh/20+wa_sh/10*MIN(2,wa_nc-1),99))-(0))/dSe -> 0.11919661 | AL20: =(((gap/20+wa_Le/10+wa_sv/10*MIN(4,wa_nr-1)))-(0))/dSe -> 0.27772811
AH21: =((IF(t_ap=1,-(dxp),99))-(0))/dSe -> -0.50062578 | AI21: =(((gap/20+fa_Lec/10+fa_s/10*MIN(1,fa_n-1)))-(0))/dSe -> 0.27772811 | AK21: =((IF(t_ap=1,-(wa_nc-1)*wa_sh/20+wa_sh/10*MIN(2,wa_nc-1),99))-(0))/dSe -> 0.11919661 | AL21: =(((gap/20+wa_Le/10+wa_sv/10*MIN(5,wa_nr-1)))-(0))/dSe -> 0.27772811
AH22: =((IF(t_ap=1,-(dxp),99))-(0))/dSe -> -0.50062578 | AI22: =(((gap/20+fa_Lec/10+fa_s/10*MIN(2,fa_n-1)))-(0))/dSe -> 0.45652303 | AK22: =((IF(t_ap=1,-(wa_nc-1)*wa_sh/20+wa_sh/10*MIN(0,wa_nc-1),99))-(0))/dSe -> -0.11919661 | AL22: =((-(gap/20+wa_Le/10+wa_sv/10*MIN(0,wa_nr-1)))-(0))/dSe -> -0.09893319
AH23: =((IF(t_ap=1,-(dxp),99))-(0))/dSe -> -0.50062578 | AI23: =(((gap/20+fa_Lec/10+fa_s/10*MIN(3,fa_n-1)))-(0))/dSe -> 0.45652303 | AK23: =((IF(t_ap=1,-(wa_nc-1)*wa_sh/20+wa_sh/10*MIN(0,wa_nc-1),99))-(0))/dSe -> -0.11919661 | AL23: =((-(gap/20+wa_Le/10+wa_sv/10*MIN(1,wa_nr-1)))-(0))/dSe -> -0.27772811
AH24: =((IF(t_ap=1,-(dxp),99))-(0))/dSe -> -0.50062578 | AI24: =(((gap/20+fa_Lec/10+fa_s/10*MIN(4,fa_n-1)))-(0))/dSe -> 0.45652303 | AK24: =((IF(t_ap=1,-(wa_nc-1)*wa_sh/20+wa_sh/10*MIN(0,wa_nc-1),99))-(0))/dSe -> -0.11919661 | AL24: =((-(gap/20+wa_Le/10+wa_sv/10*MIN(2,wa_nr-1)))-(0))/dSe -> -0.27772811
AH25: =((IF(t_ap=1,-(dxp),99))-(0))/dSe -> -0.50062578 | AI25: =(((gap/20+fa_Lec/10+fa_s/10*MIN(5,fa_n-1)))-(0))/dSe -> 0.45652303 | AK25: =((IF(t_ap=1,-(wa_nc-1)*wa_sh/20+wa_sh/10*MIN(0,wa_nc-1),99))-(0))/dSe -> -0.11919661 | AL25: =((-(gap/20+wa_Le/10+wa_sv/10*MIN(3,wa_nr-1)))-(0))/dSe -> -0.27772811
AH26: =((IF(t_ap=1,-(dxp),99))-(0))/dSe -> -0.50062578 | AI26: =(((gap/20+fa_Lec/10+fa_s/10*MIN(6,fa_n-1)))-(0))/dSe -> 0.45652303 | AK26: =((IF(t_ap=1,-(wa_nc-1)*wa_sh/20+wa_sh/10*MIN(0,wa_nc-1),99))-(0))/dSe -> -0.11919661 | AL26: =((-(gap/20+wa_Le/10+wa_sv/10*MIN(4,wa_nr-1)))-(0))/dSe -> -0.27772811
AH27: =((IF(t_ap=1,-(dxp),99))-(0))/dSe -> -0.50062578 | AI27: =(((gap/20+fa_Lec/10+fa_s/10*MIN(7,fa_n-1)))-(0))/dSe -> 0.45652303 | AK27: =((IF(t_ap=1,-(wa_nc-1)*wa_sh/20+wa_sh/10*MIN(0,wa_nc-1),99))-(0))/dSe -> -0.11919661 | AL27: =((-(gap/20+wa_Le/10+wa_sv/10*MIN(5,wa_nr-1)))-(0))/dSe -> -0.27772811
AH28: =((IF(t_ap=1,-(dxp),99))-(0))/dSe -> -0.50062578 | AI28: =((-(gap/20+fa_Lec/10+fa_s/10*MIN(0,fa_n-1)))-(0))/dSe -> -0.09893319 | AK28: =((IF(t_ap=1,-(wa_nc-1)*wa_sh/20+wa_sh/10*MIN(1,wa_nc-1),99))-(0))/dSe -> 0.11919661 | AL28: =((-(gap/20+wa_Le/10+wa_sv/10*MIN(0,wa_nr-1)))-(0))/dSe -> -0.09893319
AH29: =((IF(t_ap=1,-(dxp),99))-(0))/dSe -> -0.50062578 | AI29: =((-(gap/20+fa_Lec/10+fa_s/10*MIN(1,fa_n-1)))-(0))/dSe -> -0.27772811 | AK29: =((IF(t_ap=1,-(wa_nc-1)*wa_sh/20+wa_sh/10*MIN(1,wa_nc-1),99))-(0))/dSe -> 0.11919661 | AL29: =((-(gap/20+wa_Le/10+wa_sv/10*MIN(1,wa_nr-1)))-(0))/dSe -> -0.27772811
AH30: =((IF(t_ap=1,-(dxp),99))-(0))/dSe -> -0.50062578 | AI30: =((-(gap/20+fa_Lec/10+fa_s/10*MIN(2,fa_n-1)))-(0))/dSe -> -0.45652303 | AK30: =((IF(t_ap=1,-(wa_nc-1)*wa_sh/20+wa_sh/10*MIN(1,wa_nc-1),99))-(0))/dSe -> 0.11919661 | AL30: =((-(gap/20+wa_Le/10+wa_sv/10*MIN(2,wa_nr-1)))-(0))/dSe -> -0.27772811
AH31: =((IF(t_ap=1,-(dxp),99))-(0))/dSe -> -0.50062578 | AI31: =((-(gap/20+fa_Lec/10+fa_s/10*MIN(3,fa_n-1)))-(0))/dSe -> -0.45652303 | AK31: =((IF(t_ap=1,-(wa_nc-1)*wa_sh/20+wa_sh/10*MIN(1,wa_nc-1),99))-(0))/dSe -> 0.11919661 | AL31: =((-(gap/20+wa_Le/10+wa_sv/10*MIN(3,wa_nr-1)))-(0))/dSe -> -0.27772811
AH32: =((IF(t_ap=1,-(dxp),99))-(0))/dSe -> -0.50062578 | AI32: =((-(gap/20+fa_Lec/10+fa_s/10*MIN(4,fa_n-1)))-(0))/dSe -> -0.45652303 | AK32: =((IF(t_ap=1,-(wa_nc-1)*wa_sh/20+wa_sh/10*MIN(1,wa_nc-1),99))-(0))/dSe -> 0.11919661 | AL32: =((-(gap/20+wa_Le/10+wa_sv/10*MIN(4,wa_nr-1)))-(0))/dSe -> -0.27772811
AH33: =((IF(t_ap=1,-(dxp),99))-(0))/dSe -> -0.50062578 | AI33: =((-(gap/20+fa_Lec/10+fa_s/10*MIN(5,fa_n-1)))-(0))/dSe -> -0.45652303 | AK33: =((IF(t_ap=1,-(wa_nc-1)*wa_sh/20+wa_sh/10*MIN(1,wa_nc-1),99))-(0))/dSe -> 0.11919661 | AL33: =((-(gap/20+wa_Le/10+wa_sv/10*MIN(5,wa_nr-1)))-(0))/dSe -> -0.27772811
AH34: =((IF(t_ap=1,-(dxp),99))-(0))/dSe -> -0.50062578 | AI34: =((-(gap/20+fa_Lec/10+fa_s/10*MIN(6,fa_n-1)))-(0))/dSe -> -0.45652303 | AK34: =((IF(t_ap=1,-(wa_nc-1)*wa_sh/20+wa_sh/10*MIN(2,wa_nc-1),99))-(0))/dSe -> 0.11919661 | AL34: =((-(gap/20+wa_Le/10+wa_sv/10*MIN(0,wa_nr-1)))-(0))/dSe -> -0.09893319
AH35: =((IF(t_ap=1,-(dxp),99))-(0))/dSe -> -0.50062578 | AI35: =((-(gap/20+fa_Lec/10+fa_s/10*MIN(7,fa_n-1)))-(0))/dSe -> -0.45652303 | AK35: =((IF(t_ap=1,-(wa_nc-1)*wa_sh/20+wa_sh/10*MIN(2,wa_nc-1),99))-(0))/dSe -> 0.11919661 | AL35: =((-(gap/20+wa_Le/10+wa_sv/10*MIN(1,wa_nr-1)))-(0))/dSe -> -0.27772811
AK36: =((IF(t_ap=1,-(wa_nc-1)*wa_sh/20+wa_sh/10*MIN(2,wa_nc-1),99))-(0))/dSe -> 0.11919661 | AL36: =((-(gap/20+wa_Le/10+wa_sv/10*MIN(2,wa_nr-1)))-(0))/dSe -> -0.27772811
AK37: =((IF(t_ap=1,-(wa_nc-1)*wa_sh/20+wa_sh/10*MIN(2,wa_nc-1),99))-(0))/dSe -> 0.11919661 | AL37: =((-(gap/20+wa_Le/10+wa_sv/10*MIN(3,wa_nr-1)))-(0))/dSe -> -0.27772811
AK38: =((IF(t_ap=1,-(wa_nc-1)*wa_sh/20+wa_sh/10*MIN(2,wa_nc-1),99))-(0))/dSe -> 0.11919661 | AL38: =((-(gap/20+wa_Le/10+wa_sv/10*MIN(4,wa_nr-1)))-(0))/dSe -> -0.27772811
AK39: =((IF(t_ap=1,-(wa_nc-1)*wa_sh/20+wa_sh/10*MIN(2,wa_nc-1),99))-(0))/dSe -> 0.11919661 | AL39: =((-(gap/20+wa_Le/10+wa_sv/10*MIN(5,wa_nr-1)))-(0))/dSe -> -0.27772811
