Workbook

Sheet DISEÑO
B2: CONEXIÓN DE MOMENTO CON PLACA EXTREMA EXTENDIDA (END PLATE) — 4E · 4ES · 8ES
B3: AISC Design Guide 4 (2da ed.) · AISC 358-16 Cap. 6 · AISC 360-16 (J2, J3, J4, J10) · LRFD · Unidades: Tonf, Tonf·m, mm, kgf/cm²
B4: Celdas de ingreso: | C4: valor | D4: Calculado: | E4: valor | G4: Estados: VERDE ≤ límite · AMARILLO entre límite y 1.00 · ROJO > 1.00 (ratio = demanda / capacidad)
B6: DATOS GENERALES | G6: VISTA FRONTAL DE PLACA (●rojo: tracción) | J6: ELEVACIÓN LATERAL | N6: VERIFICACIONES — combinación gobernante por chequeo
B7: Proyecto | C7: Galpón KUBIEC — ejemplo | N7: =IF(COUNT(S12:S44)=0,"SIN CARGAS",IF(MAX(S12:S44)>1,"✖ NO CUMPLE — ratio máx. "&TEXT(MAX(S12:S44),"0.00"),IF(MAX(S12:S44)>lim_verde,"▲ CUMPLE AL LÍMITE — ratio máx. "&TEXT(MAX(S12:S44),"0.00"),"✔ CUMPLE — ratio máx. "&TEXT(MAX(S12:S44),"0.00")))) -> ✔ CUMPLE — ratio máx. 0.90
B8: Elemento / nudo | C8: Nudo viga–columna eje 2
B9: Límite verde / amarillo (ratio) | C9: 0.9
B10: CONFIGURACIÓN | N10: Verificación | O10: Referencia | P10: Demanda | Q10: Capacidad | R10: Unidad | S10: Ratio | T10: Estado | U10: Combo
B11: Tipo de conexión | C11: 4E | N11: VIGA Y PLACA EXTREMA
B12: Procedimiento | C12: No sísmico (DG4) | N12: Pernos a tracción (sin efecto palanca) | O12: DG4 · AISC 358 §6.8 pasos 3–4 | P12: =INDEX(CALCULO!$D$112:$M$112,MATCH(MAX(CALCULO!$D$116:$M$116),CALCULO!$D$116:$M$116,0))/100000 -> 14 | Q12: =k_phin*k_Mnp/100000 -> 28.575436 | R12: Tonf·m | S12: =MAX(CALCULO!$D$116:$M$116) -> 0.48993128 | T12: =IF(ISNUMBER(S12),IF(S12>1,"NO CUMPLE",IF(S12>lim_verde,"AL LÍMITE","CUMPLE")),"N/A") -> CUMPLE | U12: =IF(ISNUMBER(S12),INDEX(CALCULO!$D$110:$M$110,MATCH(MAX(CALCULO!$D$116:$M$116),CALCULO!$D$116:$M$116,0)),"—") -> 1.2D+1.0E+L
B13: 1. VIGA | N13: Flexión de placa extrema (placa gruesa) | O13: DG4 · AISC 358 Tabla 6.2 | P13: =INDEX(CALCULO!$D$117:$M$117,MATCH(MAX(CALCULO!$D$118:$M$118),CALCULO!$D$118:$M$118,0))/1 -> 31.718734 | Q13: =k_phiMpl/100000 -> 56.527655 | R13: Tonf·m | S13: =MAX(CALCULO!$D$118:$M$118) -> 0.56111888 | T13: =IF(ISNUMBER(S13),IF(S13>1,"NO CUMPLE",IF(S13>lim_verde,"AL LÍMITE","CUMPLE")),"N/A") -> CUMPLE | U13: =IF(ISNUMBER(S13),INDEX(CALCULO!$D$110:$M$110,MATCH(MAX(CALCULO!$D$118:$M$118),CALCULO!$D$118:$M$118,0)),"—") -> 1.2D+1.6L
B14: Perfil (catálogo o ARMADO) | C14: VK400X180X6X12 | E14: Armado (mm) | N14: Extensión 4E — fluencia por corte | O14: AISC 358 §6.8 · J4.2(a) | P14: =IF(k_is4E=0,"—",INDEX(CALCULO!$D$115:$M$115,MATCH(MAX(CALCULO!$D$120:$M$120),CALCULO!$D$120:$M$120,0))/2000) -> 18.041237 | Q14: =IF(k_is4E=0,"—",k_Rsy/1000) -> 105.45 | R14: Tonf | S14: =IF(k_is4E=0,"N/A",MAX(CALCULO!$D$120:$M$120)) -> 0.17108807 | T14: =IF(ISNUMBER(S14),IF(S14>1,"NO CUMPLE",IF(S14>lim_verde,"AL LÍMITE","CUMPLE")),"N/A") -> CUMPLE | U14: =IF(ISNUMBER(S14),INDEX(CALCULO!$D$110:$M$110,MATCH(MAX(CALCULO!$D$120:$M$120),CALCULO!$D$120:$M$120,0)),"—") -> 1.2D+1.0E+L
B15: Peralte d | C15: =IF(vg_perfil="ARMADO (flejes soldados)",E15,INDEX(CATALOGOS!$B$5:$B$40,MATCH(vg_perfil,CATALOGOS!$A$5:$A$40,0))) -> 400 | D15: mm | E15: 400 | N15: Extensión 4E — ruptura por corte | O15: AISC 358 §6.8 · J4.2(b) | P15: =IF(k_is4E=0,"—",INDEX(CALCULO!$D$115:$M$115,MATCH(MAX(CALCULO!$D$121:$M$121),CALCULO!$D$121:$M$121,0))/2000) -> 18.041237 | Q15: =IF(k_is4E=0,"—",k_Rsr/1000) -> 76.70745 | R15: Tonf | S15: =IF(k_is4E=0,"N/A",MAX(CALCULO!$D$121:$M$121)) -> 0.23519537 | T15: =IF(ISNUMBER(S15),IF(S15>1,"NO CUMPLE",IF(S15>lim_verde,"AL LÍMITE","CUMPLE")),"N/A") -> CUMPLE | U15: =IF(ISNUMBER(S15),INDEX(CALCULO!$D$110:$M$110,MATCH(MAX(CALCULO!$D$121:$M$121),CALCULO!$D$121:$M$121,0)),"—") -> 1.2D+1.0E+L
B16: Ancho de ala bf | C16: =IF(vg_perfil="ARMADO (flejes soldados)",E16,INDEX(CATALOGOS!$C$5:$C$40,MATCH(vg_perfil,CATALOGOS!$A$5:$A$40,0))) -> 180 | D16: mm | E16: 180 | N16: Rigidizador de placa — espesor mínimo | O16: AISC 358 §6.8 (ts ≥ tbw·Fyb/Fys) | P16: =IF(k_is4E=1,"—",k_tsr*10) -> — | Q16: =IF(k_is4E=1,"—",st_t) -> — | R16: mm | S16: =IF(k_is4E=1,"N/A",k_tsr*10/st_t) -> N/A | T16: =IF(ISNUMBER(S16),IF(S16>1,"NO CUMPLE",IF(S16>lim_verde,"AL LÍMITE","CUMPLE")),"N/A") -> N/A | U16: —
B17: Espesor de alma tw | C17: =IF(vg_perfil="ARMADO (flejes soldados)",E17,INDEX(CATALOGOS!$D$5:$D$40,MATCH(vg_perfil,CATALOGOS!$A$5:$A$40,0))) -> 6 | D17: mm | E17: 6 | N17: Rigidizador de placa — pandeo local hst/ts | O17: AISC 358 §6.8 (≤ 0.56√(E/Fys)) | P17: =IF(k_is4E=1,"—",k_hts) -> — | Q17: =IF(k_is4E=1,"—",k_htsl) -> — | R17: - | S17: =IF(k_is4E=1,"N/A",k_hts/k_htsl) -> N/A | T17: =IF(ISNUMBER(S17),IF(S17>1,"NO CUMPLE",IF(S17>lim_verde,"AL LÍMITE","CUMPLE")),"N/A") -> N/A | U17: —
B18: Espesor de ala tf | C18: =IF(vg_perfil="ARMADO (flejes soldados)",E18,INDEX(CATALOGOS!$E$5:$E$40,MATCH(vg_perfil,CATALOGOS!$A$5:$A$40,0))) -> 12 | D18: mm | E18: 12 | N18: PERNOS — CORTE EN EL LADO DE COMPRESIÓN
B19: Acero | C19: A572 Gr50 | N19: Corte en pernos | O19: AISC 358 §6.8 · J3.6 | P19: =INDEX(CALCULO!$D$113:$M$113,MATCH(MAX(CALCULO!$D$122:$M$122),CALCULO!$D$122:$M$122,0))/1000 -> 7 | Q19: =k_Rvb/1000 -> 44.191147 | R19: Tonf | S19: =MAX(CALCULO!$D$122:$M$122) -> 0.15840277 | T19: =IF(ISNUMBER(S19),IF(S19>1,"NO CUMPLE",IF(S19>lim_verde,"AL LÍMITE","CUMPLE")),"N/A") -> CUMPLE | U19: =IF(ISNUMBER(S19),INDEX(CALCULO!$D$110:$M$110,MATCH(MAX(CALCULO!$D$122:$M$122),CALCULO!$D$122:$M$122,0)),"—") -> 1.2D+1.0E+L
B20: Fy | C20: =INDEX(CATALOGOS!$N$5:$N$10,MATCH(vg_acero,CATALOGOS!$M$5:$M$10,0)) -> 3515 | D20: kgf/cm² | N20: Aplastamiento / desgarre — placa extrema | O20: J3.10 | P20: =INDEX(CALCULO!$D$113:$M$113,MATCH(MAX(CALCULO!$D$123:$M$123),CALCULO!$D$123:$M$123,0))/1000 -> 7 | Q20: =k_Rbp/1000 -> 149.18622 | R20: Tonf | S20: =MAX(CALCULO!$D$123:$M$123) -> 0.046921223 | T20: =IF(ISNUMBER(S20),IF(S20>1,"NO CUMPLE",IF(S20>lim_verde,"AL LÍMITE","CUMPLE")),"N/A") -> CUMPLE | U20: =IF(ISNUMBER(S20),INDEX(CALCULO!$D$110:$M$110,MATCH(MAX(CALCULO!$D$123:$M$123),CALCULO!$D$123:$M$123,0)),"—") -> 1.2D+1.0E+L
B21: Fu | C21: =INDEX(CATALOGOS!$O$5:$O$10,MATCH(vg_acero,CATALOGOS!$M$5:$M$10,0)) -> 4570 | D21: kgf/cm² | G21: SOLICITACIONES EN LA CARA DE LA COLUMNA (LRFD) | N21: Aplastamiento / desgarre — ala de columna | O21: J3.10 | P21: =INDEX(CALCULO!$D$113:$M$113,MATCH(MAX(CALCULO!$D$124:$M$124),CALCULO!$D$124:$M$124,0))/1000 -> 7 | Q21: =k_Rbc/1000 -> 109.69371 | R21: Tonf | S21: =MAX(CALCULO!$D$124:$M$124) -> 0.063814051 | T21: =IF(ISNUMBER(S21),IF(S21>1,"NO CUMPLE",IF(S21>lim_verde,"AL LÍMITE","CUMPLE")),"N/A") -> CUMPLE | U21: =IF(ISNUMBER(S21),INDEX(CALCULO!$D$110:$M$110,MATCH(MAX(CALCULO!$D$124:$M$124),CALCULO!$D$124:$M$124,0)),"—") -> 1.2D+1.0E+L
B22: Ry (AISC 341) | C22: =INDEX(CATALOGOS!$P$5:$P$10,MATCH(vg_acero,CATALOGOS!$M$5:$M$10,0)) -> 1.1 | G22: Combinación | H22: Mu (Tonf·m) | I22: Vu (Tonf) | J22: db,req (mm) | K22: Ffu (Tonf) | L22: Ratio máx. | N22: SOLDADURAS VIGA – PLACA
B23: 2. COLUMNA (conexión al ala) | G23: 1.2D+1.6L | H23: 9.5 | I23: 6 | J23: =IF(INDEX(CALCULO!$D$111:$M$111,1)=1,INDEX(CALCULO!$D$114:$M$114,1),"—") -> 12.814661 | K23: =IF(INDEX(CALCULO!$D$111:$M$111,1)=1,INDEX(CALCULO!$D$115:$M$115,1)/1000,"—") -> 24.484536 | L23: =IF(INDEX(CALCULO!$D$111:$M$111,1)=1,INDEX(CALCULO!$D$138:$M$138,1),"—") -> 0.86862398 | N23: Ala de viga – placa (filete) | O23: DG4 · J2.4 (sísmico: CJP §6.7.6) | P23: =IF(k_seis=1,"—",INDEX(CALCULO!$D$115:$M$115,MATCH(MAX(CALCULO!$D$125:$M$125),CALCULO!$D$125:$M$125,0))/1000) -> 36.082474 | Q23: =IF(k_seis=1,"—",k_Rwf/1000) -> 83.117324 | R23: Tonf | S23: =IF(k_seis=1,"N/A",MAX(CALCULO!$D$125:$M$125)) -> 0.43411497 | T23: =IF(ISNUMBER(S23),IF(S23>1,"NO CUMPLE",IF(S23>lim_verde,"AL LÍMITE","CUMPLE")),"N/A") -> CUMPLE | U23: =IF(ISNUMBER(S23),INDEX(CALCULO!$D$110:$M$110,MATCH(MAX(CALCULO!$D$125:$M$125),CALCULO!$D$125:$M$125,0)),"—") -> 1.2D+1.0E+L
B24: Perfil (catálogo o ARMADO) | C24: HA500X250X10X15 | E24: Armado (mm) | G24: 1.2D+1.0E+L | H24: 14 | I24: 7 | J24: =IF(INDEX(CALCULO!$D$111:$M$111,2)=1,INDEX(CALCULO!$D$114:$M$114,2),"—") -> 15.556409 | K24: =IF(INDEX(CALCULO!$D$111:$M$111,2)=1,INDEX(CALCULO!$D$115:$M$115,2)/1000,"—") -> 36.082474 | L24: =IF(INDEX(CALCULO!$D$111:$M$111,2)=1,INDEX(CALCULO!$D$138:$M$138,2),"—") -> 0.86862398 | N24: Alma – zona de tracción (desarrollar Fy del alma) | O24: DG4 · J2.4 | P24: =k_wtD -> 1898.1 | Q24: =k_wtC -> 2817.5364 | R24: kgf/cm | S24: =MAX(CALCULO!$D$126:$M$126) -> 0.67367364 | T24: =IF(ISNUMBER(S24),IF(S24>1,"NO CUMPLE",IF(S24>lim_verde,"AL LÍMITE","CUMPLE")),"N/A") -> CUMPLE | U24: =IF(ISNUMBER(S24),INDEX(CALCULO!$D$110:$M$110,MATCH(MAX(CALCULO!$D$126:$M$126),CALCULO!$D$126:$M$126,0)),"—") -> 1.2D+1.6L
B25: Peralte d | C25: =IF(co_perfil="ARMADO (flejes soldados)",E25,INDEX(CATALOGOS!$H$5:$H$40,MATCH(co_perfil,CATALOGOS!$G$5:$G$40,0))) -> 500 | D25: mm | E25: 500 | G25: 0.9D+1.0E | H25: 11.5 | I25: 4.5 | J25: =IF(INDEX(CALCULO!$D$111:$M$111,3)=1,INDEX(CALCULO!$D$114:$M$114,3),"—") -> 14.099193 | K25: =IF(INDEX(CALCULO!$D$111:$M$111,3)=1,INDEX(CALCULO!$D$115:$M$115,3)/1000,"—") -> 29.639175 | L25: =IF(INDEX(CALCULO!$D$111:$M$111,3)=1,INDEX(CALCULO!$D$138:$M$138,3),"—") -> 0.86862398 | N25: Alma – corte | O25: J2.4 | P25: =INDEX(CALCULO!$D$113:$M$113,MATCH(MAX(CALCULO!$D$127:$M$127),CALCULO!$D$127:$M$127,0))/1000 -> 7 | Q25: =k_Rwv/1000 -> 35.313123 | R25: Tonf | S25: =MAX(CALCULO!$D$127:$M$127) -> 0.19822659 | T25: =IF(ISNUMBER(S25),IF(S25>1,"NO CUMPLE",IF(S25>lim_verde,"AL LÍMITE","CUMPLE")),"N/A") -> CUMPLE | U25: =IF(ISNUMBER(S25),INDEX(CALCULO!$D$110:$M$110,MATCH(MAX(CALCULO!$D$127:$M$127),CALCULO!$D$127:$M$127,0)),"—") -> 1.2D+1.0E+L
B26: Ancho de ala bf | C26: =IF(co_perfil="ARMADO (flejes soldados)",E26,INDEX(CATALOGOS!$I$5:$I$40,MATCH(co_perfil,CATALOGOS!$G$5:$G$40,0))) -> 250 | D26: mm | E26: 250 | G26: 1.2D+1.0W+L | H26: 8 | I26: 5 | J26: =IF(INDEX(CALCULO!$D$111:$M$111,4)=1,INDEX(CALCULO!$D$114:$M$114,4),"—") -> 11.75954 | K26: =IF(INDEX(CALCULO!$D$111:$M$111,4)=1,INDEX(CALCULO!$D$115:$M$115,4)/1000,"—") -> 20.618557 | L26: =IF(INDEX(CALCULO!$D$111:$M$111,4)=1,INDEX(CALCULO!$D$138:$M$138,4),"—") -> 0.86862398 | N26: COLUMNA
B27: Espesor de alma tw | C27: =IF(co_perfil="ARMADO (flejes soldados)",E27,INDEX(CATALOGOS!$J$5:$J$40,MATCH(co_perfil,CATALOGOS!$G$5:$G$40,0))) -> 10 | D27: mm | E27: 10 | G27: C5 | J27: =IF(INDEX(CALCULO!$D$111:$M$111,5)=1,INDEX(CALCULO!$D$114:$M$114,5),"—") -> — | K27: =IF(INDEX(CALCULO!$D$111:$M$111,5)=1,INDEX(CALCULO!$D$115:$M$115,5)/1000,"—") -> — | L27: =IF(INDEX(CALCULO!$D$111:$M$111,5)=1,INDEX(CALCULO!$D$138:$M$138,5),"—") -> — | N27: Flexión del ala de columna | O27: DG4 · AISC 358 Tablas 6.5/6.6 | P27: =INDEX(CALCULO!$D$128:$M$128,MATCH(MAX(CALCULO!$D$129:$M$129),CALCULO!$D$129:$M$129,0))/1 -> 31.718734 | Q27: =k_phiMcf/100000 -> 36.51607 | R27: Tonf·m | S27: =MAX(CALCULO!$D$129:$M$129) -> 0.86862398 | T27: =IF(ISNUMBER(S27),IF(S27>1,"NO CUMPLE",IF(S27>lim_verde,"AL LÍMITE","CUMPLE")),"N/A") -> CUMPLE | U27: =IF(ISNUMBER(S27),INDEX(CALCULO!$D$110:$M$110,MATCH(MAX(CALCULO!$D$129:$M$129),CALCULO!$D$129:$M$129,0)),"—") -> 1.2D+1.6L
B28: Espesor de ala tf | C28: =IF(co_perfil="ARMADO (flejes soldados)",E28,INDEX(CATALOGOS!$K$5:$K$40,MATCH(co_perfil,CATALOGOS!$G$5:$G$40,0))) -> 15 | D28: mm | E28: 15 | G28: C6 | J28: =IF(INDEX(CALCULO!$D$111:$M$111,6)=1,INDEX(CALCULO!$D$114:$M$114,6),"—") -> — | K28: =IF(INDEX(CALCULO!$D$111:$M$111,6)=1,INDEX(CALCULO!$D$115:$M$115,6)/1000,"—") -> — | L28: =IF(INDEX(CALCULO!$D$111:$M$111,6)=1,INDEX(CALCULO!$D$138:$M$138,6),"—") -> — | N28: Fluencia local del alma | O28: DG4 · J10.2 | P28: =IF(cp_usar="Sí","—",INDEX(CALCULO!$D$115:$M$115,MATCH(MAX(CALCULO!$D$131:$M$131),CALCULO!$D$131:$M$131,0))/1000) -> — | Q28: =IF(cp_usar="Sí","—",k_Rwy/1000) -> — | R28: Tonf | S28: =IF(cp_usar="Sí","N/A",MAX(CALCULO!$D$131:$M$131)) -> N/A | T28: =IF(ISNUMBER(S28),IF(S28>1,"NO CUMPLE",IF(S28>lim_verde,"AL LÍMITE","CUMPLE")),"N/A") -> N/A | U28: =IF(ISNUMBER(S28),INDEX(CALCULO!$D$110:$M$110,MATCH(MAX(CALCULO!$D$131:$M$131),CALCULO!$D$131:$M$131,0)),"—") -> —
B29: Acero | C29: A572 Gr50 | G29: C7 | J29: =IF(INDEX(CALCULO!$D$111:$M$111,7)=1,INDEX(CALCULO!$D$114:$M$114,7),"—") -> — | K29: =IF(INDEX(CALCULO!$D$111:$M$111,7)=1,INDEX(CALCULO!$D$115:$M$115,7)/1000,"—") -> — | L29: =IF(INDEX(CALCULO!$D$111:$M$111,7)=1,INDEX(CALCULO!$D$138:$M$138,7),"—") -> — | N29: Aplastamiento del alma (crippling) | O29: J10.3 | P29: =IF(cp_usar="Sí","—",INDEX(CALCULO!$D$115:$M$115,MATCH(MAX(CALCULO!$D$132:$M$132),CALCULO!$D$132:$M$132,0))/1000) -> — | Q29: =IF(cp_usar="Sí","—",k_Rwc/1000) -> — | R29: Tonf | S29: =IF(cp_usar="Sí","N/A",MAX(CALCULO!$D$132:$M$132)) -> N/A | T29: =IF(ISNUMBER(S29),IF(S29>1,"NO CUMPLE",IF(S29>lim_verde,"AL LÍMITE","CUMPLE")),"N/A") -> N/A | U29: =IF(ISNUMBER(S29),INDEX(CALCULO!$D$110:$M$110,MATCH(MAX(CALCULO!$D$132:$M$132),CALCULO!$D$132:$M$132,0)),"—") -> —
B30: Fy | C30: =INDEX(CATALOGOS!$N$5:$N$10,MATCH(co_acero,CATALOGOS!$M$5:$M$10,0)) -> 3515 | D30: kgf/cm² | G30: C8 | J30: =IF(INDEX(CALCULO!$D$111:$M$111,8)=1,INDEX(CALCULO!$D$114:$M$114,8),"—") -> — | K30: =IF(INDEX(CALCULO!$D$111:$M$111,8)=1,INDEX(CALCULO!$D$115:$M$115,8)/1000,"—") -> — | L30: =IF(INDEX(CALCULO!$D$111:$M$111,8)=1,INDEX(CALCULO!$D$138:$M$138,8),"—") -> — | N30: Pandeo del alma en compresión | O30: J10.5 | P30: =IF(OR(cp_usar="Sí",dos_lados="No"),"—",INDEX(CALCULO!$D$115:$M$115,MATCH(MAX(CALCULO!$D$133:$M$133),CALCULO!$D$133:$M$133,0))/1000) -> — | Q30: =IF(OR(cp_usar="Sí",dos_lados="No"),"—",k_Rwb/1000) -> — | R30: Tonf | S30: =IF(OR(cp_usar="Sí",dos_lados="No"),"N/A",MAX(CALCULO!$D$133:$M$133)) -> N/A | T30: =IF(ISNUMBER(S30),IF(S30>1,"NO CUMPLE",IF(S30>lim_verde,"AL LÍMITE","CUMPLE")),"N/A") -> N/A | U30: =IF(ISNUMBER(S30),INDEX(CALCULO!$D$110:$M$110,MATCH(MAX(CALCULO!$D$133:$M$133),CALCULO!$D$133:$M$133,0)),"—") -> —
B31: Fu | C31: =INDEX(CATALOGOS!$O$5:$O$10,MATCH(co_acero,CATALOGOS!$M$5:$M$10,0)) -> 4570 | D31: kgf/cm² | G31: C9 | J31: =IF(INDEX(CALCULO!$D$111:$M$111,9)=1,INDEX(CALCULO!$D$114:$M$114,9),"—") -> — | K31: =IF(INDEX(CALCULO!$D$111:$M$111,9)=1,INDEX(CALCULO!$D$115:$M$115,9)/1000,"—") -> — | L31: =IF(INDEX(CALCULO!$D$111:$M$111,9)=1,INDEX(CALCULO!$D$138:$M$138,9),"—") -> — | N31: Rigidizadores de continuidad | O31: DG4 · J10.8 | P31: =IF(cp_usar="No","—",INDEX(CALCULO!$D$134:$M$134,MATCH(MAX(CALCULO!$D$135:$M$135),CALCULO!$D$135:$M$135,0))/1000) -> 0 | Q31: =IF(cp_usar="No","—",k_Rcp/1000) -> 83.5164 | R31: Tonf | S31: =IF(cp_usar="No","N/A",MAX(CALCULO!$D$135:$M$135)) -> 0 | T31: =IF(ISNUMBER(S31),IF(S31>1,"NO CUMPLE",IF(S31>lim_verde,"AL LÍMITE","CUMPLE")),"N/A") -> CUMPLE | U31: =IF(ISNUMBER(S31),INDEX(CALCULO!$D$110:$M$110,MATCH(MAX(CALCULO!$D$135:$M$135),CALCULO!$D$135:$M$135,0)),"—") -> 1.2D+1.6L
B32: Filete / radio alma–ala (para k) | C32: 6 | D32: mm | G32: C10 | J32: =IF(INDEX(CALCULO!$D$111:$M$111,10)=1,INDEX(CALCULO!$D$114:$M$114,10),"—") -> — | K32: =IF(INDEX(CALCULO!$D$111:$M$111,10)=1,INDEX(CALCULO!$D$115:$M$115,10)/1000,"—") -> — | L32: =IF(INDEX(CALCULO!$D$111:$M$111,10)=1,INDEX(CALCULO!$D$138:$M$138,10),"—") -> — | N32: Zona de panel (corte) | O32: J10.6(a) | P32: =INDEX(CALCULO!$D$136:$M$136,MATCH(MAX(CALCULO!$D$137:$M$137),CALCULO!$D$137:$M$137,0))/1000 -> 36.082474 | Q32: =k_Rpz/1000 -> 94.905 | R32: Tonf | S32: =MAX(CALCULO!$D$137:$M$137) -> 0.38019571 | T32: =IF(ISNUMBER(S32),IF(S32>1,"NO CUMPLE",IF(S32>lim_verde,"AL LÍMITE","CUMPLE")),"N/A") -> CUMPLE | U32: =IF(ISNUMBER(S32),INDEX(CALCULO!$D$110:$M$110,MATCH(MAX(CALCULO!$D$137:$M$137),CALCULO!$D$137:$M$137,0)),"—") -> 1.2D+1.0E+L
B33: Tope de columna → ala superior de viga | C33: 1000 | D33: mm | G33: =IF(LEFT(modo,3)="Sís","MODO SÍSMICO: la tabla no se usa; la demanda es Mf y Vu por capacidad (ver detalle).","Se usa |Mu| y |Vu|. Filas vacías se ignoran.") -> Se usa |Mu| y |Vu|. Filas vacías se ignoran. | N33: GEOMETRÍA Y DETALLES (requerido / provisto)
B34: Vigas a ambos lados (columna interior) | C34: No | N34: Ancho de placa bp ≥ bbf | O34: AISC 358 §6.8 | P34: =k_bf -> 18 | Q34: =k_bp -> 20 | R34: cm | S34: =(k_bf)/MAX(k_bp,0.001) -> 0.9 | T34: =IF(ISNUMBER(S34),IF(S34>1,"NO CUMPLE",IF(S34>lim_verde,"AL LÍMITE","CUMPLE")),"N/A") -> CUMPLE | U34: —
B35: Mu viga opuesta (suma en zona de panel) | C35: 0 | D35: Tonf·m | G35: DETALLE DE UNA COMBINACIÓN | N35: Holgura de llave: pfi, pfo ≥ db + 12.7 mm | O35: DG4 | P35: =k_db+1.27 -> 3.4925 | Q35: =MIN(k_pfi,k_pfo) -> 4.5 | R35: cm | S35: =(k_db+1.27)/MAX(MIN(k_pfi,k_pfo),0.001) -> 0.77611111 | T35: =IF(ISNUMBER(S35),IF(S35>1,"NO CUMPLE",IF(S35>lim_verde,"AL LÍMITE","CUMPLE")),"N/A") -> CUMPLE | U35: —
B36: Pu de la columna | C36: 20 | D36: Tonf | G36: Combinación: | H36: 1.2D+1.0E+L | K36: =IF(k_seis=1,1,IFERROR(MATCH(H36,cb_nom,0),1)) -> 2 | N36: Borde de ≥ mínimo | O36: J3.4 | P36: =k_emin -> 2.8575 | Q36: =k_de -> 4 | R36: cm | S36: =(k_emin)/MAX(k_de,0.001) -> 0.714375 | T36: =IF(ISNUMBER(S36),IF(S36>1,"NO CUMPLE",IF(S36>lim_verde,"AL LÍMITE","CUMPLE")),"N/A") -> CUMPLE | U36: —
B37: Rigidizadores de continuidad | C37: Sí | G37: Momento de diseño Mu (sísmico: Mf) | J37: =INDEX(CALCULO!$D$112:$M$112,det_k)/100000 -> 14 | K37: Tonf·m | N37: Borde lateral (bp − g)/2 ≥ mínimo | O37: J3.4 | P37: =k_emin -> 2.8575 | Q37: =(k_bp-k_g)/2 -> 4.5 | R37: cm | S37: =(k_emin)/MAX((k_bp-k_g)/2,0.001) -> 0.635 | T37: =IF(ISNUMBER(S37),IF(S37>1,"NO CUMPLE",IF(S37>lim_verde,"AL LÍMITE","CUMPLE")),"N/A") -> CUMPLE | U37: —
B38: Rigidizador continuidad: espesor | C38: 12 | D38: mm | G38: Cortante de diseño Vu | J38: =INDEX(CALCULO!$D$113:$M$113,det_k)/1000 -> 7 | K38: Tonf | N38: Gramil g ≥ 2⅔·db | O38: J3.3 | P38: =8/3*k_db -> 5.9266667 | Q38: =k_g -> 11 | R38: cm | S38: =(8/3*k_db)/MAX(k_g,0.001) -> 0.53878788 | T38: =IF(ISNUMBER(S38),IF(S38>1,"NO CUMPLE",IF(S38>lim_verde,"AL LÍMITE","CUMPLE")),"N/A") -> CUMPLE | U38: —
B39: Rigidizador continuidad: ancho (c/lado) | C39: 110 | D39: mm | G39: Fuerza en el ala Ffu | J39: =INDEX(CALCULO!$D$115:$M$115,det_k)/1000 -> 36.082474 | K39: Tonf | N39: Paso pb ≥ 2⅔·db (8ES) | O39: J3.3 | P39: =IF(k_is8=0,"—",8/3*k_db) -> — | Q39: =IF(k_is8=0,"—",k_pb) -> — | R39: cm | S39: =IF(k_is8=0,"N/A",(8/3*k_db)/MAX(k_pb,0.001)) -> N/A | T39: =IF(ISNUMBER(S39),IF(S39>1,"NO CUMPLE",IF(S39>lim_verde,"AL LÍMITE","CUMPLE")),"N/A") -> N/A | U39: —
B40: 3. PLACA EXTREMA | G40: Diámetro requerido db,req / provisto | J40: =INDEX(CALCULO!$D$114:$M$114,det_k) -> 15.556409 | K40: mm | L40: =k_db*10 -> 22.225 | N40: Filete mínimo ala de viga | O40: Tabla J2.4 | P40: =IF(k_seis=1,"—",IF(MIN(vg_tf_mm,pl_tp)<=6,3,IF(MIN(vg_tf_mm,pl_tp)<=13,5,IF(MIN(vg_tf_mm,pl_tp)<=19,6,8)))) -> 5 | Q40: =IF(k_seis=1,"—",sd_wf) -> 10 | R40: mm | S40: =IF(k_seis=1,"N/A",(IF(MIN(vg_tf_mm,pl_tp)<=6,3,IF(MIN(vg_tf_mm,pl_tp)<=13,5,IF(MIN(vg_tf_mm,pl_tp)<=19,6,8))))/MAX(sd_wf,0.001)) -> 0.5 | T40: =IF(ISNUMBER(S40),IF(S40>1,"NO CUMPLE",IF(S40>lim_verde,"AL LÍMITE","CUMPLE")),"N/A") -> CUMPLE | U40: —
B41: Acero | C41: A572 Gr50 | G41: φMnp = φn·2·Pt·Σhi | J41: =k_phin*k_Mnp/100000 -> 28.575436 | K41: Tonf·m | N41: Filete mínimo alma de viga | O41: Tabla J2.4 | P41: =IF(MIN(vg_tw_mm,pl_tp)<=6,3,IF(MIN(vg_tw_mm,pl_tp)<=13,5,IF(MIN(vg_tw_mm,pl_tp)<=19,6,8))) -> 3 | Q41: =sd_ww -> 6 | R41: mm | S41: =(IF(MIN(vg_tw_mm,pl_tp)<=6,3,IF(MIN(vg_tw_mm,pl_tp)<=13,5,IF(MIN(vg_tw_mm,pl_tp)<=19,6,8))))/MAX(sd_ww,0.001) -> 0.5 | T41: =IF(ISNUMBER(S41),IF(S41>1,"NO CUMPLE",IF(S41>lim_verde,"AL LÍMITE","CUMPLE")),"N/A") -> CUMPLE | U41: —
B42: Fy | C42: =INDEX(CATALOGOS!$N$5:$N$10,MATCH(pl_acero,CATALOGOS!$M$5:$M$10,0)) -> 3515 | D42: kgf/cm² | G42: Yp placa / caso | J42: =k_Yp -> 285.89931 | K42: cm | L42: =IF(cfg="4E","único",IF(k_de<=k_s,"de ≤ s","de > s")) -> único | N42: Rigid. continuidad: b + tcw/2 ≥ bbf/3 | O42: J10.8 | P42: =IF(cp_usar="No","—",k_bf/3-k_ctw/2) -> 5.5 | Q42: =IF(cp_usar="No","—",cp_b/10) -> 11 | R42: cm | S42: =IF(cp_usar="No","N/A",(k_bf/3-k_ctw/2)/MAX(cp_b/10,0.001)) -> 0.5 | T42: =IF(ISNUMBER(S42),IF(S42>1,"NO CUMPLE",IF(S42>lim_verde,"AL LÍMITE","CUMPLE")),"N/A") -> CUMPLE | U42: —
...

Sheet CALCULO
A1: HOJA DE CÁLCULO — memoria detallada (no editar)
A2: Unidades internas: kgf, cm. Líneas de fluencia: AISC 358-16 Tablas 6.2/6.5/6.6 (mismas de DG4). φ: AISC 360-16 (no sísmico) y φd = 1.00 / φn = 0.90 de AISC 358-16 §2.4.1 (sísmico).
A4: 1. GEOMETRÍA Y MATERIALES
A5: sísmico | B5: 1 = procedimiento sísmico AISC 358-16 | C5: - | D5: =IF(LEFT(modo,3)="Sís",1,0) -> 0
A6: 8ES | B6: 1 = configuración de 8 pernos | C6: - | D6: =IF(cfg="8ES",1,0) -> 0
A7: 4E | B7: 1 = 4E sin rigidizar | C7: - | D7: =IF(cfg="4E",1,0) -> 1
A8: E | B8: Módulo de elasticidad | C8: kgf/cm² | D8: =2040000 -> 2040000
A9: d | B9: Peralte de viga | C9: cm | D9: =vg_d_mm/10 -> 40
A10: bbf | B10: Ancho de ala de viga | C10: cm | D10: =vg_bf_mm/10 -> 18
A11: tbw | B11: Alma de viga | C11: cm | D11: =vg_tw_mm/10 -> 0.6
A12: tbf | B12: Ala de viga | C12: cm | D12: =vg_tf_mm/10 -> 1.2
A13: Zx | B13: bf·tf·(d−tf) + tw·(d−2tf)²/4 | C13: cm³ | D13: =k_bf*k_tf*(k_d-k_tf)+k_tw*(k_d-2*k_tf)^2/4 -> 1050.144
A14: dc | B14: Peralte de columna | C14: cm | D14: =co_d_mm/10 -> 50
A15: bcf | B15: Ancho de ala de columna | C15: cm | D15: =co_bf_mm/10 -> 25
A16: tcw | B16: Alma de columna | C16: cm | D16: =co_tw_mm/10 -> 1
A17: tcf | B17: Ala de columna | C17: cm | D17: =co_tf_mm/10 -> 1.5
A18: Ac | B18: Área de columna | C18: cm² | D18: =2*k_cbf*k_ctf+(k_cd-2*k_ctf)*k_ctw -> 122
A19: kc | B19: tcf + filete | C19: cm | D19: =k_ctf+co_kw/10 -> 2.1
A20: h | B20: dc − 2kc (alma libre) | C20: cm | D20: =k_cd-2*k_ck -> 45.8
A21: bp | B21: Ancho de placa | C21: cm | D21: =pl_bp/10 -> 20
A22: bp,ef | B22: mín(bp ; bbf + 2.54) para líneas de fluencia | C22: cm | D22: =MIN(k_bp,k_bf+2.54) -> 20
A23: tp | B23: Espesor de placa | C23: cm | D23: =pl_tp/10 -> 2.5
A24: g | B24: Gramil | C24: cm | D24: =pl_g/10 -> 11
A25: pfo | B25: Ala a fila exterior | C25: cm | D25: =pl_pfo/10 -> 4.5
A26: pfi | B26: Ala a fila interior | C26: cm | D26: =pl_pfi/10 -> 4.5
A27: pb | B27: Entre filas (8ES; 0 en 4E/4ES) | C27: cm | D27: =IF(k_is8=1,pl_pb/10,0) -> 0
A28: de | B28: Fila exterior a borde | C28: cm | D28: =pl_de/10 -> 4
A29: Hp | B29: Alto de placa: d + 2(pfo + pb + de) | C29: cm | D29: =k_d+2*(k_pfo+k_pb+k_de) -> 57
A30: db | B30: Diámetro de perno | C30: in | D30: =INDEX(CATALOGOS!$W$5:$W$12,MATCH(pn_diam,CATALOGOS!$V$5:$V$12,0)) -> 0.875
A31: db | B31: Diámetro de perno | C31: cm | D31: =k_dbi*2.54 -> 2.2225
A32: Ab | B32: π·db²/4 | C32: cm² | D32: =PI()*k_db^2/4 -> 3.8794791
A33: dh | B33: Agujero estándar (Tabla J3.3): db + 1/16 in (db < 1 in) ; db + 1/8 in | C33: cm | D33: =IF(k_dbi<1,k_dbi+1/16,k_dbi+1/8)*2.54 -> 2.38125
A34: Le,min | B34: Borde mínimo (Tabla J3.4) | C34: cm | D34: =INDEX(CATALOGOS!$X$5:$X$12,MATCH(pn_diam,CATALOGOS!$V$5:$V$12,0))*2.54 -> 2.8575
A35: nb | B35: Pernos en el lado de compresión (resisten corte) | C35: - | D35: =IF(k_is8=1,8,4) -> 4
A36: 2. DISTANCIAS DESDE EL CENTRO DEL ALA EN COMPRESIÓN (DG4 / AISC 358 Fig. 6.2)
A37: h0 | h1 | B37: 4E/4ES: h0 = d − tbf/2 + pfo ; 8ES: h1 = d − tbf/2 + pfo + pb | C37: cm | D37: =k_d-k_tf/2+k_pfo+k_pb -> 43.9
A38: h1 | h2 | B38: 4E/4ES: h1 = d − 1.5tbf − pfi ; 8ES: h2 = d − tbf/2 + pfo | C38: cm | D38: =IF(k_is8=1,k_d-k_tf/2+k_pfo,k_d-1.5*k_tf-k_pfi) -> 33.7
A39: — | h3 | B39: 8ES: h3 = d − 1.5tbf − pfi | C39: cm | D39: =IF(k_is8=1,k_d-1.5*k_tf-k_pfi,0) -> 0
A40: — | h4 | B40: 8ES: h4 = h3 − pb | C40: cm | D40: =IF(k_is8=1,k_r3-k_pb,0) -> 0
A41: Σhi | B41: Suma de brazos de las filas en tracción | C41: cm | D41: =k_r1+k_r2+k_r3+k_r4 -> 77.6
...

Sheet CATALOGOS
A1: CATÁLOGOS — ampliables agregando filas dentro de cada rango
A3: Vigas (VK: KUBIEC; W: AISC redondeado a mm) | G3: Columnas (HA: KUBIEC; W: AISC) | M3: Aceros (kgf/cm²) — Ry: AISC 341-16 Tabla A3.1 | R3: Pernos pretensados (kgf/cm²) — AISC 360-16 Tabla J3.2 | V3: Diámetros — borde mín. AISC 360-16 Tabla J3.4 | Z3: Electrodo | AC3: Opción | AE3: Configuración | AG3: Procedimiento | AI3: Espesores (mm) | AK3: Rangos ensayados — AISC 358-16 Tabla 6.1 (VERIFICAR contra la norma antes de usar)
A4: Viga | B4: d | C4: bf | D4: tw | E4: tf | G4: Columna | H4: d | I4: bf | J4: tw | K4: tf | M4: Acero | N4: Fy | O4: Fu | P4: Ry | R4: Grado | S4: Fnt | T4: Fnv | V4: Ø | W4: db (in) | X4: borde mín (in) | Z4: Electrodo | AA4: FEXX | AC4: Sí/No | AE4: Tipo | AG4: Modo | AI4: t | AK4: Parámetro (in) | AL4: 4E mín | AM4: 4E máx | AN4: 4ES mín | AO4: 4ES máx | AP4: 8ES mín | AQ4: 8ES máx
A5: ARMADO (flejes soldados) | G5: ARMADO (flejes soldados) | M5: A36 | N5: 2530 | O5: 4080 | P5: 1.5 | R5: A325-N (roscas incl.) | S5: 6328 | T5: 3797 | V5: 5/8" | W5: 0.625 | X5: 0.875 | Z5: E60XX | AA5: 4220 | AC5: Sí | AE5: 4E | AG5: No sísmico (DG4) | AI5: 8 | AK5: tbf | AL5: 0.375 | AM5: 0.75 | AN5: 0.375 | AO5: 0.75 | AP5: 0.5625 | AQ5: 1
A6: VK180X100X4X6 | B6: 180 | C6: 100 | D6: 4 | E6: 6 | G6: HA200X140X6X12 | H6: 200 | I6: 140 | J6: 6 | K6: 12 | M6: A572 Gr50 | N6: 3515 | O6: 4570 | P6: 1.1 | R6: A325-X (roscas excl.) | S6: 6328 | T6: 4781 | V6: 3/4" | W6: 0.75 | X6: 1 | Z6: E70XX | AA6: 4920 | AC6: No | AE6: 4ES | AG6: Sísmico (AISC 358) | AI6: 10 | AK6: bbf | AL6: 6 | AM6: 9.25 | AN6: 6 | AO6: 9 | AP6: 7.5 | AQ6: 12.25
A7: VK200X100X4X8 | B7: 200 | C7: 100 | D7: 4 | E7: 8 | G7: HA220X160X6X12 | H7: 220 | I7: 160 | J7: 6 | K7: 12 | M7: A992 | N7: 3515 | O7: 4570 | P7: 1.1 | R7: A490-N (roscas incl.) | S7: 7945 | T7: 4781 | V7: 7/8" | W7: 0.875 | X7: 1.125 | AE7: 8ES | AI7: 12 | AK7: d | AL7: 13.75 | AM7: 55 | AN7: 13.75 | AO7: 24 | AP7: 18.5 | AQ7: 62
A8: VK220X110X4X8 | B8: 220 | C8: 110 | D8: 4 | E8: 8 | G8: HA240X180X6X12 | H8: 240 | I8: 180 | J8: 6 | K8: 12 | M8: A588 Gr50 | N8: 3515 | O8: 4920 | P8: 1.1 | R8: A490-X (roscas excl.) | S8: 7945 | T8: 5906 | V8: 1" | W8: 1 | X8: 1.25 | AI8: 15 | AK8: tp | AL8: 0.5 | AM8: 2.25 | AN8: 0.5 | AO8: 1.5 | AP8: 0.75 | AQ8: 2.5
A9: VK250X130X4X8 | B9: 250 | C9: 130 | D9: 4 | E9: 8 | G9: HA260X180X6X12 | H9: 260 | I9: 180 | J9: 6 | K9: 12 | V9: 1-1/8" | W9: 1.125 | X9: 1.5 | AI9: 16 | AK9: bp | AL9: 7 | AM9: 10.75 | AN9: 10.75 | AO9: 12.25 | AP9: 9 | AQ9: 15
A10: VK270X140X4X8 | B10: 270 | C10: 140 | D10: 4 | E10: 8 | G10: HA280X180X6X12 | H10: 280 | I10: 180 | J10: 6 | K10: 12 | V10: 1-1/4" | W10: 1.25 | X10: 1.625 | AI10: 19 | AK10: g | AL10: 4 | AM10: 6 | AN10: 3.25 | AO10: 6 | AP10: 5 | AQ10: 6
A11: VK300X150X4X10 | B11: 300 | C11: 150 | D11: 4 | E11: 10 | G11: HA300X180X6X12 | H11: 300 | I11: 180 | J11: 6 | K11: 12 | V11: 1-3/8" | W11: 1.375 | X11: 1.719 | AI11: 20 | AK11: pfi | AL11: 1.5 | AM11: 4.5 | AN11: 1.625 | AO11: 5.5 | AP11: 1.625 | AQ11: 2
A12: VK330X160X6X10 | B12: 330 | C12: 160 | D12: 6 | E12: 10 | G12: HA320X180X6X12 | H12: 320 | I12: 180 | J12: 6 | K12: 12 | V12: 1-1/2" | W12: 1.5 | X12: 1.875 | AI12: 22 | AK12: pfo | AL12: 1.5 | AM12: 4.5 | AN12: 1.625 | AO12: 5.5 | AP12: 1.625 | AQ12: 2
A13: VK360X180X6X10 | B13: 360 | C13: 180 | D13: 6 | E13: 10 | G13: HA340X180X6X12 | H13: 340 | I13: 180 | J13: 6 | K13: 12 | AI13: 25 | AK13: pb | AP13: 3.5 | AQ13: 3.75
A14: VK380X180X6X10 | B14: 380 | C14: 180 | D14: 6 | E14: 10 | G14: HA360X180X6X12 | H14: 360 | I14: 180 | J14: 6 | K14: 12 | AI14: 28
A15: VK400X180X6X10 | B15: 400 | C15: 180 | D15: 6 | E15: 10 | G15: HA380X200X8X15 | H15: 380 | I15: 200 | J15: 8 | K15: 15 | AI15: 30
A16: VK400X180X6X12 | B16: 400 | C16: 180 | D16: 6 | E16: 12 | G16: HA400X200X8X15 | H16: 400 | I16: 200 | J16: 8 | K16: 15 | AI16: 32
A17: VK420X180X6X12 | B17: 420 | C17: 180 | D17: 6 | E17: 12 | G17: HA420X210X8X15 | H17: 420 | I17: 210 | J17: 8 | K17: 15 | AI17: 35
A18: VK440X180X6X12 | B18: 440 | C18: 180 | D18: 6 | E18: 12 | G18: HA440X220X8X15 | H18: 440 | I18: 220 | J18: 8 | K18: 15 | AI18: 38
A19: W12X26 | B19: 310 | C19: 165 | D19: 5.8 | E19: 9.7 | G19: HA460X230X8X15 | H19: 460 | I19: 230 | J19: 8 | K19: 15 | AI19: 40
A20: W14X30 | B20: 351 | C20: 171 | D20: 6.9 | E20: 9.8 | G20: HA480X240X8X15 | H20: 480 | I20: 240 | J20: 8 | K20: 15 | AI20: 45
A21: W16X31 | B21: 403 | C21: 140 | D21: 7 | E21: 11.2 | G21: HA500X250X10X15 | H21: 500 | I21: 250 | J21: 10 | K21: 15 | AI21: 50
A22: W16X40 | B22: 407 | C22: 178 | D22: 7.7 | E22: 12.8 | G22: HA520X260X10X15 | H22: 520 | I22: 260 | J22: 10 | K22: 15 | AI22: 55
A23: W18X35 | B23: 450 | C23: 152 | D23: 7.6 | E23: 10.8 | G23: HA540X270X10X15 | H23: 540 | I23: 270 | J23: 10 | K23: 15 | AI23: 60
A24: W18X50 | B24: 457 | C24: 190 | D24: 9 | E24: 14.5 | G24: W10X49 | H24: 254 | I24: 254 | J24: 8.6 | K24: 14.2
A25: W21X44 | B25: 525 | C25: 165 | D25: 8.9 | E25: 11.4 | G25: W12X65 | H25: 308 | I25: 305 | J25: 9.9 | K25: 15.4
A26: W21X62 | B26: 533 | C26: 209 | D26: 10.2 | E26: 15.6 | G26: W12X96 | H26: 323 | I26: 310 | J26: 14 | K26: 22.9
A27: W24X55 | B27: 599 | C27: 178 | D27: 10 | E27: 12.8 | G27: W14X90 | H27: 356 | I27: 368 | J27: 11.2 | K27: 18
A28: W24X76 | B28: 608 | C28: 228 | D28: 11.2 | E28: 17.3 | G28: W14X120 | H28: 368 | I28: 373 | J28: 15 | K28: 23.9

Sheet DIBUJO
A1: Coordenadas de las vistas (normalizadas a ±1). No editar.
D2: Placa | G2: Viga | J2: Rig. sup | M2: Rig. inf | P2: Pernos tracción | S2: Pernos compresión | V2: Columna | Y2: Ala int. | AB2: Ala ext. | AE2: Cont. sup | AH2: Cont. inf | AK2: Placa ext. | AN2: Ala sup viga | AQ2: Ala inf viga | AT2: Rig. sup L | AW2: Rig. inf L | AZ2: Pernos L
A3: S frontal | B3: =MAX(k_Hp,k_bp)/2*1.08 -> 30.78
A4: Lb | B4: =MAX(1.1*k_d,k_Lst+8) -> 44 | D4: =(-k_bp/2)/dSf -> -0.32488629 | E4: =(-k_Hp/2)/dSf -> -0.92592593 | G4: =(-k_bf/2)/dSf -> -0.29239766 | H4: =(k_d/2)/dSf -> 0.64977258 | J4: =(-IF(k_is4E=1,0,st_t/20))/dSf -> 0 | K4: =(k_d/2)/dSf -> 0.64977258 | M4: =(-IF(k_is4E=1,0,st_t/20))/dSf -> 0 | N4: =(-k_d/2)/dSf -> -0.64977258 | P4: =(-k_g/2)/dSf -> -0.17868746 | Q4: =(k_d/2+k_pfo)/dSf -> 0.79597141 | S4: =(-k_g/2)/dSf -> -0.17868746 | T4: =(-(k_d/2+k_pfo))/dSf -> -0.79597141 | V4: =((-k_cd)-dxc)/dSl -> -0.95238095 | W4: =(-dHc)/dSl -> -0.72045398 | Y4: =((-k_ctf)-dxc)/dSl -> 0.0049346163 | Z4: =(-dHc)/dSl -> -0.72045398 | AB4: =((-k_cd+k_ctf)-dxc)/dSl -> -0.92277325 | AC4: =(-dHc)/dSl -> -0.72045398 | AE4: =((-k_cd+k_ctf)-dxc)/dSl -> -0.92277325 | AF4: =((k_d/2-k_tf/2))/dSl -> 0.38292623 | AH4: =((-k_cd+k_ctf)-dxc)/dSl -> -0.92277325 | AI4: =(-(k_d/2-k_tf/2))/dSl -> -0.38292623 | AK4: =((0)-dxc)/dSl -> 0.034542314 | AL4: =(-k_Hp/2)/dSl -> -0.56254626 | AN4: =((k_tp)-dxc)/dSl -> 0.083888478 | AO4: =(k_d/2-k_tf)/dSl -> 0.37108315 | AQ4: =((k_tp)-dxc)/dSl -> 0.083888478 | AR4: =(-k_d/2)/dSl -> -0.39476931 | AT4: =((k_tp)-dxc)/dSl -> 0.083888478 | AU4: =(k_d/2)/dSl -> 0.39476931 | AW4: =((k_tp)-dxc)/dSl -> 0.083888478 | AX4: =(-k_d/2)/dSl -> -0.39476931 | AZ4: =(((k_tp-k_ctf)/2)-dxc)/dSl -> 0.044411547 | BA4: =(k_d/2+k_pfo)/dSl -> 0.4835924
A5: x centro lateral | B5: =(-k_cd+k_tp+dLb)/2 -> -1.75 | D5: =(-k_bp/2)/dSf -> -0.32488629 | E5: =(k_Hp/2)/dSf -> 0.92592593 | G5: =(k_bf/2)/dSf -> 0.29239766 | H5: =(k_d/2)/dSf -> 0.64977258 | J5: =(-IF(k_is4E=1,0,st_t/20))/dSf -> 0 | K5: =(IF(k_is4E=1,k_d/2,k_Hp/2))/dSf -> 0.64977258 | M5: =(-IF(k_is4E=1,0,st_t/20))/dSf -> 0 | N5: =(-IF(k_is4E=1,k_d/2,k_Hp/2))/dSf -> -0.64977258 | P5: =(k_g/2)/dSf -> 0.17868746 | Q5: =(k_d/2+k_pfo)/dSf -> 0.79597141 | S5: =(k_g/2)/dSf -> 0.17868746 | T5: =(-(k_d/2+k_pfo))/dSf -> -0.79597141 | V5: =((-k_cd)-dxc)/dSl -> -0.95238095 | W5: =(dHc)/dSl -> 0.72045398 | Y5: =((-k_ctf)-dxc)/dSl -> 0.0049346163 | Z5: =(dHc)/dSl -> 0.72045398 | AB5: =((-k_cd+k_ctf)-dxc)/dSl -> -0.92277325 | AC5: =(dHc)/dSl -> 0.72045398 | AE5: =((IF(cp_usar="Sí",-k_ctf,-k_cd+k_ctf))-dxc)/dSl -> 0.0049346163 | AF5: =((k_d/2-k_tf/2))/dSl -> 0.38292623 | AH5: =((IF(cp_usar="Sí",-k_ctf,-k_cd+k_ctf))-dxc)/dSl -> 0.0049346163 | AI5: =(-(k_d/2-k_tf/2))/dSl -> -0.38292623 | AK5: =((0)-dxc)/dSl -> 0.034542314 | AL5: =(k_Hp/2)/dSl -> 0.56254626 | AN5: =((k_tp)-dxc)/dSl -> 0.083888478 | AO5: =(k_d/2)/dSl -> 0.39476931 | AQ5: =((k_tp)-dxc)/dSl -> 0.083888478 | AR5: =(-k_d/2+k_tf)/dSl -> -0.37108315 | AT5: =((k_tp)-dxc)/dSl -> 0.083888478 | AU5: =(IF(k_is4E=1,k_d/2,k_Hp/2))/dSl -> 0.39476931 | AW5: =((k_tp)-dxc)/dSl -> 0.083888478 | AX5: =(-IF(k_is4E=1,k_d/2,k_Hp/2))/dSl -> -0.39476931 | AZ5: =(((k_tp-k_ctf)/2)-dxc)/dSl -> 0.044411547 | BA5: =(k_d/2+k_pfo+k_pb)/dSl -> 0.4835924
A6: S lateral | B6: =MAX(k_Hp+16,k_cd+k_tp+dLb)/2*1.05 -> 50.6625 | D6: =(k_bp/2)/dSf -> 0.32488629 | E6: =(k_Hp/2)/dSf -> 0.92592593 | G6: =(k_bf/2)/dSf -> 0.29239766 | H6: =(k_d/2-k_tf)/dSf -> 0.61078622 | J6: =(IF(k_is4E=1,0,st_t/20))/dSf -> 0 | K6: =(IF(k_is4E=1,k_d/2,k_Hp/2))/dSf -> 0.64977258 | M6: =(IF(k_is4E=1,0,st_t/20))/dSf -> 0 | N6: =(-IF(k_is4E=1,k_d/2,k_Hp/2))/dSf -> -0.64977258 | P6: =(-k_g/2)/dSf -> -0.17868746 | Q6: =(k_d/2+k_pfo+k_pb)/dSf -> 0.79597141 | S6: =(-k_g/2)/dSf -> -0.17868746 | T6: =(-(k_d/2+k_pfo+k_pb))/dSf -> -0.79597141 | V6: =((0)-dxc)/dSl -> 0.034542314 | W6: =(dHc)/dSl -> 0.72045398 | AK6: =((k_tp)-dxc)/dSl -> 0.083888478 | AL6: =(k_Hp/2)/dSl -> 0.56254626 | AN6: =((k_tp+dLb)-dxc)/dSl -> 0.95238095 | AO6: =(k_d/2)/dSl -> 0.39476931 | AQ6: =((k_tp+dLb)-dxc)/dSl -> 0.95238095 | AR6: =(-k_d/2+k_tf)/dSl -> -0.37108315 | AT6: =((k_tp+IF(k_is4E=1,0,k_Lst))-dxc)/dSl -> 0.083888478 | AU6: =(k_d/2)/dSl -> 0.39476931 | AW6: =((k_tp+IF(k_is4E=1,0,k_Lst))-dxc)/dSl -> 0.083888478 | AX6: =(-k_d/2)/dSl -> -0.39476931 | AZ6: =(((k_tp-k_ctf)/2)-dxc)/dSl -> 0.044411547 | BA6: =(k_d/2-k_tf-k_pfi)/dSl -> 0.28226005
A7: Hc/2 | B7: =k_Hp/2+8 -> 36.5 | D7: =(k_bp/2)/dSf -> 0.32488629 | E7: =(-k_Hp/2)/dSf -> -0.92592593 | G7: =(k_tw/2)/dSf -> 0.0097465887 | H7: =(k_d/2-k_tf)/dSf -> 0.61078622 | J7: =(IF(k_is4E=1,0,st_t/20))/dSf -> 0 | K7: =(k_d/2)/dSf -> 0.64977258 | M7: =(IF(k_is4E=1,0,st_t/20))/dSf -> 0 | N7: =(-k_d/2)/dSf -> -0.64977258 | P7: =(k_g/2)/dSf -> 0.17868746 | Q7: =(k_d/2+k_pfo+k_pb)/dSf -> 0.79597141 | S7: =(k_g/2)/dSf -> 0.17868746 | T7: =(-(k_d/2+k_pfo+k_pb))/dSf -> -0.79597141 | V7: =((0)-dxc)/dSl -> 0.034542314 | W7: =(-dHc)/dSl -> -0.72045398 | AK7: =((k_tp)-dxc)/dSl -> 0.083888478 | AL7: =(-k_Hp/2)/dSl -> -0.56254626 | AN7: =((k_tp+dLb)-dxc)/dSl -> 0.95238095 | AO7: =(k_d/2-k_tf)/dSl -> 0.37108315 | AQ7: =((k_tp+dLb)-dxc)/dSl -> 0.95238095 | AR7: =(-k_d/2)/dSl -> -0.39476931 | AZ7: =(((k_tp-k_ctf)/2)-dxc)/dSl -> 0.044411547 | BA7: =(k_d/2-k_tf-k_pfi-k_pb)/dSl -> 0.28226005
D8: =(-k_bp/2)/dSf -> -0.32488629 | E8: =(-k_Hp/2)/dSf -> -0.92592593 | G8: =(k_tw/2)/dSf -> 0.0097465887 | H8: =(-k_d/2+k_tf)/dSf -> -0.61078622 | P8: =(-k_g/2)/dSf -> -0.17868746 | Q8: =(k_d/2-k_tf-k_pfi)/dSf -> 0.46458739 | S8: =(-k_g/2)/dSf -> -0.17868746 | T8: =(-(k_d/2-k_tf-k_pfi))/dSf -> -0.46458739 | V8: =((-k_cd)-dxc)/dSl -> -0.95238095 | W8: =(-dHc)/dSl -> -0.72045398 | AK8: =((0)-dxc)/dSl -> 0.034542314 | AL8: =(-k_Hp/2)/dSl -> -0.56254626 | AN8: =((k_tp)-dxc)/dSl -> 0.083888478 | AO8: =(k_d/2-k_tf)/dSl -> 0.37108315 | AQ8: =((k_tp)-dxc)/dSl -> 0.083888478 | AR8: =(-k_d/2)/dSl -> -0.39476931 | AZ8: =(((k_tp-k_ctf)/2)-dxc)/dSl -> 0.044411547 | BA8: =(-(k_d/2+k_pfo))/dSl -> -0.4835924
G9: =(k_bf/2)/dSf -> 0.29239766 | H9: =(-k_d/2+k_tf)/dSf -> -0.61078622 | P9: =(k_g/2)/dSf -> 0.17868746 | Q9: =(k_d/2-k_tf-k_pfi)/dSf -> 0.46458739 | S9: =(k_g/2)/dSf -> 0.17868746 | T9: =(-(k_d/2-k_tf-k_pfi))/dSf -> -0.46458739 | AZ9: =(((k_tp-k_ctf)/2)-dxc)/dSl -> 0.044411547 | BA9: =(-(k_d/2+k_pfo+k_pb))/dSl -> -0.4835924
G10: =(k_bf/2)/dSf -> 0.29239766 | H10: =(-k_d/2)/dSf -> -0.64977258 | P10: =(-k_g/2)/dSf -> -0.17868746 | Q10: =(k_d/2-k_tf-k_pfi-k_pb)/dSf -> 0.46458739 | S10: =(-k_g/2)/dSf -> -0.17868746 | T10: =(-(k_d/2-k_tf-k_pfi-k_pb))/dSf -> -0.46458739 | AZ10: =(((k_tp-k_ctf)/2)-dxc)/dSl -> 0.044411547 | BA10: =(-(k_d/2-k_tf-k_pfi))/dSl -> -0.28226005
G11: =(-k_bf/2)/dSf -> -0.29239766 | H11: =(-k_d/2)/dSf -> -0.64977258 | P11: =(k_g/2)/dSf -> 0.17868746 | Q11: =(k_d/2-k_tf-k_pfi-k_pb)/dSf -> 0.46458739 | S11: =(k_g/2)/dSf -> 0.17868746 | T11: =(-(k_d/2-k_tf-k_pfi-k_pb))/dSf -> -0.46458739 | AZ11: =(((k_tp-k_ctf)/2)-dxc)/dSl -> 0.044411547 | BA11: =(-(k_d/2-k_tf-k_pfi-k_pb))/dSl -> -0.28226005
G12: =(-k_bf/2)/dSf -> -0.29239766 | H12: =(-k_d/2+k_tf)/dSf -> -0.61078622
G13: =(-k_tw/2)/dSf -> -0.0097465887 | H13: =(-k_d/2+k_tf)/dSf -> -0.61078622
G14: =(-k_tw/2)/dSf -> -0.0097465887 | H14: =(k_d/2-k_tf)/dSf -> 0.61078622
G15: =(-k_bf/2)/dSf -> -0.29239766 | H15: =(k_d/2-k_tf)/dSf -> 0.61078622
G16: =(-k_bf/2)/dSf -> -0.29239766 | H16: =(k_d/2)/dSf -> 0.64977258
