Workbook

Sheet DISEÑO
B2: DISEÑO DE PLACA BASE Y PERNOS DE ANCLAJE — COLUMNA DE ACERO
B3: AISC Design Guide 1 (3ra ed.) · AISC 360-16 (J2, J8) · ACI 318-19 Cap. 17 · LRFD · Unidades: Tonf, Tonf·m, mm, cm, kgf/cm²
B4: Celdas de ingreso: | C4: valor | D4: Calculado: | E4: valor | G4: Estados: VERDE ≤ límite · AMARILLO entre límite y 1.00 · ROJO > 1.00 (ratio = demanda / capacidad de diseño)
B6: DATOS GENERALES | G6: PLANTA (●rojo: fila en tracción) | J6: ELEVACIÓN (dirección N) | N6: VERIFICACIONES — combinación gobernante por chequeo
B7: Proyecto | C7: Galpón KUBIEC — ejemplo | N7: =IF(COUNT(S12:S34)=0,"SIN CARGAS",IF(MAX(S12:S34)>1,"✖ NO CUMPLE — ratio máx. "&TEXT(MAX(S12:S34),"0.00"),IF(MAX(S12:S34)>lim_verde,"▲ CUMPLE AL LÍMITE — ratio máx. "&TEXT(MAX(S12:S34),"0.00"),"✔ CUMPLE — ratio máx. "&TEXT(MAX(S12:S34),"0.00")))) -> ✔ CUMPLE — ratio máx. 0.85
B8: Elemento / nudo | C8: Columna interior C-1
B9: Límite verde / amarillo (ratio) | C9: 0.9
B10: 1. COLUMNA | N10: Verificación | O10: Referencia | P10: Demanda | Q10: Capacidad | R10: Unidad | S10: Ratio | T10: Estado | U10: Combo
B11: Perfil (catálogo o ARMADO) | C11: HA360X180X6X12 | E11: Armado (mm) | N11: PLACA BASE Y CONCRETO DE APOYO
B12: Peralte d | C12: =IF(col_perfil="ARMADO (flejes soldados)",E12,INDEX(CATALOGOS!$B$5:$B$60,MATCH(col_perfil,CATALOGOS!$A$5:$A$60,0))) -> 360 | D12: mm | E12: 350 | N12: Aplastamiento del concreto | O12: AISC J8 · DG1 | P12: =INDEX(CALCULO!$D$93:$M$93,MATCH(MAX(CALCULO!$D$92:$M$92),CALCULO!$D$92:$M$92,0)) -> 11 | Q12: =INDEX(CALCULO!$D$94:$M$94,MATCH(MAX(CALCULO!$D$92:$M$92),CALCULO!$D$92:$M$92,0)) -> 105.29269 | R12: =IF(INDEX(CALCULO!$D$88:$M$88,MATCH(MAX(CALCULO!$D$92:$M$92),CALCULO!$D$92:$M$92,0))=2,"Tonf·m","kgf/cm²") -> Tonf·m | S12: =MAX(CALCULO!$D$92:$M$92) -> 0.10447069 | T12: =IF(ISNUMBER(S12),IF(S12>1,"NO CUMPLE",IF(S12>lim_verde,"AL LÍMITE","CUMPLE")),"N/A") -> CUMPLE | U12: =IF(ISNUMBER(S12),INDEX(CALCULO!$D$81:$M$81,MATCH(MAX(CALCULO!$D$92:$M$92),CALCULO!$D$92:$M$92,0)),"—") -> 1.2D+1.0E+L
B13: Ancho de ala bf | C13: =IF(col_perfil="ARMADO (flejes soldados)",E13,INDEX(CATALOGOS!$C$5:$C$60,MATCH(col_perfil,CATALOGOS!$A$5:$A$60,0))) -> 180 | D13: mm | E13: 200 | N13: Flexión de placa — lado compresión | O13: DG1 Ec. 4-51a/4-52a | P13: =INDEX(CALCULO!$D$98:$M$98,MATCH(MAX(CALCULO!$D$100:$M$100),CALCULO!$D$100:$M$100,0)) -> 5869.4812 | Q13: =p_phiMn -> 6973.3125 | R13: kgf·cm/cm | S13: =MAX(CALCULO!$D$100:$M$100) -> 0.84170633 | T13: =IF(ISNUMBER(S13),IF(S13>1,"NO CUMPLE",IF(S13>lim_verde,"AL LÍMITE","CUMPLE")),"N/A") -> CUMPLE | U13: =IF(ISNUMBER(S13),INDEX(CALCULO!$D$81:$M$81,MATCH(MAX(CALCULO!$D$100:$M$100),CALCULO!$D$100:$M$100,0)),"—") -> 1.2D+1.0E+L
B14: Espesor de alma tw | C14: =IF(col_perfil="ARMADO (flejes soldados)",E14,INDEX(CATALOGOS!$D$5:$D$60,MATCH(col_perfil,CATALOGOS!$A$5:$A$60,0))) -> 6 | D14: mm | E14: 8 | N14: Flexión de placa — lado tracción | O14: DG1 Ec. 4-62 | P14: =INDEX(CALCULO!$D$99:$M$99,MATCH(MAX(CALCULO!$D$101:$M$101),CALCULO!$D$101:$M$101,0)) -> 2807.4953 | Q14: =p_phiMn -> 6973.3125 | R14: kgf·cm/cm | S14: =MAX(CALCULO!$D$101:$M$101) -> 0.40260569 | T14: =IF(ISNUMBER(S14),IF(S14>1,"NO CUMPLE",IF(S14>lim_verde,"AL LÍMITE","CUMPLE")),"N/A") -> CUMPLE | U14: =IF(ISNUMBER(S14),INDEX(CALCULO!$D$81:$M$81,MATCH(MAX(CALCULO!$D$101:$M$101),CALCULO!$D$101:$M$101,0)),"—") -> 0.9D+1.0E
B15: Espesor de ala tf | C15: =IF(col_perfil="ARMADO (flejes soldados)",E15,INDEX(CATALOGOS!$E$5:$E$60,MATCH(col_perfil,CATALOGOS!$A$5:$A$60,0))) -> 12 | D15: mm | E15: 12 | N15: PERNOS DE ANCLAJE — TRACCIÓN
B16: 2. PLACA BASE | N16: Acero del perno (por perno) | O16: ACI §17.6.1 | P16: =INDEX(CALCULO!$D$103:$M$103,MATCH(MAX(CALCULO!$D$105:$M$105),CALCULO!$D$105:$M$105,0))/1000 -> 7.3881455 | Q16: =s_phiNsa/1000 -> 15.446477 | R16: Tonf | S16: =MAX(CALCULO!$D$105:$M$105) -> 0.47830619 | T16: =IF(ISNUMBER(S16),IF(S16>1,"NO CUMPLE",IF(S16>lim_verde,"AL LÍMITE","CUMPLE")),"N/A") -> CUMPLE | U16: =IF(ISNUMBER(S16),INDEX(CALCULO!$D$81:$M$81,MATCH(MAX(CALCULO!$D$105:$M$105),CALCULO!$D$105:$M$105,0)),"—") -> 0.9D+1.0E
B17: Acero de placa | C17: A36 | N17: =IF(hp_usar="Sí","Refuerzo de anclaje (hairpins)","Arrancamiento del concreto (grupo)") -> Refuerzo de anclaje (hairpins) | O17: =IF(hp_usar="Sí","ACI §17.5.2.1","ACI §17.6.2") -> ACI §17.5.2.1 | P17: =INDEX(CALCULO!$D$110:$M$110,MATCH(MAX(CALCULO!$D$109:$M$109),CALCULO!$D$109:$M$109,0)) -> 14.776291 | Q17: =INDEX(CALCULO!$D$111:$M$111,MATCH(MAX(CALCULO!$D$109:$M$109),CALCULO!$D$109:$M$109,0)) -> 25.3386 | R17: Tonf | S17: =MAX(CALCULO!$D$109:$M$109) -> 0.58315341 | T17: =IF(ISNUMBER(S17),IF(S17>1,"NO CUMPLE",IF(S17>lim_verde,"AL LÍMITE","CUMPLE")),"N/A") -> CUMPLE | U17: =IF(ISNUMBER(S17),INDEX(CALCULO!$D$81:$M$81,MATCH(MAX(CALCULO!$D$109:$M$109),CALCULO!$D$109:$M$109,0)),"—") -> 0.9D+1.0E
B18: Fy placa | C18: =INDEX(CATALOGOS!$H$5:$H$20,MATCH(pl_acero,CATALOGOS!$G$5:$G$20,0)) -> 2530 | D18: kgf/cm² | N18: Extracción por deslizamiento (pullout) | O18: ACI §17.6.3 | P18: =INDEX(CALCULO!$D$103:$M$103,MATCH(MAX(CALCULO!$D$112:$M$112),CALCULO!$D$112:$M$112,0))/1000 -> 7.3881455 | Q18: =po_phiNp/1000 -> 33.111322 | R18: Tonf | S18: =MAX(CALCULO!$D$112:$M$112) -> 0.22313049 | T18: =IF(ISNUMBER(S18),IF(S18>1,"NO CUMPLE",IF(S18>lim_verde,"AL LÍMITE","CUMPLE")),"N/A") -> CUMPLE | U18: =IF(ISNUMBER(S18),INDEX(CALCULO!$D$81:$M$81,MATCH(MAX(CALCULO!$D$112:$M$112),CALCULO!$D$112:$M$112,0)),"—") -> 0.9D+1.0E
B19: N — largo (dirección del momento) | C19: 600 | D19: mm | N19: Desprendimiento lateral (blowout) | O19: ACI §17.6.4 | P19: =IF(AND(sf_apF=0,sf_apS=0),"—",INDEX(CALCULO!$D$116:$M$116,MATCH(MAX(CALCULO!$D$115:$M$115),CALCULO!$D$115:$M$115,0))) -> — | Q19: =IF(AND(sf_apF=0,sf_apS=0),"—",INDEX(CALCULO!$D$117:$M$117,MATCH(MAX(CALCULO!$D$115:$M$115),CALCULO!$D$115:$M$115,0))) -> — | R19: Tonf | S19: =IF(AND(sf_apF=0,sf_apS=0),"N/A",MAX(CALCULO!$D$115:$M$115)) -> N/A | T19: =IF(ISNUMBER(S19),IF(S19>1,"NO CUMPLE",IF(S19>lim_verde,"AL LÍMITE","CUMPLE")),"N/A") -> N/A | U19: =IF(ISNUMBER(S19),INDEX(CALCULO!$D$81:$M$81,MATCH(MAX(CALCULO!$D$115:$M$115),CALCULO!$D$115:$M$115,0)),"—") -> —
B20: B — ancho (perpendicular) | C20: 400 | D20: mm | N20: PERNOS DE ANCLAJE — CORTE
B21: tp — espesor | C21: 35 | D21: mm | G21: CARGAS FACTORADAS EN LA BASE (LRFD) | N21: Acero del perno (por perno) | O21: ACI §17.7.1 | P21: =INDEX(CALCULO!$D$118:$M$118,MATCH(MAX(CALCULO!$D$119:$M$119),CALCULO!$D$119:$M$119,0))/pb_nv/1000 -> 0.875 | Q21: =s_phiVsa/1000 -> 6.4257344 | R21: Tonf | S21: =MAX(CALCULO!$D$119:$M$119) -> 0.13617121 | T21: =IF(ISNUMBER(S21),IF(S21>1,"NO CUMPLE",IF(S21>lim_verde,"AL LÍMITE","CUMPLE")),"N/A") -> CUMPLE | U21: =IF(ISNUMBER(S21),INDEX(CALCULO!$D$81:$M$81,MATCH(MAX(CALCULO!$D$119:$M$119),CALCULO!$D$119:$M$119,0)),"—") -> 1.2D+1.0E+L
B22: Espesor de grout (mortero) | C22: 25 | D22: mm | G22: Combinación | H22: Pu (Tonf) | I22: Vu (Tonf) | J22: Mu (Tonf·m) | K22: Caso DG1 | L22: Ratio máx. | N22: Arrancamiento del concreto en corte | O22: ACI §17.7.2 | P22: =INDEX(CALCULO!$D$123:$M$123,MATCH(MAX(CALCULO!$D$122:$M$122),CALCULO!$D$122:$M$122,0)) -> 3.5 | Q22: =INDEX(CALCULO!$D$124:$M$124,MATCH(MAX(CALCULO!$D$122:$M$122),CALCULO!$D$122:$M$122,0)) -> 7.9681942 | R22: Tonf | S22: =MAX(CALCULO!$D$122:$M$122) -> 0.43924632 | T22: =IF(ISNUMBER(S22),IF(S22>1,"NO CUMPLE",IF(S22>lim_verde,"AL LÍMITE","CUMPLE")),"N/A") -> CUMPLE | U22: =IF(ISNUMBER(S22),INDEX(CALCULO!$D$81:$M$81,MATCH(MAX(CALCULO!$D$122:$M$122),CALCULO!$D$122:$M$122,0)),"—") -> 1.2D+1.0E+L
B23: 3. PERNOS DE ANCLAJE | G23: 1.4D | H23: 9 | I23: 0.6 | J23: 0.8 | K23: =CHOOSE(INDEX(CALCULO!$D$88:$M$88,1)+1,"—","e ≤ ecrit","M grande","Levant.") -> e ≤ ecrit | L23: =IF(INDEX(CALCULO!$D$85:$M$85,1)=1,INDEX(CALCULO!$D$132:$M$132,1),"—") -> 0.075299369 | N23: Desprendimiento por palanca (pryout) | O23: ACI §17.7.3 | P23: =INDEX(CALCULO!$D$118:$M$118,MATCH(MAX(CALCULO!$D$125:$M$125),CALCULO!$D$125:$M$125,0))/1000 -> 3.5 | Q23: =pr_phiV/1000 -> 37.901586 | R23: Tonf | S23: =MAX(CALCULO!$D$125:$M$125) -> 0.09234442 | T23: =IF(ISNUMBER(S23),IF(S23>1,"NO CUMPLE",IF(S23>lim_verde,"AL LÍMITE","CUMPLE")),"N/A") -> CUMPLE | U23: =IF(ISNUMBER(S23),INDEX(CALCULO!$D$81:$M$81,MATCH(MAX(CALCULO!$D$125:$M$125),CALCULO!$D$125:$M$125,0)),"—") -> 1.2D+1.0E+L
B24: Material | C24: F1554 Gr55 | G24: 1.2D+1.6L | H24: 12 | I24: 1.2 | J24: 2.5 | K24: =CHOOSE(INDEX(CALCULO!$D$88:$M$88,2)+1,"—","e ≤ ecrit","M grande","Levant.") -> e ≤ ecrit | L24: =IF(INDEX(CALCULO!$D$85:$M$85,2)=1,INDEX(CALCULO!$D$132:$M$132,2),"—") -> 0.19524958 | N24: Interacción tracción – corte | O24: ACI §17.8 | P24: =INDEX(CALCULO!$D$126:$M$126,MATCH(MAX(CALCULO!$D$128:$M$128),CALCULO!$D$128:$M$128,0)) -> 0.58315341 | Q24: =INDEX(CALCULO!$D$127:$M$127,MATCH(MAX(CALCULO!$D$128:$M$128),CALCULO!$D$128:$M$128,0)) -> 0.43924632 | R24: N / V | S24: =MAX(CALCULO!$D$128:$M$128) -> 0.85199978 | T24: =IF(ISNUMBER(S24),IF(S24>1,"NO CUMPLE",IF(S24>lim_verde,"AL LÍMITE","CUMPLE")),"N/A") -> CUMPLE | U24: =IF(ISNUMBER(S24),INDEX(CALCULO!$D$81:$M$81,MATCH(MAX(CALCULO!$D$128:$M$128),CALCULO!$D$128:$M$128,0)),"—") -> 0.9D+1.0E
B25: fya | C25: =INDEX(CATALOGOS!$L$5:$L$20,MATCH(pb_mat,CATALOGOS!$K$5:$K$20,0)) -> 3870 | D25: kgf/cm² | G25: 1.2D+1.0E+L | H25: 8 | I25: 3.5 | J25: 9 | K25: =CHOOSE(INDEX(CALCULO!$D$88:$M$88,3)+1,"—","e ≤ ecrit","M grande","Levant.") -> M grande | L25: =IF(INDEX(CALCULO!$D$85:$M$85,3)=1,INDEX(CALCULO!$D$132:$M$132,3),"—") -> 0.84170633 | N25: SOLDADURA COLUMNA – PLACA
B26: futa (≤ 1.9·fya ; ≤ 8790) | C26: =MIN(INDEX(CATALOGOS!$M$5:$M$20,MATCH(pb_mat,CATALOGOS!$K$5:$K$20,0)),1.9*pb_fya,8790) -> 5270 | D26: kgf/cm² | G26: 0.9D+1.0E | H26: 3 | I26: 3.5 | J26: 8.8 | K26: =CHOOSE(INDEX(CALCULO!$D$88:$M$88,4)+1,"—","e ≤ ecrit","M grande","Levant.") -> M grande | L26: =IF(INDEX(CALCULO!$D$85:$M$85,4)=1,INDEX(CALCULO!$D$132:$M$132,4),"—") -> 0.85199978 | N26: Filete en alas (tracción de ala) | O26: AISC J2.4 · Ec. J2-5 | P26: =INDEX(CALCULO!$D$129:$M$129,MATCH(MAX(CALCULO!$D$130:$M$130),CALCULO!$D$130:$M$130,0))/1000 -> 24.264629 | Q26: =w_phiRf/1000 -> 66.493859 | R26: Tonf | S26: =MAX(CALCULO!$D$130:$M$130) -> 0.36491534 | T26: =IF(ISNUMBER(S26),IF(S26>1,"NO CUMPLE",IF(S26>lim_verde,"AL LÍMITE","CUMPLE")),"N/A") -> CUMPLE | U26: =IF(ISNUMBER(S26),INDEX(CALCULO!$D$81:$M$81,MATCH(MAX(CALCULO!$D$130:$M$130),CALCULO!$D$130:$M$130,0)),"—") -> 0.9D+1.0E
B27: Diámetro | C27: 1" | G27: 0.9D+1.0W | H27: -3.5 | I27: 2 | J27: 2.5 | K27: =CHOOSE(INDEX(CALCULO!$D$88:$M$88,5)+1,"—","e ≤ ecrit","M grande","Levant.") -> M grande | L27: =IF(INDEX(CALCULO!$D$85:$M$85,5)=1,INDEX(CALCULO!$D$132:$M$132,5),"—") -> 0.42181918 | N27: Filete en alma (corte) | O27: AISC J2.4 | P27: =INDEX(CALCULO!$D$83:$M$83,MATCH(MAX(CALCULO!$D$131:$M$131),CALCULO!$D$131:$M$131,0))/1000 -> 3.5 | Q27: =w_phiRw/1000 -> 63.112815 | R27: Tonf | S27: =MAX(CALCULO!$D$131:$M$131) -> 0.055456249 | T27: =IF(ISNUMBER(S27),IF(S27>1,"NO CUMPLE",IF(S27>lim_verde,"AL LÍMITE","CUMPLE")),"N/A") -> CUMPLE | U27: =IF(ISNUMBER(S27),INDEX(CALCULO!$D$81:$M$81,MATCH(MAX(CALCULO!$D$131:$M$131),CALCULO!$D$131:$M$131,0)),"—") -> 1.2D+1.0E+L
B28: Pernos por fila (2 filas) | C28: 2 | G28: C6 | K28: =CHOOSE(INDEX(CALCULO!$D$88:$M$88,6)+1,"—","e ≤ ecrit","M grande","Levant.") -> — | L28: =IF(INDEX(CALCULO!$D$85:$M$85,6)=1,INDEX(CALCULO!$D$132:$M$132,6),"—") -> — | N28: GEOMETRÍA Y DETALLES (requerido / provisto)
B29: Total de pernos | C29: =2*pb_nfila -> 4 | G29: C7 | K29: =CHOOSE(INDEX(CALCULO!$D$88:$M$88,7)+1,"—","e ≤ ecrit","M grande","Levant.") -> — | L29: =IF(INDEX(CALCULO!$D$85:$M$85,7)=1,INDEX(CALCULO!$D$132:$M$132,7),"—") -> — | N29: Espaciamiento mínimo 4·da | O29: ACI §17.9.2 | P29: =4*a_da -> 10.16 | Q29: =IF(a_nf>1,MIN(g_sx,2*g_f),2*g_f) -> 30 | R29: cm | S29: =(4*a_da)/MAX(IF(a_nf>1,MIN(g_sx,2*g_f),2*g_f),0.001) -> 0.33866667 | T29: =IF(ISNUMBER(S29),IF(S29>1,"NO CUMPLE",IF(S29>lim_verde,"AL LÍMITE","CUMPLE")),"N/A") -> CUMPLE | U29: —
B30: Borde perno → placa (dir. N) | C30: 50 | D30: mm | G30: C8 | K30: =CHOOSE(INDEX(CALCULO!$D$88:$M$88,8)+1,"—","e ≤ ecrit","M grande","Levant.") -> — | L30: =IF(INDEX(CALCULO!$D$85:$M$85,8)=1,INDEX(CALCULO!$D$132:$M$132,8),"—") -> — | N30: Placa contenida en el pedestal | O30: Geometría | P30: =MAX(p_N,p_B) -> 60 | Q30: =IF(p_N/ped_Np>=p_B/ped_Bp,ped_Np,ped_Bp) -> 90 | R30: cm | S30: =MAX(p_N/ped_Np,p_B/ped_Bp) -> 0.66666667 | T30: =IF(ISNUMBER(S30),IF(S30>1,"NO CUMPLE",IF(S30>lim_verde,"AL LÍMITE","CUMPLE")),"N/A") -> CUMPLE | U30: —
B31: Borde perno → placa (dir. B) | C31: 50 | D31: mm | G31: C9 | K31: =CHOOSE(INDEX(CALCULO!$D$88:$M$88,9)+1,"—","e ≤ ecrit","M grande","Levant.") -> — | L31: =IF(INDEX(CALCULO!$D$85:$M$85,9)=1,INDEX(CALCULO!$D$132:$M$132,9),"—") -> — | N31: Holgura perno – cara de ala ≥ 1.5·da | O31: Práctica (tuerca/llave) | P31: =1.5*a_da -> 3.81 | Q31: =g_f-c_d/2 -> 7 | R31: cm | S31: =(1.5*a_da)/MAX(g_f-c_d/2,0.001) -> 0.54428571 | T31: =IF(ISNUMBER(S31),IF(S31>1,"NO CUMPLE",IF(S31>lim_verde,"AL LÍMITE","CUMPLE")),"N/A") -> CUMPLE | U31: —
B32: Empotramiento efectivo hef | C32: 500 | D32: mm | G32: C10 | K32: =CHOOSE(INDEX(CALCULO!$D$88:$M$88,10)+1,"—","e ≤ ecrit","M grande","Levant.") -> — | L32: =IF(INDEX(CALCULO!$D$85:$M$85,10)=1,INDEX(CALCULO!$D$132:$M$132,10),"—") -> — | N32: Borde perno – placa ≥ 1.5·da | O32: Práctica / DG1 | P32: =1.5*a_da -> 3.81 | Q32: =MIN(pb_eN_mm,pb_eB_mm)/10 -> 5 | R32: cm | S32: =(1.5*a_da)/MAX(MIN(pb_eN_mm,pb_eB_mm)/10,0.001) -> 0.762 | T32: =IF(ISNUMBER(S32),IF(S32>1,"NO CUMPLE",IF(S32>lim_verde,"AL LÍMITE","CUMPLE")),"N/A") -> CUMPLE | U32: —
B33: Arandela inferior: lado (0 = solo tuerca) | C33: 70 | D33: mm | G33: Pu (+) compresión, (−) tracción. Mu alrededor del eje fuerte (se usa |Mu|). Vu en la dirección N. Filas vacías se ignoran. | N33: Filete mínimo en alas | O33: AISC Tabla J2.4 | P33: =IF(MIN(col_tf_mm,pl_tp_mm)<=6,3,IF(MIN(col_tf_mm,pl_tp_mm)<=13,5,IF(MIN(col_tf_mm,pl_tp_mm)<=19,6,8))) -> 5 | Q33: =sold_wf -> 8 | R33: mm | S33: =(IF(MIN(col_tf_mm,pl_tp_mm)<=6,3,IF(MIN(col_tf_mm,pl_tp_mm)<=13,5,IF(MIN(col_tf_mm,pl_tp_mm)<=19,6,8))))/MAX(sold_wf,0.001) -> 0.625 | T33: =IF(ISNUMBER(S33),IF(S33>1,"NO CUMPLE",IF(S33>lim_verde,"AL LÍMITE","CUMPLE")),"N/A") -> CUMPLE | U33: —
B34: Arandela inferior: espesor | C34: 12 | D34: mm | N34: Filete mínimo en alma | O34: AISC Tabla J2.4 | P34: =IF(MIN(col_tw_mm,pl_tp_mm)<=6,3,IF(MIN(col_tw_mm,pl_tp_mm)<=13,5,IF(MIN(col_tw_mm,pl_tp_mm)<=19,6,8))) -> 3 | Q34: =sold_ww -> 6 | R34: mm | S34: =(IF(MIN(col_tw_mm,pl_tp_mm)<=6,3,IF(MIN(col_tw_mm,pl_tp_mm)<=13,5,IF(MIN(col_tw_mm,pl_tp_mm)<=19,6,8))))/MAX(sold_ww,0.001) -> 0.5 | T34: =IF(ISNUMBER(S34),IF(S34>1,"NO CUMPLE",IF(S34>lim_verde,"AL LÍMITE","CUMPLE")),"N/A") -> CUMPLE | U34: —
B35: Arandelas superiores soldadas a la placa | C35: Sí | G35: DETALLE DE UNA COMBINACIÓN (AISC DG1)
B36: Pernos efectivos a corte | C36: 4 | G36: Combinación: | H36: 1.2D+1.0E+L | J36: índice: | K36: =IFERROR(MATCH(H36,cb_nom,0),1) -> 3 | N36: ALCANCE Y SUPUESTOS
B37: 4. PEDESTAL Y CONCRETO | G37: Caso DG1 | J37: =INDEX(CALCULO!$D$88:$M$88,det_k) -> 2 | L37: =CHOOSE(J37+1,"inactiva","e ≤ ecrit","momento grande","levantamiento") -> momento grande | N37: • LRFD con cargas factoradas del análisis. Momento alrededor del eje fuerte; corte en la dirección N.
B38: f'c | C38: 210 | D38: kgf/cm² | G38: Excentricidad e = Mu/Pu | J38: =INDEX(CALCULO!$D$86:$M$86,det_k) -> 112.5 | K38: cm | N38: • Placa rígida, pedestal concéntrico; A2 geométricamente similar a A1 (AISC J8).
B39: Pedestal Np (dirección N) | C39: 90 | D39: cm | G39: Excentricidad crítica ecrit | J39: =INDEX(CALCULO!$D$87:$M$87,det_k) -> 29.425411 | K39: cm | N39: • Placa: voladizos m, n y λn' de DG1; momento grande por Y (ecuación cuadrática) y Tu de DG1.
B40: Pedestal Bp (dirección B) | C40: 80 | D40: cm | G40: Longitud de apoyo Y | J40: =INDEX(CALCULO!$D$90:$M$90,det_k) -> 2.9521744 | K40: cm | N40: • Pernos colados en sitio con tuerca hex. pesada; φ Condición B (sin refuerzo suplementario).
B41: Concreto fisurado | C41: Sí | G41: Presión de apoyo fp | J41: =INDEX(CALCULO!$D$91:$M$91,det_k) -> 174.0375 | K41: kgf/cm² | N41: • Arrancamiento con h'ef de ACI §17.6.2.1.2 cuando hay ≥ 3 bordes a menos de 1.5hef (pedestales).
B42: Refuerzo de borde ≥ Ø12 (ψc,V = 1.2) | C42: Sí | G42: Tracción fila de pernos Tu | J42: =INDEX(CALCULO!$D$95:$M$95,det_k)/1000 -> 12.551562 | K42: Tonf | N42: • Hairpins: deben desarrollarse (ACI 25.4) a ambos lados del plano de falla — verificar el detalle.
...

Sheet CALCULO
A1: HOJA DE CÁLCULO — memoria detallada (no editar; todo se alimenta de la hoja DISEÑO)
A2: Unidades internas: kgf, cm. φ según ACI 318-19 Tabla 17.5.3 (Condición B, pernos colados en sitio) y AISC 360-16.
A4: 1. GEOMETRÍA Y MATERIALES
A5: d | B5: Peralte de columna | C5: cm | D5: =col_d_mm/10 -> 36
A6: bf | B6: Ancho de ala | C6: cm | D6: =col_bf_mm/10 -> 18
A7: tw | B7: Espesor de alma | C7: cm | D7: =col_tw_mm/10 -> 0.6
A8: tf | B8: Espesor de ala | C8: cm | D8: =col_tf_mm/10 -> 1.2
A9: A | B9: Área del perfil ≈ 2·bf·tf + (d−2tf)·tw | C9: cm² | D9: =2*c_bf*c_tf+(c_d-2*c_tf)*c_tw -> 63.36
A10: N | B10: Largo de placa (dir. del momento) | C10: cm | D10: =pl_N_mm/10 -> 60
A11: B | B11: Ancho de placa | C11: cm | D11: =pl_B_mm/10 -> 40
A12: tp | B12: Espesor de placa | C12: cm | D12: =pl_tp_mm/10 -> 3.5
A13: g | B13: Espesor de grout | C13: cm | D13: =grout_mm/10 -> 2.5
A14: da | B14: Diámetro del perno | C14: in | D14: =INDEX(CATALOGOS!$P$5:$P$20,MATCH(pb_diam,CATALOGOS!$O$5:$O$20,0)) -> 1
A15: nt | B15: Hilos por pulgada (UNC) | C15: 1/in | D15: =INDEX(CATALOGOS!$Q$5:$Q$20,MATCH(pb_diam,CATALOGOS!$O$5:$O$20,0)) -> 8
A16: da | B16: Diámetro del perno | C16: cm | D16: =a_din*2.54 -> 2.54
A17: Ase,N | B17: Área efectiva a tracción = 0.7854·(da−0.9743/nt)² | C17: cm² | D17: =0.7854*(a_din-0.9743/a_tpi)^2*6.4516 -> 3.908027
A18: b,ar | B18: Lado efectivo de arandela = mín(lado ; F + 2·t), F = 1.5da + 1/8 (tuerca) | C18: in | D18: =MIN(ar_lado,(1.5*a_din+0.125)*25.4+2*ar_t)/25.4 -> 2.5698819
A19: Abrg | B19: Tuerca hex. pesada 0.866·F² − π·da²/4 ; con arandela b² − π·da²/4 | C19: cm² | D19: =(IF(a_bef>1.5*a_din+0.125,a_bef^2,0.866*(1.5*a_din+0.125)^2)-PI()*a_din^2/4)*6.4516 -> 37.541181
A20: nf | B20: Pernos por fila | C20: - | D20: =pb_nfila -> 2
A21: n | B21: Pernos totales | C21: - | D21: =pb_ntot -> 4
A22: f | B22: Distancia centro de placa → fila de pernos (DG1) | C22: cm | D22: =p_N/2-pb_eN_mm/10 -> 25
A23: xb | B23: Distancia eje de placa → perno extremo (dir. B) | C23: cm | D23: =p_B/2-pb_eB_mm/10 -> 15
A24: s | B24: Espaciamiento entre pernos de una fila | C24: cm | D24: =2*g_xb/(a_nf-1) -> 30
A25: hef | B25: Empotramiento efectivo | C25: cm | D25: =pb_hef_mm/10 -> 50
A26: ca,F | B26: Fila en tracción → cara frontal del pedestal | C26: cm | D26: =ped_Np/2-g_f -> 20
A27: ca,S | B27: Perno extremo → cara lateral del pedestal | C27: cm | D27: =ped_Bp/2-g_xb -> 25
A28: ca,P | B28: Fila en tracción → cara posterior del pedestal | C28: cm | D28: =ped_Np/2+g_f -> 70
A29: k sis | B29: Factor sísmico concreto en tracción (ACI §17.10.5.4) | C29: - | D29: =IF(sismo="Sí",0.75,1) -> 0.75
A30: 2. APLASTAMIENTO — AISC 360-16 J8 / DG1
A31: √(A2/A1) | B31: A2 geométricamente similar y concéntrica, 1 ≤ √(A2/A1) ≤ 2 | C31: - | D31: =MIN(2,MAX(1,MIN(ped_Bp/p_B,ped_Np/p_N))) -> 1.5
A32: fpu,max | B32: φc·0.85·f'c·√(A2/A1), φc = 0.65 | C32: kgf/cm² | D32: =0.65*0.85*fc*b_raiz -> 174.0375
A33: qmax | B33: fpu,max·B | C33: kgf/cm | D33: =b_fpu*p_B -> 6961.5
A34: m | B34: (N − 0.95·d)/2 | C34: cm | D34: =(p_N-0.95*c_d)/2 -> 12.9
A35: n | B35: (B − 0.80·bf)/2 | C35: cm | D35: =(p_B-0.8*c_bf)/2 -> 12.8
A36: n' | B36: √(d·bf)/4 | C36: cm | D36: =SQRT(c_d*c_bf)/4 -> 6.363961
A37: x | B37: Brazo lado tracción: f − d/2 + tf/2 (DG1) | C37: cm | D37: =g_f-c_d/2+c_tf/2 -> 7.6
A38: φMn | B38: 0.90·Fy·tp²/4 (por unidad de ancho) | C38: kgf·cm/cm | D38: =0.9*pl_Fy*p_tp^2/4 -> 6973.3125
A39: 3. PERNOS — RESISTENCIAS (ACI 318-19 Cap. 17)
A40: φNsa | B40: Acero a tracción por perno: 0.75·Ase·futa (§17.6.1) | C40: kgf | D40: =0.75*a_Ase*pb_futa -> 15446.477
A41: φVsa | B41: Acero a corte por perno: 0.65·0.6·Ase·futa·(0.8 si grout) (§17.7.1) | C41: kgf | D41: =0.65*0.6*a_Ase*pb_futa*IF(p_g>0,0.8,1) -> 6425.7344
...

Sheet CATALOGOS
A1: CATÁLOGOS — se pueden ampliar agregando filas al final de cada tabla (dentro del rango indicado)
A3: Perfiles (HA: catálogo KUBIEC; W: AISC, redondeado a mm) | G3: Acero de placa (kgf/cm²) | K3: Pernos de anclaje (kgf/cm²) — ASTM F1554 | O3: Diámetros (UNC) | S3: Espesor placa (mm) | U3: f'c (kgf/cm²) | W3: Electrodo (kgf/cm²) | Z3: Opción | AB3: Pernos por fila | AD3: Varilla (mm)
A4: Perfil | B4: d (mm) | C4: bf (mm) | D4: tw (mm) | E4: tf (mm) | G4: Acero | H4: Fy | I4: Fu | K4: Material | L4: fya | M4: futa | O4: Diámetro | P4: da (in) | Q4: hilos/in | S4: tp | U4: f'c | W4: Electrodo | X4: FEXX | Z4: Sí/No | AB4: n | AD4: Ø | AE4: As (cm²)
A5: ARMADO (flejes soldados) | G5: A36 | H5: 2530 | I5: 4080 | K5: F1554 Gr36 | L5: 2530 | M5: 4080 | O5: 1/2" | P5: 0.5 | Q5: 13 | S5: 10 | U5: 210 | W5: E60XX | X5: 4220 | Z5: Sí | AB5: 2 | AD5: 8 | AE5: 0.503
A6: HA200X140X6X12 | B6: 200 | C6: 140 | D6: 6 | E6: 12 | G6: A572 Gr50 | H6: 3515 | I6: 4570 | K6: F1554 Gr55 | L6: 3870 | M6: 5270 | O6: 5/8" | P6: 0.625 | Q6: 11 | S6: 12 | U6: 240 | W6: E70XX | X6: 4920 | Z6: No | AB6: 3 | AD6: 10 | AE6: 0.785
A7: HA220X160X6X12 | B7: 220 | C7: 160 | D7: 6 | E7: 12 | G7: A588 Gr50 | H7: 3515 | I7: 4920 | K7: F1554 Gr105 | L7: 7380 | M7: 8790 | O7: 3/4" | P7: 0.75 | Q7: 10 | S7: 15 | U7: 280 | AB7: 4 | AD7: 12 | AE7: 1.131
A8: HA240X180X6X12 | B8: 240 | C8: 180 | D8: 6 | E8: 12 | K8: A36 varilla roscada | L8: 2530 | M8: 4080 | O8: 7/8" | P8: 0.875 | Q8: 9 | S8: 16 | U8: 300 | AD8: 14 | AE8: 1.539
A9: HA260X180X6X12 | B9: 260 | C9: 180 | D9: 6 | E9: 12 | O9: 1" | P9: 1 | Q9: 8 | S9: 19 | U9: 350 | AD9: 16 | AE9: 2.011
A10: HA280X180X6X12 | B10: 280 | C10: 180 | D10: 6 | E10: 12 | O10: 1-1/8" | P10: 1.125 | Q10: 7 | S10: 20 | U10: 420 | AD10: 18 | AE10: 2.545
A11: HA300X180X6X12 | B11: 300 | C11: 180 | D11: 6 | E11: 12 | O11: 1-1/4" | P11: 1.25 | Q11: 7 | S11: 22 | AD11: 20 | AE11: 3.142
A12: HA320X180X6X12 | B12: 320 | C12: 180 | D12: 6 | E12: 12 | O12: 1-3/8" | P12: 1.375 | Q12: 6 | S12: 25 | AD12: 22 | AE12: 3.801
A13: HA340X180X6X12 | B13: 340 | C13: 180 | D13: 6 | E13: 12 | O13: 1-1/2" | P13: 1.5 | Q13: 6 | S13: 28 | AD13: 25 | AE13: 4.909
A14: HA360X180X6X12 | B14: 360 | C14: 180 | D14: 6 | E14: 12 | O14: 1-3/4" | P14: 1.75 | Q14: 5 | S14: 30
A15: HA380X200X8X15 | B15: 380 | C15: 200 | D15: 8 | E15: 15 | O15: 2" | P15: 2 | Q15: 4.5 | S15: 32
A16: HA400X200X8X15 | B16: 400 | C16: 200 | D16: 8 | E16: 15 | S16: 35
A17: HA420X210X8X15 | B17: 420 | C17: 210 | D17: 8 | E17: 15 | S17: 38
A18: HA440X220X8X15 | B18: 440 | C18: 220 | D18: 8 | E18: 15 | S18: 40
A19: HA460X230X8X15 | B19: 460 | C19: 230 | D19: 8 | E19: 15 | S19: 45
A20: HA480X240X8X15 | B20: 480 | C20: 240 | D20: 8 | E20: 15 | S20: 50
A21: HA500X250X10X15 | B21: 500 | C21: 250 | D21: 10 | E21: 15 | S21: 55
A22: HA520X260X10X15 | B22: 520 | C22: 260 | D22: 10 | E22: 15 | S22: 60
A23: HA540X270X10X15 | B23: 540 | C23: 270 | D23: 10 | E23: 15 | S23: 65
A24: W8X31 | B24: 203 | C24: 203 | D24: 7.2 | E24: 11 | S24: 70
A25: W10X33 | B25: 247 | C25: 202 | D25: 7.4 | E25: 11 | S25: 75
A26: W10X49 | B26: 254 | C26: 254 | D26: 8.6 | E26: 14.2 | S26: 80
A27: W12X40 | B27: 303 | C27: 203 | D27: 7.5 | E27: 13.1
A28: W12X53 | B28: 306 | C28: 254 | D28: 8.8 | E28: 14.6
A29: W12X65 | B29: 308 | C29: 305 | D29: 9.9 | E29: 15.4
A30: W14X48 | B30: 351 | C30: 204 | D30: 8.6 | E30: 15.1
A31: W14X68 | B31: 357 | C31: 255 | D31: 10.5 | E31: 18.3
A32: W14X90 | B32: 356 | C32: 368 | D32: 11.2 | E32: 18
A33: W16X57 | B33: 417 | C33: 181 | D33: 10.9 | E33: 18.2
A34: W18X60 | B34: 455 | C34: 191 | D34: 11.4 | E34: 17.3
A35: W24X76 | B35: 608 | C35: 228 | D35: 11.2 | E35: 17.3
A40: Conversión: 1 ksi = 70.307 kgf/cm². futa F1554: Gr36 58 ksi, Gr55 75 ksi, Gr105 125 ksi (ASTM F1554). Ase = 0.7854·(da − 0.9743/nt)² [in²]; Abrg tuerca hex. pesada = 0.866·(1.5da+1/8)² − π·da²/4 [in²].

Sheet DIBUJO
A1: Coordenadas para las vistas de la hoja DISEÑO (normalizadas a ±1). No editar.
D2: Pedestal | G2: Placa | J2: Columna | M2: Pernos tracción | P2: Pernos compresión | S2: Pedestal | V2: Grout | Y2: Placa | AB2: Columna | AE2: Ala izq. | AH2: Ala der. | AK2: Perno T | AN2: Perno C | AQ2: Tuercas
A3: Escala planta S | B3: =MAX(ped_Np,ped_Bp,p_N,p_B)/2*1.08 -> 48.6 | D3: x | E3: y | G3: x | H3: y | J3: x | K3: y | M3: x | N3: y | P3: x | Q3: y | S3: x | T3: y | V3: x | W3: y | Y3: x | Z3: y | AB3: x | AC3: y | AE3: x | AF3: y | AH3: x | AI3: y | AK3: x | AL3: y | AN3: x | AO3: y | AQ3: x | AR3: y
A4: z mín | B4: =-(g_hef+10) -> -60 | D4: =(-ped_Np/2)/dS -> -0.92592593 | E4: =(-ped_Bp/2)/dS -> -0.82304527 | G4: =(-p_N/2)/dS -> -0.61728395 | H4: =(-p_B/2)/dS -> -0.41152263 | J4: =(-c_d/2)/dS -> -0.37037037 | K4: =(-c_bf/2)/dS -> -0.18518519 | M4: =(-g_f)/dS -> -0.51440329 | N4: =(IF(1<=a_nf,-g_xb+(1-1)*2*g_xb/MAX(a_nf-1,1),-g_xb))/dS -> -0.30864198 | P4: =(g_f)/dS -> 0.51440329 | Q4: =(IF(1<=a_nf,-g_xb+(1-1)*2*g_xb/MAX(a_nf-1,1),-g_xb))/dS -> -0.30864198 | S4: =(-ped_Np/2)/dSe -> -0.92592593 | T4: =((dzmin)-dzc)/dSe -> -0.90123457 | V4: =(-p_N/2-p_g)/dSe -> -0.66872428 | W4: =((0)-dzc)/dSe -> 0.33333333 | Y4: =(-p_N/2)/dSe -> -0.61728395 | Z4: =((p_g)-dzc)/dSe -> 0.38477366 | AB4: =(-c_d/2)/dSe -> -0.37037037 | AC4: =((dzmax)-dzc)/dSe -> 0.90123457 | AE4: =(-c_d/2+c_tf)/dSe -> -0.34567901 | AF4: =(((p_g+p_tp))-dzc)/dSe -> 0.45679012 | AH4: =(c_d/2-c_tf)/dSe -> 0.34567901 | AI4: =(((p_g+p_tp))-dzc)/dSe -> 0.45679012 | AK4: =(-g_f)/dSe -> -0.51440329 | AL4: =(((p_g+p_tp)+4)-dzc)/dSe -> 0.53909465 | AN4: =(g_f)/dSe -> 0.51440329 | AO4: =(((p_g+p_tp)+4)-dzc)/dSe -> 0.53909465 | AQ4: =(-g_f)/dSe -> -0.51440329 | AR4: =((-g_hef)-dzc)/dSe -> -0.69547325
A5: z máx | B5: =p_g+p_tp+MAX(0.6*c_d,15) -> 27.6 | D5: =(-ped_Np/2)/dS -> -0.92592593 | E5: =(ped_Bp/2)/dS -> 0.82304527 | G5: =(-p_N/2)/dS -> -0.61728395 | H5: =(p_B/2)/dS -> 0.41152263 | J5: =(-c_d/2)/dS -> -0.37037037 | K5: =(c_bf/2)/dS -> 0.18518519 | M5: =(-g_f)/dS -> -0.51440329 | N5: =(IF(2<=a_nf,-g_xb+(2-1)*2*g_xb/MAX(a_nf-1,1),-g_xb))/dS -> 0.30864198 | P5: =(g_f)/dS -> 0.51440329 | Q5: =(IF(2<=a_nf,-g_xb+(2-1)*2*g_xb/MAX(a_nf-1,1),-g_xb))/dS -> 0.30864198 | S5: =(-ped_Np/2)/dSe -> -0.92592593 | T5: =((0)-dzc)/dSe -> 0.33333333 | V5: =(-p_N/2)/dSe -> -0.61728395 | W5: =((p_g)-dzc)/dSe -> 0.38477366 | Y5: =(-p_N/2)/dSe -> -0.61728395 | Z5: =(((p_g+p_tp))-dzc)/dSe -> 0.45679012 | AB5: =(-c_d/2)/dSe -> -0.37037037 | AC5: =(((p_g+p_tp))-dzc)/dSe -> 0.45679012 | AE5: =(-c_d/2+c_tf)/dSe -> -0.34567901 | AF5: =((dzmax)-dzc)/dSe -> 0.90123457 | AH5: =(c_d/2-c_tf)/dSe -> 0.34567901 | AI5: =((dzmax)-dzc)/dSe -> 0.90123457 | AK5: =(-g_f)/dSe -> -0.51440329 | AL5: =((-g_hef)-dzc)/dSe -> -0.69547325 | AN5: =(g_f)/dSe -> 0.51440329 | AO5: =((-g_hef)-dzc)/dSe -> -0.69547325 | AQ5: =(g_f)/dSe -> 0.51440329 | AR5: =((-g_hef)-dzc)/dSe -> -0.69547325
A6: Escala elevación | B6: =MAX(ped_Np,p_N+2*p_g,dzmax-dzmin)/2*1.08 -> 48.6 | D6: =(ped_Np/2)/dS -> 0.92592593 | E6: =(ped_Bp/2)/dS -> 0.82304527 | G6: =(p_N/2)/dS -> 0.61728395 | H6: =(p_B/2)/dS -> 0.41152263 | J6: =(-c_d/2+c_tf)/dS -> -0.34567901 | K6: =(c_bf/2)/dS -> 0.18518519 | M6: =(-g_f)/dS -> -0.51440329 | N6: =(IF(3<=a_nf,-g_xb+(3-1)*2*g_xb/MAX(a_nf-1,1),-g_xb))/dS -> -0.30864198 | P6: =(g_f)/dS -> 0.51440329 | Q6: =(IF(3<=a_nf,-g_xb+(3-1)*2*g_xb/MAX(a_nf-1,1),-g_xb))/dS -> -0.30864198 | S6: =(ped_Np/2)/dSe -> 0.92592593 | T6: =((0)-dzc)/dSe -> 0.33333333 | V6: =(p_N/2)/dSe -> 0.61728395 | W6: =((p_g)-dzc)/dSe -> 0.38477366 | Y6: =(p_N/2)/dSe -> 0.61728395 | Z6: =(((p_g+p_tp))-dzc)/dSe -> 0.45679012 | AB6: =(c_d/2)/dSe -> 0.37037037 | AC6: =(((p_g+p_tp))-dzc)/dSe -> 0.45679012 | AQ6: =(-g_f)/dSe -> -0.51440329 | AR6: =(((p_g+p_tp)+1)-dzc)/dSe -> 0.47736626
A7: z centro | B7: =(dzmax+dzmin)/2 -> -16.2 | D7: =(ped_Np/2)/dS -> 0.92592593 | E7: =(-ped_Bp/2)/dS -> -0.82304527 | G7: =(p_N/2)/dS -> 0.61728395 | H7: =(-p_B/2)/dS -> -0.41152263 | J7: =(-c_d/2+c_tf)/dS -> -0.34567901 | K7: =(c_tw/2)/dS -> 0.0061728395 | M7: =(-g_f)/dS -> -0.51440329 | N7: =(IF(4<=a_nf,-g_xb+(4-1)*2*g_xb/MAX(a_nf-1,1),-g_xb))/dS -> -0.30864198 | P7: =(g_f)/dS -> 0.51440329 | Q7: =(IF(4<=a_nf,-g_xb+(4-1)*2*g_xb/MAX(a_nf-1,1),-g_xb))/dS -> -0.30864198 | S7: =(ped_Np/2)/dSe -> 0.92592593 | T7: =((dzmin)-dzc)/dSe -> -0.90123457 | V7: =(p_N/2+p_g)/dSe -> 0.66872428 | W7: =((0)-dzc)/dSe -> 0.33333333 | Y7: =(p_N/2)/dSe -> 0.61728395 | Z7: =((p_g)-dzc)/dSe -> 0.38477366 | AB7: =(c_d/2)/dSe -> 0.37037037 | AC7: =((dzmax)-dzc)/dSe -> 0.90123457 | AQ7: =(g_f)/dSe -> 0.51440329 | AR7: =(((p_g+p_tp)+1)-dzc)/dSe -> 0.47736626
D8: =(-ped_Np/2)/dS -> -0.92592593 | E8: =(-ped_Bp/2)/dS -> -0.82304527 | G8: =(-p_N/2)/dS -> -0.61728395 | H8: =(-p_B/2)/dS -> -0.41152263 | J8: =(c_d/2-c_tf)/dS -> 0.34567901 | K8: =(c_tw/2)/dS -> 0.0061728395 | Y8: =(-p_N/2)/dSe -> -0.61728395 | Z8: =((p_g)-dzc)/dSe -> 0.38477366
J9: =(c_d/2-c_tf)/dS -> 0.34567901 | K9: =(c_bf/2)/dS -> 0.18518519
J10: =(c_d/2)/dS -> 0.37037037 | K10: =(c_bf/2)/dS -> 0.18518519
J11: =(c_d/2)/dS -> 0.37037037 | K11: =(-c_bf/2)/dS -> -0.18518519
J12: =(c_d/2-c_tf)/dS -> 0.34567901 | K12: =(-c_bf/2)/dS -> -0.18518519
J13: =(c_d/2-c_tf)/dS -> 0.34567901 | K13: =(-c_tw/2)/dS -> -0.0061728395
J14: =(-c_d/2+c_tf)/dS -> -0.34567901 | K14: =(-c_tw/2)/dS -> -0.0061728395
J15: =(-c_d/2+c_tf)/dS -> -0.34567901 | K15: =(-c_bf/2)/dS -> -0.18518519
J16: =(-c_d/2)/dS -> -0.37037037 | K16: =(-c_bf/2)/dS -> -0.18518519
