Workbook

Sheet DISEÑO
B2: GALPÓN — CONEXIÓN DE RODILLA Y CUMBRERA CON PLACA EXTREMA
B3: AISC Design Guide 16 y Design Guide 4 (placa gruesa) · AISC 358-16 Tabla 6.2/6.5 (4E) · AISC 360-16 (J2, J3, J4, J10) · LRFD · Unidades: Tonf, Tonf·m, mm, kgf/cm²
B4: Celdas de ingreso: | C4: valor | D4: Calculado: | E4: valor | G4: Estados: VERDE ≤ límite · AMARILLO entre límite y 1.00 · ROJO > 1.00 (ratio = demanda / capacidad, o requerido / provisto)
B6: DATOS GENERALES | G6: VISTA FRONTAL (●rojo sup. · ●verde inf.) | J6: ELEVACIÓN LATERAL | N6: VERIFICACIONES — combinación gobernante por chequeo
B7: Proyecto | C7: Galpón KUBIEC — ejemplo | N7: =IF(COUNT(S12:S44)=0,"SIN CARGAS",IF(MAX(S12:S44)>1,"✖ NO CUMPLE — ratio máx. "&TEXT(MAX(S12:S44),"0.00"),IF(MAX(S12:S44)>lim_verde,"▲ CUMPLE AL LÍMITE — ratio máx. "&TEXT(MAX(S12:S44),"0.00"),"✔ CUMPLE — ratio máx. "&TEXT(MAX(S12:S44),"0.00")))) -> ✔ CUMPLE — ratio máx. 0.90
B8: Elemento / nudo | C8: Pórtico tipo, eje 3
B9: Límite verde / amarillo (ratio) | C9: 0.9
B10: CONEXIÓN | N10: Verificación | O10: Referencia | P10: Demanda | Q10: Capacidad | R10: Unidad | S10: Ratio | T10: Estado | U10: Combo
B11: Tipo | C11: Rodilla (placa al ala de columna) | N11: PLACA EXTREMA Y PERNOS
B12: Configuración lado superior | C12: Extendida — 1+1 (4E) | N12: Pernos a tracción (sin efecto palanca) | O12: DG16 / DG4 | P12: =INDEX(CALCULO!$D$103:$M$103,MATCH(MAX(CALCULO!$D$107:$M$107),CALCULO!$D$107:$M$107,0))/100000 -> 16.336961 | Q12: =INDEX(CALCULO!$D$106:$M$106,MATCH(MAX(CALCULO!$D$107:$M$107),CALCULO!$D$107:$M$107,0))/1 -> 43.973093 | R12: Tonf·m | S12: =MAX(CALCULO!$D$107:$M$107) -> 0.37152176 | T12: =IF(ISNUMBER(S12),IF(S12>1,"NO CUMPLE",IF(S12>lim_verde,"AL LÍMITE","CUMPLE")),"N/A") -> CUMPLE | U12: =IF(ISNUMBER(S12),INDEX(CALCULO!$D$95:$M$95,MATCH(MAX(CALCULO!$D$107:$M$107),CALCULO!$D$107:$M$107,0)),"—") -> 1.2D+1.6Lr
B13: Configuración lado inferior | C13: Al ras — 1 fila (2 pernos) | N13: Flexión de placa (placa gruesa, γr) | O13: DG16 / DG4 · Yp | P13: =INDEX(CALCULO!$D$108:$M$108,MATCH(MAX(CALCULO!$D$110:$M$110),CALCULO!$D$110:$M$110,0))/1 -> 48.810133 | Q13: =INDEX(CALCULO!$D$109:$M$109,MATCH(MAX(CALCULO!$D$110:$M$110),CALCULO!$D$110:$M$110,0))/1 -> 84.801409 | R13: Tonf·m | S13: =MAX(CALCULO!$D$110:$M$110) -> 0.57558163 | T13: =IF(ISNUMBER(S13),IF(S13>1,"NO CUMPLE",IF(S13>lim_verde,"AL LÍMITE","CUMPLE")),"N/A") -> CUMPLE | U13: =IF(ISNUMBER(S13),INDEX(CALCULO!$D$95:$M$95,MATCH(MAX(CALCULO!$D$110:$M$110),CALCULO!$D$110:$M$110,0)),"—") -> 1.2D+1.6Lr
B14: Pendiente de la viga θ | C14: 10 | D14: ° | N14: Extensión — fluencia por corte | O14: DG4 · J4.2(a) | P14: =IF(AND(cfg_u<>"Extendida — 1+1 (4E)",cfg_d<>"Extendida — 1+1 (4E)"),"—",INDEX(CALCULO!$D$104:$M$104,MATCH(MAX(CALCULO!$D$113:$M$113),CALCULO!$D$113:$M$113,0))/2000) -> 13.680923 | Q14: =IF(AND(cfg_u<>"Extendida — 1+1 (4E)",cfg_d<>"Extendida — 1+1 (4E)"),"—",r_Rsy/1000) -> 105.45 | R14: Tonf | S14: =IF(AND(cfg_u<>"Extendida — 1+1 (4E)",cfg_d<>"Extendida — 1+1 (4E)"),"N/A",MAX(CALCULO!$D$113:$M$113)) -> 0.12973848 | T14: =IF(ISNUMBER(S14),IF(S14>1,"NO CUMPLE",IF(S14>lim_verde,"AL LÍMITE","CUMPLE")),"N/A") -> CUMPLE | U14: =IF(ISNUMBER(S14),INDEX(CALCULO!$D$95:$M$95,MATCH(MAX(CALCULO!$D$113:$M$113),CALCULO!$D$113:$M$113,0)),"—") -> 1.2D+1.6Lr
B15: Soldadura ala – placa | C15: Filete (ambos lados) | N15: Extensión — ruptura por corte | O15: DG4 · J4.2(b) | P15: =IF(AND(cfg_u<>"Extendida — 1+1 (4E)",cfg_d<>"Extendida — 1+1 (4E)"),"—",INDEX(CALCULO!$D$104:$M$104,MATCH(MAX(CALCULO!$D$114:$M$114),CALCULO!$D$114:$M$114,0))/2000) -> 13.680923 | Q15: =IF(AND(cfg_u<>"Extendida — 1+1 (4E)",cfg_d<>"Extendida — 1+1 (4E)"),"—",r_Rsr/1000) -> 76.70745 | R15: Tonf | S15: =IF(AND(cfg_u<>"Extendida — 1+1 (4E)",cfg_d<>"Extendida — 1+1 (4E)"),"N/A",MAX(CALCULO!$D$114:$M$114)) -> 0.17835195 | T15: =IF(ISNUMBER(S15),IF(S15>1,"NO CUMPLE",IF(S15>lim_verde,"AL LÍMITE","CUMPLE")),"N/A") -> CUMPLE | U15: =IF(ISNUMBER(S15),INDEX(CALCULO!$D$95:$M$95,MATCH(MAX(CALCULO!$D$114:$M$114),CALCULO!$D$114:$M$114,0)),"—") -> 1.2D+1.6Lr
B16: 1. VIGA (RAFTER) | N16: Corte en pernos (lado en compresión) | O16: J3.6 | P16: =INDEX(CALCULO!$D$102:$M$102,MATCH(MAX(CALCULO!$D$116:$M$116),CALCULO!$D$116:$M$116,0))/1000 -> 7.0958431 | Q16: =INDEX(CALCULO!$D$115:$M$115,MATCH(MAX(CALCULO!$D$116:$M$116),CALCULO!$D$116:$M$116,0))/1 -> 22.095573 | R16: Tonf | S16: =MAX(CALCULO!$D$116:$M$116) -> 0.3211432 | T16: =IF(ISNUMBER(S16),IF(S16>1,"NO CUMPLE",IF(S16>lim_verde,"AL LÍMITE","CUMPLE")),"N/A") -> CUMPLE | U16: =IF(ISNUMBER(S16),INDEX(CALCULO!$D$95:$M$95,MATCH(MAX(CALCULO!$D$116:$M$116),CALCULO!$D$116:$M$116,0)),"—") -> 1.2D+1.6Lr
B17: Perfil (catálogo o ARMADO) | C17: VK400X180X6X12 | E17: Armado (mm) | N17: Aplastamiento / desgarre — placa | O17: J3.10 | P17: =INDEX(CALCULO!$D$102:$M$102,MATCH(MAX(CALCULO!$D$118:$M$118),CALCULO!$D$118:$M$118,0))/1000 -> 7.0958431 | Q17: =INDEX(CALCULO!$D$117:$M$117,MATCH(MAX(CALCULO!$D$118:$M$118),CALCULO!$D$118:$M$118,0))/1 -> 91.411425 | R17: Tonf | S17: =MAX(CALCULO!$D$118:$M$118) -> 0.077625342 | T17: =IF(ISNUMBER(S17),IF(S17>1,"NO CUMPLE",IF(S17>lim_verde,"AL LÍMITE","CUMPLE")),"N/A") -> CUMPLE | U17: =IF(ISNUMBER(S17),INDEX(CALCULO!$D$95:$M$95,MATCH(MAX(CALCULO!$D$118:$M$118),CALCULO!$D$118:$M$118,0)),"—") -> 1.2D+1.6Lr
B18: Peralte d | C18: =IF(vg_perfil="ARMADO (flejes soldados)",E18,INDEX(CATALOGOS!$B$5:$B$40,MATCH(vg_perfil,CATALOGOS!$A$5:$A$40,0))) -> 400 | D18: mm | E18: 400 | N18: Aplastamiento — ala de columna / placa gemela | O18: J3.10 | P18: =INDEX(CALCULO!$D$102:$M$102,MATCH(MAX(CALCULO!$D$120:$M$120),CALCULO!$D$120:$M$120,0))/1000 -> 7.0958431 | Q18: =INDEX(CALCULO!$D$119:$M$119,MATCH(MAX(CALCULO!$D$120:$M$120),CALCULO!$D$120:$M$120,0))/1 -> 54.846855 | R18: Tonf | S18: =MAX(CALCULO!$D$120:$M$120) -> 0.12937557 | T18: =IF(ISNUMBER(S18),IF(S18>1,"NO CUMPLE",IF(S18>lim_verde,"AL LÍMITE","CUMPLE")),"N/A") -> CUMPLE | U18: =IF(ISNUMBER(S18),INDEX(CALCULO!$D$95:$M$95,MATCH(MAX(CALCULO!$D$120:$M$120),CALCULO!$D$120:$M$120,0)),"—") -> 1.2D+1.6Lr
B19: Ancho de ala bf | C19: =IF(vg_perfil="ARMADO (flejes soldados)",E19,INDEX(CATALOGOS!$C$5:$C$40,MATCH(vg_perfil,CATALOGOS!$A$5:$A$40,0))) -> 180 | D19: mm | E19: 180 | N19: SOLDADURAS VIGA – PLACA
B20: Espesor de alma tw | C20: =IF(vg_perfil="ARMADO (flejes soldados)",E20,INDEX(CATALOGOS!$D$5:$D$40,MATCH(vg_perfil,CATALOGOS!$A$5:$A$40,0))) -> 6 | D20: mm | E20: 6 | J20: =IF(t_rod=1,"Rodilla: columna a la izquierda","Cumbrera: dos placas gemelas") -> Rodilla: columna a la izquierda | N20: Ala – placa (filete o CJP) | O20: J2.4 / J2.1 | P20: =INDEX(CALCULO!$D$104:$M$104,MATCH(MAX(CALCULO!$D$121:$M$121),CALCULO!$D$121:$M$121,0))/1000 -> 27.361846 | Q20: =r_Rwf/1000 -> 83.117324 | R20: Tonf | S20: =MAX(CALCULO!$D$121:$M$121) -> 0.32919547 | T20: =IF(ISNUMBER(S20),IF(S20>1,"NO CUMPLE",IF(S20>lim_verde,"AL LÍMITE","CUMPLE")),"N/A") -> CUMPLE | U20: =IF(ISNUMBER(S20),INDEX(CALCULO!$D$95:$M$95,MATCH(MAX(CALCULO!$D$121:$M$121),CALCULO!$D$121:$M$121,0)),"—") -> 1.2D+1.6Lr
B21: Espesor de ala tf | C21: =IF(vg_perfil="ARMADO (flejes soldados)",E21,INDEX(CATALOGOS!$E$5:$E$40,MATCH(vg_perfil,CATALOGOS!$A$5:$A$40,0))) -> 12 | D21: mm | E21: 12 | G21: SOLICITACIONES EN LA CARA DE LA PLACA (LRFD) | N21: Alma – zona de tracción (desarrollar Fy) | O21: DG16 / DG4 | P21: =r_wtD -> 1898.1 | Q21: =r_wtC -> 2817.5364 | R21: kgf/cm | S21: =MAX(CALCULO!$D$122:$M$122) -> 0.67367364 | T21: =IF(ISNUMBER(S21),IF(S21>1,"NO CUMPLE",IF(S21>lim_verde,"AL LÍMITE","CUMPLE")),"N/A") -> CUMPLE | U21: =IF(ISNUMBER(S21),INDEX(CALCULO!$D$95:$M$95,MATCH(MAX(CALCULO!$D$122:$M$122),CALCULO!$D$122:$M$122,0)),"—") -> 1.2D+1.6Lr
B22: Acero | C22: A572 Gr50 | G22: Combinación | H22: Mu (Tonf·m) (−) tracc. arriba | I22: Vu (Tonf) | J22: Pu (Tonf) (+) tracción | K22: Lado en tracción | L22: Ratio máx. | N22: Alma – corte | O22: J2.4 | P22: =INDEX(CALCULO!$D$102:$M$102,MATCH(MAX(CALCULO!$D$123:$M$123),CALCULO!$D$123:$M$123,0))/1000 -> 7.0958431 | Q22: =r_Rwv/1000 -> 54.931228 | R22: Tonf | S22: =MAX(CALCULO!$D$123:$M$123) -> 0.12917685 | T22: =IF(ISNUMBER(S22),IF(S22>1,"NO CUMPLE",IF(S22>lim_verde,"AL LÍMITE","CUMPLE")),"N/A") -> CUMPLE | U22: =IF(ISNUMBER(S22),INDEX(CALCULO!$D$95:$M$95,MATCH(MAX(CALCULO!$D$123:$M$123),CALCULO!$D$123:$M$123,0)),"—") -> 1.2D+1.6Lr
B23: Fy / Fu | C23: =INDEX(CATALOGOS!$N$5:$N$10,MATCH(vg_acero,CATALOGOS!$M$5:$M$10,0)) -> 3515 | D23: kgf/cm² | E23: =INDEX(CATALOGOS!$O$5:$O$10,MATCH(vg_acero,CATALOGOS!$M$5:$M$10,0)) -> 4570 | G23: 1.2D+1.6Lr | H23: -16 | I23: 6.5 | J23: -4 | K23: =IF(INDEX(CALCULO!$D$99:$M$99,1)=1,IF(INDEX(CALCULO!$D$100:$M$100,1)=1,"superior","inferior"),"—") -> superior | L23: =IF(INDEX(CALCULO!$D$99:$M$99,1)=1,INDEX(CALCULO!$D$134:$M$134,1),"—") -> 0.8942995 | N23: COLUMNA (solo rodilla)
B24: Peralte con cartela en la placa (0 = sin) | C24: 600 | D24: mm | G24: 1.2D+0.5Lr+1.0W | H24: -8 | I24: 3.5 | J24: -2 | K24: =IF(INDEX(CALCULO!$D$99:$M$99,2)=1,IF(INDEX(CALCULO!$D$100:$M$100,2)=1,"superior","inferior"),"—") -> superior | L24: =IF(INDEX(CALCULO!$D$99:$M$99,2)=1,INDEX(CALCULO!$D$134:$M$134,2),"—") -> 0.8942995 | N24: Flexión del ala de columna | O24: 4E: Tabla 6.5/6.6 · al ras: J10.1 | P24: =IF(OR(t_rod=0,AND(cp_usar="Sí",cfg_u<>"Extendida — 1+1 (4E)",cfg_d<>"Extendida — 1+1 (4E)")),"—",INDEX(CALCULO!$D$124:$M$124,MATCH(MAX(CALCULO!$D$126:$M$126),CALCULO!$D$126:$M$126,0))/1) -> 48.810133 | Q24: =IF(OR(t_rod=0,AND(cp_usar="Sí",cfg_u<>"Extendida — 1+1 (4E)",cfg_d<>"Extendida — 1+1 (4E)")),"—",INDEX(CALCULO!$D$125:$M$125,MATCH(MAX(CALCULO!$D$126:$M$126),CALCULO!$D$126:$M$126,0))/1) -> 54.57918 | R24: T·m | T | S24: =IF(OR(t_rod=0,AND(cp_usar="Sí",cfg_u<>"Extendida — 1+1 (4E)",cfg_d<>"Extendida — 1+1 (4E)")),"N/A",MAX(CALCULO!$D$126:$M$126)) -> 0.8942995 | T24: =IF(ISNUMBER(S24),IF(S24>1,"NO CUMPLE",IF(S24>lim_verde,"AL LÍMITE","CUMPLE")),"N/A") -> CUMPLE | U24: =IF(ISNUMBER(S24),INDEX(CALCULO!$D$95:$M$95,MATCH(MAX(CALCULO!$D$126:$M$126),CALCULO!$D$126:$M$126,0)),"—") -> 1.2D+1.6Lr
B25: Largo de la cartela (dibujo) | C25: 1500 | D25: mm | G25: 0.9D+1.0W (succión) | H25: 6.5 | I25: -2.8 | J25: 1.5 | K25: =IF(INDEX(CALCULO!$D$99:$M$99,3)=1,IF(INDEX(CALCULO!$D$100:$M$100,3)=1,"superior","inferior"),"—") -> inferior | L25: =IF(INDEX(CALCULO!$D$99:$M$99,3)=1,INDEX(CALCULO!$D$134:$M$134,3),"—") -> 0.67367364 | N25: Fluencia local del alma | O25: J10.2 | P25: =IF(OR(t_rod=0,cp_usar="Sí"),"—",INDEX(CALCULO!$D$104:$M$104,MATCH(MAX(CALCULO!$D$129:$M$129),CALCULO!$D$129:$M$129,0))/1000) -> — | Q25: =IF(OR(t_rod=0,cp_usar="Sí"),"—",INDEX(CALCULO!$D$127:$M$127,MATCH(MAX(CALCULO!$D$129:$M$129),CALCULO!$D$129:$M$129,0))/1) -> — | R25: Tonf | S25: =IF(OR(t_rod=0,cp_usar="Sí"),"N/A",MAX(CALCULO!$D$129:$M$129)) -> N/A | T25: =IF(ISNUMBER(S25),IF(S25>1,"NO CUMPLE",IF(S25>lim_verde,"AL LÍMITE","CUMPLE")),"N/A") -> N/A | U25: =IF(ISNUMBER(S25),INDEX(CALCULO!$D$95:$M$95,MATCH(MAX(CALCULO!$D$129:$M$129),CALCULO!$D$129:$M$129,0)),"—") -> —
B26: 2. COLUMNA (solo rodilla) | G26: 1.2D+1.0E+Lr | H26: -13 | I26: 5.5 | J26: -3.5 | K26: =IF(INDEX(CALCULO!$D$99:$M$99,4)=1,IF(INDEX(CALCULO!$D$100:$M$100,4)=1,"superior","inferior"),"—") -> superior | L26: =IF(INDEX(CALCULO!$D$99:$M$99,4)=1,INDEX(CALCULO!$D$134:$M$134,4),"—") -> 0.8942995 | N26: Aplastamiento del alma (crippling) | O26: J10.3 | P26: =IF(OR(t_rod=0,cp_usar="Sí"),"—",INDEX(CALCULO!$D$104:$M$104,MATCH(MAX(CALCULO!$D$130:$M$130),CALCULO!$D$130:$M$130,0))/1000) -> — | Q26: =IF(OR(t_rod=0,cp_usar="Sí"),"—",INDEX(CALCULO!$D$128:$M$128,MATCH(MAX(CALCULO!$D$130:$M$130),CALCULO!$D$130:$M$130,0))/1) -> — | R26: Tonf | S26: =IF(OR(t_rod=0,cp_usar="Sí"),"N/A",MAX(CALCULO!$D$130:$M$130)) -> N/A | T26: =IF(ISNUMBER(S26),IF(S26>1,"NO CUMPLE",IF(S26>lim_verde,"AL LÍMITE","CUMPLE")),"N/A") -> N/A | U26: =IF(ISNUMBER(S26),INDEX(CALCULO!$D$95:$M$95,MATCH(MAX(CALCULO!$D$130:$M$130),CALCULO!$D$130:$M$130,0)),"—") -> —
B27: Perfil (catálogo o ARMADO) | C27: HA500X250X10X15 | E27: Armado (mm) | G27: C5 | K27: =IF(INDEX(CALCULO!$D$99:$M$99,5)=1,IF(INDEX(CALCULO!$D$100:$M$100,5)=1,"superior","inferior"),"—") -> — | L27: =IF(INDEX(CALCULO!$D$99:$M$99,5)=1,INDEX(CALCULO!$D$134:$M$134,5),"—") -> — | N27: Rigidizadores de continuidad | O27: J10.8 | P27: =IF(OR(t_rod=0,cp_usar="No"),"—",INDEX(CALCULO!$D$131:$M$131,MATCH(MAX(CALCULO!$D$132:$M$132),CALCULO!$D$132:$M$132,0))/1000) -> 0 | Q27: =IF(OR(t_rod=0,cp_usar="No"),"—",r_Rcp/1000) -> 83.5164 | R27: Tonf | S27: =IF(OR(t_rod=0,cp_usar="No"),"N/A",MAX(CALCULO!$D$132:$M$132)) -> 0 | T27: =IF(ISNUMBER(S27),IF(S27>1,"NO CUMPLE",IF(S27>lim_verde,"AL LÍMITE","CUMPLE")),"N/A") -> CUMPLE | U27: =IF(ISNUMBER(S27),INDEX(CALCULO!$D$95:$M$95,MATCH(MAX(CALCULO!$D$132:$M$132),CALCULO!$D$132:$M$132,0)),"—") -> 1.2D+1.6Lr
B28: Peralte d | C28: =IF(co_perfil="ARMADO (flejes soldados)",E28,INDEX(CATALOGOS!$H$5:$H$40,MATCH(co_perfil,CATALOGOS!$G$5:$G$40,0))) -> 500 | D28: mm | E28: 500 | G28: C6 | K28: =IF(INDEX(CALCULO!$D$99:$M$99,6)=1,IF(INDEX(CALCULO!$D$100:$M$100,6)=1,"superior","inferior"),"—") -> — | L28: =IF(INDEX(CALCULO!$D$99:$M$99,6)=1,INDEX(CALCULO!$D$134:$M$134,6),"—") -> — | N28: Zona de panel (corte) | O28: J10.6(a) | P28: =IF(t_rod=0,"—",INDEX(CALCULO!$D$104:$M$104,MATCH(MAX(CALCULO!$D$133:$M$133),CALCULO!$D$133:$M$133,0))/1000) -> 27.361846 | Q28: =IF(t_rod=0,"—",r_Rpz/1000) -> 94.905 | R28: Tonf | S28: =IF(t_rod=0,"N/A",MAX(CALCULO!$D$133:$M$133)) -> 0.28830774 | T28: =IF(ISNUMBER(S28),IF(S28>1,"NO CUMPLE",IF(S28>lim_verde,"AL LÍMITE","CUMPLE")),"N/A") -> CUMPLE | U28: =IF(ISNUMBER(S28),INDEX(CALCULO!$D$95:$M$95,MATCH(MAX(CALCULO!$D$133:$M$133),CALCULO!$D$133:$M$133,0)),"—") -> 1.2D+1.6Lr
B29: Ancho de ala bf | C29: =IF(co_perfil="ARMADO (flejes soldados)",E29,INDEX(CATALOGOS!$I$5:$I$40,MATCH(co_perfil,CATALOGOS!$G$5:$G$40,0))) -> 250 | D29: mm | E29: 250 | G29: C7 | K29: =IF(INDEX(CALCULO!$D$99:$M$99,7)=1,IF(INDEX(CALCULO!$D$100:$M$100,7)=1,"superior","inferior"),"—") -> — | L29: =IF(INDEX(CALCULO!$D$99:$M$99,7)=1,INDEX(CALCULO!$D$134:$M$134,7),"—") -> — | N29: GEOMETRÍA Y DETALLES (requerido / provisto)
B30: Espesor de alma tw | C30: =IF(co_perfil="ARMADO (flejes soldados)",E30,INDEX(CATALOGOS!$J$5:$J$40,MATCH(co_perfil,CATALOGOS!$G$5:$G$40,0))) -> 10 | D30: mm | E30: 10 | G30: C8 | K30: =IF(INDEX(CALCULO!$D$99:$M$99,8)=1,IF(INDEX(CALCULO!$D$100:$M$100,8)=1,"superior","inferior"),"—") -> — | L30: =IF(INDEX(CALCULO!$D$99:$M$99,8)=1,INDEX(CALCULO!$D$134:$M$134,8),"—") -> — | N30: Ancho de placa bp ≥ bf | O30: DG4 / DG16 | P30: =b_bf -> 18 | Q30: =p_bp -> 20 | R30: cm | S30: =(b_bf)/MAX(p_bp,0.000000001) -> 0.9 | T30: =IF(ISNUMBER(S30),IF(S30>1,"NO CUMPLE",IF(S30>lim_verde,"AL LÍMITE","CUMPLE")),"N/A") -> CUMPLE | U30: —
B31: Espesor de ala tf | C31: =IF(co_perfil="ARMADO (flejes soldados)",E31,INDEX(CATALOGOS!$K$5:$K$40,MATCH(co_perfil,CATALOGOS!$G$5:$G$40,0))) -> 15 | D31: mm | E31: 15 | G31: C9 | K31: =IF(INDEX(CALCULO!$D$99:$M$99,9)=1,IF(INDEX(CALCULO!$D$100:$M$100,9)=1,"superior","inferior"),"—") -> — | L31: =IF(INDEX(CALCULO!$D$99:$M$99,9)=1,INDEX(CALCULO!$D$134:$M$134,9),"—") -> — | N31: Holgura de llave pfi ≥ db + 12.7 mm | O31: DG16 | P31: =a_db+1.27 -> 3.4925 | Q31: =p_pfi -> 5 | R31: cm | S31: =(a_db+1.27)/MAX(p_pfi,0.000000001) -> 0.6985 | T31: =IF(ISNUMBER(S31),IF(S31>1,"NO CUMPLE",IF(S31>lim_verde,"AL LÍMITE","CUMPLE")),"N/A") -> CUMPLE | U31: —
B32: Acero | C32: A572 Gr50 | G32: C10 | K32: =IF(INDEX(CALCULO!$D$99:$M$99,10)=1,IF(INDEX(CALCULO!$D$100:$M$100,10)=1,"superior","inferior"),"—") -> — | L32: =IF(INDEX(CALCULO!$D$99:$M$99,10)=1,INDEX(CALCULO!$D$134:$M$134,10),"—") -> — | N32: Holgura de llave pfo ≥ db + 12.7 mm | O32: DG16 | P32: =IF(AND(cfg_u<>"Extendida — 1+1 (4E)",cfg_d<>"Extendida — 1+1 (4E)"),"—",a_db+1.27) -> 3.4925 | Q32: =IF(AND(cfg_u<>"Extendida — 1+1 (4E)",cfg_d<>"Extendida — 1+1 (4E)"),"—",p_pfo) -> 5 | R32: cm | S32: =IF(AND(cfg_u<>"Extendida — 1+1 (4E)",cfg_d<>"Extendida — 1+1 (4E)"),"N/A",(a_db+1.27)/MAX(p_pfo,0.000000001)) -> 0.6985 | T32: =IF(ISNUMBER(S32),IF(S32>1,"NO CUMPLE",IF(S32>lim_verde,"AL LÍMITE","CUMPLE")),"N/A") -> CUMPLE | U32: —
B33: Fy / Fu | C33: =INDEX(CATALOGOS!$N$5:$N$10,MATCH(co_acero,CATALOGOS!$M$5:$M$10,0)) -> 3515 | D33: kgf/cm² | E33: =INDEX(CATALOGOS!$O$5:$O$10,MATCH(co_acero,CATALOGOS!$M$5:$M$10,0)) -> 4570 | G33: Convención SAP2000: M3 negativo = tracción en el ala superior. Pu positivo = tracción. Filas vacías se ignoran. | N33: Borde de ≥ mínimo | O33: J3.4 | P33: =IF(AND(cfg_u<>"Extendida — 1+1 (4E)",cfg_d<>"Extendida — 1+1 (4E)"),"—",a_emin) -> 2.8575 | Q33: =IF(AND(cfg_u<>"Extendida — 1+1 (4E)",cfg_d<>"Extendida — 1+1 (4E)"),"—",p_de) -> 4 | R33: cm | S33: =IF(AND(cfg_u<>"Extendida — 1+1 (4E)",cfg_d<>"Extendida — 1+1 (4E)"),"N/A",(a_emin)/MAX(p_de,0.000000001)) -> 0.714375 | T33: =IF(ISNUMBER(S33),IF(S33>1,"NO CUMPLE",IF(S33>lim_verde,"AL LÍMITE","CUMPLE")),"N/A") -> CUMPLE | U33: —
B34: Filete / radio alma–ala (para k) | C34: 6 | D34: mm | N34: Borde lateral (bp − g)/2 ≥ mínimo | O34: J3.4 | P34: =a_emin -> 2.8575 | Q34: =(p_bp-p_g)/2 -> 4.5 | R34: cm | S34: =(a_emin)/MAX((p_bp-p_g)/2,0.000000001) -> 0.635 | T34: =IF(ISNUMBER(S34),IF(S34>1,"NO CUMPLE",IF(S34>lim_verde,"AL LÍMITE","CUMPLE")),"N/A") -> CUMPLE | U34: —
B35: Tope de columna → ala superior de viga | C35: 0 | D35: mm | G35: DETALLE DE UNA COMBINACIÓN | N35: Gramil g ≥ 2⅔·db | O35: J3.3 | P35: =8/3*a_db -> 5.9266667 | Q35: =p_g -> 11 | R35: cm | S35: =(8/3*a_db)/MAX(p_g,0.000000001) -> 0.53878788 | T35: =IF(ISNUMBER(S35),IF(S35>1,"NO CUMPLE",IF(S35>lim_verde,"AL LÍMITE","CUMPLE")),"N/A") -> CUMPLE | U35: —
B36: Pu de la columna | C36: 10 | D36: Tonf | G36: Combinación: | H36: 1.2D+1.6Lr | K36: =IFERROR(MATCH(H36,cb_nom,0),1) -> 1 | N36: Paso pb ≥ 2⅔·db | O36: J3.3 | P36: =IF(AND(cfg_u<>"Al ras — 2 filas (4 pernos)",cfg_d<>"Al ras — 2 filas (4 pernos)"),"—",8/3*a_db) -> — | Q36: =IF(AND(cfg_u<>"Al ras — 2 filas (4 pernos)",cfg_d<>"Al ras — 2 filas (4 pernos)"),"—",p_pb) -> — | R36: cm | S36: =IF(AND(cfg_u<>"Al ras — 2 filas (4 pernos)",cfg_d<>"Al ras — 2 filas (4 pernos)"),"N/A",(8/3*a_db)/MAX(p_pb,0.000000001)) -> N/A | T36: =IF(ISNUMBER(S36),IF(S36>1,"NO CUMPLE",IF(S36>lim_verde,"AL LÍMITE","CUMPLE")),"N/A") -> N/A | U36: —
B37: Rigidizadores de continuidad | C37: Sí | G37: Lado en tracción | J37: =IF(INDEX(CALCULO!$D$100:$M$100,det_k)=1,"superior","inferior") -> superior | N37: Segunda fila interior dentro del alma (h2 > dp/2) | O37: Geometría | P37: =IF(AND(cfg_u<>"Al ras — 2 filas (4 pernos)",cfg_d<>"Al ras — 2 filas (4 pernos)"),"—",b_dp/2) -> — | Q37: =IF(AND(cfg_u<>"Al ras — 2 filas (4 pernos)",cfg_d<>"Al ras — 2 filas (4 pernos)"),"—",h_i2) -> — | R37: cm | S37: =IF(AND(cfg_u<>"Al ras — 2 filas (4 pernos)",cfg_d<>"Al ras — 2 filas (4 pernos)"),"N/A",(b_dp/2)/MAX(h_i2,0.000000001)) -> N/A | T37: =IF(ISNUMBER(S37),IF(S37>1,"NO CUMPLE",IF(S37>lim_verde,"AL LÍMITE","CUMPLE")),"N/A") -> N/A | U37: —
B38: Rigid. continuidad: espesor | C38: 12 | D38: mm | G38: Configuración del lado en tracción | J38: =IF(INDEX(CALCULO!$D$100:$M$100,det_k)=1,cfg_u,cfg_d) -> Extendida — 1+1 (4E) | N38: Filete mínimo ala | O38: Tabla J2.4 | P38: =IF(sd_tipo="CJP","—",IF(MIN(vg_tf_mm,pl_tp)<=6,3,IF(MIN(vg_tf_mm,pl_tp)<=13,5,IF(MIN(vg_tf_mm,pl_tp)<=19,6,8)))) -> 5 | Q38: =IF(sd_tipo="CJP","—",sd_wf) -> 10 | R38: mm | S38: =IF(sd_tipo="CJP","N/A",(IF(MIN(vg_tf_mm,pl_tp)<=6,3,IF(MIN(vg_tf_mm,pl_tp)<=13,5,IF(MIN(vg_tf_mm,pl_tp)<=19,6,8))))/MAX(sd_wf,0.000000001)) -> 0.5 | T38: =IF(ISNUMBER(S38),IF(S38>1,"NO CUMPLE",IF(S38>lim_verde,"AL LÍMITE","CUMPLE")),"N/A") -> CUMPLE | U38: —
B39: Rigid. continuidad: ancho (c/lado) | C39: 110 | D39: mm | G39: Momento equivalente Meq (con axial) | J39: =INDEX(CALCULO!$D$103:$M$103,det_k)/100000 -> 16.336961 | L39: Tonf·m | N39: Filete mínimo alma | O39: Tabla J2.4 | P39: =IF(MIN(vg_tw_mm,pl_tp)<=6,3,IF(MIN(vg_tw_mm,pl_tp)<=13,5,IF(MIN(vg_tw_mm,pl_tp)<=19,6,8))) -> 3 | Q39: =sd_ww -> 6 | R39: mm | S39: =(IF(MIN(vg_tw_mm,pl_tp)<=6,3,IF(MIN(vg_tw_mm,pl_tp)<=13,5,IF(MIN(vg_tw_mm,pl_tp)<=19,6,8))))/MAX(sd_ww,0.000000001) -> 0.5 | T39: =IF(ISNUMBER(S39),IF(S39>1,"NO CUMPLE",IF(S39>lim_verde,"AL LÍMITE","CUMPLE")),"N/A") -> CUMPLE | U39: —
B40: Placa de refuerzo del alma (doubler) | C40: 0 | D40: mm | G40: Fuerza en el ala Ffu | J40: =INDEX(CALCULO!$D$104:$M$104,det_k)/1000 -> 27.361846 | L40: Tonf | N40: Rigid. continuidad: b + tcw/2 ≥ bf/3 | O40: J10.8 | P40: =IF(OR(t_rod=0,cp_usar="No"),"—",b_bf/3-c_tw/2) -> 5.5 | Q40: =IF(OR(t_rod=0,cp_usar="No"),"—",cp_b/10) -> 11 | R40: cm | S40: =IF(OR(t_rod=0,cp_usar="No"),"N/A",(b_bf/3-c_tw/2)/MAX(cp_b/10,0.000000001)) -> 0.5 | T40: =IF(ISNUMBER(S40),IF(S40>1,"NO CUMPLE",IF(S40>lim_verde,"AL LÍMITE","CUMPLE")),"N/A") -> CUMPLE | U40: —
B41: 3. PLACA EXTREMA | G41: Corte en el plano de la placa Vp | J41: =INDEX(CALCULO!$D$102:$M$102,det_k)/1000 -> 7.0958431 | L41: Tonf | N41: Rigid. continuidad: t ≥ tf/2 | O41: J10.8 | P41: =IF(OR(t_rod=0,cp_usar="No"),"—",b_tf/2) -> 0.6 | Q41: =IF(OR(t_rod=0,cp_usar="No"),"—",cp_t/10) -> 1.2 | R41: cm | S41: =IF(OR(t_rod=0,cp_usar="No"),"N/A",(b_tf/2)/MAX(cp_t/10,0.000000001)) -> 0.5 | T41: =IF(ISNUMBER(S41),IF(S41>1,"NO CUMPLE",IF(S41>lim_verde,"AL LÍMITE","CUMPLE")),"N/A") -> CUMPLE | U41: —
B42: Acero | C42: A572 Gr50 | G42: ="db requerido (provisto "&TEXT(a_db*10,"0.0")&" mm)" -> db requerido (provisto 22.2 mm) | J42: =INDEX(CALCULO!$D$105:$M$105,det_k) -> 13.546712 | L42: mm | N42: Placa dentro del ala de columna: bp ≤ bcf | O42: Geometría | P42: =IF(t_rod=0,"—",p_bp) -> 20 | Q42: =IF(t_rod=0,"—",c_bf) -> 25 | R42: cm | S42: =IF(t_rod=0,"N/A",(p_bp)/MAX(c_bf,0.000000001)) -> 0.8 | T42: =IF(ISNUMBER(S42),IF(S42>1,"NO CUMPLE",IF(S42>lim_verde,"AL LÍMITE","CUMPLE")),"N/A") -> CUMPLE | U42: —
...

Sheet CALCULO
A1: HOJA DE CÁLCULO — memoria detallada (no editar)
A2: Unidades: kgf, cm. Placa gruesa (DG16/DG4): la placa se dimensiona para 1.11·γr·φ·Mnp, así los pernos no tienen efecto palanca. γr = 1.25 al ras, 1.00 extendida (DG16).
A4: 0. GEOMETRÍA Y MATERIALES
A5: rodilla | B5: 1 = rodilla ; 0 = cumbrera | C5: - | D5: =IF(LEFT(tipo,3)="Rod",1,0) -> 1
A6: E | B6: Módulo de elasticidad | C6: kgf/cm² | D6: =2040000 -> 2040000
A7: cos θ | B7: Pendiente de la viga | C7: - | D7: =COS(RADIANS(theta)) -> 0.98480775
A8: sen θ | B8: Pendiente de la viga | C8: - | D8: =SIN(RADIANS(theta)) -> 0.17364818
A9: d | B9: Peralte en la conexión (con cartela si existe), perpendicular al eje | C9: cm | D9: =IF(vg_dh>0,vg_dh,vg_d_mm)/10 -> 60
A10: bf | B10: Ancho de ala | C10: cm | D10: =vg_bf_mm/10 -> 18
A11: tw | B11: Alma | C11: cm | D11: =vg_tw_mm/10 -> 0.6
A12: tf | B12: Ala | C12: cm | D12: =vg_tf_mm/10 -> 1.2
A13: dp | B13: Peralte a lo largo de la placa = d/cos θ | C13: cm | D13: =b_d/k_cos -> 60.925597
A14: tfp | B14: Ala proyectada = tf/cos θ | C14: cm | D14: =b_tf/k_cos -> 1.2185119
A15: dc | B15: Columna | C15: cm | D15: =co_d_mm/10 -> 50
A16: bcf | B16: Columna | C16: cm | D16: =co_bf_mm/10 -> 25
A17: tcw | B17: Columna | C17: cm | D17: =co_tw_mm/10 -> 1
A18: tcf | B18: Columna | C18: cm | D18: =co_tf_mm/10 -> 1.5
A19: Ac | B19: Área de columna | C19: cm² | D19: =2*c_bf*c_tf+(c_d-2*c_tf)*c_tw -> 122
A20: kc | B20: tcf + filete | C20: cm | D20: =c_tf+co_kw/10 -> 2.1
A21: bp | B21: Ancho de placa | C21: cm | D21: =pl_bp/10 -> 20
A22: bp,ef | B22: mín(bp ; bf + 2.54) | C22: cm | D22: =MIN(p_bp,b_bf+2.54) -> 20
A23: tp | B23: Espesor | C23: cm | D23: =pl_tp/10 -> 2.5
A24: g | B24: Gramil | C24: cm | D24: =pl_g/10 -> 11
A25: pfo | B25: Ala a fila exterior | C25: cm | D25: =pl_pfo/10 -> 5
A26: pfi | B26: Ala a primera fila interior | C26: cm | D26: =pl_pfi/10 -> 5
A27: pb | B27: Entre filas interiores | C27: cm | D27: =pl_pb/10 -> 9
A28: de | B28: Fila exterior a borde | C28: cm | D28: =pl_de/10 -> 4
A29: s | B29: ½·√(bp,ef·g) | C29: cm | D29: =0.5*SQRT(p_bpe*p_g) -> 7.4161985
A30: pf,ef | B30: pfi ≤ s | C30: cm | D30: =MIN(p_pfi,p_s) -> 5
A31: h0 | B31: Fila exterior: dp − tfp/2 + pfo | C31: cm | D31: =b_dp-b_tfp/2+p_pfo -> 65.316341
A32: h1 | B32: Primera fila interior: dp − 1.5·tfp − pfi | C32: cm | D32: =b_dp-1.5*b_tfp-p_pfi -> 54.097829
A33: h2 | B33: Segunda fila interior: h1 − pb | C33: cm | D33: =h_i1-p_pb -> 45.097829
A34: db | B34: Diámetro | C34: in | D34: =INDEX(CATALOGOS!$V$5:$V$10,MATCH(pn_diam,CATALOGOS!$U$5:$U$10,0)) -> 0.875
A35: db | B35: Diámetro | C35: cm | D35: =a_dbi*2.54 -> 2.2225
A36: Ab | B36: π·db²/4 | C36: cm² | D36: =PI()*a_db^2/4 -> 3.8794791
A37: dh | B37: Agujero estándar | C37: cm | D37: =IF(a_dbi<1,a_dbi+1/16,a_dbi+1/8)*2.54 -> 2.38125
A38: Le,min | B38: Borde mínimo (J3.4) | C38: cm | D38: =INDEX(CATALOGOS!$W$5:$W$10,MATCH(pn_diam,CATALOGOS!$U$5:$U$10,0))*2.54 -> 2.8575
A39: Pt | B39: Fnt·Ab | C39: kgf | D39: =pn_Fnt*a_Ab -> 24549.344
A40: FEXX | B40: Electrodo | C40: kgf/cm² | D40: =INDEX(CATALOGOS!$Z$5:$Z$6,MATCH(sd_elec,CATALOGOS!$Y$5:$Y$6,0)) -> 4920
A41: 1U. TRACCIÓN EN EL ALA SUPERIOR (Mu < 0) — configuración del lado superior
...

Sheet CATALOGOS
A1: CATÁLOGOS — ampliables agregando filas dentro de cada rango
A3: Vigas / rafters (VK: KUBIEC; W: AISC; ARMADO: medidas manuales) | G3: Columnas (HA: KUBIEC; W: AISC; ARMADO: medidas manuales) | M3: Aceros (kgf/cm²) | Q3: Pernos pretensados (kgf/cm²) — AISC 360-16 Tabla J3.2 | U3: Diámetros — borde mín. Tabla J3.4 | Y3: Electrodo | AB3: Opción | AD3: Conexión | AF3: Configuración por lado | AH3: Soldadura ala–placa | AJ3: Espesores (mm)
A4: Viga | B4: d | C4: bf | D4: tw | E4: tf | G4: Columna | H4: d | I4: bf | J4: tw | K4: tf | M4: Acero | N4: Fy | O4: Fu | Q4: Grado | R4: Fnt | S4: Fnv | U4: Ø | V4: db (in) | W4: borde mín (in) | Y4: Electrodo | Z4: FEXX | AB4: Sí/No | AD4: Tipo | AF4: Config. | AH4: Tipo | AJ4: t
A5: ARMADO (flejes soldados) | G5: ARMADO (flejes soldados) | M5: A36 | N5: 2530 | O5: 4080 | Q5: A325-N (roscas incl.) | R5: 6328 | S5: 3797 | U5: 5/8" | V5: 0.625 | W5: 0.875 | Y5: E60XX | Z5: 4220 | AB5: Sí | AD5: Rodilla (placa al ala de columna) | AF5: Al ras — 1 fila (2 pernos) | AH5: Filete (ambos lados) | AJ5: 0
A6: VK180X100X4X6 | B6: 180 | C6: 100 | D6: 4 | E6: 6 | G6: HA200X140X6X12 | H6: 200 | I6: 140 | J6: 6 | K6: 12 | M6: A572 Gr50 | N6: 3515 | O6: 4570 | Q6: A325-X (roscas excl.) | R6: 6328 | S6: 4781 | U6: 3/4" | V6: 0.75 | W6: 1 | Y6: E70XX | Z6: 4920 | AB6: No | AD6: Cumbrera (placa a placa) | AF6: Al ras — 2 filas (4 pernos) | AH6: CJP | AJ6: 6
A7: VK200X100X4X8 | B7: 200 | C7: 100 | D7: 4 | E7: 8 | G7: HA220X160X6X12 | H7: 220 | I7: 160 | J7: 6 | K7: 12 | M7: A992 | N7: 3515 | O7: 4570 | Q7: A490-N (roscas incl.) | R7: 7945 | S7: 4781 | U7: 7/8" | V7: 0.875 | W7: 1.125 | AF7: Extendida — 1+1 (4E) | AJ7: 8
A8: VK220X110X4X8 | B8: 220 | C8: 110 | D8: 4 | E8: 8 | G8: HA240X180X6X12 | H8: 240 | I8: 180 | J8: 6 | K8: 12 | M8: A588 Gr50 | N8: 3515 | O8: 4920 | Q8: A490-X (roscas excl.) | R8: 7945 | S8: 5906 | U8: 1" | V8: 1 | W8: 1.25 | AJ8: 10
A9: VK250X130X4X8 | B9: 250 | C9: 130 | D9: 4 | E9: 8 | G9: HA260X180X6X12 | H9: 260 | I9: 180 | J9: 6 | K9: 12 | U9: 1-1/8" | V9: 1.125 | W9: 1.5 | AJ9: 12
A10: VK270X140X4X8 | B10: 270 | C10: 140 | D10: 4 | E10: 8 | G10: HA280X180X6X12 | H10: 280 | I10: 180 | J10: 6 | K10: 12 | U10: 1-1/4" | V10: 1.25 | W10: 1.625 | AJ10: 15
A11: VK300X150X4X10 | B11: 300 | C11: 150 | D11: 4 | E11: 10 | G11: HA300X180X6X12 | H11: 300 | I11: 180 | J11: 6 | K11: 12 | AJ11: 16
A12: VK330X160X6X10 | B12: 330 | C12: 160 | D12: 6 | E12: 10 | G12: HA320X180X6X12 | H12: 320 | I12: 180 | J12: 6 | K12: 12 | AJ12: 19
A13: VK360X180X6X10 | B13: 360 | C13: 180 | D13: 6 | E13: 10 | G13: HA340X180X6X12 | H13: 340 | I13: 180 | J13: 6 | K13: 12 | AJ13: 20
A14: VK380X180X6X10 | B14: 380 | C14: 180 | D14: 6 | E14: 10 | G14: HA360X180X6X12 | H14: 360 | I14: 180 | J14: 6 | K14: 12 | AJ14: 22
A15: VK400X180X6X10 | B15: 400 | C15: 180 | D15: 6 | E15: 10 | G15: HA380X200X8X15 | H15: 380 | I15: 200 | J15: 8 | K15: 15 | AJ15: 25
A16: VK400X180X6X12 | B16: 400 | C16: 180 | D16: 6 | E16: 12 | G16: HA400X200X8X15 | H16: 400 | I16: 200 | J16: 8 | K16: 15 | AJ16: 28
A17: VK420X180X6X12 | B17: 420 | C17: 180 | D17: 6 | E17: 12 | G17: HA420X210X8X15 | H17: 420 | I17: 210 | J17: 8 | K17: 15 | AJ17: 30
A18: VK440X180X6X12 | B18: 440 | C18: 180 | D18: 6 | E18: 12 | G18: HA440X220X8X15 | H18: 440 | I18: 220 | J18: 8 | K18: 15 | AJ18: 32
A19: W12X26 | B19: 310 | C19: 165 | D19: 5.8 | E19: 9.7 | G19: HA460X230X8X15 | H19: 460 | I19: 230 | J19: 8 | K19: 15 | AJ19: 35
A20: W14X30 | B20: 351 | C20: 171 | D20: 6.9 | E20: 9.8 | G20: HA480X240X8X15 | H20: 480 | I20: 240 | J20: 8 | K20: 15 | AJ20: 38
A21: W16X31 | B21: 403 | C21: 140 | D21: 7 | E21: 11.2 | G21: HA500X250X10X15 | H21: 500 | I21: 250 | J21: 10 | K21: 15 | AJ21: 40
A22: W18X35 | B22: 450 | C22: 152 | D22: 7.6 | E22: 10.8 | G22: HA520X260X10X15 | H22: 520 | I22: 260 | J22: 10 | K22: 15
A23: W21X44 | B23: 525 | C23: 165 | D23: 8.9 | E23: 11.4 | G23: HA540X270X10X15 | H23: 540 | I23: 270 | J23: 10 | K23: 15
G24: W10X49 | H24: 254 | I24: 254 | J24: 8.6 | K24: 14.2
G25: W12X65 | H25: 308 | I25: 305 | J25: 9.9 | K25: 15.4
G26: W14X90 | H26: 356 | I26: 368 | J26: 11.2 | K26: 18

Sheet DIBUJO
A1: Coordenadas de las vistas (normalizadas a ±1). No editar.
D2: Placa | G2: Viga | J2: Pernos sup. | M2: Pernos inf. | P2: Columna | S2: Ala int. | V2: Ala ext. | Y2: Placa | AB2: Placa gemela | AE2: Ala sup der | AH2: Ala inf der | AK2: Ala sup izq | AN2: Ala inf izq | AQ2: Cont. sup | AT2: Cont. inf | AW2: Pernos L
A3: Extensión superior | B3: =IF(cfg_u="Extendida — 1+1 (4E)",p_pfo+p_de,0) -> 9
A4: Extensión inferior | B4: =IF(cfg_d="Extendida — 1+1 (4E)",p_pfo+p_de,0) -> 0 | D4: =(-p_bp/2)/dSf -> -0.26483176 | E4: =((dYb)-dYc)/dSf -> -0.92592593 | G4: =(-b_bf/2)/dSf -> -0.23834858 | H4: =((b_dp/2)-dYc)/dSf -> 0.68757735 | J4: =(-p_g/2)/dSf -> -0.14565747 | K4: =(((IF(cfg_u="Extendida — 1+1 (4E)",b_dp/2+p_pfo,b_dp/2-b_tfp-p_pfi)))-dYc)/dSf -> 0.81999322 | M4: =(-p_g/2)/dSf -> -0.14565747 | N4: =((-(IF(cfg_d="Extendida — 1+1 (4E)",b_dp/2+p_pfo,b_dp/2-b_tfp-p_pfi)))-dYc)/dSf -> -0.76123998 | P4: =((-c_d*t_rod)-dxc)/dSl -> -0.95238095 | Q4: =(dYb-10)/dSl -> -0.51900335 | S4: =((-c_tf*t_rod)-dxc)/dSl -> -0.330287 | T4: =(dYb-10)/dSl -> -0.51900335 | V4: =(((-c_d+c_tf)*t_rod)-dxc)/dSl -> -0.93314093 | W4: =(dYb-10)/dSl -> -0.51900335 | Y4: =((0)-dxc)/dSl -> -0.31104698 | Z4: =(dYb)/dSl -> -0.39073655 | AB4: =((-p_tp*(1-t_rod))-dxc)/dSl -> -0.31104698 | AC4: =(dYb*(1-t_rod))/dSl -> 0 | AE4: =((p_tp)-dxc)/dSl -> -0.27898028 | AF4: =(b_dp/2)/dSl -> 0.39073655 | AH4: =((p_tp)-dxc)/dSl -> -0.27898028 | AI4: =(-b_dp/2)/dSl -> -0.39073655 | AK4: =((IF(t_rod=1,0,-p_tp))-dxc)/dSl -> -0.31104698 | AL4: =(IF(t_rod=1,0,b_dp/2))/dSl -> 0 | AN4: =((IF(t_rod=1,0,-p_tp))-dxc)/dSl -> -0.31104698 | AO4: =(IF(t_rod=1,0,-b_dp/2))/dSl -> 0 | AQ4: =(((-c_d+c_tf)*t_rod)-dxc)/dSl -> -0.93314093 | AR4: =(b_dp/2-b_tfp/2)/dSl -> 0.38292182 | AT4: =(((-c_d+c_tf)*t_rod)-dxc)/dSl -> -0.93314093 | AU4: =(-b_dp/2+b_tfp/2)/dSl -> -0.38292182 | AW4: =((IF(t_rod=1,(p_tp-c_tf)/2,0))-dxc)/dSl -> -0.30463364 | AX4: =((IF(cfg_u="Extendida — 1+1 (4E)",b_dp/2+p_pfo,b_dp/2-b_tfp-p_pfi)))/dSl -> 0.45486995
A5: y tope de placa | B5: =b_dp/2+dEu -> 39.462798 | D5: =(-p_bp/2)/dSf -> -0.26483176 | E5: =((dYt)-dYc)/dSf -> 0.92592593 | G5: =(b_bf/2)/dSf -> 0.23834858 | H5: =((b_dp/2)-dYc)/dSf -> 0.68757735 | J5: =(p_g/2)/dSf -> 0.14565747 | K5: =(((IF(cfg_u="Extendida — 1+1 (4E)",b_dp/2+p_pfo,b_dp/2-b_tfp-p_pfi)))-dYc)/dSf -> 0.81999322 | M5: =(p_g/2)/dSf -> 0.14565747 | N5: =((-(IF(cfg_d="Extendida — 1+1 (4E)",b_dp/2+p_pfo,b_dp/2-b_tfp-p_pfi)))-dYc)/dSf -> -0.76123998 | P5: =((-c_d*t_rod)-dxc)/dSl -> -0.95238095 | Q5: =(dYt+3)/dSl -> 0.5446567 | S5: =((-c_tf*t_rod)-dxc)/dSl -> -0.330287 | T5: =(dYt+3)/dSl -> 0.5446567 | V5: =(((-c_d+c_tf)*t_rod)-dxc)/dSl -> -0.93314093 | W5: =(dYt+3)/dSl -> 0.5446567 | Y5: =((0)-dxc)/dSl -> -0.31104698 | Z5: =(dYt)/dSl -> 0.50617667 | AB5: =((-p_tp*(1-t_rod))-dxc)/dSl -> -0.31104698 | AC5: =(dYt*(1-t_rod))/dSl -> 0 | AE5: =((p_tp+1*dLr)-dxc)/dSl -> 0.95238095 | AF5: =(b_dp/2+dsg*dT*dLr)/dSl -> 0.60785876 | AH5: =((p_tp+1*dLh)-dxc)/dSl -> 0.95238095 | AI5: =(-b_dp/2+dsg*dT*dLh+(b_d-dd2)/k_cos)/dSl -> 0.086876691 | AK5: =((IF(t_rod=1,0,-p_tp+-1*dLr))-dxc)/dSl -> -0.31104698 | AL5: =(IF(t_rod=1,0,b_dp/2+dsg*dT*dLr))/dSl -> 0 | AN5: =((IF(t_rod=1,0,-p_tp+-1*dLh))-dxc)/dSl -> -0.31104698 | AO5: =(IF(t_rod=1,0,-b_dp/2+dsg*dT*dLh+(b_d-dd2)/k_cos))/dSl -> 0 | AQ5: =((IF(AND(t_rod=1,cp_usar="Sí"),-c_tf,(-c_d+c_tf)*t_rod))-dxc)/dSl -> -0.330287 | AR5: =(b_dp/2-b_tfp/2)/dSl -> 0.38292182 | AT5: =((IF(AND(t_rod=1,cp_usar="Sí"),-c_tf,(-c_d+c_tf)*t_rod))-dxc)/dSl -> -0.330287 | AU5: =(-b_dp/2+b_tfp/2)/dSl -> -0.38292182 | AW5: =((IF(t_rod=1,(p_tp-c_tf)/2,0))-dxc)/dSl -> -0.30463364 | AX5: =((b_dp/2-b_tfp-p_pfi))/dSl -> 0.31097369
A6: y base de placa | B6: =-b_dp/2-dEd -> -30.462798 | D6: =(p_bp/2)/dSf -> 0.26483176 | E6: =((dYt)-dYc)/dSf -> 0.92592593 | G6: =(b_bf/2)/dSf -> 0.23834858 | H6: =((b_dp/2-b_tfp)-dYc)/dSf -> 0.65530728 | J6: =(-p_g/2)/dSf -> -0.14565747 | K6: =(((b_dp/2-b_tfp-p_pfi))-dYc)/dSf -> 0.5228914 | M6: =(-p_g/2)/dSf -> -0.14565747 | N6: =((-(b_dp/2-b_tfp-p_pfi))-dYc)/dSf -> -0.76123998 | P6: =((-0.0001*t_rod)-dxc)/dSl -> -0.31104826 | Q6: =(dYt+3)/dSl -> 0.5446567 | Y6: =((p_tp)-dxc)/dSl -> -0.27898028 | Z6: =(dYt)/dSl -> 0.50617667 | AB6: =((0)-dxc)/dSl -> -0.31104698 | AC6: =(dYt*(1-t_rod))/dSl -> 0 | AH6: =((p_tp+1*dLr)-dxc)/dSl -> 0.95238095 | AI6: =(-b_dp/2+dsg*dT*dLr+(b_d-dd2)/k_cos)/dSl -> 0.086876691 | AN6: =((IF(t_rod=1,0,-p_tp+-1*dLr))-dxc)/dSl -> -0.31104698 | AO6: =(IF(t_rod=1,0,-b_dp/2+dsg*dT*dLr+(b_d-dd2)/k_cos))/dSl -> 0 | AW6: =((IF(t_rod=1,(p_tp-c_tf)/2,0))-dxc)/dSl -> -0.30463364 | AX6: =((IF(cfg_u="Al ras — 2 filas (4 pernos)",b_dp/2-b_tfp-p_pfi-p_pb,b_dp/2-b_tfp-p_pfi)))/dSl -> 0.31097369
A7: S frontal | B7: =MAX(dYt-dYb,p_bp)/2*1.08 -> 37.759822 | D7: =(p_bp/2)/dSf -> 0.26483176 | E7: =((dYb)-dYc)/dSf -> -0.92592593 | G7: =(b_tw/2)/dSf -> 0.0079449527 | H7: =((b_dp/2-b_tfp)-dYc)/dSf -> 0.65530728 | J7: =(p_g/2)/dSf -> 0.14565747 | K7: =(((b_dp/2-b_tfp-p_pfi))-dYc)/dSf -> 0.5228914 | M7: =(p_g/2)/dSf -> 0.14565747 | N7: =((-(b_dp/2-b_tfp-p_pfi))-dYc)/dSf -> -0.76123998 | P7: =((-0.0001*t_rod)-dxc)/dSl -> -0.31104826 | Q7: =(dYb-10)/dSl -> -0.51900335 | Y7: =((p_tp)-dxc)/dSl -> -0.27898028 | Z7: =(dYb)/dSl -> -0.39073655 | AB7: =((0)-dxc)/dSl -> -0.31104698 | AC7: =(dYb*(1-t_rod))/dSl -> 0 | AW7: =((IF(t_rod=1,(p_tp-c_tf)/2,0))-dxc)/dSl -> -0.30463364 | AX7: =(-(IF(cfg_d="Extendida — 1+1 (4E)",b_dp/2+p_pfo,b_dp/2-b_tfp-p_pfi)))/dSl -> -0.31097369
A8: y centro | B8: =(dYt+dYb)/2 -> 4.5 | D8: =(-p_bp/2)/dSf -> -0.26483176 | E8: =((dYb)-dYc)/dSf -> -0.92592593 | G8: =(b_tw/2)/dSf -> 0.0079449527 | H8: =((-b_dp/2+b_tfp)-dYc)/dSf -> -0.89365586 | J8: =(-p_g/2)/dSf -> -0.14565747 | K8: =(((IF(cfg_u="Al ras — 2 filas (4 pernos)",b_dp/2-b_tfp-p_pfi-p_pb,b_dp/2-b_tfp-p_pfi)))-dYc)/dSf -> 0.5228914 | M8: =(-p_g/2)/dSf -> -0.14565747 | N8: =((-(IF(cfg_d="Al ras — 2 filas (4 pernos)",b_dp/2-b_tfp-p_pfi-p_pb,b_dp/2-b_tfp-p_pfi)))-dYc)/dSf -> -0.76123998 | P8: =((-c_d*t_rod)-dxc)/dSl -> -0.95238095 | Q8: =(dYb-10)/dSl -> -0.51900335 | Y8: =((0)-dxc)/dSl -> -0.31104698 | Z8: =(dYb)/dSl -> -0.39073655 | AB8: =((-p_tp*(1-t_rod))-dxc)/dSl -> -0.31104698 | AC8: =(dYb*(1-t_rod))/dSl -> 0 | AW8: =((IF(t_rod=1,(p_tp-c_tf)/2,0))-dxc)/dSl -> -0.30463364 | AX8: =(-(b_dp/2-b_tfp-p_pfi))/dSl -> -0.31097369
A9: Largo de viga dibujado | B9: =MAX(1.6*b_d,vg_Lh/10*0.6) -> 96 | G9: =(b_bf/2)/dSf -> 0.23834858 | H9: =((-b_dp/2+b_tfp)-dYc)/dSf -> -0.89365586 | J9: =(p_g/2)/dSf -> 0.14565747 | K9: =(((IF(cfg_u="Al ras — 2 filas (4 pernos)",b_dp/2-b_tfp-p_pfi-p_pb,b_dp/2-b_tfp-p_pfi)))-dYc)/dSf -> 0.5228914 | M9: =(p_g/2)/dSf -> 0.14565747 | N9: =((-(IF(cfg_d="Al ras — 2 filas (4 pernos)",b_dp/2-b_tfp-p_pfi-p_pb,b_dp/2-b_tfp-p_pfi)))-dYc)/dSf -> -0.76123998 | AW9: =((IF(t_rod=1,(p_tp-c_tf)/2,0))-dxc)/dSl -> -0.30463364 | AX9: =(-(IF(cfg_d="Al ras — 2 filas (4 pernos)",b_dp/2-b_tfp-p_pfi-p_pb,b_dp/2-b_tfp-p_pfi)))/dSl -> -0.31097369
A10: tan θ | B10: =TAN(RADIANS(theta)) -> 0.17632698 | G10: =(b_bf/2)/dSf -> 0.23834858 | H10: =((-b_dp/2)-dYc)/dSf -> -0.92592593
A11: x inicio (izquierda) | B11: =IF(t_rod=1,-c_d,-p_tp-dLr) -> -50 | G11: =(-b_bf/2)/dSf -> -0.23834858 | H11: =((-b_dp/2)-dYc)/dSf -> -0.92592593
A12: x fin (derecha) | B12: =p_tp+dLr -> 98.5 | G12: =(-b_bf/2)/dSf -> -0.23834858 | H12: =((-b_dp/2+b_tfp)-dYc)/dSf -> -0.89365586
A13: signo pendiente a la derecha (+ sube en rodilla, − baja en cumbrera) | B13: =IF(t_rod=1,1,-1) -> 1 | G13: =(-b_tw/2)/dSf -> -0.0079449527 | H13: =((-b_dp/2+b_tfp)-dYc)/dSf -> -0.89365586
A14: y extrema | B14: =MAX(ABS(dYt),ABS(dYb))+dLr*dT -> 56.390189 | G14: =(-b_tw/2)/dSf -> -0.0079449527 | H14: =((b_dp/2-b_tfp)-dYc)/dSf -> 0.65530728
A15: S lateral | B15: =MAX(dx1-dx0,2*dym)/2*1.05 -> 77.9625 | G15: =(-b_bf/2)/dSf -> -0.23834858 | H15: =((b_dp/2-b_tfp)-dYc)/dSf -> 0.65530728
A16: x centro lateral | B16: =(dx0+dx1)/2 -> 24.25 | G16: =(-b_bf/2)/dSf -> -0.23834858 | H16: =((b_dp/2)-dYc)/dSf -> 0.68757735
A17: Peralte del rafter fuera de la cartela | B17: =vg_d_mm/10 -> 40
A18: Largo cartela dibujado | B18: =IF(vg_dh>0,MIN(vg_Lh/10,dLr),0.001) -> 96
